Workbook

Sheet Dashboard
A1: 💰 Personal Finance Command Center
A3: 📊 BUDGET SUMMARY | H3: 💾 SAVINGS SNAPSHOT
A4: Annual Income | H4: Emergency Fund Goal
A5: Monthly Income | D5: =IFERROR(D4/12,0) | H5: Current Emergency Fund
A6: Total Monthly Expenses | D6: =IFERROR(Jan!G50,0) | H6: % Funded | K6: =IFERROR(H5/H4,0)
A7: Left to Spend | D7: =IFERROR(D5-D6,0) | G7: ← red if negative | H7: Monthly Savings Target
A8: Annual Savings Rate % | D8: =IFERROR(D8/D4,0) | H8: YTD Savings | K8: =IFERROR(Jan!G48,0)
A9: YTD Savings | D9: =IFERROR(Jan!G48,0)
A12: 🏆 TOP SPENDING CATEGORIES (Current Month) | H12: 📆 BILLS DUE THIS MONTH
A13: Category | B13: Budgeted | C13: Actual | D13: Difference | E13: % Used | F13: Notes | H13: Bill | I13: Amount | J13: Due | K13: Auto-Pay? | L13: Status
A14: 🏠 Housing | C14: =IFERROR(Jan!D18,0) | D14: =IFERROR(Jan!E18,0) | E14: =IFERROR(C14-D14,0) | F14: =IFERROR(D14/C14,0) | H14: =IFERROR('Bill Calendar'!A3,"") | I14: =IFERROR('Bill Calendar'!C3,0) | J14: =IFERROR('Bill Calendar'!D3,"") | K14: =IFERROR('Bill Calendar'!F3,"") | L14: =IFERROR('Bill Calendar'!G3,"")
A15: 🚗 Transport | C15: =IFERROR(Jan!D24,0) | D15: =IFERROR(Jan!E24,0) | E15: =IFERROR(C15-D15,0) | F15: =IFERROR(D15/C15,0) | H15: =IFERROR('Bill Calendar'!A4,"") | I15: =IFERROR('Bill Calendar'!C4,0) | J15: =IFERROR('Bill Calendar'!D4,"") | K15: =IFERROR('Bill Calendar'!F4,"") | L15: =IFERROR('Bill Calendar'!G4,"")
A16: 🛒 Food | C16: =IFERROR(Jan!D30,0) | D16: =IFERROR(Jan!E30,0) | E16: =IFERROR(C16-D16,0) | F16: =IFERROR(D16/C16,0) | H16: =IFERROR('Bill Calendar'!A5,"") | I16: =IFERROR('Bill Calendar'!C5,0) | J16: =IFERROR('Bill Calendar'!D5,"") | K16: =IFERROR('Bill Calendar'!F5,"") | L16: =IFERROR('Bill Calendar'!G5,"")
A17: 🏥 Health | C17: =IFERROR(Jan!D36,0) | D17: =IFERROR(Jan!E36,0) | E17: =IFERROR(C17-D17,0) | F17: =IFERROR(D17/C17,0) | H17: =IFERROR('Bill Calendar'!A6,"") | I17: =IFERROR('Bill Calendar'!C6,0) | J17: =IFERROR('Bill Calendar'!D6,"") | K17: =IFERROR('Bill Calendar'!F6,"") | L17: =IFERROR('Bill Calendar'!G6,"")
A18: 🎬 Lifestyle | C18: =IFERROR(Jan!D42,0) | D18: =IFERROR(Jan!E42,0) | E18: =IFERROR(C18-D18,0) | F18: =IFERROR(D18/C18,0) | H18: =IFERROR('Bill Calendar'!A7,"") | I18: =IFERROR('Bill Calendar'!C7,0) | J18: =IFERROR('Bill Calendar'!D7,"") | K18: =IFERROR('Bill Calendar'!F7,"") | L18: =IFERROR('Bill Calendar'!G7,"")
A22: [ Insert Chart Here: Monthly Income vs Expenses ]

Sheet Jan
A1: 📅 Monthly Budget — January
A2: Category | B2: Subcategory | C2: Budgeted | D2: Actual | E2: Difference | F2: % Used | G2: Notes
A3: 💵 INCOME
A4: Income | B4: Primary Income | E4: =IFERROR(C4-D4,0) | F4: =IFERROR(D4/C4,0)
A5: Income | B5: Side Income | E5: =IFERROR(C5-D5,0) | F5: =IFERROR(D5/C5,0)
A6: Income | B6: Other Income | E6: =IFERROR(C6-D6,0) | F6: =IFERROR(D6/C6,0)
A7: TOTAL INCOME | C7: =SUM(C4:C6) | D7: =SUM(D4:D6) | E7: =IFERROR(C7-D7,0) | F7: =IFERROR(D7/C7,0)
A8: 🏠 HOUSING
A9: HOUSING | B9: Rent/Mortgage | E9: =IFERROR(C9-D9,0) | F9: =IFERROR(D9/C9,0)
A10: HOUSING | B10: Utilities | E10: =IFERROR(C10-D10,0) | F10: =IFERROR(D10/C10,0)
A11: HOUSING | B11: Internet | E11: =IFERROR(C11-D11,0) | F11: =IFERROR(D11/C11,0)
A12: HOUSING | B12: Renter's Insurance | E12: =IFERROR(C12-D12,0) | F12: =IFERROR(D12/C12,0)
A13: Subtotal 🏠 HOUSING | C13: =SUM(C9:C12) | D13: =SUM(D9:D12) | E13: =IFERROR(C13-D13,0) | F13: =IFERROR(D13/C13,0)
A14: 🚗 TRANSPORT
A15: TRANSPORT | B15: Car Payment | E15: =IFERROR(C15-D15,0) | F15: =IFERROR(D15/C15,0)
A16: TRANSPORT | B16: Gas | E16: =IFERROR(C16-D16,0) | F16: =IFERROR(D16/C16,0)
A17: TRANSPORT | B17: Insurance | E17: =IFERROR(C17-D17,0) | F17: =IFERROR(D17/C17,0)
A18: TRANSPORT | B18: Parking | E18: =IFERROR(C18-D18,0) | F18: =IFERROR(D18/C18,0)
A19: TRANSPORT | B19: Public Transit | E19: =IFERROR(C19-D19,0) | F19: =IFERROR(D19/C19,0)
A20: Subtotal 🚗 TRANSPORT | C20: =SUM(C15:C19) | D20: =SUM(D15:D19) | E20: =IFERROR(C20-D20,0) | F20: =IFERROR(D20/C20,0)
A21: 🛒 FOOD
A22: FOOD | B22: Groceries | E22: =IFERROR(C22-D22,0) | F22: =IFERROR(D22/C22,0)
A23: FOOD | B23: Dining Out | E23: =IFERROR(C23-D23,0) | F23: =IFERROR(D23/C23,0)
A24: FOOD | B24: Coffee Shops | E24: =IFERROR(C24-D24,0) | F24: =IFERROR(D24/C24,0)
A25: FOOD | B25: Meal Delivery | E25: =IFERROR(C25-D25,0) | F25: =IFERROR(D25/C25,0)
A26: Subtotal 🛒 FOOD | C26: =SUM(C22:C25) | D26: =SUM(D22:D25) | E26: =IFERROR(C26-D26,0) | F26: =IFERROR(D26/C26,0)
A27: 🏥 HEALTH
A28: HEALTH | B28: Health Insurance | E28: =IFERROR(C28-D28,0) | F28: =IFERROR(D28/C28,0)
A29: HEALTH | B29: Gym | E29: =IFERROR(C29-D29,0) | F29: =IFERROR(D29/C29,0)
A30: HEALTH | B30: Pharmacy | E30: =IFERROR(C30-D30,0) | F30: =IFERROR(D30/C30,0)
A31: HEALTH | B31: Doctor Visits | E31: =IFERROR(C31-D31,0) | F31: =IFERROR(D31/C31,0)
A32: Subtotal 🏥 HEALTH | C32: =SUM(C28:C31) | D32: =SUM(D28:D31) | E32: =IFERROR(C32-D32,0) | F32: =IFERROR(D32/C32,0)
A33: 🎬 LIFESTYLE
A34: LIFESTYLE | B34: Subscriptions | E34: =IFERROR(C34-D34,0) | F34: =IFERROR(D34/C34,0)
A35: LIFESTYLE | B35: Entertainment | E35: =IFERROR(C35-D35,0) | F35: =IFERROR(D35/C35,0)
A36: LIFESTYLE | B36: Hobbies | E36: =IFERROR(C36-D36,0) | F36: =IFERROR(D36/C36,0)
A37: LIFESTYLE | B37: Personal Care | E37: =IFERROR(C37-D37,0) | F37: =IFERROR(D37/C37,0)
A38: Subtotal 🎬 LIFESTYLE | C38: =SUM(C34:C37) | D38: =SUM(D34:D37) | E38: =IFERROR(C38-D38,0) | F38: =IFERROR(D38/C38,0)
A39: 👔 PERSONAL
A40: PERSONAL | B40: Clothing | E40: =IFERROR(C40-D40,0) | F40: =IFERROR(D40/C40,0)
...

Sheet Feb
A1: 📅 Monthly Budget — February
A2: Category | B2: Subcategory | C2: Budgeted | D2: Actual | E2: Difference | F2: % Used | G2: Notes
A3: 💵 INCOME
A4: Income | B4: Primary Income | E4: =IFERROR(C4-D4,0) | F4: =IFERROR(D4/C4,0)
A5: Income | B5: Side Income | E5: =IFERROR(C5-D5,0) | F5: =IFERROR(D5/C5,0)
A6: Income | B6: Other Income | E6: =IFERROR(C6-D6,0) | F6: =IFERROR(D6/C6,0)
A7: TOTAL INCOME | C7: =SUM(C4:C6) | D7: =SUM(D4:D6) | E7: =IFERROR(C7-D7,0) | F7: =IFERROR(D7/C7,0)
A8: 🏠 HOUSING
A9: HOUSING | B9: Rent/Mortgage | E9: =IFERROR(C9-D9,0) | F9: =IFERROR(D9/C9,0)
A10: HOUSING | B10: Utilities | E10: =IFERROR(C10-D10,0) | F10: =IFERROR(D10/C10,0)
A11: HOUSING | B11: Internet | E11: =IFERROR(C11-D11,0) | F11: =IFERROR(D11/C11,0)
A12: HOUSING | B12: Renter's Insurance | E12: =IFERROR(C12-D12,0) | F12: =IFERROR(D12/C12,0)
A13: Subtotal 🏠 HOUSING | C13: =SUM(C9:C12) | D13: =SUM(D9:D12) | E13: =IFERROR(C13-D13,0) | F13: =IFERROR(D13/C13,0)
A14: 🚗 TRANSPORT
A15: TRANSPORT | B15: Car Payment | E15: =IFERROR(C15-D15,0) | F15: =IFERROR(D15/C15,0)
A16: TRANSPORT | B16: Gas | E16: =IFERROR(C16-D16,0) | F16: =IFERROR(D16/C16,0)
A17: TRANSPORT | B17: Insurance | E17: =IFERROR(C17-D17,0) | F17: =IFERROR(D17/C17,0)
A18: TRANSPORT | B18: Parking | E18: =IFERROR(C18-D18,0) | F18: =IFERROR(D18/C18,0)
A19: TRANSPORT | B19: Public Transit | E19: =IFERROR(C19-D19,0) | F19: =IFERROR(D19/C19,0)
A20: Subtotal 🚗 TRANSPORT | C20: =SUM(C15:C19) | D20: =SUM(D15:D19) | E20: =IFERROR(C20-D20,0) | F20: =IFERROR(D20/C20,0)
A21: 🛒 FOOD
A22: FOOD | B22: Groceries | E22: =IFERROR(C22-D22,0) | F22: =IFERROR(D22/C22,0)
A23: FOOD | B23: Dining Out | E23: =IFERROR(C23-D23,0) | F23: =IFERROR(D23/C23,0)
A24: FOOD | B24: Coffee Shops | E24: =IFERROR(C24-D24,0) | F24: =IFERROR(D24/C24,0)
A25: FOOD | B25: Meal Delivery | E25: =IFERROR(C25-D25,0) | F25: =IFERROR(D25/C25,0)
A26: Subtotal 🛒 FOOD | C26: =SUM(C22:C25) | D26: =SUM(D22:D25) | E26: =IFERROR(C26-D26,0) | F26: =IFERROR(D26/C26,0)
A27: 🏥 HEALTH
A28: HEALTH | B28: Health Insurance | E28: =IFERROR(C28-D28,0) | F28: =IFERROR(D28/C28,0)
A29: HEALTH | B29: Gym | E29: =IFERROR(C29-D29,0) | F29: =IFERROR(D29/C29,0)
A30: HEALTH | B30: Pharmacy | E30: =IFERROR(C30-D30,0) | F30: =IFERROR(D30/C30,0)
A31: HEALTH | B31: Doctor Visits | E31: =IFERROR(C31-D31,0) | F31: =IFERROR(D31/C31,0)
A32: Subtotal 🏥 HEALTH | C32: =SUM(C28:C31) | D32: =SUM(D28:D31) | E32: =IFERROR(C32-D32,0) | F32: =IFERROR(D32/C32,0)
A33: 🎬 LIFESTYLE
A34: LIFESTYLE | B34: Subscriptions | E34: =IFERROR(C34-D34,0) | F34: =IFERROR(D34/C34,0)
A35: LIFESTYLE | B35: Entertainment | E35: =IFERROR(C35-D35,0) | F35: =IFERROR(D35/C35,0)
A36: LIFESTYLE | B36: Hobbies | E36: =IFERROR(C36-D36,0) | F36: =IFERROR(D36/C36,0)
A37: LIFESTYLE | B37: Personal Care | E37: =IFERROR(C37-D37,0) | F37: =IFERROR(D37/C37,0)
A38: Subtotal 🎬 LIFESTYLE | C38: =SUM(C34:C37) | D38: =SUM(D34:D37) | E38: =IFERROR(C38-D38,0) | F38: =IFERROR(D38/C38,0)
A39: 👔 PERSONAL
A40: PERSONAL | B40: Clothing | E40: =IFERROR(C40-D40,0) | F40: =IFERROR(D40/C40,0)
...

Sheet Mar
A1: 📅 Monthly Budget — March
A2: Category | B2: Subcategory | C2: Budgeted | D2: Actual | E2: Difference | F2: % Used | G2: Notes
A3: 💵 INCOME
A4: Income | B4: Primary Income | E4: =IFERROR(C4-D4,0) | F4: =IFERROR(D4/C4,0)
A5: Income | B5: Side Income | E5: =IFERROR(C5-D5,0) | F5: =IFERROR(D5/C5,0)
A6: Income | B6: Other Income | E6: =IFERROR(C6-D6,0) | F6: =IFERROR(D6/C6,0)
A7: TOTAL INCOME | C7: =SUM(C4:C6) | D7: =SUM(D4:D6) | E7: =IFERROR(C7-D7,0) | F7: =IFERROR(D7/C7,0)
A8: 🏠 HOUSING
A9: HOUSING | B9: Rent/Mortgage | E9: =IFERROR(C9-D9,0) | F9: =IFERROR(D9/C9,0)
A10: HOUSING | B10: Utilities | E10: =IFERROR(C10-D10,0) | F10: =IFERROR(D10/C10,0)
A11: HOUSING | B11: Internet | E11: =IFERROR(C11-D11,0) | F11: =IFERROR(D11/C11,0)
A12: HOUSING | B12: Renter's Insurance | E12: =IFERROR(C12-D12,0) | F12: =IFERROR(D12/C12,0)
A13: Subtotal 🏠 HOUSING | C13: =SUM(C9:C12) | D13: =SUM(D9:D12) | E13: =IFERROR(C13-D13,0) | F13: =IFERROR(D13/C13,0)
A14: 🚗 TRANSPORT
A15: TRANSPORT | B15: Car Payment | E15: =IFERROR(C15-D15,0) | F15: =IFERROR(D15/C15,0)
A16: TRANSPORT | B16: Gas | E16: =IFERROR(C16-D16,0) | F16: =IFERROR(D16/C16,0)
A17: TRANSPORT | B17: Insurance | E17: =IFERROR(C17-D17,0) | F17: =IFERROR(D17/C17,0)
A18: TRANSPORT | B18: Parking | E18: =IFERROR(C18-D18,0) | F18: =IFERROR(D18/C18,0)
A19: TRANSPORT | B19: Public Transit | E19: =IFERROR(C19-D19,0) | F19: =IFERROR(D19/C19,0)
A20: Subtotal 🚗 TRANSPORT | C20: =SUM(C15:C19) | D20: =SUM(D15:D19) | E20: =IFERROR(C20-D20,0) | F20: =IFERROR(D20/C20,0)
A21: 🛒 FOOD
A22: FOOD | B22: Groceries | E22: =IFERROR(C22-D22,0) | F22: =IFERROR(D22/C22,0)
A23: FOOD | B23: Dining Out | E23: =IFERROR(C23-D23,0) | F23: =IFERROR(D23/C23,0)
A24: FOOD | B24: Coffee Shops | E24: =IFERROR(C24-D24,0) | F24: =IFERROR(D24/C24,0)
A25: FOOD | B25: Meal Delivery | E25: =IFERROR(C25-D25,0) | F25: =IFERROR(D25/C25,0)
A26: Subtotal 🛒 FOOD | C26: =SUM(C22:C25) | D26: =SUM(D22:D25) | E26: =IFERROR(C26-D26,0) | F26: =IFERROR(D26/C26,0)
A27: 🏥 HEALTH
A28: HEALTH | B28: Health Insurance | E28: =IFERROR(C28-D28,0) | F28: =IFERROR(D28/C28,0)
A29: HEALTH | B29: Gym | E29: =IFERROR(C29-D29,0) | F29: =IFERROR(D29/C29,0)
A30: HEALTH | B30: Pharmacy | E30: =IFERROR(C30-D30,0) | F30: =IFERROR(D30/C30,0)
A31: HEALTH | B31: Doctor Visits | E31: =IFERROR(C31-D31,0) | F31: =IFERROR(D31/C31,0)
A32: Subtotal 🏥 HEALTH | C32: =SUM(C28:C31) | D32: =SUM(D28:D31) | E32: =IFERROR(C32-D32,0) | F32: =IFERROR(D32/C32,0)
A33: 🎬 LIFESTYLE
A34: LIFESTYLE | B34: Subscriptions | E34: =IFERROR(C34-D34,0) | F34: =IFERROR(D34/C34,0)
A35: LIFESTYLE | B35: Entertainment | E35: =IFERROR(C35-D35,0) | F35: =IFERROR(D35/C35,0)
A36: LIFESTYLE | B36: Hobbies | E36: =IFERROR(C36-D36,0) | F36: =IFERROR(D36/C36,0)
A37: LIFESTYLE | B37: Personal Care | E37: =IFERROR(C37-D37,0) | F37: =IFERROR(D37/C37,0)
A38: Subtotal 🎬 LIFESTYLE | C38: =SUM(C34:C37) | D38: =SUM(D34:D37) | E38: =IFERROR(C38-D38,0) | F38: =IFERROR(D38/C38,0)
A39: 👔 PERSONAL
A40: PERSONAL | B40: Clothing | E40: =IFERROR(C40-D40,0) | F40: =IFERROR(D40/C40,0)
...

Sheet Apr
A1: 📅 Monthly Budget — April
A2: Category | B2: Subcategory | C2: Budgeted | D2: Actual | E2: Difference | F2: % Used | G2: Notes
A3: 💵 INCOME
A4: Income | B4: Primary Income | E4: =IFERROR(C4-D4,0) | F4: =IFERROR(D4/C4,0)
A5: Income | B5: Side Income | E5: =IFERROR(C5-D5,0) | F5: =IFERROR(D5/C5,0)
A6: Income | B6: Other Income | E6: =IFERROR(C6-D6,0) | F6: =IFERROR(D6/C6,0)
A7: TOTAL INCOME | C7: =SUM(C4:C6) | D7: =SUM(D4:D6) | E7: =IFERROR(C7-D7,0) | F7: =IFERROR(D7/C7,0)
A8: 🏠 HOUSING
A9: HOUSING | B9: Rent/Mortgage | E9: =IFERROR(C9-D9,0) | F9: =IFERROR(D9/C9,0)
A10: HOUSING | B10: Utilities | E10: =IFERROR(C10-D10,0) | F10: =IFERROR(D10/C10,0)
A11: HOUSING | B11: Internet | E11: =IFERROR(C11-D11,0) | F11: =IFERROR(D11/C11,0)
A12: HOUSING | B12: Renter's Insurance | E12: =IFERROR(C12-D12,0) | F12: =IFERROR(D12/C12,0)
A13: Subtotal 🏠 HOUSING | C13: =SUM(C9:C12) | D13: =SUM(D9:D12) | E13: =IFERROR(C13-D13,0) | F13: =IFERROR(D13/C13,0)
A14: 🚗 TRANSPORT
A15: TRANSPORT | B15: Car Payment | E15: =IFERROR(C15-D15,0) | F15: =IFERROR(D15/C15,0)
A16: TRANSPORT | B16: Gas | E16: =IFERROR(C16-D16,0) | F16: =IFERROR(D16/C16,0)
A17: TRANSPORT | B17: Insurance | E17: =IFERROR(C17-D17,0) | F17: =IFERROR(D17/C17,0)
A18: TRANSPORT | B18: Parking | E18: =IFERROR(C18-D18,0) | F18: =IFERROR(D18/C18,0)
A19: TRANSPORT | B19: Public Transit | E19: =IFERROR(C19-D19,0) | F19: =IFERROR(D19/C19,0)
A20: Subtotal 🚗 TRANSPORT | C20: =SUM(C15:C19) | D20: =SUM(D15:D19) | E20: =IFERROR(C20-D20,0) | F20: =IFERROR(D20/C20,0)
A21: 🛒 FOOD
A22: FOOD | B22: Groceries | E22: =IFERROR(C22-D22,0) | F22: =IFERROR(D22/C22,0)
A23: FOOD | B23: Dining Out | E23: =IFERROR(C23-D23,0) | F23: =IFERROR(D23/C23,0)
A24: FOOD | B24: Coffee Shops | E24: =IFERROR(C24-D24,0) | F24: =IFERROR(D24/C24,0)
A25: FOOD | B25: Meal Delivery | E25: =IFERROR(C25-D25,0) | F25: =IFERROR(D25/C25,0)
A26: Subtotal 🛒 FOOD | C26: =SUM(C22:C25) | D26: =SUM(D22:D25) | E26: =IFERROR(C26-D26,0) | F26: =IFERROR(D26/C26,0)
A27: 🏥 HEALTH
A28: HEALTH | B28: Health Insurance | E28: =IFERROR(C28-D28,0) | F28: =IFERROR(D28/C28,0)
A29: HEALTH | B29: Gym | E29: =IFERROR(C29-D29,0) | F29: =IFERROR(D29/C29,0)
A30: HEALTH | B30: Pharmacy | E30: =IFERROR(C30-D30,0) | F30: =IFERROR(D30/C30,0)
A31: HEALTH | B31: Doctor Visits | E31: =IFERROR(C31-D31,0) | F31: =IFERROR(D31/C31,0)
A32: Subtotal 🏥 HEALTH | C32: =SUM(C28:C31) | D32: =SUM(D28:D31) | E32: =IFERROR(C32-D32,0) | F32: =IFERROR(D32/C32,0)
A33: 🎬 LIFESTYLE
A34: LIFESTYLE | B34: Subscriptions | E34: =IFERROR(C34-D34,0) | F34: =IFERROR(D34/C34,0)
A35: LIFESTYLE | B35: Entertainment | E35: =IFERROR(C35-D35,0) | F35: =IFERROR(D35/C35,0)
A36: LIFESTYLE | B36: Hobbies | E36: =IFERROR(C36-D36,0) | F36: =IFERROR(D36/C36,0)
A37: LIFESTYLE | B37: Personal Care | E37: =IFERROR(C37-D37,0) | F37: =IFERROR(D37/C37,0)
A38: Subtotal 🎬 LIFESTYLE | C38: =SUM(C34:C37) | D38: =SUM(D34:D37) | E38: =IFERROR(C38-D38,0) | F38: =IFERROR(D38/C38,0)
A39: 👔 PERSONAL
A40: PERSONAL | B40: Clothing | E40: =IFERROR(C40-D40,0) | F40: =IFERROR(D40/C40,0)
...

Sheet May
A1: 📅 Monthly Budget — May
A2: Category | B2: Subcategory | C2: Budgeted | D2: Actual | E2: Difference | F2: % Used | G2: Notes
A3: 💵 INCOME
A4: Income | B4: Primary Income | E4: =IFERROR(C4-D4,0) | F4: =IFERROR(D4/C4,0)
A5: Income | B5: Side Income | E5: =IFERROR(C5-D5,0) | F5: =IFERROR(D5/C5,0)
A6: Income | B6: Other Income | E6: =IFERROR(C6-D6,0) | F6: =IFERROR(D6/C6,0)
A7: TOTAL INCOME | C7: =SUM(C4:C6) | D7: =SUM(D4:D6) | E7: =IFERROR(C7-D7,0) | F7: =IFERROR(D7/C7,0)
A8: 🏠 HOUSING
A9: HOUSING | B9: Rent/Mortgage | E9: =IFERROR(C9-D9,0) | F9: =IFERROR(D9/C9,0)
A10: HOUSING | B10: Utilities | E10: =IFERROR(C10-D10,0) | F10: =IFERROR(D10/C10,0)
A11: HOUSING | B11: Internet | E11: =IFERROR(C11-D11,0) | F11: =IFERROR(D11/C11,0)
A12: HOUSING | B12: Renter's Insurance | E12: =IFERROR(C12-D12,0) | F12: =IFERROR(D12/C12,0)
A13: Subtotal 🏠 HOUSING | C13: =SUM(C9:C12) | D13: =SUM(D9:D12) | E13: =IFERROR(C13-D13,0) | F13: =IFERROR(D13/C13,0)
A14: 🚗 TRANSPORT
A15: TRANSPORT | B15: Car Payment | E15: =IFERROR(C15-D15,0) | F15: =IFERROR(D15/C15,0)
A16: TRANSPORT | B16: Gas | E16: =IFERROR(C16-D16,0) | F16: =IFERROR(D16/C16,0)
A17: TRANSPORT | B17: Insurance | E17: =IFERROR(C17-D17,0) | F17: =IFERROR(D17/C17,0)
A18: TRANSPORT | B18: Parking | E18: =IFERROR(C18-D18,0) | F18: =IFERROR(D18/C18,0)
A19: TRANSPORT | B19: Public Transit | E19: =IFERROR(C19-D19,0) | F19: =IFERROR(D19/C19,0)
A20: Subtotal 🚗 TRANSPORT | C20: =SUM(C15:C19) | D20: =SUM(D15:D19) | E20: =IFERROR(C20-D20,0) | F20: =IFERROR(D20/C20,0)
A21: 🛒 FOOD
A22: FOOD | B22: Groceries | E22: =IFERROR(C22-D22,0) | F22: =IFERROR(D22/C22,0)
A23: FOOD | B23: Dining Out | E23: =IFERROR(C23-D23,0) | F23: =IFERROR(D23/C23,0)
A24: FOOD | B24: Coffee Shops | E24: =IFERROR(C24-D24,0) | F24: =IFERROR(D24/C24,0)
A25: FOOD | B25: Meal Delivery | E25: =IFERROR(C25-D25,0) | F25: =IFERROR(D25/C25,0)
A26: Subtotal 🛒 FOOD | C26: =SUM(C22:C25) | D26: =SUM(D22:D25) | E26: =IFERROR(C26-D26,0) | F26: =IFERROR(D26/C26,0)
A27: 🏥 HEALTH
A28: HEALTH | B28: Health Insurance | E28: =IFERROR(C28-D28,0) | F28: =IFERROR(D28/C28,0)
A29: HEALTH | B29: Gym | E29: =IFERROR(C29-D29,0) | F29: =IFERROR(D29/C29,0)
A30: HEALTH | B30: Pharmacy | E30: =IFERROR(C30-D30,0) | F30: =IFERROR(D30/C30,0)
A31: HEALTH | B31: Doctor Visits | E31: =IFERROR(C31-D31,0) | F31: =IFERROR(D31/C31,0)
A32: Subtotal 🏥 HEALTH | C32: =SUM(C28:C31) | D32: =SUM(D28:D31) | E32: =IFERROR(C32-D32,0) | F32: =IFERROR(D32/C32,0)
A33: 🎬 LIFESTYLE
A34: LIFESTYLE | B34: Subscriptions | E34: =IFERROR(C34-D34,0) | F34: =IFERROR(D34/C34,0)
A35: LIFESTYLE | B35: Entertainment | E35: =IFERROR(C35-D35,0) | F35: =IFERROR(D35/C35,0)
A36: LIFESTYLE | B36: Hobbies | E36: =IFERROR(C36-D36,0) | F36: =IFERROR(D36/C36,0)
A37: LIFESTYLE | B37: Personal Care | E37: =IFERROR(C37-D37,0) | F37: =IFERROR(D37/C37,0)
A38: Subtotal 🎬 LIFESTYLE | C38: =SUM(C34:C37) | D38: =SUM(D34:D37) | E38: =IFERROR(C38-D38,0) | F38: =IFERROR(D38/C38,0)
A39: 👔 PERSONAL
A40: PERSONAL | B40: Clothing | E40: =IFERROR(C40-D40,0) | F40: =IFERROR(D40/C40,0)
...

Sheet Jun
A1: 📅 Monthly Budget — June
A2: Category | B2: Subcategory | C2: Budgeted | D2: Actual | E2: Difference | F2: % Used | G2: Notes
A3: 💵 INCOME
A4: Income | B4: Primary Income | E4: =IFERROR(C4-D4,0) | F4: =IFERROR(D4/C4,0)
A5: Income | B5: Side Income | E5: =IFERROR(C5-D5,0) | F5: =IFERROR(D5/C5,0)
A6: Income | B6: Other Income | E6: =IFERROR(C6-D6,0) | F6: =IFERROR(D6/C6,0)
A7: TOTAL INCOME | C7: =SUM(C4:C6) | D7: =SUM(D4:D6) | E7: =IFERROR(C7-D7,0) | F7: =IFERROR(D7/C7,0)
A8: 🏠 HOUSING
A9: HOUSING | B9: Rent/Mortgage | E9: =IFERROR(C9-D9,0) | F9: =IFERROR(D9/C9,0)
A10: HOUSING | B10: Utilities | E10: =IFERROR(C10-D10,0) | F10: =IFERROR(D10/C10,0)
A11: HOUSING | B11: Internet | E11: =IFERROR(C11-D11,0) | F11: =IFERROR(D11/C11,0)
A12: HOUSING | B12: Renter's Insurance | E12: =IFERROR(C12-D12,0) | F12: =IFERROR(D12/C12,0)
A13: Subtotal 🏠 HOUSING | C13: =SUM(C9:C12) | D13: =SUM(D9:D12) | E13: =IFERROR(C13-D13,0) | F13: =IFERROR(D13/C13,0)
A14: 🚗 TRANSPORT
A15: TRANSPORT | B15: Car Payment | E15: =IFERROR(C15-D15,0) | F15: =IFERROR(D15/C15,0)
A16: TRANSPORT | B16: Gas | E16: =IFERROR(C16-D16,0) | F16: =IFERROR(D16/C16,0)
A17: TRANSPORT | B17: Insurance | E17: =IFERROR(C17-D17,0) | F17: =IFERROR(D17/C17,0)
A18: TRANSPORT | B18: Parking | E18: =IFERROR(C18-D18,0) | F18: =IFERROR(D18/C18,0)
A19: TRANSPORT | B19: Public Transit | E19: =IFERROR(C19-D19,0) | F19: =IFERROR(D19/C19,0)
A20: Subtotal 🚗 TRANSPORT | C20: =SUM(C15:C19) | D20: =SUM(D15:D19) | E20: =IFERROR(C20-D20,0) | F20: =IFERROR(D20/C20,0)
A21: 🛒 FOOD
A22: FOOD | B22: Groceries | E22: =IFERROR(C22-D22,0) | F22: =IFERROR(D22/C22,0)
A23: FOOD | B23: Dining Out | E23: =IFERROR(C23-D23,0) | F23: =IFERROR(D23/C23,0)
A24: FOOD | B24: Coffee Shops | E24: =IFERROR(C24-D24,0) | F24: =IFERROR(D24/C24,0)
A25: FOOD | B25: Meal Delivery | E25: =IFERROR(C25-D25,0) | F25: =IFERROR(D25/C25,0)
A26: Subtotal 🛒 FOOD | C26: =SUM(C22:C25) | D26: =SUM(D22:D25) | E26: =IFERROR(C26-D26,0) | F26: =IFERROR(D26/C26,0)
A27: 🏥 HEALTH
A28: HEALTH | B28: Health Insurance | E28: =IFERROR(C28-D28,0) | F28: =IFERROR(D28/C28,0)
A29: HEALTH | B29: Gym | E29: =IFERROR(C29-D29,0) | F29: =IFERROR(D29/C29,0)
A30: HEALTH | B30: Pharmacy | E30: =IFERROR(C30-D30,0) | F30: =IFERROR(D30/C30,0)
A31: HEALTH | B31: Doctor Visits | E31: =IFERROR(C31-D31,0) | F31: =IFERROR(D31/C31,0)
A32: Subtotal 🏥 HEALTH | C32: =SUM(C28:C31) | D32: =SUM(D28:D31) | E32: =IFERROR(C32-D32,0) | F32: =IFERROR(D32/C32,0)
A33: 🎬 LIFESTYLE
A34: LIFESTYLE | B34: Subscriptions | E34: =IFERROR(C34-D34,0) | F34: =IFERROR(D34/C34,0)
A35: LIFESTYLE | B35: Entertainment | E35: =IFERROR(C35-D35,0) | F35: =IFERROR(D35/C35,0)
A36: LIFESTYLE | B36: Hobbies | E36: =IFERROR(C36-D36,0) | F36: =IFERROR(D36/C36,0)
A37: LIFESTYLE | B37: Personal Care | E37: =IFERROR(C37-D37,0) | F37: =IFERROR(D37/C37,0)
A38: Subtotal 🎬 LIFESTYLE | C38: =SUM(C34:C37) | D38: =SUM(D34:D37) | E38: =IFERROR(C38-D38,0) | F38: =IFERROR(D38/C38,0)
A39: 👔 PERSONAL
A40: PERSONAL | B40: Clothing | E40: =IFERROR(C40-D40,0) | F40: =IFERROR(D40/C40,0)
...

Sheet Jul
A1: 📅 Monthly Budget — July
A2: Category | B2: Subcategory | C2: Budgeted | D2: Actual | E2: Difference | F2: % Used | G2: Notes
A3: 💵 INCOME
A4: Income | B4: Primary Income | E4: =IFERROR(C4-D4,0) | F4: =IFERROR(D4/C4,0)
A5: Income | B5: Side Income | E5: =IFERROR(C5-D5,0) | F5: =IFERROR(D5/C5,0)
A6: Income | B6: Other Income | E6: =IFERROR(C6-D6,0) | F6: =IFERROR(D6/C6,0)
A7: TOTAL INCOME | C7: =SUM(C4:C6) | D7: =SUM(D4:D6) | E7: =IFERROR(C7-D7,0) | F7: =IFERROR(D7/C7,0)
A8: 🏠 HOUSING
A9: HOUSING | B9: Rent/Mortgage | E9: =IFERROR(C9-D9,0) | F9: =IFERROR(D9/C9,0)
A10: HOUSING | B10: Utilities | E10: =IFERROR(C10-D10,0) | F10: =IFERROR(D10/C10,0)
A11: HOUSING | B11: Internet | E11: =IFERROR(C11-D11,0) | F11: =IFERROR(D11/C11,0)
A12: HOUSING | B12: Renter's Insurance | E12: =IFERROR(C12-D12,0) | F12: =IFERROR(D12/C12,0)
A13: Subtotal 🏠 HOUSING | C13: =SUM(C9:C12) | D13: =SUM(D9:D12) | E13: =IFERROR(C13-D13,0) | F13: =IFERROR(D13/C13,0)
A14: 🚗 TRANSPORT
A15: TRANSPORT | B15: Car Payment | E15: =IFERROR(C15-D15,0) | F15: =IFERROR(D15/C15,0)
A16: TRANSPORT | B16: Gas | E16: =IFERROR(C16-D16,0) | F16: =IFERROR(D16/C16,0)
A17: TRANSPORT | B17: Insurance | E17: =IFERROR(C17-D17,0) | F17: =IFERROR(D17/C17,0)
A18: TRANSPORT | B18: Parking | E18: =IFERROR(C18-D18,0) | F18: =IFERROR(D18/C18,0)
A19: TRANSPORT | B19: Public Transit | E19: =IFERROR(C19-D19,0) | F19: =IFERROR(D19/C19,0)
A20: Subtotal 🚗 TRANSPORT | C20: =SUM(C15:C19) | D20: =SUM(D15:D19) | E20: =IFERROR(C20-D20,0) | F20: =IFERROR(D20/C20,0)
A21: 🛒 FOOD
A22: FOOD | B22: Groceries | E22: =IFERROR(C22-D22,0) | F22: =IFERROR(D22/C22,0)
A23: FOOD | B23: Dining Out | E23: =IFERROR(C23-D23,0) | F23: =IFERROR(D23/C23,0)
A24: FOOD | B24: Coffee Shops | E24: =IFERROR(C24-D24,0) | F24: =IFERROR(D24/C24,0)
A25: FOOD | B25: Meal Delivery | E25: =IFERROR(C25-D25,0) | F25: =IFERROR(D25/C25,0)
A26: Subtotal 🛒 FOOD | C26: =SUM(C22:C25) | D26: =SUM(D22:D25) | E26: =IFERROR(C26-D26,0) | F26: =IFERROR(D26/C26,0)
A27: 🏥 HEALTH
A28: HEALTH | B28: Health Insurance | E28: =IFERROR(C28-D28,0) | F28: =IFERROR(D28/C28,0)
A29: HEALTH | B29: Gym | E29: =IFERROR(C29-D29,0) | F29: =IFERROR(D29/C29,0)
A30: HEALTH | B30: Pharmacy | E30: =IFERROR(C30-D30,0) | F30: =IFERROR(D30/C30,0)
A31: HEALTH | B31: Doctor Visits | E31: =IFERROR(C31-D31,0) | F31: =IFERROR(D31/C31,0)
A32: Subtotal 🏥 HEALTH | C32: =SUM(C28:C31) | D32: =SUM(D28:D31) | E32: =IFERROR(C32-D32,0) | F32: =IFERROR(D32/C32,0)
A33: 🎬 LIFESTYLE
A34: LIFESTYLE | B34: Subscriptions | E34: =IFERROR(C34-D34,0) | F34: =IFERROR(D34/C34,0)
A35: LIFESTYLE | B35: Entertainment | E35: =IFERROR(C35-D35,0) | F35: =IFERROR(D35/C35,0)
A36: LIFESTYLE | B36: Hobbies | E36: =IFERROR(C36-D36,0) | F36: =IFERROR(D36/C36,0)
A37: LIFESTYLE | B37: Personal Care | E37: =IFERROR(C37-D37,0) | F37: =IFERROR(D37/C37,0)
A38: Subtotal 🎬 LIFESTYLE | C38: =SUM(C34:C37) | D38: =SUM(D34:D37) | E38: =IFERROR(C38-D38,0) | F38: =IFERROR(D38/C38,0)
A39: 👔 PERSONAL
A40: PERSONAL | B40: Clothing | E40: =IFERROR(C40-D40,0) | F40: =IFERROR(D40/C40,0)
...

Sheet Aug
A1: 📅 Monthly Budget — August
A2: Category | B2: Subcategory | C2: Budgeted | D2: Actual | E2: Difference | F2: % Used | G2: Notes
A3: 💵 INCOME
A4: Income | B4: Primary Income | E4: =IFERROR(C4-D4,0) | F4: =IFERROR(D4/C4,0)
A5: Income | B5: Side Income | E5: =IFERROR(C5-D5,0) | F5: =IFERROR(D5/C5,0)
A6: Income | B6: Other Income | E6: =IFERROR(C6-D6,0) | F6: =IFERROR(D6/C6,0)
A7: TOTAL INCOME | C7: =SUM(C4:C6) | D7: =SUM(D4:D6) | E7: =IFERROR(C7-D7,0) | F7: =IFERROR(D7/C7,0)
A8: 🏠 HOUSING
A9: HOUSING | B9: Rent/Mortgage | E9: =IFERROR(C9-D9,0) | F9: =IFERROR(D9/C9,0)
A10: HOUSING | B10: Utilities | E10: =IFERROR(C10-D10,0) | F10: =IFERROR(D10/C10,0)
A11: HOUSING | B11: Internet | E11: =IFERROR(C11-D11,0) | F11: =IFERROR(D11/C11,0)
A12: HOUSING | B12: Renter's Insurance | E12: =IFERROR(C12-D12,0) | F12: =IFERROR(D12/C12,0)
A13: Subtotal 🏠 HOUSING | C13: =SUM(C9:C12) | D13: =SUM(D9:D12) | E13: =IFERROR(C13-D13,0) | F13: =IFERROR(D13/C13,0)
A14: 🚗 TRANSPORT
A15: TRANSPORT | B15: Car Payment | E15: =IFERROR(C15-D15,0) | F15: =IFERROR(D15/C15,0)
A16: TRANSPORT | B16: Gas | E16: =IFERROR(C16-D16,0) | F16: =IFERROR(D16/C16,0)
A17: TRANSPORT | B17: Insurance | E17: =IFERROR(C17-D17,0) | F17: =IFERROR(D17/C17,0)
A18: TRANSPORT | B18: Parking | E18: =IFERROR(C18-D18,0) | F18: =IFERROR(D18/C18,0)
A19: TRANSPORT | B19: Public Transit | E19: =IFERROR(C19-D19,0) | F19: =IFERROR(D19/C19,0)
A20: Subtotal 🚗 TRANSPORT | C20: =SUM(C15:C19) | D20: =SUM(D15:D19) | E20: =IFERROR(C20-D20,0) | F20: =IFERROR(D20/C20,0)
A21: 🛒 FOOD
A22: FOOD | B22: Groceries | E22: =IFERROR(C22-D22,0) | F22: =IFERROR(D22/C22,0)
A23: FOOD | B23: Dining Out | E23: =IFERROR(C23-D23,0) | F23: =IFERROR(D23/C23,0)
A24: FOOD | B24: Coffee Shops | E24: =IFERROR(C24-D24,0) | F24: =IFERROR(D24/C24,0)
A25: FOOD | B25: Meal Delivery | E25: =IFERROR(C25-D25,0) | F25: =IFERROR(D25/C25,0)
A26: Subtotal 🛒 FOOD | C26: =SUM(C22:C25) | D26: =SUM(D22:D25) | E26: =IFERROR(C26-D26,0) | F26: =IFERROR(D26/C26,0)
A27: 🏥 HEALTH
A28: HEALTH | B28: Health Insurance | E28: =IFERROR(C28-D28,0) | F28: =IFERROR(D28/C28,0)
A29: HEALTH | B29: Gym | E29: =IFERROR(C29-D29,0) | F29: =IFERROR(D29/C29,0)
A30: HEALTH | B30: Pharmacy | E30: =IFERROR(C30-D30,0) | F30: =IFERROR(D30/C30,0)
A31: HEALTH | B31: Doctor Visits | E31: =IFERROR(C31-D31,0) | F31: =IFERROR(D31/C31,0)
A32: Subtotal 🏥 HEALTH | C32: =SUM(C28:C31) | D32: =SUM(D28:D31) | E32: =IFERROR(C32-D32,0) | F32: =IFERROR(D32/C32,0)
A33: 🎬 LIFESTYLE
A34: LIFESTYLE | B34: Subscriptions | E34: =IFERROR(C34-D34,0) | F34: =IFERROR(D34/C34,0)
A35: LIFESTYLE | B35: Entertainment | E35: =IFERROR(C35-D35,0) | F35: =IFERROR(D35/C35,0)
A36: LIFESTYLE | B36: Hobbies | E36: =IFERROR(C36-D36,0) | F36: =IFERROR(D36/C36,0)
A37: LIFESTYLE | B37: Personal Care | E37: =IFERROR(C37-D37,0) | F37: =IFERROR(D37/C37,0)
A38: Subtotal 🎬 LIFESTYLE | C38: =SUM(C34:C37) | D38: =SUM(D34:D37) | E38: =IFERROR(C38-D38,0) | F38: =IFERROR(D38/C38,0)
A39: 👔 PERSONAL
A40: PERSONAL | B40: Clothing | E40: =IFERROR(C40-D40,0) | F40: =IFERROR(D40/C40,0)
...

Sheet Sep
A1: 📅 Monthly Budget — September
A2: Category | B2: Subcategory | C2: Budgeted | D2: Actual | E2: Difference | F2: % Used | G2: Notes
A3: 💵 INCOME
A4: Income | B4: Primary Income | E4: =IFERROR(C4-D4,0) | F4: =IFERROR(D4/C4,0)
A5: Income | B5: Side Income | E5: =IFERROR(C5-D5,0) | F5: =IFERROR(D5/C5,0)
A6: Income | B6: Other Income | E6: =IFERROR(C6-D6,0) | F6: =IFERROR(D6/C6,0)
A7: TOTAL INCOME | C7: =SUM(C4:C6) | D7: =SUM(D4:D6) | E7: =IFERROR(C7-D7,0) | F7: =IFERROR(D7/C7,0)
A8: 🏠 HOUSING
A9: HOUSING | B9: Rent/Mortgage | E9: =IFERROR(C9-D9,0) | F9: =IFERROR(D9/C9,0)
A10: HOUSING | B10: Utilities | E10: =IFERROR(C10-D10,0) | F10: =IFERROR(D10/C10,0)
A11: HOUSING | B11: Internet | E11: =IFERROR(C11-D11,0) | F11: =IFERROR(D11/C11,0)
A12: HOUSING | B12: Renter's Insurance | E12: =IFERROR(C12-D12,0) | F12: =IFERROR(D12/C12,0)
A13: Subtotal 🏠 HOUSING | C13: =SUM(C9:C12) | D13: =SUM(D9:D12) | E13: =IFERROR(C13-D13,0) | F13: =IFERROR(D13/C13,0)
A14: 🚗 TRANSPORT
A15: TRANSPORT | B15: Car Payment | E15: =IFERROR(C15-D15,0) | F15: =IFERROR(D15/C15,0)
A16: TRANSPORT | B16: Gas | E16: =IFERROR(C16-D16,0) | F16: =IFERROR(D16/C16,0)
A17: TRANSPORT | B17: Insurance | E17: =IFERROR(C17-D17,0) | F17: =IFERROR(D17/C17,0)
A18: TRANSPORT | B18: Parking | E18: =IFERROR(C18-D18,0) | F18: =IFERROR(D18/C18,0)
A19: TRANSPORT | B19: Public Transit | E19: =IFERROR(C19-D19,0) | F19: =IFERROR(D19/C19,0)
A20: Subtotal 🚗 TRANSPORT | C20: =SUM(C15:C19) | D20: =SUM(D15:D19) | E20: =IFERROR(C20-D20,0) | F20: =IFERROR(D20/C20,0)
A21: 🛒 FOOD
A22: FOOD | B22: Groceries | E22: =IFERROR(C22-D22,0) | F22: =IFERROR(D22/C22,0)
A23: FOOD | B23: Dining Out | E23: =IFERROR(C23-D23,0) | F23: =IFERROR(D23/C23,0)
A24: FOOD | B24: Coffee Shops | E24: =IFERROR(C24-D24,0) | F24: =IFERROR(D24/C24,0)
A25: FOOD | B25: Meal Delivery | E25: =IFERROR(C25-D25,0) | F25: =IFERROR(D25/C25,0)
A26: Subtotal 🛒 FOOD | C26: =SUM(C22:C25) | D26: =SUM(D22:D25) | E26: =IFERROR(C26-D26,0) | F26: =IFERROR(D26/C26,0)
A27: 🏥 HEALTH
A28: HEALTH | B28: Health Insurance | E28: =IFERROR(C28-D28,0) | F28: =IFERROR(D28/C28,0)
A29: HEALTH | B29: Gym | E29: =IFERROR(C29-D29,0) | F29: =IFERROR(D29/C29,0)
A30: HEALTH | B30: Pharmacy | E30: =IFERROR(C30-D30,0) | F30: =IFERROR(D30/C30,0)
A31: HEALTH | B31: Doctor Visits | E31: =IFERROR(C31-D31,0) | F31: =IFERROR(D31/C31,0)
A32: Subtotal 🏥 HEALTH | C32: =SUM(C28:C31) | D32: =SUM(D28:D31) | E32: =IFERROR(C32-D32,0) | F32: =IFERROR(D32/C32,0)
A33: 🎬 LIFESTYLE
A34: LIFESTYLE | B34: Subscriptions | E34: =IFERROR(C34-D34,0) | F34: =IFERROR(D34/C34,0)
A35: LIFESTYLE | B35: Entertainment | E35: =IFERROR(C35-D35,0) | F35: =IFERROR(D35/C35,0)
A36: LIFESTYLE | B36: Hobbies | E36: =IFERROR(C36-D36,0) | F36: =IFERROR(D36/C36,0)
A37: LIFESTYLE | B37: Personal Care | E37: =IFERROR(C37-D37,0) | F37: =IFERROR(D37/C37,0)
A38: Subtotal 🎬 LIFESTYLE | C38: =SUM(C34:C37) | D38: =SUM(D34:D37) | E38: =IFERROR(C38-D38,0) | F38: =IFERROR(D38/C38,0)
A39: 👔 PERSONAL
A40: PERSONAL | B40: Clothing | E40: =IFERROR(C40-D40,0) | F40: =IFERROR(D40/C40,0)
...

Sheet Oct
A1: 📅 Monthly Budget — October
A2: Category | B2: Subcategory | C2: Budgeted | D2: Actual | E2: Difference | F2: % Used | G2: Notes
A3: 💵 INCOME
A4: Income | B4: Primary Income | E4: =IFERROR(C4-D4,0) | F4: =IFERROR(D4/C4,0)
A5: Income | B5: Side Income | E5: =IFERROR(C5-D5,0) | F5: =IFERROR(D5/C5,0)
A6: Income | B6: Other Income | E6: =IFERROR(C6-D6,0) | F6: =IFERROR(D6/C6,0)
A7: TOTAL INCOME | C7: =SUM(C4:C6) | D7: =SUM(D4:D6) | E7: =IFERROR(C7-D7,0) | F7: =IFERROR(D7/C7,0)
A8: 🏠 HOUSING
A9: HOUSING | B9: Rent/Mortgage | E9: =IFERROR(C9-D9,0) | F9: =IFERROR(D9/C9,0)
A10: HOUSING | B10: Utilities | E10: =IFERROR(C10-D10,0) | F10: =IFERROR(D10/C10,0)
A11: HOUSING | B11: Internet | E11: =IFERROR(C11-D11,0) | F11: =IFERROR(D11/C11,0)
A12: HOUSING | B12: Renter's Insurance | E12: =IFERROR(C12-D12,0) | F12: =IFERROR(D12/C12,0)
A13: Subtotal 🏠 HOUSING | C13: =SUM(C9:C12) | D13: =SUM(D9:D12) | E13: =IFERROR(C13-D13,0) | F13: =IFERROR(D13/C13,0)
A14: 🚗 TRANSPORT
A15: TRANSPORT | B15: Car Payment | E15: =IFERROR(C15-D15,0) | F15: =IFERROR(D15/C15,0)
A16: TRANSPORT | B16: Gas | E16: =IFERROR(C16-D16,0) | F16: =IFERROR(D16/C16,0)
A17: TRANSPORT | B17: Insurance | E17: =IFERROR(C17-D17,0) | F17: =IFERROR(D17/C17,0)
A18: TRANSPORT | B18: Parking | E18: =IFERROR(C18-D18,0) | F18: =IFERROR(D18/C18,0)
A19: TRANSPORT | B19: Public Transit | E19: =IFERROR(C19-D19,0) | F19: =IFERROR(D19/C19,0)
A20: Subtotal 🚗 TRANSPORT | C20: =SUM(C15:C19) | D20: =SUM(D15:D19) | E20: =IFERROR(C20-D20,0) | F20: =IFERROR(D20/C20,0)
A21: 🛒 FOOD
A22: FOOD | B22: Groceries | E22: =IFERROR(C22-D22,0) | F22: =IFERROR(D22/C22,0)
A23: FOOD | B23: Dining Out | E23: =IFERROR(C23-D23,0) | F23: =IFERROR(D23/C23,0)
A24: FOOD | B24: Coffee Shops | E24: =IFERROR(C24-D24,0) | F24: =IFERROR(D24/C24,0)
A25: FOOD | B25: Meal Delivery | E25: =IFERROR(C25-D25,0) | F25: =IFERROR(D25/C25,0)
A26: Subtotal 🛒 FOOD | C26: =SUM(C22:C25) | D26: =SUM(D22:D25) | E26: =IFERROR(C26-D26,0) | F26: =IFERROR(D26/C26,0)
A27: 🏥 HEALTH
A28: HEALTH | B28: Health Insurance | E28: =IFERROR(C28-D28,0) | F28: =IFERROR(D28/C28,0)
A29: HEALTH | B29: Gym | E29: =IFERROR(C29-D29,0) | F29: =IFERROR(D29/C29,0)
A30: HEALTH | B30: Pharmacy | E30: =IFERROR(C30-D30,0) | F30: =IFERROR(D30/C30,0)
A31: HEALTH | B31: Doctor Visits | E31: =IFERROR(C31-D31,0) | F31: =IFERROR(D31/C31,0)
A32: Subtotal 🏥 HEALTH | C32: =SUM(C28:C31) | D32: =SUM(D28:D31) | E32: =IFERROR(C32-D32,0) | F32: =IFERROR(D32/C32,0)
A33: 🎬 LIFESTYLE
A34: LIFESTYLE | B34: Subscriptions | E34: =IFERROR(C34-D34,0) | F34: =IFERROR(D34/C34,0)
A35: LIFESTYLE | B35: Entertainment | E35: =IFERROR(C35-D35,0) | F35: =IFERROR(D35/C35,0)
A36: LIFESTYLE | B36: Hobbies | E36: =IFERROR(C36-D36,0) | F36: =IFERROR(D36/C36,0)
A37: LIFESTYLE | B37: Personal Care | E37: =IFERROR(C37-D37,0) | F37: =IFERROR(D37/C37,0)
A38: Subtotal 🎬 LIFESTYLE | C38: =SUM(C34:C37) | D38: =SUM(D34:D37) | E38: =IFERROR(C38-D38,0) | F38: =IFERROR(D38/C38,0)
A39: 👔 PERSONAL
A40: PERSONAL | B40: Clothing | E40: =IFERROR(C40-D40,0) | F40: =IFERROR(D40/C40,0)
...

Sheet Nov
A1: 📅 Monthly Budget — November
A2: Category | B2: Subcategory | C2: Budgeted | D2: Actual | E2: Difference | F2: % Used | G2: Notes
A3: 💵 INCOME
A4: Income | B4: Primary Income | E4: =IFERROR(C4-D4,0) | F4: =IFERROR(D4/C4,0)
A5: Income | B5: Side Income | E5: =IFERROR(C5-D5,0) | F5: =IFERROR(D5/C5,0)
A6: Income | B6: Other Income | E6: =IFERROR(C6-D6,0) | F6: =IFERROR(D6/C6,0)
A7: TOTAL INCOME | C7: =SUM(C4:C6) | D7: =SUM(D4:D6) | E7: =IFERROR(C7-D7,0) | F7: =IFERROR(D7/C7,0)
A8: 🏠 HOUSING
A9: HOUSING | B9: Rent/Mortgage | E9: =IFERROR(C9-D9,0) | F9: =IFERROR(D9/C9,0)
A10: HOUSING | B10: Utilities | E10: =IFERROR(C10-D10,0) | F10: =IFERROR(D10/C10,0)
A11: HOUSING | B11: Internet | E11: =IFERROR(C11-D11,0) | F11: =IFERROR(D11/C11,0)
A12: HOUSING | B12: Renter's Insurance | E12: =IFERROR(C12-D12,0) | F12: =IFERROR(D12/C12,0)
A13: Subtotal 🏠 HOUSING | C13: =SUM(C9:C12) | D13: =SUM(D9:D12) | E13: =IFERROR(C13-D13,0) | F13: =IFERROR(D13/C13,0)
A14: 🚗 TRANSPORT
A15: TRANSPORT | B15: Car Payment | E15: =IFERROR(C15-D15,0) | F15: =IFERROR(D15/C15,0)
A16: TRANSPORT | B16: Gas | E16: =IFERROR(C16-D16,0) | F16: =IFERROR(D16/C16,0)
A17: TRANSPORT | B17: Insurance | E17: =IFERROR(C17-D17,0) | F17: =IFERROR(D17/C17,0)
A18: TRANSPORT | B18: Parking | E18: =IFERROR(C18-D18,0) | F18: =IFERROR(D18/C18,0)
A19: TRANSPORT | B19: Public Transit | E19: =IFERROR(C19-D19,0) | F19: =IFERROR(D19/C19,0)
A20: Subtotal 🚗 TRANSPORT | C20: =SUM(C15:C19) | D20: =SUM(D15:D19) | E20: =IFERROR(C20-D20,0) | F20: =IFERROR(D20/C20,0)
A21: 🛒 FOOD
A22: FOOD | B22: Groceries | E22: =IFERROR(C22-D22,0) | F22: =IFERROR(D22/C22,0)
A23: FOOD | B23: Dining Out | E23: =IFERROR(C23-D23,0) | F23: =IFERROR(D23/C23,0)
A24: FOOD | B24: Coffee Shops | E24: =IFERROR(C24-D24,0) | F24: =IFERROR(D24/C24,0)
A25: FOOD | B25: Meal Delivery | E25: =IFERROR(C25-D25,0) | F25: =IFERROR(D25/C25,0)
A26: Subtotal 🛒 FOOD | C26: =SUM(C22:C25) | D26: =SUM(D22:D25) | E26: =IFERROR(C26-D26,0) | F26: =IFERROR(D26/C26,0)
A27: 🏥 HEALTH
A28: HEALTH | B28: Health Insurance | E28: =IFERROR(C28-D28,0) | F28: =IFERROR(D28/C28,0)
A29: HEALTH | B29: Gym | E29: =IFERROR(C29-D29,0) | F29: =IFERROR(D29/C29,0)
A30: HEALTH | B30: Pharmacy | E30: =IFERROR(C30-D30,0) | F30: =IFERROR(D30/C30,0)
A31: HEALTH | B31: Doctor Visits | E31: =IFERROR(C31-D31,0) | F31: =IFERROR(D31/C31,0)
A32: Subtotal 🏥 HEALTH | C32: =SUM(C28:C31) | D32: =SUM(D28:D31) | E32: =IFERROR(C32-D32,0) | F32: =IFERROR(D32/C32,0)
A33: 🎬 LIFESTYLE
A34: LIFESTYLE | B34: Subscriptions | E34: =IFERROR(C34-D34,0) | F34: =IFERROR(D34/C34,0)
A35: LIFESTYLE | B35: Entertainment | E35: =IFERROR(C35-D35,0) | F35: =IFERROR(D35/C35,0)
A36: LIFESTYLE | B36: Hobbies | E36: =IFERROR(C36-D36,0) | F36: =IFERROR(D36/C36,0)
A37: LIFESTYLE | B37: Personal Care | E37: =IFERROR(C37-D37,0) | F37: =IFERROR(D37/C37,0)
A38: Subtotal 🎬 LIFESTYLE | C38: =SUM(C34:C37) | D38: =SUM(D34:D37) | E38: =IFERROR(C38-D38,0) | F38: =IFERROR(D38/C38,0)
A39: 👔 PERSONAL
A40: PERSONAL | B40: Clothing | E40: =IFERROR(C40-D40,0) | F40: =IFERROR(D40/C40,0)
...

Sheet Dec
A1: 📅 Monthly Budget — December
A2: Category | B2: Subcategory | C2: Budgeted | D2: Actual | E2: Difference | F2: % Used | G2: Notes
A3: 💵 INCOME
A4: Income | B4: Primary Income | E4: =IFERROR(C4-D4,0) | F4: =IFERROR(D4/C4,0)
A5: Income | B5: Side Income | E5: =IFERROR(C5-D5,0) | F5: =IFERROR(D5/C5,0)
A6: Income | B6: Other Income | E6: =IFERROR(C6-D6,0) | F6: =IFERROR(D6/C6,0)
A7: TOTAL INCOME | C7: =SUM(C4:C6) | D7: =SUM(D4:D6) | E7: =IFERROR(C7-D7,0) | F7: =IFERROR(D7/C7,0)
A8: 🏠 HOUSING
A9: HOUSING | B9: Rent/Mortgage | E9: =IFERROR(C9-D9,0) | F9: =IFERROR(D9/C9,0)
A10: HOUSING | B10: Utilities | E10: =IFERROR(C10-D10,0) | F10: =IFERROR(D10/C10,0)
A11: HOUSING | B11: Internet | E11: =IFERROR(C11-D11,0) | F11: =IFERROR(D11/C11,0)
A12: HOUSING | B12: Renter's Insurance | E12: =IFERROR(C12-D12,0) | F12: =IFERROR(D12/C12,0)
A13: Subtotal 🏠 HOUSING | C13: =SUM(C9:C12) | D13: =SUM(D9:D12) | E13: =IFERROR(C13-D13,0) | F13: =IFERROR(D13/C13,0)
A14: 🚗 TRANSPORT
A15: TRANSPORT | B15: Car Payment | E15: =IFERROR(C15-D15,0) | F15: =IFERROR(D15/C15,0)
A16: TRANSPORT | B16: Gas | E16: =IFERROR(C16-D16,0) | F16: =IFERROR(D16/C16,0)
A17: TRANSPORT | B17: Insurance | E17: =IFERROR(C17-D17,0) | F17: =IFERROR(D17/C17,0)
A18: TRANSPORT | B18: Parking | E18: =IFERROR(C18-D18,0) | F18: =IFERROR(D18/C18,0)
A19: TRANSPORT | B19: Public Transit | E19: =IFERROR(C19-D19,0) | F19: =IFERROR(D19/C19,0)
A20: Subtotal 🚗 TRANSPORT | C20: =SUM(C15:C19) | D20: =SUM(D15:D19) | E20: =IFERROR(C20-D20,0) | F20: =IFERROR(D20/C20,0)
A21: 🛒 FOOD
A22: FOOD | B22: Groceries | E22: =IFERROR(C22-D22,0) | F22: =IFERROR(D22/C22,0)
A23: FOOD | B23: Dining Out | E23: =IFERROR(C23-D23,0) | F23: =IFERROR(D23/C23,0)
A24: FOOD | B24: Coffee Shops | E24: =IFERROR(C24-D24,0) | F24: =IFERROR(D24/C24,0)
A25: FOOD | B25: Meal Delivery | E25: =IFERROR(C25-D25,0) | F25: =IFERROR(D25/C25,0)
A26: Subtotal 🛒 FOOD | C26: =SUM(C22:C25) | D26: =SUM(D22:D25) | E26: =IFERROR(C26-D26,0) | F26: =IFERROR(D26/C26,0)
A27: 🏥 HEALTH
A28: HEALTH | B28: Health Insurance | E28: =IFERROR(C28-D28,0) | F28: =IFERROR(D28/C28,0)
A29: HEALTH | B29: Gym | E29: =IFERROR(C29-D29,0) | F29: =IFERROR(D29/C29,0)
A30: HEALTH | B30: Pharmacy | E30: =IFERROR(C30-D30,0) | F30: =IFERROR(D30/C30,0)
A31: HEALTH | B31: Doctor Visits | E31: =IFERROR(C31-D31,0) | F31: =IFERROR(D31/C31,0)
A32: Subtotal 🏥 HEALTH | C32: =SUM(C28:C31) | D32: =SUM(D28:D31) | E32: =IFERROR(C32-D32,0) | F32: =IFERROR(D32/C32,0)
A33: 🎬 LIFESTYLE
A34: LIFESTYLE | B34: Subscriptions | E34: =IFERROR(C34-D34,0) | F34: =IFERROR(D34/C34,0)
A35: LIFESTYLE | B35: Entertainment | E35: =IFERROR(C35-D35,0) | F35: =IFERROR(D35/C35,0)
A36: LIFESTYLE | B36: Hobbies | E36: =IFERROR(C36-D36,0) | F36: =IFERROR(D36/C36,0)
A37: LIFESTYLE | B37: Personal Care | E37: =IFERROR(C37-D37,0) | F37: =IFERROR(D37/C37,0)
A38: Subtotal 🎬 LIFESTYLE | C38: =SUM(C34:C37) | D38: =SUM(D34:D37) | E38: =IFERROR(C38-D38,0) | F38: =IFERROR(D38/C38,0)
A39: 👔 PERSONAL
A40: PERSONAL | B40: Clothing | E40: =IFERROR(C40-D40,0) | F40: =IFERROR(D40/C40,0)
...

Sheet Debt Tracker
A1: 💳 Debt Payoff Tracker
A2: Debt Name | B2: Lender | C2: Original Balance | D2: Current Balance | E2: Interest Rate | F2: Min Payment | G2: Monthly Payment | H2: Payoff Date | I2: Status | J2: Avalanche Rank
A3: Credit Card 1 | I3: Active | J3: =IFERROR(RANK(E3,E3:E8,0),"N/A")
A4: Credit Card 2 | I4: Active | J4: =IFERROR(RANK(E4,E3:E8,0),"N/A")
A5: Student Loan | I5: Active | J5: =IFERROR(RANK(E5,E3:E8,0),"N/A")
A6: Car Loan | I6: Active | J6: =IFERROR(RANK(E6,E3:E8,0),"N/A")
A7: Personal Loan | I7: Active | J7: =IFERROR(RANK(E7,E3:E8,0),"N/A")
A8: Other | I8: Active | J8: =IFERROR(RANK(E8,E3:E8,0),"N/A")
A11: 📊 DEBT SUMMARY
A12: Total Debt | D12: =IFERROR(SUM(D3:D8),0)
A13: Total Monthly Minimums | D13: =IFERROR(SUM(F3:F8),0)
A14: Debt-to-Income Ratio | D14: =IFERROR(SUM(F3:F8)/Dashboard!D5,0)
A15: Est. Total Interest | D15: =IFERROR(SUMPRODUCT(D3:D8,E3:E8)/12*12,"N/A")

Sheet Bill Calendar
A1: 📆 Bill Calendar
A2: Bill Name | B2: Category | C2: Amount | D2: Due Date | E2: Frequency | F2: Auto-Pay? | G2: Paid? | H2: Notes
A3: Rent/Mortgage | B3: Housing | C3: 1500 | D3: 2026-01-01 | E3: Monthly | F3: No | G3: No
A4: Electric | B4: Utilities | C4: 120 | D4: 2026-01-15 | E4: Monthly | F4: Yes | G4: No
A5: Internet | B5: Utilities | C5: 60 | D5: 2026-01-22 | E5: Monthly | F5: Yes | G5: No
A6: Netflix | B6: Subscriptions | C6: 18 | D6: 2026-01-08 | E6: Monthly | F6: Yes | G6: No
A7: Phone | B7: Subscriptions | C7: 85 | D7: 2026-01-12 | E7: Monthly | F7: Yes | G7: No
A8: Car Insurance | B8: Insurance | C8: 150 | D8: 2026-01-20 | E8: Monthly | F8: No | G8: No
A9: Gym | B9: Other | C9: 40 | D9: 2026-01-01 | E9: Monthly | F9: Yes | G9: No
A10: Spotify | B10: Subscriptions | C10: 11 | D10: 2026-01-05 | E10: Monthly | F10: Yes | G10: No
A24: MONTHLY TOTAL | C24: =SUM(C3:C23)

Sheet Savings Goals
A1: 🎯 Savings Goals Tracker
A2: Goal Name | B2: Target Amount | C2: Current Saved | D2: Monthly Contribution | E2: Target Date | F2: % Complete | G2: Progress | H2: Priority
A3: Emergency Fund | B3: 10000 | C3: 0 | D3: 500 | E3: 2026-12-31 | F3: =IFERROR(C3/B3,0) | G3: =IFERROR(REPT("█",ROUND(C3/B3*20,0))&REPT("░",20-ROUND(C3/B3*20,0)),"░░░░░░░░░░░░░░░░░░░░") | H3: High
A4: Vacation | B4: 3000 | C4: 0 | D4: 200 | E4: 2026-07-01 | F4: =IFERROR(C4/B4,0) | G4: =IFERROR(REPT("█",ROUND(C4/B4*20,0))&REPT("░",20-ROUND(C4/B4*20,0)),"░░░░░░░░░░░░░░░░░░░░") | H4: Medium
A5: Down Payment | B5: 50000 | C5: 0 | D5: 800 | E5: 2029-01-01 | F5: =IFERROR(C5/B5,0) | G5: =IFERROR(REPT("█",ROUND(C5/B5*20,0))&REPT("░",20-ROUND(C5/B5*20,0)),"░░░░░░░░░░░░░░░░░░░░") | H5: High
A6: New Car | B6: 15000 | C6: 0 | D6: 300 | E6: 2027-06-01 | F6: =IFERROR(C6/B6,0) | G6: =IFERROR(REPT("█",ROUND(C6/B6*20,0))&REPT("░",20-ROUND(C6/B6*20,0)),"░░░░░░░░░░░░░░░░░░░░") | H6: Medium
A7: Retirement Boost | B7: 20000 | C7: 0 | D7: 400 | E7: 2030-01-01 | F7: =IFERROR(C7/B7,0) | G7: =IFERROR(REPT("█",ROUND(C7/B7*20,0))&REPT("░",20-ROUND(C7/B7*20,0)),"░░░░░░░░░░░░░░░░░░░░") | H7: Low
A8: Other | B8: 5000 | C8: 0 | D8: 100 | E8: 2027-01-01 | F8: =IFERROR(C8/B8,0) | G8: =IFERROR(REPT("█",ROUND(C8/B8*20,0))&REPT("░",20-ROUND(C8/B8*20,0)),"░░░░░░░░░░░░░░░░░░░░") | H8: Low
A9: TOTALS | B9: =SUM(B3:B8) | C9: =SUM(C3:C8) | D9: =SUM(D3:D8)

Sheet Annual Overview
A1: 📊 Annual Summary 2026
A2: Category | B2: Jan | C2: Feb | D2: Mar | E2: Apr | F2: May | G2: Jun | H2: Jul | I2: Aug | J2: Sep | K2: Oct | L2: Nov | M2: Dec | N2: Annual Total | O2: Annual Budget | P2: Variance
A3: Income | B3: =IFERROR(Jan!D7,0) | C3: =IFERROR(Feb!D7,0) | D3: =IFERROR(Mar!D7,0) | E3: =IFERROR(Apr!D7,0) | F3: =IFERROR(May!D7,0) | G3: =IFERROR(Jun!D7,0) | H3: =IFERROR(Jul!D7,0) | I3: =IFERROR(Aug!D7,0) | J3: =IFERROR(Sep!D7,0) | K3: =IFERROR(Oct!D7,0) | L3: =IFERROR(Nov!D7,0) | M3: =IFERROR(Dec!D7,0) | N3: =SUM(B3:M3) | P3: =IFERROR(N3-O3,0)
A4: Total Expenses | B4: =IFERROR(Jan!D57,0) | C4: =IFERROR(Feb!D57,0) | D4: =IFERROR(Mar!D57,0) | E4: =IFERROR(Apr!D57,0) | F4: =IFERROR(May!D57,0) | G4: =IFERROR(Jun!D57,0) | H4: =IFERROR(Jul!D57,0) | I4: =IFERROR(Aug!D57,0) | J4: =IFERROR(Sep!D57,0) | K4: =IFERROR(Oct!D57,0) | L4: =IFERROR(Nov!D57,0) | M4: =IFERROR(Dec!D57,0) | N4: =SUM(B4:M4) | P4: =IFERROR(N4-O4,0)
A5: Housing | B5: =IFERROR(Jan!D13,0) | C5: =IFERROR(Feb!D13,0) | D5: =IFERROR(Mar!D13,0) | E5: =IFERROR(Apr!D13,0) | F5: =IFERROR(May!D13,0) | G5: =IFERROR(Jun!D13,0) | H5: =IFERROR(Jul!D13,0) | I5: =IFERROR(Aug!D13,0) | J5: =IFERROR(Sep!D13,0) | K5: =IFERROR(Oct!D13,0) | L5: =IFERROR(Nov!D13,0) | M5: =IFERROR(Dec!D13,0) | N5: =SUM(B5:M5) | P5: =IFERROR(N5-O5,0)
A6: Transport | B6: =IFERROR(Jan!D20,0) | C6: =IFERROR(Feb!D20,0) | D6: =IFERROR(Mar!D20,0) | E6: =IFERROR(Apr!D20,0) | F6: =IFERROR(May!D20,0) | G6: =IFERROR(Jun!D20,0) | H6: =IFERROR(Jul!D20,0) | I6: =IFERROR(Aug!D20,0) | J6: =IFERROR(Sep!D20,0) | K6: =IFERROR(Oct!D20,0) | L6: =IFERROR(Nov!D20,0) | M6: =IFERROR(Dec!D20,0) | N6: =SUM(B6:M6) | P6: =IFERROR(N6-O6,0)
A7: Food | B7: =IFERROR(Jan!D26,0) | C7: =IFERROR(Feb!D26,0) | D7: =IFERROR(Mar!D26,0) | E7: =IFERROR(Apr!D26,0) | F7: =IFERROR(May!D26,0) | G7: =IFERROR(Jun!D26,0) | H7: =IFERROR(Jul!D26,0) | I7: =IFERROR(Aug!D26,0) | J7: =IFERROR(Sep!D26,0) | K7: =IFERROR(Oct!D26,0) | L7: =IFERROR(Nov!D26,0) | M7: =IFERROR(Dec!D26,0) | N7: =SUM(B7:M7) | P7: =IFERROR(N7-O7,0)
A8: Health | B8: =IFERROR(Jan!D32,0) | C8: =IFERROR(Feb!D32,0) | D8: =IFERROR(Mar!D32,0) | E8: =IFERROR(Apr!D32,0) | F8: =IFERROR(May!D32,0) | G8: =IFERROR(Jun!D32,0) | H8: =IFERROR(Jul!D32,0) | I8: =IFERROR(Aug!D32,0) | J8: =IFERROR(Sep!D32,0) | K8: =IFERROR(Oct!D32,0) | L8: =IFERROR(Nov!D32,0) | M8: =IFERROR(Dec!D32,0) | N8: =SUM(B8:M8) | P8: =IFERROR(N8-O8,0)
A9: Lifestyle | B9: =IFERROR(Jan!D38,0) | C9: =IFERROR(Feb!D38,0) | D9: =IFERROR(Mar!D38,0) | E9: =IFERROR(Apr!D38,0) | F9: =IFERROR(May!D38,0) | G9: =IFERROR(Jun!D38,0) | H9: =IFERROR(Jul!D38,0) | I9: =IFERROR(Aug!D38,0) | J9: =IFERROR(Sep!D38,0) | K9: =IFERROR(Oct!D38,0) | L9: =IFERROR(Nov!D38,0) | M9: =IFERROR(Dec!D38,0) | N9: =SUM(B9:M9) | P9: =IFERROR(N9-O9,0)
A10: Personal | B10: =IFERROR(Jan!D44,0) | C10: =IFERROR(Feb!D44,0) | D10: =IFERROR(Mar!D44,0) | E10: =IFERROR(Apr!D44,0) | F10: =IFERROR(May!D44,0) | G10: =IFERROR(Jun!D44,0) | H10: =IFERROR(Jul!D44,0) | I10: =IFERROR(Aug!D44,0) | J10: =IFERROR(Sep!D44,0) | K10: =IFERROR(Oct!D44,0) | L10: =IFERROR(Nov!D44,0) | M10: =IFERROR(Dec!D44,0) | N10: =SUM(B10:M10) | P10: =IFERROR(N10-O10,0)
A11: Savings | B11: =IFERROR(Jan!D50,0) | C11: =IFERROR(Feb!D50,0) | D11: =IFERROR(Mar!D50,0) | E11: =IFERROR(Apr!D50,0) | F11: =IFERROR(May!D50,0) | G11: =IFERROR(Jun!D50,0) | H11: =IFERROR(Jul!D50,0) | I11: =IFERROR(Aug!D50,0) | J11: =IFERROR(Sep!D50,0) | K11: =IFERROR(Oct!D50,0) | L11: =IFERROR(Nov!D50,0) | M11: =IFERROR(Dec!D50,0) | N11: =SUM(B11:M11) | P11: =IFERROR(N11-O11,0)
A12: Debt Payments | B12: =IFERROR(Jan!D56,0) | C12: =IFERROR(Feb!D56,0) | D12: =IFERROR(Mar!D56,0) | E12: =IFERROR(Apr!D56,0) | F12: =IFERROR(May!D56,0) | G12: =IFERROR(Jun!D56,0) | H12: =IFERROR(Jul!D56,0) | I12: =IFERROR(Aug!D56,0) | J12: =IFERROR(Sep!D56,0) | K12: =IFERROR(Oct!D56,0) | L12: =IFERROR(Nov!D56,0) | M12: =IFERROR(Dec!D56,0) | N12: =SUM(B12:M12) | P12: =IFERROR(N12-O12,0)
A13: Net Cash Flow | B13: =IFERROR(Jan!D58,0) | C13: =IFERROR(Feb!D58,0) | D13: =IFERROR(Mar!D58,0) | E13: =IFERROR(Apr!D58,0) | F13: =IFERROR(May!D58,0) | G13: =IFERROR(Jun!D58,0) | H13: =IFERROR(Jul!D58,0) | I13: =IFERROR(Aug!D58,0) | J13: =IFERROR(Sep!D58,0) | K13: =IFERROR(Oct!D58,0) | L13: =IFERROR(Nov!D58,0) | M13: =IFERROR(Dec!D58,0) | N13: =SUM(B13:M13) | P13: =IFERROR(N13-O13,0)
A15: 📈 ANNUAL STATISTICS
A16: YTD Savings Rate | D16: =IFERROR(N11/N3,0)
A17: Highest Spending Month | D17: =IFERROR(INDEX(A2:M2,MATCH(MAX(B4:M4),B4:M4,0)+1,1),"N/A")
A18: Lowest Spending Month | D18: =IFERROR(INDEX(A2:M2,MATCH(MIN(B4:M4),B4:M4,0)+1,1),"N/A")
A19: Total Annual Income | D19: =IFERROR(N3,0)
A20: Total Annual Expenses | D20: =IFERROR(N4,0)
A21: Annual Net Cash Flow | D21: =IFERROR(N13,0)
