Workbook
Name CatList: Settings!$A$30:$A$59
Name IncomeCatList: Settings!$A$30:$A$37
Name ExpenseCatList: Settings!$A$38:$A$59
Name AcctList: Settings!$A$62:$A$69
Name CurList: Settings!$A$7:$A$26
Name BudgetYear: Settings!$B$2

Sheet Start Here
B2: 🌿 The Ultimate Budget
B3: ⭐ #1 BESTSELLER ⭐
B5: WELCOME!
B6: Thank you for downloading The Ultimate Budget — your all-in-one personal finance system.
B8: ✅ Works in Microsoft Excel 2016+ (Windows & Mac)
B9: ✅ Compatible with Google Sheets
B10: ✅ No Copy & Paste Required — enter transactions once, everything updates automatically
B11: ✅ Instant Download — start using immediately
B13: HOW TO USE THIS WORKBOOK
B14: 1. Go to the SETTINGS tab and set your Budget Year and Currency.
B15: 2. Enter your income & expense budgets in the Category table (Settings rows 30-59).
B16: 3. Go to TRANSACTIONS and enter each transaction as it happens.
... B35: Budget vs Actual · Changelog

Sheet Dashboard
B2: 🌿 The Ultimate Budget — Dashboard
B3: =Settings!B2
B5: Total Income | F5: Total Expenses | J5: Net Savings | N5: Savings Rate
B6: ="Income: "&Settings!C4&TEXT('Annual Summary'!N3,"#,##0") | F6: ="Expenses: "&Settings!C4&TEXT('Annual Summary'!N4,"#,##0") | J6: ="Net: "&Settings!C4&TEXT('Annual Summary'!N5,"#,##0") | N6: =IF('Annual Summary'!N3=0,"Rate: 0%","Rate: "&TEXT(IF('Annual Summary'!N3=0,0,'Annual Summary'!N5/'Annual Summary'!N3),"0.0%"))

Sheet Overview
A1: Overview — Quick Summary
A3: Total Income (YTD)
A4: ='Annual Summary'!N3
A5: Total Expenses (YTD)
A6: ='Annual Summary'!N4
A7: Net Savings (YTD)
A8: ='Annual Summary'!N5
A9: Savings Rate
A10: =IF('Annual Summary'!N3=0,0,'Annual Summary'!N5/'Annual Summary'!N3)
A11: Monthly Avg Income
A12: =IF('Annual Summary'!N3=0,0,'Annual Summary'!N3/12)
A13: Monthly Avg Expenses
A14: =IF('Annual Summary'!N4=0,0,'Annual Summary'!N4/12)
A17: Top Spending Category
A18: =IFERROR(INDEX(Settings!$A$38:$A$59,MATCH(MAX('Annual Summary'!N16:N37),'Annual Summary'!N16:N37,0)),"N/A")

Sheet Settings
A1: ⚙ Settings
A2: Budget Year | B2: 2026
A4: Currency | B4: USD | C4: =IFERROR(VLOOKUP(B4,A6:B25,2,FALSE),"$")
A5: ↑ code | C5: ← symbol
A6: Code | B6: Symbol
A7: USD | B7: $
A8: EUR | B8: €
A9: GBP | B9: £
A10: JPY | B10: ¥
A11: CAD | B11: $
A12: AUD | B12: $
A13: INR | B13: ₹
A14: CHF | B14: Fr
A15: SEK | B15: kr
A16: NOK | B16: kr
A17: DKK | B17: kr
... A26: TRY | B26: ₺
A29: Category | B29: Type | C29: Monthly Budget
A30: Salary | B30: Income | C30: 0
A31: Partner Income | B31: Income | C31: 0
A32: Freelance | B32: Income | C32: 0
A33: Business | B33: Income | C33: 0
A34: Investments | B34: Income | C34: 0
A35: Rental Income | B35: Income | C35: 0
A36: Refunds | B36: Income | C36: 0
A37: Other Income | B37: Income | C37: 0
A38: Rent/Mortgage | B38: Expense | C38: 1500
A39: Utilities | B39: Expense | C39: 150
A40: Groceries | B40: Expense | C40: 400
A41: Dining Out | B41: Expense | C41: 200
... A59: Miscellaneous | B59: Expense | C59: 100
A61: Accounts
A62: Checking
A63: Savings
A64: Cash
A65: Credit Card
A66: Debit Card
A67: PayPal
A68: Investment
A69: Other

Sheet Transactions
A1: Date | B1: Type | C1: Category | D1: Account | E1: Description | F1: Amount | G1: Month | H1: Year | I1: Day
A2: 46027 | B2: Income | C2: Salary | D2: Checking | E2: January Salary | F2: 5000 | G2: =IF(A2="","",MONTH(A2)) | H2: =IF(A2="","",YEAR(A2)) | I2: =IF(A2="","",DAY(A2))
A3: 46032 | B3: Expense | C3: Rent/Mortgage | D3: Checking | E3: January Rent | F3: 1500 | G3: =IF(A3="","",MONTH(A3)) | H3: =IF(A3="","",YEAR(A3)) | I3: =IF(A3="","",DAY(A3))
A4: 46034 | B4: Expense | C4: Groceries | D4: Checking | E4: Grocery Run | F4: 120 | G4: =IF(A4="","",MONTH(A4)) | H4: =IF(A4="","",YEAR(A4)) | I4: =IF(A4="","",DAY(A4))
A5: 46037 | B5: Expense | C5: Utilities | D5: Checking | E5: Electric Bill | F5: 80 | G5: =IF(A5="","",MONTH(A5)) | H5: =IF(A5="","",YEAR(A5)) | I5: =IF(A5="","",DAY(A5))
A6: 46042 | B6: Expense | C6: Dining Out | D6: Credit Card | E6: Restaurant | F6: 45 | G6: =IF(A6="","",MONTH(A6)) | H6: =IF(A6="","",YEAR(A6)) | I6: =IF(A6="","",DAY(A6))
A7: 46058 | B7: Income | C7: Salary | D7: Checking | E7: February Salary | F7: 5000 | G7: =IF(A7="","",MONTH(A7)) | H7: =IF(A7="","",YEAR(A7)) | I7: =IF(A7="","",DAY(A7))
A8: 46061 | B8: Expense | C8: Rent/Mortgage | D8: Checking | E8: February Rent | F8: 1500 | G8: =IF(A8="","",MONTH(A8)) | H8: =IF(A8="","",YEAR(A8)) | I8: =IF(A8="","",DAY(A8))
A9: 46067 | B9: Expense | C9: Groceries | D9: Checking | E9: Grocery Run | F9: 135 | G9: =IF(A9="","",MONTH(A9)) | H9: =IF(A9="","",YEAR(A9)) | I9: =IF(A9="","",DAY(A9))
A10: 46071 | B10: Expense | C10: Entertainment | D10: Credit Card | E10: Netflix+Cinema | F10: 60 | G10: =IF(A10="","",MONTH(A10)) | H10: =IF(A10="","",YEAR(A10)) | I10: =IF(A10="","",DAY(A10))
A11: 46086 | B11: Income | C11: Salary | D11: Checking | E11: March Salary | F11: 5000 | G11: =IF(A11="","",MONTH(A11)) | H11: =IF(A11="","",YEAR(A11)) | I11: =IF(A11="","",DAY(A11))
A12: 46088 | B12: Expense | C12: Rent/Mortgage | D12: Checking | E12: March Rent | F12: 1500 | G12: =IF(A12="","",MONTH(A12)) | H12: =IF(A12="","",YEAR(A12)) | I12: =IF(A12="","",DAY(A12))
A13: 46096 | B13: Expense | C13: Groceries | D13: Checking | E13: Grocery Run | F13: 110 | G13: =IF(A13="","",MONTH(A13)) | H13: =IF(A13="","",YEAR(A13)) | I13: =IF(A13="","",DAY(A13))
G14: =IF(A14="","",MONTH(A14)) | H14: =IF(A14="","",YEAR(A14)) | I14: =IF(A14="","",DAY(A14))
G15: =IF(A15="","",MONTH(A15)) | H15: =IF(A15="","",YEAR(A15)) | I15: =IF(A15="","",DAY(A15))
G16: =IF(A16="","",MONTH(A16)) | H16: =IF(A16="","",YEAR(A16)) | I16: =IF(A16="","",DAY(A16))
G17: =IF(A17="","",MONTH(A17)) | H17: =IF(A17="","",YEAR(A17)) | I17: =IF(A17="","",DAY(A17))
G18: =IF(A18="","",MONTH(A18)) | H18: =IF(A18="","",YEAR(A18)) | I18: =IF(A18="","",DAY(A18))
G19: =IF(A19="","",MONTH(A19)) | H19: =IF(A19="","",YEAR(A19)) | I19: =IF(A19="","",DAY(A19))
G20: =IF(A20="","",MONTH(A20)) | H20: =IF(A20="","",YEAR(A20)) | I20: =IF(A20="","",DAY(A20))
G21: =IF(A21="","",MONTH(A21)) | H21: =IF(A21="","",YEAR(A21)) | I21: =IF(A21="","",DAY(A21))
G22: =IF(A22="","",MONTH(A22)) | H22: =IF(A22="","",YEAR(A22)) | I22: =IF(A22="","",DAY(A22))
G23: =IF(A23="","",MONTH(A23)) | H23: =IF(A23="","",YEAR(A23)) | I23: =IF(A23="","",DAY(A23))
G24: =IF(A24="","",MONTH(A24)) | H24: =IF(A24="","",YEAR(A24)) | I24: =IF(A24="","",DAY(A24))
G25: =IF(A25="","",MONTH(A25)) | H25: =IF(A25="","",YEAR(A25)) | I25: =IF(A25="","",DAY(A25))
... G601: =IF(A601="","",MONTH(A601)) | H601: =IF(A601="","",YEAR(A601)) | I601: =IF(A601="","",DAY(A601))

Sheet Recurring
A1: Recurring Bills & Subscriptions
A2: Name | B2: Category | C2: Amount | D2: Frequency | E2: Due Day | F2: Account | G2: Status | H2: Next Due
A3: Rent | B3: Rent/Mortgage | C3: 1500 | D3: Monthly | E3: 1 | F3: Checking | G3: Unpaid | H3: 2026-02-01
A4: Netflix | B4: Subscriptions | C4: 16 | D4: Monthly | E4: 5 | F4: Credit Card | G4: Paid | H4: 2026-02-05
A5: Gym | B5: Gym/Fitness | C5: 50 | D5: Monthly | E5: 3 | F5: Credit Card | G5: Paid | H5: 2026-02-03
A6: Phone | B6: Phone | C6: 80 | D6: Monthly | E6: 10 | F6: Checking | G6: Unpaid | H6: 2026-02-10
A7: Internet | B7: Internet | C7: 60 | D7: Monthly | E7: 15 | F7: Checking | G7: Unpaid | H7: 2026-02-15
A8: Car Insurance | B8: Insurance | C8: 120 | D8: Monthly | E8: 20 | F8: Checking | G8: Unpaid | H8: 2026-02-20
A9: Spotify | B9: Subscriptions | C9: 10 | D9: Monthly | E9: 8 | F9: Credit Card | G9: Paid | H9: 2026-02-08
A10: Amazon Prime | B10: Subscriptions | C10: 15 | D10: Monthly | E10: 12 | F10: Credit Card | G10: Unpaid | H10: 2026-02-12
A11: Health Ins | B11: Insurance | C11: 200 | D11: Monthly | E11: 25 | F11: Checking | G11: Unpaid | H11: 2026-02-25
A12: Electric Bill | B12: Utilities | C12: 80 | D12: Monthly | E12: 18 | F12: Checking | G12: Overdue | H12: 2026-01-18

Sheet Annual Summary
A1: Annual Summary
A2: Category | B2: Jan | C2: Feb | D2: Mar | E2: Apr | F2: May | G2: Jun | H2: Jul | I2: Aug | J2: Sep | K2: Oct | L2: Nov | M2: Dec | N2: YTD
A3: Total Income | B3: =IFERROR(SUMIFS(Transactions!$F$2:$F$601,Transactions!$H$2:$H$601,Settings!$B$2,Transactions!$G$2:$G$601,1,Transactions!$B$2:$B$601,"Income"),0) | C3: =IFERROR(SUMIFS(Transactions!$F$2:$F$601,Transactions!$H$2:$H$601,Settings!$B$2,Transactions!$G$2:$G$601,2,Transactions!$B$2:$B$601,"Income"),0) | D3: =IFERROR(SUMIFS(Transactions!$F$2:$F$601,Transactions!$H$2:$H$601,Settings!$B$2,Transactions!$G$2:$G$601,3,Transactions!$B$2:$B$601,"Income"),0) | E3: =IFERROR(SUMIFS(Transactions!$F$2:$F$601,Transactions!$H$2:$H$601,Settings!$B$2,Transactions!$G$2:$G$601,4,Transactions!$B$2:$B$601,"Income"),0) | F3: =IFERROR(SUMIFS(Transactions!$F$2:$F$601,Transactions!$H$2:$H$601,Settings!$B$2,Transactions!$G$2:$G$601,5,Transactions!$B$2:$B$601,"Income"),0) | G3: =IFERROR(SUMIFS(Transactions!$F$2:$F$601,Transactions!$H$2:$H$601,Settings!$B$2,Transactions!$G$2:$G$601,6,Transactions!$B$2:$B$601,"Income"),0) | H3: =IFERROR(SUMIFS(Transactions!$F$2:$F$601,Transactions!$H$2:$H$601,Settings!$B$2,Transactions!$G$2:$G$601,7,Transactions!$B$2:$B$601,"Income"),0) | I3: =IFERROR(SUMIFS(Transactions!$F$2:$F$601,Transactions!$H$2:$H$601,Settings!$B$2,Transactions!$G$2:$G$601,8,Transactions!$B$2:$B$601,"Income"),0) | J3: =IFERROR(SUMIFS(Transactions!$F$2:$F$601,Transactions!$H$2:$H$601,Settings!$B$2,Transactions!$G$2:$G$601,9,Transactions!$B$2:$B$601,"Income"),0) | K3: =IFERROR(SUMIFS(Transactions!$F$2:$F$601,Transactions!$H$2:$H$601,Settings!$B$2,Transactions!$G$2:$G$601,10,Transactions!$B$2:$B$601,"Income"),0) | L3: =IFERROR(SUMIFS(Transactions!$F$2:$F$601,Transactions!$H$2:$H$601,Settings!$B$2,Transactions!$G$2:$G$601,11,Transactions!$B$2:$B$601,"Income"),0) | M3: =IFERROR(SUMIFS(Transactions!$F$2:$F$601,Transactions!$H$2:$H$601,Settings!$B$2,Transactions!$G$2:$G$601,12,Transactions!$B$2:$B$601,"Income"),0) | N3: =IFERROR(SUM(B3:M3),0) | Q3: Recurring Bills
A4: Total Expenses | B4: =IFERROR(SUMIFS(Transactions!$F$2:$F$601,Transactions!$H$2:$H$601,Settings!$B$2,Transactions!$G$2:$G$601,1,Transactions!$B$2:$B$601,"Expense"),0) | C4: =IFERROR(SUMIFS(Transactions!$F$2:$F$601,Transactions!$H$2:$H$601,Settings!$B$2,Transactions!$G$2:$G$601,2,Transactions!$B$2:$B$601,"Expense"),0) | D4: =IFERROR(SUMIFS(Transactions!$F$2:$F$601,Transactions!$H$2:$H$601,Settings!$B$2,Transactions!$G$2:$G$601,3,Transactions!$B$2:$B$601,"Expense"),0) | E4: =IFERROR(SUMIFS(Transactions!$F$2:$F$601,Transactions!$H$2:$H$601,Settings!$B$2,Transactions!$G$2:$G$601,4,Transactions!$B$2:$B$601,"Expense"),0) | F4: =IFERROR(SUMIFS(Transactions!$F$2:$F$601,Transactions!$H$2:$H$601,Settings!$B$2,Transactions!$G$2:$G$601,5,Transactions!$B$2:$B$601,"Expense"),0) | G4: =IFERROR(SUMIFS(Transactions!$F$2:$F$601,Transactions!$H$2:$H$601,Settings!$B$2,Transactions!$G$2:$G$601,6,Transactions!$B$2:$B$601,"Expense"),0) | H4: =IFERROR(SUMIFS(Transactions!$F$2:$F$601,Transactions!$H$2:$H$601,Settings!$B$2,Transactions!$G$2:$G$601,7,Transactions!$B$2:$B$601,"Expense"),0) | I4: =IFERROR(SUMIFS(Transactions!$F$2:$F$601,Transactions!$H$2:$H$601,Settings!$B$2,Transactions!$G$2:$G$601,8,Transactions!$B$2:$B$601,"Expense"),0) | J4: =IFERROR(SUMIFS(Transactions!$F$2:$F$601,Transactions!$H$2:$H$601,Settings!$B$2,Transactions!$G$2:$G$601,9,Transactions!$B$2:$B$601,"Expense"),0) | K4: =IFERROR(SUMIFS(Transactions!$F$2:$F$601,Transactions!$H$2:$H$601,Settings!$B$2,Transactions!$G$2:$G$601,10,Transactions!$B$2:$B$601,"Expense"),0) | L4: =IFERROR(SUMIFS(Transactions!$F$2:$F$601,Transactions!$H$2:$H$601,Settings!$B$2,Transactions!$G$2:$G$601,11,Transactions!$B$2:$B$601,"Expense"),0) | M4: =IFERROR(SUMIFS(Transactions!$F$2:$F$601,Transactions!$H$2:$H$601,Settings!$B$2,Transactions!$G$2:$G$601,12,Transactions!$B$2:$B$601,"Expense"),0) | N4: =IFERROR(SUM(B4:M4),0)
A5: Net Savings | B5: =B3-B4 | C5: =C3-C4 | D5: =D3-D4 | E5: =E3-E4 | F5: =F3-F4 | G5: =G3-G4 | H5: =H3-H4 | I5: =I3-I4 | ... M5: =M3-M4 | N5: =IFERROR(SUM(B5:M5),0)
A7: Category Actual vs Budget | O7: Budget/Mo
A8: Salary | B8: =IFERROR(SUMIFS(Transactions!$F$2:$F$601,Transactions!$H$2:$H$601,Settings!$B$2,Transactions!$G$2:$G$601,1,Transactions!$C$2:$C$601,A8),0) | C8: =IFERROR(SUMIFS(Transactions!$F$2:$F$601,Transactions!$H$2:$H$601,Settings!$B$2,Transactions!$G$2:$G$601,2,Transactions!$C$2:$C$601,A8),0) | D8: =IFERROR(SUMIFS(Transactions!$F$2:$F$601,Transactions!$H$2:$H$601,Settings!$B$2,Transactions!$G$2:$G$601,3,Transactions!$C$2:$C$601,A8),0) | E8: =IFERROR(SUMIFS(Transactions!$F$2:$F$601,Transactions!$H$2:$H$601,Settings!$B$2,Transactions!$G$2:$G$601,4,Transactions!$C$2:$C$601,A8),0) | F8: =IFERROR(SUMIFS(Transactions!$F$2:$F$601,Transactions!$H$2:$H$601,Settings!$B$2,Transactions!$G$2:$G$601,5,Transactions!$C$2:$C$601,A8),0) | G8: =IFERROR(SUMIFS(Transactions!$F$2:$F$601,Transactions!$H$2:$H$601,Settings!$B$2,Transactions!$G$2:$G$601,6,Transactions!$C$2:$C$601,A8),0) | H8: =IFERROR(SUMIFS(Transactions!$F$2:$F$601,Transactions!$H$2:$H$601,Settings!$B$2,Transactions!$G$2:$G$601,7,Transactions!$C$2:$C$601,A8),0) | I8: =IFERROR(SUMIFS(Transactions!$F$2:$F$601,Transactions!$H$2:$H$601,Settings!$B$2,Transactions!$G$2:$G$601,8,Transactions!$C$2:$C$601,A8),0) | J8: =IFERROR(SUMIFS(Transactions!$F$2:$F$601,Transactions!$H$2:$H$601,Settings!$B$2,Transactions!$G$2:$G$601,9,Transactions!$C$2:$C$601,A8),0) | K8: =IFERROR(SUMIFS(Transactions!$F$2:$F$601,Transactions!$H$2:$H$601,Settings!$B$2,Transactions!$G$2:$G$601,10,Transactions!$C$2:$C$601,A8),0) | L8: =IFERROR(SUMIFS(Transactions!$F$2:$F$601,Transactions!$H$2:$H$601,Settings!$B$2,Transactions!$G$2:$G$601,11,Transactions!$C$2:$C$601,A8),0) | M8: =IFERROR(SUMIFS(Transactions!$F$2:$F$601,Transactions!$H$2:$H$601,Settings!$B$2,Transactions!$G$2:$G$601,12,Transactions!$C$2:$C$601,A8),0) | N8: =IFERROR(SUM(B8:M8),0) | O8: =IFERROR(VLOOKUP(A8,Settings!$A$30:$C$59,3,FALSE),0)
A9: Partner Income | B9: =IFERROR(SUMIFS(Transactions!$F$2:$F$601,Transactions!$H$2:$H$601,Settings!$B$2,Transactions!$G$2:$G$601,1,Transactions!$C$2:$C$601,A9),0) | C9: =IFERROR(SUMIFS(Transactions!$F$2:$F$601,Transactions!$H$2:$H$601,Settings!$B$2,Transactions!$G$2:$G$601,2,Transactions!$C$2:$C$601,A9),0) | D9: =IFERROR(SUMIFS(Transactions!$F$2:$F$601,Transactions!$H$2:$H$601,Settings!$B$2,Transactions!$G$2:$G$601,3,Transactions!$C$2:$C$601,A9),0) | E9: =IFERROR(SUMIFS(Transactions!$F$2:$F$601,Transactions!$H$2:$H$601,Settings!$B$2,Transactions!$G$2:$G$601,4,Transactions!$C$2:$C$601,A9),0) | F9: =IFERROR(SUMIFS(Transactions!$F$2:$F$601,Transactions!$H$2:$H$601,Settings!$B$2,Transactions!$G$2:$G$601,5,Transactions!$C$2:$C$601,A9),0) | G9: =IFERROR(SUMIFS(Transactions!$F$2:$F$601,Transactions!$H$2:$H$601,Settings!$B$2,Transactions!$G$2:$G$601,6,Transactions!$C$2:$C$601,A9),0) | H9: =IFERROR(SUMIFS(Transactions!$F$2:$F$601,Transactions!$H$2:$H$601,Settings!$B$2,Transactions!$G$2:$G$601,7,Transactions!$C$2:$C$601,A9),0) | I9: =IFERROR(SUMIFS(Transactions!$F$2:$F$601,Transactions!$H$2:$H$601,Settings!$B$2,Transactions!$G$2:$G$601,8,Transactions!$C$2:$C$601,A9),0) | J9: =IFERROR(SUMIFS(Transactions!$F$2:$F$601,Transactions!$H$2:$H$601,Settings!$B$2,Transactions!$G$2:$G$601,9,Transactions!$C$2:$C$601,A9),0) | K9: =IFERROR(SUMIFS(Transactions!$F$2:$F$601,Transactions!$H$2:$H$601,Settings!$B$2,Transactions!$G$2:$G$601,10,Transactions!$C$2:$C$601,A9),0) | L9: =IFERROR(SUMIFS(Transactions!$F$2:$F$601,Transactions!$H$2:$H$601,Settings!$B$2,Transactions!$G$2:$G$601,11,Transactions!$C$2:$C$601,A9),0) | M9: =IFERROR(SUMIFS(Transactions!$F$2:$F$601,Transactions!$H$2:$H$601,Settings!$B$2,Transactions!$G$2:$G$601,12,Transactions!$C$2:$C$601,A9),0) | N9: =IFERROR(SUM(B9:M9),0) | O9: =IFERROR(VLOOKUP(A9,Settings!$A$30:$C$59,3,FALSE),0)
A10: Freelance | B10: =IFERROR(SUMIFS(Transactions!$F$2:$F$601,Transactions!$H$2:$H$601,Settings!$B$2,Transactions!$G$2:$G$601,1,Transactions!$C$2:$C$601,A10),0) | C10: =IFERROR(SUMIFS(Transactions!$F$2:$F$601,Transactions!$H$2:$H$601,Settings!$B$2,Transactions!$G$2:$G$601,2,Transactions!$C$2:$C$601,A10),0) | D10: =IFERROR(SUMIFS(Transactions!$F$2:$F$601,Transactions!$H$2:$H$601,Settings!$B$2,Transactions!$G$2:$G$601,3,Transactions!$C$2:$C$601,A10),0) | E10: =IFERROR(SUMIFS(Transactions!$F$2:$F$601,Transactions!$H$2:$H$601,Settings!$B$2,Transactions!$G$2:$G$601,4,Transactions!$C$2:$C$601,A10),0) | F10: =IFERROR(SUMIFS(Transactions!$F$2:$F$601,Transactions!$H$2:$H$601,Settings!$B$2,Transactions!$G$2:$G$601,5,Transactions!$C$2:$C$601,A10),0) | G10: =IFERROR(SUMIFS(Transactions!$F$2:$F$601,Transactions!$H$2:$H$601,Settings!$B$2,Transactions!$G$2:$G$601,6,Transactions!$C$2:$C$601,A10),0) | H10: =IFERROR(SUMIFS(Transactions!$F$2:$F$601,Transactions!$H$2:$H$601,Settings!$B$2,Transactions!$G$2:$G$601,7,Transactions!$C$2:$C$601,A10),0) | I10: =IFERROR(SUMIFS(Transactions!$F$2:$F$601,Transactions!$H$2:$H$601,Settings!$B$2,Transactions!$G$2:$G$601,8,Transactions!$C$2:$C$601,A10),0) | J10: =IFERROR(SUMIFS(Transactions!$F$2:$F$601,Transactions!$H$2:$H$601,Settings!$B$2,Transactions!$G$2:$G$601,9,Transactions!$C$2:$C$601,A10),0) | K10: =IFERROR(SUMIFS(Transactions!$F$2:$F$601,Transactions!$H$2:$H$601,Settings!$B$2,Transactions!$G$2:$G$601,10,Transactions!$C$2:$C$601,A10),0) | L10: =IFERROR(SUMIFS(Transactions!$F$2:$F$601,Transactions!$H$2:$H$601,Settings!$B$2,Transactions!$G$2:$G$601,11,Transactions!$C$2:$C$601,A10),0) | M10: =IFERROR(SUMIFS(Transactions!$F$2:$F$601,Transactions!$H$2:$H$601,Settings!$B$2,Transactions!$G$2:$G$601,12,Transactions!$C$2:$C$601,A10),0) | N10: =IFERROR(SUM(B10:M10),0) | O10: =IFERROR(VLOOKUP(A10,Settings!$A$30:$C$59,3,FALSE),0)
A11: Business | B11: =IFERROR(SUMIFS(Transactions!$F$2:$F$601,Transactions!$H$2:$H$601,Settings!$B$2,Transactions!$G$2:$G$601,1,Transactions!$C$2:$C$601,A11),0) | C11: =IFERROR(SUMIFS(Transactions!$F$2:$F$601,Transactions!$H$2:$H$601,Settings!$B$2,Transactions!$G$2:$G$601,2,Transactions!$C$2:$C$601,A11),0) | D11: =IFERROR(SUMIFS(Transactions!$F$2:$F$601,Transactions!$H$2:$H$601,Settings!$B$2,Transactions!$G$2:$G$601,3,Transactions!$C$2:$C$601,A11),0) | E11: =IFERROR(SUMIFS(Transactions!$F$2:$F$601,Transactions!$H$2:$H$601,Settings!$B$2,Transactions!$G$2:$G$601,4,Transactions!$C$2:$C$601,A11),0) | F11: =IFERROR(SUMIFS(Transactions!$F$2:$F$601,Transactions!$H$2:$H$601,Settings!$B$2,Transactions!$G$2:$G$601,5,Transactions!$C$2:$C$601,A11),0) | G11: =IFERROR(SUMIFS(Transactions!$F$2:$F$601,Transactions!$H$2:$H$601,Settings!$B$2,Transactions!$G$2:$G$601,6,Transactions!$C$2:$C$601,A11),0) | H11: =IFERROR(SUMIFS(Transactions!$F$2:$F$601,Transactions!$H$2:$H$601,Settings!$B$2,Transactions!$G$2:$G$601,7,Transactions!$C$2:$C$601,A11),0) | I11: =IFERROR(SUMIFS(Transactions!$F$2:$F$601,Transactions!$H$2:$H$601,Settings!$B$2,Transactions!$G$2:$G$601,8,Transactions!$C$2:$C$601,A11),0) | J11: =IFERROR(SUMIFS(Transactions!$F$2:$F$601,Transactions!$H$2:$H$601,Settings!$B$2,Transactions!$G$2:$G$601,9,Transactions!$C$2:$C$601,A11),0) | K11: =IFERROR(SUMIFS(Transactions!$F$2:$F$601,Transactions!$H$2:$H$601,Settings!$B$2,Transactions!$G$2:$G$601,10,Transactions!$C$2:$C$601,A11),0) | L11: =IFERROR(SUMIFS(Transactions!$F$2:$F$601,Transactions!$H$2:$H$601,Settings!$B$2,Transactions!$G$2:$G$601,11,Transactions!$C$2:$C$601,A11),0) | M11: =IFERROR(SUMIFS(Transactions!$F$2:$F$601,Transactions!$H$2:$H$601,Settings!$B$2,Transactions!$G$2:$G$601,12,Transactions!$C$2:$C$601,A11),0) | N11: =IFERROR(SUM(B11:M11),0) | O11: =IFERROR(VLOOKUP(A11,Settings!$A$30:$C$59,3,FALSE),0)
A12: Investments | B12: =IFERROR(SUMIFS(Transactions!$F$2:$F$601,Transactions!$H$2:$H$601,Settings!$B$2,Transactions!$G$2:$G$601,1,Transactions!$C$2:$C$601,A12),0) | C12: =IFERROR(SUMIFS(Transactions!$F$2:$F$601,Transactions!$H$2:$H$601,Settings!$B$2,Transactions!$G$2:$G$601,2,Transactions!$C$2:$C$601,A12),0) | D12: =IFERROR(SUMIFS(Transactions!$F$2:$F$601,Transactions!$H$2:$H$601,Settings!$B$2,Transactions!$G$2:$G$601,3,Transactions!$C$2:$C$601,A12),0) | E12: =IFERROR(SUMIFS(Transactions!$F$2:$F$601,Transactions!$H$2:$H$601,Settings!$B$2,Transactions!$G$2:$G$601,4,Transactions!$C$2:$C$601,A12),0) | F12: =IFERROR(SUMIFS(Transactions!$F$2:$F$601,Transactions!$H$2:$H$601,Settings!$B$2,Transactions!$G$2:$G$601,5,Transactions!$C$2:$C$601,A12),0) | G12: =IFERROR(SUMIFS(Transactions!$F$2:$F$601,Transactions!$H$2:$H$601,Settings!$B$2,Transactions!$G$2:$G$601,6,Transactions!$C$2:$C$601,A12),0) | H12: =IFERROR(SUMIFS(Transactions!$F$2:$F$601,Transactions!$H$2:$H$601,Settings!$B$2,Transactions!$G$2:$G$601,7,Transactions!$C$2:$C$601,A12),0) | I12: =IFERROR(SUMIFS(Transactions!$F$2:$F$601,Transactions!$H$2:$H$601,Settings!$B$2,Transactions!$G$2:$G$601,8,Transactions!$C$2:$C$601,A12),0) | J12: =IFERROR(SUMIFS(Transactions!$F$2:$F$601,Transactions!$H$2:$H$601,Settings!$B$2,Transactions!$G$2:$G$601,9,Transactions!$C$2:$C$601,A12),0) | K12: =IFERROR(SUMIFS(Transactions!$F$2:$F$601,Transactions!$H$2:$H$601,Settings!$B$2,Transactions!$G$2:$G$601,10,Transactions!$C$2:$C$601,A12),0) | L12: =IFERROR(SUMIFS(Transactions!$F$2:$F$601,Transactions!$H$2:$H$601,Settings!$B$2,Transactions!$G$2:$G$601,11,Transactions!$C$2:$C$601,A12),0) | M12: =IFERROR(SUMIFS(Transactions!$F$2:$F$601,Transactions!$H$2:$H$601,Settings!$B$2,Transactions!$G$2:$G$601,12,Transactions!$C$2:$C$601,A12),0) | N12: =IFERROR(SUM(B12:M12),0) | O12: =IFERROR(VLOOKUP(A12,Settings!$A$30:$C$59,3,FALSE),0)
A13: Rental Income | B13: =IFERROR(SUMIFS(Transactions!$F$2:$F$601,Transactions!$H$2:$H$601,Settings!$B$2,Transactions!$G$2:$G$601,1,Transactions!$C$2:$C$601,A13),0) | C13: =IFERROR(SUMIFS(Transactions!$F$2:$F$601,Transactions!$H$2:$H$601,Settings!$B$2,Transactions!$G$2:$G$601,2,Transactions!$C$2:$C$601,A13),0) | D13: =IFERROR(SUMIFS(Transactions!$F$2:$F$601,Transactions!$H$2:$H$601,Settings!$B$2,Transactions!$G$2:$G$601,3,Transactions!$C$2:$C$601,A13),0) | E13: =IFERROR(SUMIFS(Transactions!$F$2:$F$601,Transactions!$H$2:$H$601,Settings!$B$2,Transactions!$G$2:$G$601,4,Transactions!$C$2:$C$601,A13),0) | F13: =IFERROR(SUMIFS(Transactions!$F$2:$F$601,Transactions!$H$2:$H$601,Settings!$B$2,Transactions!$G$2:$G$601,5,Transactions!$C$2:$C$601,A13),0) | G13: =IFERROR(SUMIFS(Transactions!$F$2:$F$601,Transactions!$H$2:$H$601,Settings!$B$2,Transactions!$G$2:$G$601,6,Transactions!$C$2:$C$601,A13),0) | H13: =IFERROR(SUMIFS(Transactions!$F$2:$F$601,Transactions!$H$2:$H$601,Settings!$B$2,Transactions!$G$2:$G$601,7,Transactions!$C$2:$C$601,A13),0) | I13: =IFERROR(SUMIFS(Transactions!$F$2:$F$601,Transactions!$H$2:$H$601,Settings!$B$2,Transactions!$G$2:$G$601,8,Transactions!$C$2:$C$601,A13),0) | J13: =IFERROR(SUMIFS(Transactions!$F$2:$F$601,Transactions!$H$2:$H$601,Settings!$B$2,Transactions!$G$2:$G$601,9,Transactions!$C$2:$C$601,A13),0) | K13: =IFERROR(SUMIFS(Transactions!$F$2:$F$601,Transactions!$H$2:$H$601,Settings!$B$2,Transactions!$G$2:$G$601,10,Transactions!$C$2:$C$601,A13),0) | L13: =IFERROR(SUMIFS(Transactions!$F$2:$F$601,Transactions!$H$2:$H$601,Settings!$B$2,Transactions!$G$2:$G$601,11,Transactions!$C$2:$C$601,A13),0) | M13: =IFERROR(SUMIFS(Transactions!$F$2:$F$601,Transactions!$H$2:$H$601,Settings!$B$2,Transactions!$G$2:$G$601,12,Transactions!$C$2:$C$601,A13),0) | N13: =IFERROR(SUM(B13:M13),0) | O13: =IFERROR(VLOOKUP(A13,Settings!$A$30:$C$59,3,FALSE),0)
A14: Refunds | B14: =IFERROR(SUMIFS(Transactions!$F$2:$F$601,Transactions!$H$2:$H$601,Settings!$B$2,Transactions!$G$2:$G$601,1,Transactions!$C$2:$C$601,A14),0) | C14: =IFERROR(SUMIFS(Transactions!$F$2:$F$601,Transactions!$H$2:$H$601,Settings!$B$2,Transactions!$G$2:$G$601,2,Transactions!$C$2:$C$601,A14),0) | D14: =IFERROR(SUMIFS(Transactions!$F$2:$F$601,Transactions!$H$2:$H$601,Settings!$B$2,Transactions!$G$2:$G$601,3,Transactions!$C$2:$C$601,A14),0) | E14: =IFERROR(SUMIFS(Transactions!$F$2:$F$601,Transactions!$H$2:$H$601,Settings!$B$2,Transactions!$G$2:$G$601,4,Transactions!$C$2:$C$601,A14),0) | F14: =IFERROR(SUMIFS(Transactions!$F$2:$F$601,Transactions!$H$2:$H$601,Settings!$B$2,Transactions!$G$2:$G$601,5,Transactions!$C$2:$C$601,A14),0) | G14: =IFERROR(SUMIFS(Transactions!$F$2:$F$601,Transactions!$H$2:$H$601,Settings!$B$2,Transactions!$G$2:$G$601,6,Transactions!$C$2:$C$601,A14),0) | H14: =IFERROR(SUMIFS(Transactions!$F$2:$F$601,Transactions!$H$2:$H$601,Settings!$B$2,Transactions!$G$2:$G$601,7,Transactions!$C$2:$C$601,A14),0) | I14: =IFERROR(SUMIFS(Transactions!$F$2:$F$601,Transactions!$H$2:$H$601,Settings!$B$2,Transactions!$G$2:$G$601,8,Transactions!$C$2:$C$601,A14),0) | J14: =IFERROR(SUMIFS(Transactions!$F$2:$F$601,Transactions!$H$2:$H$601,Settings!$B$2,Transactions!$G$2:$G$601,9,Transactions!$C$2:$C$601,A14),0) | K14: =IFERROR(SUMIFS(Transactions!$F$2:$F$601,Transactions!$H$2:$H$601,Settings!$B$2,Transactions!$G$2:$G$601,10,Transactions!$C$2:$C$601,A14),0) | L14: =IFERROR(SUMIFS(Transactions!$F$2:$F$601,Transactions!$H$2:$H$601,Settings!$B$2,Transactions!$G$2:$G$601,11,Transactions!$C$2:$C$601,A14),0) | M14: =IFERROR(SUMIFS(Transactions!$F$2:$F$601,Transactions!$H$2:$H$601,Settings!$B$2,Transactions!$G$2:$G$601,12,Transactions!$C$2:$C$601,A14),0) | N14: =IFERROR(SUM(B14:M14),0) | O14: =IFERROR(VLOOKUP(A14,Settings!$A$30:$C$59,3,FALSE),0)
A15: Other Income | B15: =IFERROR(SUMIFS(Transactions!$F$2:$F$601,Transactions!$H$2:$H$601,Settings!$B$2,Transactions!$G$2:$G$601,1,Transactions!$C$2:$C$601,A15),0) | C15: =IFERROR(SUMIFS(Transactions!$F$2:$F$601,Transactions!$H$2:$H$601,Settings!$B$2,Transactions!$G$2:$G$601,2,Transactions!$C$2:$C$601,A15),0) | D15: =IFERROR(SUMIFS(Transactions!$F$2:$F$601,Transactions!$H$2:$H$601,Settings!$B$2,Transactions!$G$2:$G$601,3,Transactions!$C$2:$C$601,A15),0) | E15: =IFERROR(SUMIFS(Transactions!$F$2:$F$601,Transactions!$H$2:$H$601,Settings!$B$2,Transactions!$G$2:$G$601,4,Transactions!$C$2:$C$601,A15),0) | F15: =IFERROR(SUMIFS(Transactions!$F$2:$F$601,Transactions!$H$2:$H$601,Settings!$B$2,Transactions!$G$2:$G$601,5,Transactions!$C$2:$C$601,A15),0) | G15: =IFERROR(SUMIFS(Transactions!$F$2:$F$601,Transactions!$H$2:$H$601,Settings!$B$2,Transactions!$G$2:$G$601,6,Transactions!$C$2:$C$601,A15),0) | H15: =IFERROR(SUMIFS(Transactions!$F$2:$F$601,Transactions!$H$2:$H$601,Settings!$B$2,Transactions!$G$2:$G$601,7,Transactions!$C$2:$C$601,A15),0) | I15: =IFERROR(SUMIFS(Transactions!$F$2:$F$601,Transactions!$H$2:$H$601,Settings!$B$2,Transactions!$G$2:$G$601,8,Transactions!$C$2:$C$601,A15),0) | J15: =IFERROR(SUMIFS(Transactions!$F$2:$F$601,Transactions!$H$2:$H$601,Settings!$B$2,Transactions!$G$2:$G$601,9,Transactions!$C$2:$C$601,A15),0) | K15: =IFERROR(SUMIFS(Transactions!$F$2:$F$601,Transactions!$H$2:$H$601,Settings!$B$2,Transactions!$G$2:$G$601,10,Transactions!$C$2:$C$601,A15),0) | L15: =IFERROR(SUMIFS(Transactions!$F$2:$F$601,Transactions!$H$2:$H$601,Settings!$B$2,Transactions!$G$2:$G$601,11,Transactions!$C$2:$C$601,A15),0) | M15: =IFERROR(SUMIFS(Transactions!$F$2:$F$601,Transactions!$H$2:$H$601,Settings!$B$2,Transactions!$G$2:$G$601,12,Transactions!$C$2:$C$601,A15),0) | N15: =IFERROR(SUM(B15:M15),0) | O15: =IFERROR(VLOOKUP(A15,Settings!$A$30:$C$59,3,FALSE),0)
A16: Rent/Mortgage | B16: =IFERROR(SUMIFS(Transactions!$F$2:$F$601,Transactions!$H$2:$H$601,Settings!$B$2,Transactions!$G$2:$G$601,1,Transactions!$C$2:$C$601,A16),0) | C16: =IFERROR(SUMIFS(Transactions!$F$2:$F$601,Transactions!$H$2:$H$601,Settings!$B$2,Transactions!$G$2:$G$601,2,Transactions!$C$2:$C$601,A16),0) | D16: =IFERROR(SUMIFS(Transactions!$F$2:$F$601,Transactions!$H$2:$H$601,Settings!$B$2,Transactions!$G$2:$G$601,3,Transactions!$C$2:$C$601,A16),0) | E16: =IFERROR(SUMIFS(Transactions!$F$2:$F$601,Transactions!$H$2:$H$601,Settings!$B$2,Transactions!$G$2:$G$601,4,Transactions!$C$2:$C$601,A16),0) | F16: =IFERROR(SUMIFS(Transactions!$F$2:$F$601,Transactions!$H$2:$H$601,Settings!$B$2,Transactions!$G$2:$G$601,5,Transactions!$C$2:$C$601,A16),0) | G16: =IFERROR(SUMIFS(Transactions!$F$2:$F$601,Transactions!$H$2:$H$601,Settings!$B$2,Transactions!$G$2:$G$601,6,Transactions!$C$2:$C$601,A16),0) | H16: =IFERROR(SUMIFS(Transactions!$F$2:$F$601,Transactions!$H$2:$H$601,Settings!$B$2,Transactions!$G$2:$G$601,7,Transactions!$C$2:$C$601,A16),0) | I16: =IFERROR(SUMIFS(Transactions!$F$2:$F$601,Transactions!$H$2:$H$601,Settings!$B$2,Transactions!$G$2:$G$601,8,Transactions!$C$2:$C$601,A16),0) | J16: =IFERROR(SUMIFS(Transactions!$F$2:$F$601,Transactions!$H$2:$H$601,Settings!$B$2,Transactions!$G$2:$G$601,9,Transactions!$C$2:$C$601,A16),0) | K16: =IFERROR(SUMIFS(Transactions!$F$2:$F$601,Transactions!$H$2:$H$601,Settings!$B$2,Transactions!$G$2:$G$601,10,Transactions!$C$2:$C$601,A16),0) | L16: =IFERROR(SUMIFS(Transactions!$F$2:$F$601,Transactions!$H$2:$H$601,Settings!$B$2,Transactions!$G$2:$G$601,11,Transactions!$C$2:$C$601,A16),0) | M16: =IFERROR(SUMIFS(Transactions!$F$2:$F$601,Transactions!$H$2:$H$601,Settings!$B$2,Transactions!$G$2:$G$601,12,Transactions!$C$2:$C$601,A16),0) | N16: =IFERROR(SUM(B16:M16),0) | O16: =IFERROR(VLOOKUP(A16,Settings!$A$30:$C$59,3,FALSE),0)
A17: Utilities | B17: =IFERROR(SUMIFS(Transactions!$F$2:$F$601,Transactions!$H$2:$H$601,Settings!$B$2,Transactions!$G$2:$G$601,1,Transactions!$C$2:$C$601,A17),0) | C17: =IFERROR(SUMIFS(Transactions!$F$2:$F$601,Transactions!$H$2:$H$601,Settings!$B$2,Transactions!$G$2:$G$601,2,Transactions!$C$2:$C$601,A17),0) | D17: =IFERROR(SUMIFS(Transactions!$F$2:$F$601,Transactions!$H$2:$H$601,Settings!$B$2,Transactions!$G$2:$G$601,3,Transactions!$C$2:$C$601,A17),0) | E17: =IFERROR(SUMIFS(Transactions!$F$2:$F$601,Transactions!$H$2:$H$601,Settings!$B$2,Transactions!$G$2:$G$601,4,Transactions!$C$2:$C$601,A17),0) | F17: =IFERROR(SUMIFS(Transactions!$F$2:$F$601,Transactions!$H$2:$H$601,Settings!$B$2,Transactions!$G$2:$G$601,5,Transactions!$C$2:$C$601,A17),0) | G17: =IFERROR(SUMIFS(Transactions!$F$2:$F$601,Transactions!$H$2:$H$601,Settings!$B$2,Transactions!$G$2:$G$601,6,Transactions!$C$2:$C$601,A17),0) | H17: =IFERROR(SUMIFS(Transactions!$F$2:$F$601,Transactions!$H$2:$H$601,Settings!$B$2,Transactions!$G$2:$G$601,7,Transactions!$C$2:$C$601,A17),0) | I17: =IFERROR(SUMIFS(Transactions!$F$2:$F$601,Transactions!$H$2:$H$601,Settings!$B$2,Transactions!$G$2:$G$601,8,Transactions!$C$2:$C$601,A17),0) | J17: =IFERROR(SUMIFS(Transactions!$F$2:$F$601,Transactions!$H$2:$H$601,Settings!$B$2,Transactions!$G$2:$G$601,9,Transactions!$C$2:$C$601,A17),0) | K17: =IFERROR(SUMIFS(Transactions!$F$2:$F$601,Transactions!$H$2:$H$601,Settings!$B$2,Transactions!$G$2:$G$601,10,Transactions!$C$2:$C$601,A17),0) | L17: =IFERROR(SUMIFS(Transactions!$F$2:$F$601,Transactions!$H$2:$H$601,Settings!$B$2,Transactions!$G$2:$G$601,11,Transactions!$C$2:$C$601,A17),0) | M17: =IFERROR(SUMIFS(Transactions!$F$2:$F$601,Transactions!$H$2:$H$601,Settings!$B$2,Transactions!$G$2:$G$601,12,Transactions!$C$2:$C$601,A17),0) | N17: =IFERROR(SUM(B17:M17),0) | O17: =IFERROR(VLOOKUP(A17,Settings!$A$30:$C$59,3,FALSE),0)
A18: Groceries | B18: =IFERROR(SUMIFS(Transactions!$F$2:$F$601,Transactions!$H$2:$H$601,Settings!$B$2,Transactions!$G$2:$G$601,1,Transactions!$C$2:$C$601,A18),0) | C18: =IFERROR(SUMIFS(Transactions!$F$2:$F$601,Transactions!$H$2:$H$601,Settings!$B$2,Transactions!$G$2:$G$601,2,Transactions!$C$2:$C$601,A18),0) | D18: =IFERROR(SUMIFS(Transactions!$F$2:$F$601,Transactions!$H$2:$H$601,Settings!$B$2,Transactions!$G$2:$G$601,3,Transactions!$C$2:$C$601,A18),0) | E18: =IFERROR(SUMIFS(Transactions!$F$2:$F$601,Transactions!$H$2:$H$601,Settings!$B$2,Transactions!$G$2:$G$601,4,Transactions!$C$2:$C$601,A18),0) | F18: =IFERROR(SUMIFS(Transactions!$F$2:$F$601,Transactions!$H$2:$H$601,Settings!$B$2,Transactions!$G$2:$G$601,5,Transactions!$C$2:$C$601,A18),0) | G18: =IFERROR(SUMIFS(Transactions!$F$2:$F$601,Transactions!$H$2:$H$601,Settings!$B$2,Transactions!$G$2:$G$601,6,Transactions!$C$2:$C$601,A18),0) | H18: =IFERROR(SUMIFS(Transactions!$F$2:$F$601,Transactions!$H$2:$H$601,Settings!$B$2,Transactions!$G$2:$G$601,7,Transactions!$C$2:$C$601,A18),0) | I18: =IFERROR(SUMIFS(Transactions!$F$2:$F$601,Transactions!$H$2:$H$601,Settings!$B$2,Transactions!$G$2:$G$601,8,Transactions!$C$2:$C$601,A18),0) | J18: =IFERROR(SUMIFS(Transactions!$F$2:$F$601,Transactions!$H$2:$H$601,Settings!$B$2,Transactions!$G$2:$G$601,9,Transactions!$C$2:$C$601,A18),0) | K18: =IFERROR(SUMIFS(Transactions!$F$2:$F$601,Transactions!$H$2:$H$601,Settings!$B$2,Transactions!$G$2:$G$601,10,Transactions!$C$2:$C$601,A18),0) | L18: =IFERROR(SUMIFS(Transactions!$F$2:$F$601,Transactions!$H$2:$H$601,Settings!$B$2,Transactions!$G$2:$G$601,11,Transactions!$C$2:$C$601,A18),0) | M18: =IFERROR(SUMIFS(Transactions!$F$2:$F$601,Transactions!$H$2:$H$601,Settings!$B$2,Transactions!$G$2:$G$601,12,Transactions!$C$2:$C$601,A18),0) | N18: =IFERROR(SUM(B18:M18),0) | O18: =IFERROR(VLOOKUP(A18,Settings!$A$30:$C$59,3,FALSE),0)
A19: Dining Out | B19: =IFERROR(SUMIFS(Transactions!$F$2:$F$601,Transactions!$H$2:$H$601,Settings!$B$2,Transactions!$G$2:$G$601,1,Transactions!$C$2:$C$601,A19),0) | C19: =IFERROR(SUMIFS(Transactions!$F$2:$F$601,Transactions!$H$2:$H$601,Settings!$B$2,Transactions!$G$2:$G$601,2,Transactions!$C$2:$C$601,A19),0) | D19: =IFERROR(SUMIFS(Transactions!$F$2:$F$601,Transactions!$H$2:$H$601,Settings!$B$2,Transactions!$G$2:$G$601,3,Transactions!$C$2:$C$601,A19),0) | E19: =IFERROR(SUMIFS(Transactions!$F$2:$F$601,Transactions!$H$2:$H$601,Settings!$B$2,Transactions!$G$2:$G$601,4,Transactions!$C$2:$C$601,A19),0) | F19: =IFERROR(SUMIFS(Transactions!$F$2:$F$601,Transactions!$H$2:$H$601,Settings!$B$2,Transactions!$G$2:$G$601,5,Transactions!$C$2:$C$601,A19),0) | G19: =IFERROR(SUMIFS(Transactions!$F$2:$F$601,Transactions!$H$2:$H$601,Settings!$B$2,Transactions!$G$2:$G$601,6,Transactions!$C$2:$C$601,A19),0) | H19: =IFERROR(SUMIFS(Transactions!$F$2:$F$601,Transactions!$H$2:$H$601,Settings!$B$2,Transactions!$G$2:$G$601,7,Transactions!$C$2:$C$601,A19),0) | I19: =IFERROR(SUMIFS(Transactions!$F$2:$F$601,Transactions!$H$2:$H$601,Settings!$B$2,Transactions!$G$2:$G$601,8,Transactions!$C$2:$C$601,A19),0) | J19: =IFERROR(SUMIFS(Transactions!$F$2:$F$601,Transactions!$H$2:$H$601,Settings!$B$2,Transactions!$G$2:$G$601,9,Transactions!$C$2:$C$601,A19),0) | K19: =IFERROR(SUMIFS(Transactions!$F$2:$F$601,Transactions!$H$2:$H$601,Settings!$B$2,Transactions!$G$2:$G$601,10,Transactions!$C$2:$C$601,A19),0) | L19: =IFERROR(SUMIFS(Transactions!$F$2:$F$601,Transactions!$H$2:$H$601,Settings!$B$2,Transactions!$G$2:$G$601,11,Transactions!$C$2:$C$601,A19),0) | M19: =IFERROR(SUMIFS(Transactions!$F$2:$F$601,Transactions!$H$2:$H$601,Settings!$B$2,Transactions!$G$2:$G$601,12,Transactions!$C$2:$C$601,A19),0) | N19: =IFERROR(SUM(B19:M19),0) | O19: =IFERROR(VLOOKUP(A19,Settings!$A$30:$C$59,3,FALSE),0)
... A37: Miscellaneous | B37: =IFERROR(SUMIFS(Transactions!$F$2:$F$601,Transactions!$H$2:$H$601,Settings!$B$2,Transactions!$G$2:$G$601,1,Transactions!$C$2:$C$601,A37),0) | C37: =IFERROR(SUMIFS(Transactions!$F$2:$F$601,Transactions!$H$2:$H$601,Settings!$B$2,Transactions!$G$2:$G$601,2,Transactions!$C$2:$C$601,A37),0) | D37: =IFERROR(SUMIFS(Transactions!$F$2:$F$601,Transactions!$H$2:$H$601,Settings!$B$2,Transactions!$G$2:$G$601,3,Transactions!$C$2:$C$601,A37),0) | E37: =IFERROR(SUMIFS(Transactions!$F$2:$F$601,Transactions!$H$2:$H$601,Settings!$B$2,Transactions!$G$2:$G$601,4,Transactions!$C$2:$C$601,A37),0) | F37: =IFERROR(SUMIFS(Transactions!$F$2:$F$601,Transactions!$H$2:$H$601,Settings!$B$2,Transactions!$G$2:$G$601,5,Transactions!$C$2:$C$601,A37),0) | G37: =IFERROR(SUMIFS(Transactions!$F$2:$F$601,Transactions!$H$2:$H$601,Settings!$B$2,Transactions!$G$2:$G$601,6,Transactions!$C$2:$C$601,A37),0) | H37: =IFERROR(SUMIFS(Transactions!$F$2:$F$601,Transactions!$H$2:$H$601,Settings!$B$2,Transactions!$G$2:$G$601,7,Transactions!$C$2:$C$601,A37),0) | I37: =IFERROR(SUMIFS(Transactions!$F$2:$F$601,Transactions!$H$2:$H$601,Settings!$B$2,Transactions!$G$2:$G$601,8,Transactions!$C$2:$C$601,A37),0) | J37: =IFERROR(SUMIFS(Transactions!$F$2:$F$601,Transactions!$H$2:$H$601,Settings!$B$2,Transactions!$G$2:$G$601,9,Transactions!$C$2:$C$601,A37),0) | K37: =IFERROR(SUMIFS(Transactions!$F$2:$F$601,Transactions!$H$2:$H$601,Settings!$B$2,Transactions!$G$2:$G$601,10,Transactions!$C$2:$C$601,A37),0) | L37: =IFERROR(SUMIFS(Transactions!$F$2:$F$601,Transactions!$H$2:$H$601,Settings!$B$2,Transactions!$G$2:$G$601,11,Transactions!$C$2:$C$601,A37),0) | M37: =IFERROR(SUMIFS(Transactions!$F$2:$F$601,Transactions!$H$2:$H$601,Settings!$B$2,Transactions!$G$2:$G$601,12,Transactions!$C$2:$C$601,A37),0) | N37: =IFERROR(SUM(B37:M37),0) | O37: =IFERROR(VLOOKUP(A37,Settings!$A$30:$C$59,3,FALSE),0)

Sheet Jan
A1: Jan 2026 — Budget vs Actual
A2: Category | B2: Budget | C2: Actual | D2: Remaining | E2: % Used
A3: — INCOME —
A4: Salary | B4: =IFERROR(VLOOKUP("Salary",Settings!$A$30:$C$59,3,FALSE),0) | C4: =IFERROR(SUMIFS(Transactions!$F$2:$F$601,Transactions!$H$2:$H$601,Settings!$B$2,Transactions!$G$2:$G$601,1,Transactions!$C$2:$C$601,A4),0)
A5: Partner Income | B5: =IFERROR(VLOOKUP("Partner Income",Settings!$A$30:$C$59,3,FALSE),0) | C5: =IFERROR(SUMIFS(Transactions!$F$2:$F$601,Transactions!$H$2:$H$601,Settings!$B$2,Transactions!$G$2:$G$601,1,Transactions!$C$2:$C$601,A5),0)
A6: Freelance | B6: =IFERROR(VLOOKUP("Freelance",Settings!$A$30:$C$59,3,FALSE),0) | C6: =IFERROR(SUMIFS(Transactions!$F$2:$F$601,Transactions!$H$2:$H$601,Settings!$B$2,Transactions!$G$2:$G$601,1,Transactions!$C$2:$C$601,A6),0)
A7: Business | B7: =IFERROR(VLOOKUP("Business",Settings!$A$30:$C$59,3,FALSE),0) | C7: =IFERROR(SUMIFS(Transactions!$F$2:$F$601,Transactions!$H$2:$H$601,Settings!$B$2,Transactions!$G$2:$G$601,1,Transactions!$C$2:$C$601,A7),0)
A8: Investments | B8: =IFERROR(VLOOKUP("Investments",Settings!$A$30:$C$59,3,FALSE),0) | C8: =IFERROR(SUMIFS(Transactions!$F$2:$F$601,Transactions!$H$2:$H$601,Settings!$B$2,Transactions!$G$2:$G$601,1,Transactions!$C$2:$C$601,A8),0)
A9: Rental Income | B9: =IFERROR(VLOOKUP("Rental Income",Settings!$A$30:$C$59,3,FALSE),0) | C9: =IFERROR(SUMIFS(Transactions!$F$2:$F$601,Transactions!$H$2:$H$601,Settings!$B$2,Transactions!$G$2:$G$601,1,Transactions!$C$2:$C$601,A9),0)
A10: Refunds | B10: =IFERROR(VLOOKUP("Refunds",Settings!$A$30:$C$59,3,FALSE),0) | C10: =IFERROR(SUMIFS(Transactions!$F$2:$F$601,Transactions!$H$2:$H$601,Settings!$B$2,Transactions!$G$2:$G$601,1,Transactions!$C$2:$C$601,A10),0)
A11: Other Income | B11: =IFERROR(VLOOKUP("Other Income",Settings!$A$30:$C$59,3,FALSE),0) | C11: =IFERROR(SUMIFS(Transactions!$F$2:$F$601,Transactions!$H$2:$H$601,Settings!$B$2,Transactions!$G$2:$G$601,1,Transactions!$C$2:$C$601,A11),0)
A12: Total Income | B12: =SUM(B4:B11) | C12: =SUM(C4:C11) | D12: =SUM(D4:D11)
A14: — EXPENSES —
A15: Rent/Mortgage | B15: =IFERROR(VLOOKUP("Rent/Mortgage",Settings!$A$30:$C$59,3,FALSE),0) | C15: =IFERROR(SUMIFS(Transactions!$F$2:$F$601,Transactions!$H$2:$H$601,Settings!$B$2,Transactions!$G$2:$G$601,1,Transactions!$C$2:$C$601,A15),0) | D15: =B15-C15 | E15: =IF(B15=0,0,C15/B15)
A16: Utilities | B16: =IFERROR(VLOOKUP("Utilities",Settings!$A$30:$C$59,3,FALSE),0) | C16: =IFERROR(SUMIFS(Transactions!$F$2:$F$601,Transactions!$H$2:$H$601,Settings!$B$2,Transactions!$G$2:$G$601,1,Transactions!$C$2:$C$601,A16),0) | D16: =B16-C16 | E16: =IF(B16=0,0,C16/B16)
A17: Groceries | B17: =IFERROR(VLOOKUP("Groceries",Settings!$A$30:$C$59,3,FALSE),0) | C17: =IFERROR(SUMIFS(Transactions!$F$2:$F$601,Transactions!$H$2:$H$601,Settings!$B$2,Transactions!$G$2:$G$601,1,Transactions!$C$2:$C$601,A17),0) | D17: =B17-C17 | E17: =IF(B17=0,0,C17/B17)
A18: Dining Out | B18: =IFERROR(VLOOKUP("Dining Out",Settings!$A$30:$C$59,3,FALSE),0) | C18: =IFERROR(SUMIFS(Transactions!$F$2:$F$601,Transactions!$H$2:$H$601,Settings!$B$2,Transactions!$G$2:$G$601,1,Transactions!$C$2:$C$601,A18),0) | D18: =B18-C18 | E18: =IF(B18=0,0,C18/B18)
A19: Transport | B19: =IFERROR(VLOOKUP("Transport",Settings!$A$30:$C$59,3,FALSE),0) | C19: =IFERROR(SUMIFS(Transactions!$F$2:$F$601,Transactions!$H$2:$H$601,Settings!$B$2,Transactions!$G$2:$G$601,1,Transactions!$C$2:$C$601,A19),0) | D19: =B19-C19 | E19: =IF(B19=0,0,C19/B19)
A20: Fuel | B20: =IFERROR(VLOOKUP("Fuel",Settings!$A$30:$C$59,3,FALSE),0) | C20: =IFERROR(SUMIFS(Transactions!$F$2:$F$601,Transactions!$H$2:$H$601,Settings!$B$2,Transactions!$G$2:$G$601,1,Transactions!$C$2:$C$601,A20),0) | D20: =B20-C20 | E20: =IF(B20=0,0,C20/B20)
A21: Car/Auto | B21: =IFERROR(VLOOKUP("Car/Auto",Settings!$A$30:$C$59,3,FALSE),0) | C21: =IFERROR(SUMIFS(Transactions!$F$2:$F$601,Transactions!$H$2:$H$601,Settings!$B$2,Transactions!$G$2:$G$601,1,Transactions!$C$2:$C$601,A21),0) | D21: =B21-C21 | E21: =IF(B21=0,0,C21/B21)
A22: Insurance | B22: =IFERROR(VLOOKUP("Insurance",Settings!$A$30:$C$59,3,FALSE),0) | C22: =IFERROR(SUMIFS(Transactions!$F$2:$F$601,Transactions!$H$2:$H$601,Settings!$B$2,Transactions!$G$2:$G$601,1,Transactions!$C$2:$C$601,A22),0) | D22: =B22-C22 | E22: =IF(B22=0,0,C22/B22)
A23: Health | B23: =IFERROR(VLOOKUP("Health",Settings!$A$30:$C$59,3,FALSE),0) | C23: =IFERROR(SUMIFS(Transactions!$F$2:$F$601,Transactions!$H$2:$H$601,Settings!$B$2,Transactions!$G$2:$G$601,1,Transactions!$C$2:$C$601,A23),0) | D23: =B23-C23 | E23: =IF(B23=0,0,C23/B23)
A24: Phone | B24: =IFERROR(VLOOKUP("Phone",Settings!$A$30:$C$59,3,FALSE),0) | C24: =IFERROR(SUMIFS(Transactions!$F$2:$F$601,Transactions!$H$2:$H$601,Settings!$B$2,Transactions!$G$2:$G$601,1,Transactions!$C$2:$C$601,A24),0) | D24: =B24-C24 | E24: =IF(B24=0,0,C24/B24)
A25: Internet | B25: =IFERROR(VLOOKUP("Internet",Settings!$A$30:$C$59,3,FALSE),0) | C25: =IFERROR(SUMIFS(Transactions!$F$2:$F$601,Transactions!$H$2:$H$601,Settings!$B$2,Transactions!$G$2:$G$601,1,Transactions!$C$2:$C$601,A25),0) | D25: =B25-C25 | E25: =IF(B25=0,0,C25/B25)
A26: Subscriptions | B26: =IFERROR(VLOOKUP("Subscriptions",Settings!$A$30:$C$59,3,FALSE),0) | C26: =IFERROR(SUMIFS(Transactions!$F$2:$F$601,Transactions!$H$2:$H$601,Settings!$B$2,Transactions!$G$2:$G$601,1,Transactions!$C$2:$C$601,A26),0) | D26: =B26-C26 | E26: =IF(B26=0,0,C26/B26)
A27: Entertainment | B27: =IFERROR(VLOOKUP("Entertainment",Settings!$A$30:$C$59,3,FALSE),0) | C27: =IFERROR(SUMIFS(Transactions!$F$2:$F$601,Transactions!$H$2:$H$601,Settings!$B$2,Transactions!$G$2:$G$601,1,Transactions!$C$2:$C$601,A27),0) | D27: =B27-C27 | E27: =IF(B27=0,0,C27/B27)
A28: Shopping | B28: =IFERROR(VLOOKUP("Shopping",Settings!$A$30:$C$59,3,FALSE),0) | C28: =IFERROR(SUMIFS(Transactions!$F$2:$F$601,Transactions!$H$2:$H$601,Settings!$B$2,Transactions!$G$2:$G$601,1,Transactions!$C$2:$C$601,A28),0) | D28: =B28-C28 | E28: =IF(B28=0,0,C28/B28)
A29: Clothing | B29: =IFERROR(VLOOKUP("Clothing",Settings!$A$30:$C$59,3,FALSE),0) | C29: =IFERROR(SUMIFS(Transactions!$F$2:$F$601,Transactions!$H$2:$H$601,Settings!$B$2,Transactions!$G$2:$G$601,1,Transactions!$C$2:$C$601,A29),0) | D29: =B29-C29 | E29: =IF(B29=0,0,C29/B29)
A30: Personal Care | B30: =IFERROR(VLOOKUP("Personal Care",Settings!$A$30:$C$59,3,FALSE),0) | C30: =IFERROR(SUMIFS(Transactions!$F$2:$F$601,Transactions!$H$2:$H$601,Settings!$B$2,Transactions!$G$2:$G$601,1,Transactions!$C$2:$C$601,A30),0) | D30: =B30-C30 | E30: =IF(B30=0,0,C30/B30)
A31: Gym/Fitness | B31: =IFERROR(VLOOKUP("Gym/Fitness",Settings!$A$30:$C$59,3,FALSE),0) | C31: =IFERROR(SUMIFS(Transactions!$F$2:$F$601,Transactions!$H$2:$H$601,Settings!$B$2,Transactions!$G$2:$G$601,1,Transactions!$C$2:$C$601,A31),0) | D31: =B31-C31 | E31: =IF(B31=0,0,C31/B31)
A32: Pets | B32: =IFERROR(VLOOKUP("Pets",Settings!$A$30:$C$59,3,FALSE),0) | C32: =IFERROR(SUMIFS(Transactions!$F$2:$F$601,Transactions!$H$2:$H$601,Settings!$B$2,Transactions!$G$2:$G$601,1,Transactions!$C$2:$C$601,A32),0) | D32: =B32-C32 | E32: =IF(B32=0,0,C32/B32)
A33: Kids | B33: =IFERROR(VLOOKUP("Kids",Settings!$A$30:$C$59,3,FALSE),0) | C33: =IFERROR(SUMIFS(Transactions!$F$2:$F$601,Transactions!$H$2:$H$601,Settings!$B$2,Transactions!$G$2:$G$601,1,Transactions!$C$2:$C$601,A33),0) | D33: =B33-C33 | E33: =IF(B33=0,0,C33/B33)
A34: Gifts/Donations | B34: =IFERROR(VLOOKUP("Gifts/Donations",Settings!$A$30:$C$59,3,FALSE),0) | C34: =IFERROR(SUMIFS(Transactions!$F$2:$F$601,Transactions!$H$2:$H$601,Settings!$B$2,Transactions!$G$2:$G$601,1,Transactions!$C$2:$C$601,A34),0) | D34: =B34-C34 | E34: =IF(B34=0,0,C34/B34)
A35: Travel | B35: =IFERROR(VLOOKUP("Travel",Settings!$A$30:$C$59,3,FALSE),0) | C35: =IFERROR(SUMIFS(Transactions!$F$2:$F$601,Transactions!$H$2:$H$601,Settings!$B$2,Transactions!$G$2:$G$601,1,Transactions!$C$2:$C$601,A35),0) | D35: =B35-C35 | E35: =IF(B35=0,0,C35/B35)
A36: Miscellaneous | B36: =IFERROR(VLOOKUP("Miscellaneous",Settings!$A$30:$C$59,3,FALSE),0) | C36: =IFERROR(SUMIFS(Transactions!$F$2:$F$601,Transactions!$H$2:$H$601,Settings!$B$2,Transactions!$G$2:$G$601,1,Transactions!$C$2:$C$601,A36),0) | D36: =B36-C36 | E36: =IF(B36=0,0,C36/B36)
A37: Total Expenses | B37: =SUM(B15:B36) | C37: =SUM(C15:C36) | D37: =SUM(D15:D36)

Sheet Feb
A1: Feb 2026 — Budget vs Actual
A2: Category | B2: Budget | C2: Actual | D2: Remaining | E2: % Used
A3: — INCOME —
A4: Salary | B4: =IFERROR(VLOOKUP("Salary",Settings!$A$30:$C$59,3,FALSE),0) | C4: =IFERROR(SUMIFS(Transactions!$F$2:$F$601,Transactions!$H$2:$H$601,Settings!$B$2,Transactions!$G$2:$G$601,2,Transactions!$C$2:$C$601,A4),0)
A5: Partner Income | B5: =IFERROR(VLOOKUP("Partner Income",Settings!$A$30:$C$59,3,FALSE),0) | C5: =IFERROR(SUMIFS(Transactions!$F$2:$F$601,Transactions!$H$2:$H$601,Settings!$B$2,Transactions!$G$2:$G$601,2,Transactions!$C$2:$C$601,A5),0)
A6: Freelance | B6: =IFERROR(VLOOKUP("Freelance",Settings!$A$30:$C$59,3,FALSE),0) | C6: =IFERROR(SUMIFS(Transactions!$F$2:$F$601,Transactions!$H$2:$H$601,Settings!$B$2,Transactions!$G$2:$G$601,2,Transactions!$C$2:$C$601,A6),0)
A7: Business | B7: =IFERROR(VLOOKUP("Business",Settings!$A$30:$C$59,3,FALSE),0) | C7: =IFERROR(SUMIFS(Transactions!$F$2:$F$601,Transactions!$H$2:$H$601,Settings!$B$2,Transactions!$G$2:$G$601,2,Transactions!$C$2:$C$601,A7),0)
A8: Investments | B8: =IFERROR(VLOOKUP("Investments",Settings!$A$30:$C$59,3,FALSE),0) | C8: =IFERROR(SUMIFS(Transactions!$F$2:$F$601,Transactions!$H$2:$H$601,Settings!$B$2,Transactions!$G$2:$G$601,2,Transactions!$C$2:$C$601,A8),0)
A9: Rental Income | B9: =IFERROR(VLOOKUP("Rental Income",Settings!$A$30:$C$59,3,FALSE),0) | C9: =IFERROR(SUMIFS(Transactions!$F$2:$F$601,Transactions!$H$2:$H$601,Settings!$B$2,Transactions!$G$2:$G$601,2,Transactions!$C$2:$C$601,A9),0)
A10: Refunds | B10: =IFERROR(VLOOKUP("Refunds",Settings!$A$30:$C$59,3,FALSE),0) | C10: =IFERROR(SUMIFS(Transactions!$F$2:$F$601,Transactions!$H$2:$H$601,Settings!$B$2,Transactions!$G$2:$G$601,2,Transactions!$C$2:$C$601,A10),0)
A11: Other Income | B11: =IFERROR(VLOOKUP("Other Income",Settings!$A$30:$C$59,3,FALSE),0) | C11: =IFERROR(SUMIFS(Transactions!$F$2:$F$601,Transactions!$H$2:$H$601,Settings!$B$2,Transactions!$G$2:$G$601,2,Transactions!$C$2:$C$601,A11),0)
A12: Total Income | B12: =SUM(B4:B11) | C12: =SUM(C4:C11) | D12: =SUM(D4:D11)
A14: — EXPENSES —
A15: Rent/Mortgage | B15: =IFERROR(VLOOKUP("Rent/Mortgage",Settings!$A$30:$C$59,3,FALSE),0) | C15: =IFERROR(SUMIFS(Transactions!$F$2:$F$601,Transactions!$H$2:$H$601,Settings!$B$2,Transactions!$G$2:$G$601,2,Transactions!$C$2:$C$601,A15),0) | D15: =B15-C15 | E15: =IF(B15=0,0,C15/B15)
A16: Utilities | B16: =IFERROR(VLOOKUP("Utilities",Settings!$A$30:$C$59,3,FALSE),0) | C16: =IFERROR(SUMIFS(Transactions!$F$2:$F$601,Transactions!$H$2:$H$601,Settings!$B$2,Transactions!$G$2:$G$601,2,Transactions!$C$2:$C$601,A16),0) | D16: =B16-C16 | E16: =IF(B16=0,0,C16/B16)
A17: Groceries | B17: =IFERROR(VLOOKUP("Groceries",Settings!$A$30:$C$59,3,FALSE),0) | C17: =IFERROR(SUMIFS(Transactions!$F$2:$F$601,Transactions!$H$2:$H$601,Settings!$B$2,Transactions!$G$2:$G$601,2,Transactions!$C$2:$C$601,A17),0) | D17: =B17-C17 | E17: =IF(B17=0,0,C17/B17)
A18: Dining Out | B18: =IFERROR(VLOOKUP("Dining Out",Settings!$A$30:$C$59,3,FALSE),0) | C18: =IFERROR(SUMIFS(Transactions!$F$2:$F$601,Transactions!$H$2:$H$601,Settings!$B$2,Transactions!$G$2:$G$601,2,Transactions!$C$2:$C$601,A18),0) | D18: =B18-C18 | E18: =IF(B18=0,0,C18/B18)
A19: Transport | B19: =IFERROR(VLOOKUP("Transport",Settings!$A$30:$C$59,3,FALSE),0) | C19: =IFERROR(SUMIFS(Transactions!$F$2:$F$601,Transactions!$H$2:$H$601,Settings!$B$2,Transactions!$G$2:$G$601,2,Transactions!$C$2:$C$601,A19),0) | D19: =B19-C19 | E19: =IF(B19=0,0,C19/B19)
A20: Fuel | B20: =IFERROR(VLOOKUP("Fuel",Settings!$A$30:$C$59,3,FALSE),0) | C20: =IFERROR(SUMIFS(Transactions!$F$2:$F$601,Transactions!$H$2:$H$601,Settings!$B$2,Transactions!$G$2:$G$601,2,Transactions!$C$2:$C$601,A20),0) | D20: =B20-C20 | E20: =IF(B20=0,0,C20/B20)
A21: Car/Auto | B21: =IFERROR(VLOOKUP("Car/Auto",Settings!$A$30:$C$59,3,FALSE),0) | C21: =IFERROR(SUMIFS(Transactions!$F$2:$F$601,Transactions!$H$2:$H$601,Settings!$B$2,Transactions!$G$2:$G$601,2,Transactions!$C$2:$C$601,A21),0) | D21: =B21-C21 | E21: =IF(B21=0,0,C21/B21)
A22: Insurance | B22: =IFERROR(VLOOKUP("Insurance",Settings!$A$30:$C$59,3,FALSE),0) | C22: =IFERROR(SUMIFS(Transactions!$F$2:$F$601,Transactions!$H$2:$H$601,Settings!$B$2,Transactions!$G$2:$G$601,2,Transactions!$C$2:$C$601,A22),0) | D22: =B22-C22 | E22: =IF(B22=0,0,C22/B22)
A23: Health | B23: =IFERROR(VLOOKUP("Health",Settings!$A$30:$C$59,3,FALSE),0) | C23: =IFERROR(SUMIFS(Transactions!$F$2:$F$601,Transactions!$H$2:$H$601,Settings!$B$2,Transactions!$G$2:$G$601,2,Transactions!$C$2:$C$601,A23),0) | D23: =B23-C23 | E23: =IF(B23=0,0,C23/B23)
A24: Phone | B24: =IFERROR(VLOOKUP("Phone",Settings!$A$30:$C$59,3,FALSE),0) | C24: =IFERROR(SUMIFS(Transactions!$F$2:$F$601,Transactions!$H$2:$H$601,Settings!$B$2,Transactions!$G$2:$G$601,2,Transactions!$C$2:$C$601,A24),0) | D24: =B24-C24 | E24: =IF(B24=0,0,C24/B24)
A25: Internet | B25: =IFERROR(VLOOKUP("Internet",Settings!$A$30:$C$59,3,FALSE),0) | C25: =IFERROR(SUMIFS(Transactions!$F$2:$F$601,Transactions!$H$2:$H$601,Settings!$B$2,Transactions!$G$2:$G$601,2,Transactions!$C$2:$C$601,A25),0) | D25: =B25-C25 | E25: =IF(B25=0,0,C25/B25)
A26: Subscriptions | B26: =IFERROR(VLOOKUP("Subscriptions",Settings!$A$30:$C$59,3,FALSE),0) | C26: =IFERROR(SUMIFS(Transactions!$F$2:$F$601,Transactions!$H$2:$H$601,Settings!$B$2,Transactions!$G$2:$G$601,2,Transactions!$C$2:$C$601,A26),0) | D26: =B26-C26 | E26: =IF(B26=0,0,C26/B26)
A27: Entertainment | B27: =IFERROR(VLOOKUP("Entertainment",Settings!$A$30:$C$59,3,FALSE),0) | C27: =IFERROR(SUMIFS(Transactions!$F$2:$F$601,Transactions!$H$2:$H$601,Settings!$B$2,Transactions!$G$2:$G$601,2,Transactions!$C$2:$C$601,A27),0) | D27: =B27-C27 | E27: =IF(B27=0,0,C27/B27)
A28: Shopping | B28: =IFERROR(VLOOKUP("Shopping",Settings!$A$30:$C$59,3,FALSE),0) | C28: =IFERROR(SUMIFS(Transactions!$F$2:$F$601,Transactions!$H$2:$H$601,Settings!$B$2,Transactions!$G$2:$G$601,2,Transactions!$C$2:$C$601,A28),0) | D28: =B28-C28 | E28: =IF(B28=0,0,C28/B28)
A29: Clothing | B29: =IFERROR(VLOOKUP("Clothing",Settings!$A$30:$C$59,3,FALSE),0) | C29: =IFERROR(SUMIFS(Transactions!$F$2:$F$601,Transactions!$H$2:$H$601,Settings!$B$2,Transactions!$G$2:$G$601,2,Transactions!$C$2:$C$601,A29),0) | D29: =B29-C29 | E29: =IF(B29=0,0,C29/B29)
A30: Personal Care | B30: =IFERROR(VLOOKUP("Personal Care",Settings!$A$30:$C$59,3,FALSE),0) | C30: =IFERROR(SUMIFS(Transactions!$F$2:$F$601,Transactions!$H$2:$H$601,Settings!$B$2,Transactions!$G$2:$G$601,2,Transactions!$C$2:$C$601,A30),0) | D30: =B30-C30 | E30: =IF(B30=0,0,C30/B30)
A31: Gym/Fitness | B31: =IFERROR(VLOOKUP("Gym/Fitness",Settings!$A$30:$C$59,3,FALSE),0) | C31: =IFERROR(SUMIFS(Transactions!$F$2:$F$601,Transactions!$H$2:$H$601,Settings!$B$2,Transactions!$G$2:$G$601,2,Transactions!$C$2:$C$601,A31),0) | D31: =B31-C31 | E31: =IF(B31=0,0,C31/B31)
A32: Pets | B32: =IFERROR(VLOOKUP("Pets",Settings!$A$30:$C$59,3,FALSE),0) | C32: =IFERROR(SUMIFS(Transactions!$F$2:$F$601,Transactions!$H$2:$H$601,Settings!$B$2,Transactions!$G$2:$G$601,2,Transactions!$C$2:$C$601,A32),0) | D32: =B32-C32 | E32: =IF(B32=0,0,C32/B32)
A33: Kids | B33: =IFERROR(VLOOKUP("Kids",Settings!$A$30:$C$59,3,FALSE),0) | C33: =IFERROR(SUMIFS(Transactions!$F$2:$F$601,Transactions!$H$2:$H$601,Settings!$B$2,Transactions!$G$2:$G$601,2,Transactions!$C$2:$C$601,A33),0) | D33: =B33-C33 | E33: =IF(B33=0,0,C33/B33)
A34: Gifts/Donations | B34: =IFERROR(VLOOKUP("Gifts/Donations",Settings!$A$30:$C$59,3,FALSE),0) | C34: =IFERROR(SUMIFS(Transactions!$F$2:$F$601,Transactions!$H$2:$H$601,Settings!$B$2,Transactions!$G$2:$G$601,2,Transactions!$C$2:$C$601,A34),0) | D34: =B34-C34 | E34: =IF(B34=0,0,C34/B34)
A35: Travel | B35: =IFERROR(VLOOKUP("Travel",Settings!$A$30:$C$59,3,FALSE),0) | C35: =IFERROR(SUMIFS(Transactions!$F$2:$F$601,Transactions!$H$2:$H$601,Settings!$B$2,Transactions!$G$2:$G$601,2,Transactions!$C$2:$C$601,A35),0) | D35: =B35-C35 | E35: =IF(B35=0,0,C35/B35)
A36: Miscellaneous | B36: =IFERROR(VLOOKUP("Miscellaneous",Settings!$A$30:$C$59,3,FALSE),0) | C36: =IFERROR(SUMIFS(Transactions!$F$2:$F$601,Transactions!$H$2:$H$601,Settings!$B$2,Transactions!$G$2:$G$601,2,Transactions!$C$2:$C$601,A36),0) | D36: =B36-C36 | E36: =IF(B36=0,0,C36/B36)
A37: Total Expenses | B37: =SUM(B15:B36) | C37: =SUM(C15:C36) | D37: =SUM(D15:D36)

Sheet Mar
A1: Mar 2026 — Budget vs Actual
A2: Category | B2: Budget | C2: Actual | D2: Remaining | E2: % Used
A3: — INCOME —
A4: Salary | B4: =IFERROR(VLOOKUP("Salary",Settings!$A$30:$C$59,3,FALSE),0) | C4: =IFERROR(SUMIFS(Transactions!$F$2:$F$601,Transactions!$H$2:$H$601,Settings!$B$2,Transactions!$G$2:$G$601,3,Transactions!$C$2:$C$601,A4),0)
A5: Partner Income | B5: =IFERROR(VLOOKUP("Partner Income",Settings!$A$30:$C$59,3,FALSE),0) | C5: =IFERROR(SUMIFS(Transactions!$F$2:$F$601,Transactions!$H$2:$H$601,Settings!$B$2,Transactions!$G$2:$G$601,3,Transactions!$C$2:$C$601,A5),0)
A6: Freelance | B6: =IFERROR(VLOOKUP("Freelance",Settings!$A$30:$C$59,3,FALSE),0) | C6: =IFERROR(SUMIFS(Transactions!$F$2:$F$601,Transactions!$H$2:$H$601,Settings!$B$2,Transactions!$G$2:$G$601,3,Transactions!$C$2:$C$601,A6),0)
A7: Business | B7: =IFERROR(VLOOKUP("Business",Settings!$A$30:$C$59,3,FALSE),0) | C7: =IFERROR(SUMIFS(Transactions!$F$2:$F$601,Transactions!$H$2:$H$601,Settings!$B$2,Transactions!$G$2:$G$601,3,Transactions!$C$2:$C$601,A7),0)
A8: Investments | B8: =IFERROR(VLOOKUP("Investments",Settings!$A$30:$C$59,3,FALSE),0) | C8: =IFERROR(SUMIFS(Transactions!$F$2:$F$601,Transactions!$H$2:$H$601,Settings!$B$2,Transactions!$G$2:$G$601,3,Transactions!$C$2:$C$601,A8),0)
A9: Rental Income | B9: =IFERROR(VLOOKUP("Rental Income",Settings!$A$30:$C$59,3,FALSE),0) | C9: =IFERROR(SUMIFS(Transactions!$F$2:$F$601,Transactions!$H$2:$H$601,Settings!$B$2,Transactions!$G$2:$G$601,3,Transactions!$C$2:$C$601,A9),0)
A10: Refunds | B10: =IFERROR(VLOOKUP("Refunds",Settings!$A$30:$C$59,3,FALSE),0) | C10: =IFERROR(SUMIFS(Transactions!$F$2:$F$601,Transactions!$H$2:$H$601,Settings!$B$2,Transactions!$G$2:$G$601,3,Transactions!$C$2:$C$601,A10),0)
A11: Other Income | B11: =IFERROR(VLOOKUP("Other Income",Settings!$A$30:$C$59,3,FALSE),0) | C11: =IFERROR(SUMIFS(Transactions!$F$2:$F$601,Transactions!$H$2:$H$601,Settings!$B$2,Transactions!$G$2:$G$601,3,Transactions!$C$2:$C$601,A11),0)
A12: Total Income | B12: =SUM(B4:B11) | C12: =SUM(C4:C11) | D12: =SUM(D4:D11)
A14: — EXPENSES —
A15: Rent/Mortgage | B15: =IFERROR(VLOOKUP("Rent/Mortgage",Settings!$A$30:$C$59,3,FALSE),0) | C15: =IFERROR(SUMIFS(Transactions!$F$2:$F$601,Transactions!$H$2:$H$601,Settings!$B$2,Transactions!$G$2:$G$601,3,Transactions!$C$2:$C$601,A15),0) | D15: =B15-C15 | E15: =IF(B15=0,0,C15/B15)
A16: Utilities | B16: =IFERROR(VLOOKUP("Utilities",Settings!$A$30:$C$59,3,FALSE),0) | C16: =IFERROR(SUMIFS(Transactions!$F$2:$F$601,Transactions!$H$2:$H$601,Settings!$B$2,Transactions!$G$2:$G$601,3,Transactions!$C$2:$C$601,A16),0) | D16: =B16-C16 | E16: =IF(B16=0,0,C16/B16)
A17: Groceries | B17: =IFERROR(VLOOKUP("Groceries",Settings!$A$30:$C$59,3,FALSE),0) | C17: =IFERROR(SUMIFS(Transactions!$F$2:$F$601,Transactions!$H$2:$H$601,Settings!$B$2,Transactions!$G$2:$G$601,3,Transactions!$C$2:$C$601,A17),0) | D17: =B17-C17 | E17: =IF(B17=0,0,C17/B17)
A18: Dining Out | B18: =IFERROR(VLOOKUP("Dining Out",Settings!$A$30:$C$59,3,FALSE),0) | C18: =IFERROR(SUMIFS(Transactions!$F$2:$F$601,Transactions!$H$2:$H$601,Settings!$B$2,Transactions!$G$2:$G$601,3,Transactions!$C$2:$C$601,A18),0) | D18: =B18-C18 | E18: =IF(B18=0,0,C18/B18)
A19: Transport | B19: =IFERROR(VLOOKUP("Transport",Settings!$A$30:$C$59,3,FALSE),0) | C19: =IFERROR(SUMIFS(Transactions!$F$2:$F$601,Transactions!$H$2:$H$601,Settings!$B$2,Transactions!$G$2:$G$601,3,Transactions!$C$2:$C$601,A19),0) | D19: =B19-C19 | E19: =IF(B19=0,0,C19/B19)
A20: Fuel | B20: =IFERROR(VLOOKUP("Fuel",Settings!$A$30:$C$59,3,FALSE),0) | C20: =IFERROR(SUMIFS(Transactions!$F$2:$F$601,Transactions!$H$2:$H$601,Settings!$B$2,Transactions!$G$2:$G$601,3,Transactions!$C$2:$C$601,A20),0) | D20: =B20-C20 | E20: =IF(B20=0,0,C20/B20)
A21: Car/Auto | B21: =IFERROR(VLOOKUP("Car/Auto",Settings!$A$30:$C$59,3,FALSE),0) | C21: =IFERROR(SUMIFS(Transactions!$F$2:$F$601,Transactions!$H$2:$H$601,Settings!$B$2,Transactions!$G$2:$G$601,3,Transactions!$C$2:$C$601,A21),0) | D21: =B21-C21 | E21: =IF(B21=0,0,C21/B21)
A22: Insurance | B22: =IFERROR(VLOOKUP("Insurance",Settings!$A$30:$C$59,3,FALSE),0) | C22: =IFERROR(SUMIFS(Transactions!$F$2:$F$601,Transactions!$H$2:$H$601,Settings!$B$2,Transactions!$G$2:$G$601,3,Transactions!$C$2:$C$601,A22),0) | D22: =B22-C22 | E22: =IF(B22=0,0,C22/B22)
A23: Health | B23: =IFERROR(VLOOKUP("Health",Settings!$A$30:$C$59,3,FALSE),0) | C23: =IFERROR(SUMIFS(Transactions!$F$2:$F$601,Transactions!$H$2:$H$601,Settings!$B$2,Transactions!$G$2:$G$601,3,Transactions!$C$2:$C$601,A23),0) | D23: =B23-C23 | E23: =IF(B23=0,0,C23/B23)
A24: Phone | B24: =IFERROR(VLOOKUP("Phone",Settings!$A$30:$C$59,3,FALSE),0) | C24: =IFERROR(SUMIFS(Transactions!$F$2:$F$601,Transactions!$H$2:$H$601,Settings!$B$2,Transactions!$G$2:$G$601,3,Transactions!$C$2:$C$601,A24),0) | D24: =B24-C24 | E24: =IF(B24=0,0,C24/B24)
A25: Internet | B25: =IFERROR(VLOOKUP("Internet",Settings!$A$30:$C$59,3,FALSE),0) | C25: =IFERROR(SUMIFS(Transactions!$F$2:$F$601,Transactions!$H$2:$H$601,Settings!$B$2,Transactions!$G$2:$G$601,3,Transactions!$C$2:$C$601,A25),0) | D25: =B25-C25 | E25: =IF(B25=0,0,C25/B25)
A26: Subscriptions | B26: =IFERROR(VLOOKUP("Subscriptions",Settings!$A$30:$C$59,3,FALSE),0) | C26: =IFERROR(SUMIFS(Transactions!$F$2:$F$601,Transactions!$H$2:$H$601,Settings!$B$2,Transactions!$G$2:$G$601,3,Transactions!$C$2:$C$601,A26),0) | D26: =B26-C26 | E26: =IF(B26=0,0,C26/B26)
A27: Entertainment | B27: =IFERROR(VLOOKUP("Entertainment",Settings!$A$30:$C$59,3,FALSE),0) | C27: =IFERROR(SUMIFS(Transactions!$F$2:$F$601,Transactions!$H$2:$H$601,Settings!$B$2,Transactions!$G$2:$G$601,3,Transactions!$C$2:$C$601,A27),0) | D27: =B27-C27 | E27: =IF(B27=0,0,C27/B27)
A28: Shopping | B28: =IFERROR(VLOOKUP("Shopping",Settings!$A$30:$C$59,3,FALSE),0) | C28: =IFERROR(SUMIFS(Transactions!$F$2:$F$601,Transactions!$H$2:$H$601,Settings!$B$2,Transactions!$G$2:$G$601,3,Transactions!$C$2:$C$601,A28),0) | D28: =B28-C28 | E28: =IF(B28=0,0,C28/B28)
A29: Clothing | B29: =IFERROR(VLOOKUP("Clothing",Settings!$A$30:$C$59,3,FALSE),0) | C29: =IFERROR(SUMIFS(Transactions!$F$2:$F$601,Transactions!$H$2:$H$601,Settings!$B$2,Transactions!$G$2:$G$601,3,Transactions!$C$2:$C$601,A29),0) | D29: =B29-C29 | E29: =IF(B29=0,0,C29/B29)
A30: Personal Care | B30: =IFERROR(VLOOKUP("Personal Care",Settings!$A$30:$C$59,3,FALSE),0) | C30: =IFERROR(SUMIFS(Transactions!$F$2:$F$601,Transactions!$H$2:$H$601,Settings!$B$2,Transactions!$G$2:$G$601,3,Transactions!$C$2:$C$601,A30),0) | D30: =B30-C30 | E30: =IF(B30=0,0,C30/B30)
A31: Gym/Fitness | B31: =IFERROR(VLOOKUP("Gym/Fitness",Settings!$A$30:$C$59,3,FALSE),0) | C31: =IFERROR(SUMIFS(Transactions!$F$2:$F$601,Transactions!$H$2:$H$601,Settings!$B$2,Transactions!$G$2:$G$601,3,Transactions!$C$2:$C$601,A31),0) | D31: =B31-C31 | E31: =IF(B31=0,0,C31/B31)
A32: Pets | B32: =IFERROR(VLOOKUP("Pets",Settings!$A$30:$C$59,3,FALSE),0) | C32: =IFERROR(SUMIFS(Transactions!$F$2:$F$601,Transactions!$H$2:$H$601,Settings!$B$2,Transactions!$G$2:$G$601,3,Transactions!$C$2:$C$601,A32),0) | D32: =B32-C32 | E32: =IF(B32=0,0,C32/B32)
A33: Kids | B33: =IFERROR(VLOOKUP("Kids",Settings!$A$30:$C$59,3,FALSE),0) | C33: =IFERROR(SUMIFS(Transactions!$F$2:$F$601,Transactions!$H$2:$H$601,Settings!$B$2,Transactions!$G$2:$G$601,3,Transactions!$C$2:$C$601,A33),0) | D33: =B33-C33 | E33: =IF(B33=0,0,C33/B33)
