Workbook

Sheet Dashboard
A1: PERSONAL FINANCE COMMAND CENTER · 2026
A2: Live Summary Dashboard
A3: BUDGET SUMMARY | F3: SAVINGS SNAPSHOT
A4: METRIC | C4: VALUE | F4: GOAL | H4: AMOUNT
A5: Annual Income | C5: 0 | F5: Emergency Fund Goal | H5: 0
A6: Monthly Income | C6: =IFERROR(D5/12,0) | F6: Emergency Fund Current | H6: 0
A7: This Month Expenses | C7: =IFERROR(Jan!D65,0) | F7: % Funded | H7: =IFERROR(H6/H5,0)
A8: Left to Spend | C8: =IFERROR(D6-D7,0) | F8: Monthly Target | H8: 0
A9: Annual Savings Rate | C9: =IFERROR(IFERROR(D6-D7,0)/IFERROR(D6,1),0) | F9: YTD Saved | H9: =IFERROR(Jan!D57+Feb!D57+Mar!D57+Apr!D57+May!D57+Jun!D57+Jul!D57+Aug!D57+Sep!D57+Oct!D57+Nov!D57+Dec!D57,0)
A10: YTD Total Savings | C10: =IFERROR(Jan!D57+Feb!D57+Mar!D57+Apr!D57+May!D57+Jun!D57+Jul!D57+Aug!D57+Sep!D57+Oct!D57+Nov!D57+Dec!D57,0)
A15: TOP EXPENSE CATEGORIES — JANUARY | F15: BILLS THIS MONTH
A16: CATEGORY | B16: BUDGETED | C16: ACTUAL | F16: BILL NAME | G16: AMOUNT | H16: DUE DATE
A17: HOUSING | B17: =IFERROR(Jan!C15,0) | C17: =IFERROR(Jan!D15,0) | F17: Rent/Mortgage | G17: 1200 | H17: 01/01/2026
A18: TRANSPORT | B18: =IFERROR(Jan!C22,0) | C18: =IFERROR(Jan!D22,0) | F18: Electricity | G18: 80 | H18: 01/15/2026
A19: FOOD & DINING | B19: =IFERROR(Jan!C29,0) | C19: =IFERROR(Jan!D29,0) | F19: Internet | G19: 60 | H19: 01/22/2026
A20: HEALTH & WELLNESS | B20: =IFERROR(Jan!C36,0) | C20: =IFERROR(Jan!D36,0) | F20: Streaming | G20: 18 | H20: 01/08/2026
A21: LIFESTYLE | B21: =IFERROR(Jan!C43,0) | C21: =IFERROR(Jan!D43,0) | F21: Phone | G21: 70 | H21: 01/12/2026
A22: PERSONAL | B22: =IFERROR(Jan!C50,0) | C22: =IFERROR(Jan!D50,0) | F22: Car Insurance | G22: 120 | H22: 01/20/2026
A25: INSERT CHART — Annual Income vs Expenses (from Annual Overview)

Sheet Jan
A1: JANUARY · MONTHLY BUDGET
A2: Track your income and expenses for January
A3: CATEGORY | B3: SUBCATEGORY | C3: BUDGETED | D3: ACTUAL | E3: DIFFERENCE | F3: % USED | G3: NOTES
A4: INCOME
A5: INCOME | B5: Primary Income | C5: 0 | D5: 0 | E5: =IFERROR(C5-D5,0) | F5: =IFERROR(D5/C5,0)
A6: INCOME | B6: Side Income | C6: 0 | D6: 0 | E6: =IFERROR(C6-D6,0) | F6: =IFERROR(D6/C6,0)
A7: INCOME | B7: Other Income | C7: 0 | D7: 0 | E7: =IFERROR(C7-D7,0) | F7: =IFERROR(D7/C7,0)
A8: TOTAL INCOME | C8: =SUM(C5:C7) | D8: =SUM(D5:D7) | E8: =IFERROR(C8-D8,0) | F8: =IFERROR(D8/C8,0)
A9: HOUSING
A10: HOUSING | B10: Rent/Mortgage | C10: 0 | D10: 0 | E10: =IFERROR(C10-D10,0) | F10: =IFERROR(D10/C10,0)
A11: HOUSING | B11: Utilities | C11: 0 | D11: 0 | E11: =IFERROR(C11-D11,0) | F11: =IFERROR(D11/C11,0)
A12: HOUSING | B12: Electricity | C12: 0 | D12: 0 | E12: =IFERROR(C12-D12,0) | F12: =IFERROR(D12/C12,0)
A13: HOUSING | B13: Internet | C13: 0 | D13: 0 | E13: =IFERROR(C13-D13,0) | F13: =IFERROR(D13/C13,0)
A14: HOUSING | B14: Home Insurance | C14: 0 | D14: 0 | E14: =IFERROR(C14-D14,0) | F14: =IFERROR(D14/C14,0)
A15: HOUSING TOTAL | C15: =SUM(C10:C14) | D15: =SUM(D10:D14) | E15: =IFERROR(C15-D15,0) | F15: =IFERROR(D15/C15,0)
A16: TRANSPORT
A17: TRANSPORT | B17: Car Payment | C17: 0 | D17: 0 | E17: =IFERROR(C17-D17,0) | F17: =IFERROR(D17/C17,0)
A18: TRANSPORT | B18: Fuel | C18: 0 | D18: 0 | E18: =IFERROR(C18-D18,0) | F18: =IFERROR(D18/C18,0)
A19: TRANSPORT | B19: Car Insurance | C19: 0 | D19: 0 | E19: =IFERROR(C19-D19,0) | F19: =IFERROR(D19/C19,0)
A20: TRANSPORT | B20: Parking | C20: 0 | D20: 0 | E20: =IFERROR(C20-D20,0) | F20: =IFERROR(D20/C20,0)
A21: TRANSPORT | B21: Public Transport | C21: 0 | D21: 0 | E21: =IFERROR(C21-D21,0) | F21: =IFERROR(D21/C21,0)
A22: TRANSPORT TOTAL | C22: =SUM(C17:C21) | D22: =SUM(D17:D21) | E22: =IFERROR(C22-D22,0) | F22: =IFERROR(D22/C22,0)
A23: FOOD & DINING
A24: FOOD & DINING | B24: Groceries | C24: 0 | D24: 0 | E24: =IFERROR(C24-D24,0) | F24: =IFERROR(D24/C24,0)
A25: FOOD & DINING | B25: Restaurants | C25: 0 | D25: 0 | E25: =IFERROR(C25-D25,0) | F25: =IFERROR(D25/C25,0)
A26: FOOD & DINING | B26: Coffee | C26: 0 | D26: 0 | E26: =IFERROR(C26-D26,0) | F26: =IFERROR(D26/C26,0)
A27: FOOD & DINING | B27: Food Delivery | C27: 0 | D27: 0 | E27: =IFERROR(C27-D27,0) | F27: =IFERROR(D27/C27,0)
A28: FOOD & DINING | B28: Work Lunch | C28: 0 | D28: 0 | E28: =IFERROR(C28-D28,0) | F28: =IFERROR(D28/C28,0)
A29: FOOD & DINING TOTAL | C29: =SUM(C24:C28) | D29: =SUM(D24:D28) | E29: =IFERROR(C29-D29,0) | F29: =IFERROR(D29/C29,0)
A30: HEALTH & WELLNESS
A31: HEALTH & WELLNESS | B31: Health Insurance | C31: 0 | D31: 0 | E31: =IFERROR(C31-D31,0) | F31: =IFERROR(D31/C31,0)
A32: HEALTH & WELLNESS | B32: Gym | C32: 0 | D32: 0 | E32: =IFERROR(C32-D32,0) | F32: =IFERROR(D32/C32,0)
A33: HEALTH & WELLNESS | B33: Pharmacy | C33: 0 | D33: 0 | E33: =IFERROR(C33-D33,0) | F33: =IFERROR(D33/C33,0)
A34: HEALTH & WELLNESS | B34: Doctor | C34: 0 | D34: 0 | E34: =IFERROR(C34-D34,0) | F34: =IFERROR(D34/C34,0)
A35: HEALTH & WELLNESS | B35: Dental | C35: 0 | D35: 0 | E35: =IFERROR(C35-D35,0) | F35: =IFERROR(D35/C35,0)
A36: HEALTH & WELLNESS TOTAL | C36: =SUM(C31:C35) | D36: =SUM(D31:D35) | E36: =IFERROR(C36-D36,0) | F36: =IFERROR(D36/C36,0)
A37: LIFESTYLE
A38: LIFESTYLE | B38: Streaming Services | C38: 0 | D38: 0 | E38: =IFERROR(C38-D38,0) | F38: =IFERROR(D38/C38,0)
A39: LIFESTYLE | B39: Entertainment | C39: 0 | D39: 0 | E39: =IFERROR(C39-D39,0) | F39: =IFERROR(D39/C39,0)
A40: LIFESTYLE | B40: Hobbies | C40: 0 | D40: 0 | E40: =IFERROR(C40-D40,0) | F40: =IFERROR(D40/C40,0)
...

Sheet Feb
A1: FEBRUARY · MONTHLY BUDGET
A2: Track your income and expenses for February
A3: CATEGORY | B3: SUBCATEGORY | C3: BUDGETED | D3: ACTUAL | E3: DIFFERENCE | F3: % USED | G3: NOTES
A4: INCOME
A5: INCOME | B5: Primary Income | C5: 0 | D5: 0 | E5: =IFERROR(C5-D5,0) | F5: =IFERROR(D5/C5,0)
A6: INCOME | B6: Side Income | C6: 0 | D6: 0 | E6: =IFERROR(C6-D6,0) | F6: =IFERROR(D6/C6,0)
A7: INCOME | B7: Other Income | C7: 0 | D7: 0 | E7: =IFERROR(C7-D7,0) | F7: =IFERROR(D7/C7,0)
A8: TOTAL INCOME | C8: =SUM(C5:C7) | D8: =SUM(D5:D7) | E8: =IFERROR(C8-D8,0) | F8: =IFERROR(D8/C8,0)
A9: HOUSING
A10: HOUSING | B10: Rent/Mortgage | C10: 0 | D10: 0 | E10: =IFERROR(C10-D10,0) | F10: =IFERROR(D10/C10,0)
A11: HOUSING | B11: Utilities | C11: 0 | D11: 0 | E11: =IFERROR(C11-D11,0) | F11: =IFERROR(D11/C11,0)
A12: HOUSING | B12: Electricity | C12: 0 | D12: 0 | E12: =IFERROR(C12-D12,0) | F12: =IFERROR(D12/C12,0)
A13: HOUSING | B13: Internet | C13: 0 | D13: 0 | E13: =IFERROR(C13-D13,0) | F13: =IFERROR(D13/C13,0)
A14: HOUSING | B14: Home Insurance | C14: 0 | D14: 0 | E14: =IFERROR(C14-D14,0) | F14: =IFERROR(D14/C14,0)
A15: HOUSING TOTAL | C15: =SUM(C10:C14) | D15: =SUM(D10:D14) | E15: =IFERROR(C15-D15,0) | F15: =IFERROR(D15/C15,0)
A16: TRANSPORT
A17: TRANSPORT | B17: Car Payment | C17: 0 | D17: 0 | E17: =IFERROR(C17-D17,0) | F17: =IFERROR(D17/C17,0)
A18: TRANSPORT | B18: Fuel | C18: 0 | D18: 0 | E18: =IFERROR(C18-D18,0) | F18: =IFERROR(D18/C18,0)
A19: TRANSPORT | B19: Car Insurance | C19: 0 | D19: 0 | E19: =IFERROR(C19-D19,0) | F19: =IFERROR(D19/C19,0)
A20: TRANSPORT | B20: Parking | C20: 0 | D20: 0 | E20: =IFERROR(C20-D20,0) | F20: =IFERROR(D20/C20,0)
A21: TRANSPORT | B21: Public Transport | C21: 0 | D21: 0 | E21: =IFERROR(C21-D21,0) | F21: =IFERROR(D21/C21,0)
A22: TRANSPORT TOTAL | C22: =SUM(C17:C21) | D22: =SUM(D17:D21) | E22: =IFERROR(C22-D22,0) | F22: =IFERROR(D22/C22,0)
A23: FOOD & DINING
A24: FOOD & DINING | B24: Groceries | C24: 0 | D24: 0 | E24: =IFERROR(C24-D24,0) | F24: =IFERROR(D24/C24,0)
A25: FOOD & DINING | B25: Restaurants | C25: 0 | D25: 0 | E25: =IFERROR(C25-D25,0) | F25: =IFERROR(D25/C25,0)
A26: FOOD & DINING | B26: Coffee | C26: 0 | D26: 0 | E26: =IFERROR(C26-D26,0) | F26: =IFERROR(D26/C26,0)
A27: FOOD & DINING | B27: Food Delivery | C27: 0 | D27: 0 | E27: =IFERROR(C27-D27,0) | F27: =IFERROR(D27/C27,0)
A28: FOOD & DINING | B28: Work Lunch | C28: 0 | D28: 0 | E28: =IFERROR(C28-D28,0) | F28: =IFERROR(D28/C28,0)
A29: FOOD & DINING TOTAL | C29: =SUM(C24:C28) | D29: =SUM(D24:D28) | E29: =IFERROR(C29-D29,0) | F29: =IFERROR(D29/C29,0)
A30: HEALTH & WELLNESS
A31: HEALTH & WELLNESS | B31: Health Insurance | C31: 0 | D31: 0 | E31: =IFERROR(C31-D31,0) | F31: =IFERROR(D31/C31,0)
A32: HEALTH & WELLNESS | B32: Gym | C32: 0 | D32: 0 | E32: =IFERROR(C32-D32,0) | F32: =IFERROR(D32/C32,0)
A33: HEALTH & WELLNESS | B33: Pharmacy | C33: 0 | D33: 0 | E33: =IFERROR(C33-D33,0) | F33: =IFERROR(D33/C33,0)
A34: HEALTH & WELLNESS | B34: Doctor | C34: 0 | D34: 0 | E34: =IFERROR(C34-D34,0) | F34: =IFERROR(D34/C34,0)
A35: HEALTH & WELLNESS | B35: Dental | C35: 0 | D35: 0 | E35: =IFERROR(C35-D35,0) | F35: =IFERROR(D35/C35,0)
A36: HEALTH & WELLNESS TOTAL | C36: =SUM(C31:C35) | D36: =SUM(D31:D35) | E36: =IFERROR(C36-D36,0) | F36: =IFERROR(D36/C36,0)
A37: LIFESTYLE
A38: LIFESTYLE | B38: Streaming Services | C38: 0 | D38: 0 | E38: =IFERROR(C38-D38,0) | F38: =IFERROR(D38/C38,0)
A39: LIFESTYLE | B39: Entertainment | C39: 0 | D39: 0 | E39: =IFERROR(C39-D39,0) | F39: =IFERROR(D39/C39,0)
A40: LIFESTYLE | B40: Hobbies | C40: 0 | D40: 0 | E40: =IFERROR(C40-D40,0) | F40: =IFERROR(D40/C40,0)
...

Sheet Mar
A1: MARCH · MONTHLY BUDGET
A2: Track your income and expenses for March
A3: CATEGORY | B3: SUBCATEGORY | C3: BUDGETED | D3: ACTUAL | E3: DIFFERENCE | F3: % USED | G3: NOTES
A4: INCOME
A5: INCOME | B5: Primary Income | C5: 0 | D5: 0 | E5: =IFERROR(C5-D5,0) | F5: =IFERROR(D5/C5,0)
A6: INCOME | B6: Side Income | C6: 0 | D6: 0 | E6: =IFERROR(C6-D6,0) | F6: =IFERROR(D6/C6,0)
A7: INCOME | B7: Other Income | C7: 0 | D7: 0 | E7: =IFERROR(C7-D7,0) | F7: =IFERROR(D7/C7,0)
A8: TOTAL INCOME | C8: =SUM(C5:C7) | D8: =SUM(D5:D7) | E8: =IFERROR(C8-D8,0) | F8: =IFERROR(D8/C8,0)
A9: HOUSING
A10: HOUSING | B10: Rent/Mortgage | C10: 0 | D10: 0 | E10: =IFERROR(C10-D10,0) | F10: =IFERROR(D10/C10,0)
A11: HOUSING | B11: Utilities | C11: 0 | D11: 0 | E11: =IFERROR(C11-D11,0) | F11: =IFERROR(D11/C11,0)
A12: HOUSING | B12: Electricity | C12: 0 | D12: 0 | E12: =IFERROR(C12-D12,0) | F12: =IFERROR(D12/C12,0)
A13: HOUSING | B13: Internet | C13: 0 | D13: 0 | E13: =IFERROR(C13-D13,0) | F13: =IFERROR(D13/C13,0)
A14: HOUSING | B14: Home Insurance | C14: 0 | D14: 0 | E14: =IFERROR(C14-D14,0) | F14: =IFERROR(D14/C14,0)
A15: HOUSING TOTAL | C15: =SUM(C10:C14) | D15: =SUM(D10:D14) | E15: =IFERROR(C15-D15,0) | F15: =IFERROR(D15/C15,0)
A16: TRANSPORT
A17: TRANSPORT | B17: Car Payment | C17: 0 | D17: 0 | E17: =IFERROR(C17-D17,0) | F17: =IFERROR(D17/C17,0)
A18: TRANSPORT | B18: Fuel | C18: 0 | D18: 0 | E18: =IFERROR(C18-D18,0) | F18: =IFERROR(D18/C18,0)
A19: TRANSPORT | B19: Car Insurance | C19: 0 | D19: 0 | E19: =IFERROR(C19-D19,0) | F19: =IFERROR(D19/C19,0)
A20: TRANSPORT | B20: Parking | C20: 0 | D20: 0 | E20: =IFERROR(C20-D20,0) | F20: =IFERROR(D20/C20,0)
A21: TRANSPORT | B21: Public Transport | C21: 0 | D21: 0 | E21: =IFERROR(C21-D21,0) | F21: =IFERROR(D21/C21,0)
A22: TRANSPORT TOTAL | C22: =SUM(C17:C21) | D22: =SUM(D17:D21) | E22: =IFERROR(C22-D22,0) | F22: =IFERROR(D22/C22,0)
A23: FOOD & DINING
A24: FOOD & DINING | B24: Groceries | C24: 0 | D24: 0 | E24: =IFERROR(C24-D24,0) | F24: =IFERROR(D24/C24,0)
A25: FOOD & DINING | B25: Restaurants | C25: 0 | D25: 0 | E25: =IFERROR(C25-D25,0) | F25: =IFERROR(D25/C25,0)
A26: FOOD & DINING | B26: Coffee | C26: 0 | D26: 0 | E26: =IFERROR(C26-D26,0) | F26: =IFERROR(D26/C26,0)
A27: FOOD & DINING | B27: Food Delivery | C27: 0 | D27: 0 | E27: =IFERROR(C27-D27,0) | F27: =IFERROR(D27/C27,0)
A28: FOOD & DINING | B28: Work Lunch | C28: 0 | D28: 0 | E28: =IFERROR(C28-D28,0) | F28: =IFERROR(D28/C28,0)
A29: FOOD & DINING TOTAL | C29: =SUM(C24:C28) | D29: =SUM(D24:D28) | E29: =IFERROR(C29-D29,0) | F29: =IFERROR(D29/C29,0)
A30: HEALTH & WELLNESS
A31: HEALTH & WELLNESS | B31: Health Insurance | C31: 0 | D31: 0 | E31: =IFERROR(C31-D31,0) | F31: =IFERROR(D31/C31,0)
A32: HEALTH & WELLNESS | B32: Gym | C32: 0 | D32: 0 | E32: =IFERROR(C32-D32,0) | F32: =IFERROR(D32/C32,0)
A33: HEALTH & WELLNESS | B33: Pharmacy | C33: 0 | D33: 0 | E33: =IFERROR(C33-D33,0) | F33: =IFERROR(D33/C33,0)
A34: HEALTH & WELLNESS | B34: Doctor | C34: 0 | D34: 0 | E34: =IFERROR(C34-D34,0) | F34: =IFERROR(D34/C34,0)
A35: HEALTH & WELLNESS | B35: Dental | C35: 0 | D35: 0 | E35: =IFERROR(C35-D35,0) | F35: =IFERROR(D35/C35,0)
A36: HEALTH & WELLNESS TOTAL | C36: =SUM(C31:C35) | D36: =SUM(D31:D35) | E36: =IFERROR(C36-D36,0) | F36: =IFERROR(D36/C36,0)
A37: LIFESTYLE
A38: LIFESTYLE | B38: Streaming Services | C38: 0 | D38: 0 | E38: =IFERROR(C38-D38,0) | F38: =IFERROR(D38/C38,0)
A39: LIFESTYLE | B39: Entertainment | C39: 0 | D39: 0 | E39: =IFERROR(C39-D39,0) | F39: =IFERROR(D39/C39,0)
A40: LIFESTYLE | B40: Hobbies | C40: 0 | D40: 0 | E40: =IFERROR(C40-D40,0) | F40: =IFERROR(D40/C40,0)
...

Sheet Apr
A1: APRIL · MONTHLY BUDGET
A2: Track your income and expenses for April
A3: CATEGORY | B3: SUBCATEGORY | C3: BUDGETED | D3: ACTUAL | E3: DIFFERENCE | F3: % USED | G3: NOTES
A4: INCOME
A5: INCOME | B5: Primary Income | C5: 0 | D5: 0 | E5: =IFERROR(C5-D5,0) | F5: =IFERROR(D5/C5,0)
A6: INCOME | B6: Side Income | C6: 0 | D6: 0 | E6: =IFERROR(C6-D6,0) | F6: =IFERROR(D6/C6,0)
A7: INCOME | B7: Other Income | C7: 0 | D7: 0 | E7: =IFERROR(C7-D7,0) | F7: =IFERROR(D7/C7,0)
A8: TOTAL INCOME | C8: =SUM(C5:C7) | D8: =SUM(D5:D7) | E8: =IFERROR(C8-D8,0) | F8: =IFERROR(D8/C8,0)
A9: HOUSING
A10: HOUSING | B10: Rent/Mortgage | C10: 0 | D10: 0 | E10: =IFERROR(C10-D10,0) | F10: =IFERROR(D10/C10,0)
A11: HOUSING | B11: Utilities | C11: 0 | D11: 0 | E11: =IFERROR(C11-D11,0) | F11: =IFERROR(D11/C11,0)
A12: HOUSING | B12: Electricity | C12: 0 | D12: 0 | E12: =IFERROR(C12-D12,0) | F12: =IFERROR(D12/C12,0)
A13: HOUSING | B13: Internet | C13: 0 | D13: 0 | E13: =IFERROR(C13-D13,0) | F13: =IFERROR(D13/C13,0)
A14: HOUSING | B14: Home Insurance | C14: 0 | D14: 0 | E14: =IFERROR(C14-D14,0) | F14: =IFERROR(D14/C14,0)
A15: HOUSING TOTAL | C15: =SUM(C10:C14) | D15: =SUM(D10:D14) | E15: =IFERROR(C15-D15,0) | F15: =IFERROR(D15/C15,0)
A16: TRANSPORT
A17: TRANSPORT | B17: Car Payment | C17: 0 | D17: 0 | E17: =IFERROR(C17-D17,0) | F17: =IFERROR(D17/C17,0)
A18: TRANSPORT | B18: Fuel | C18: 0 | D18: 0 | E18: =IFERROR(C18-D18,0) | F18: =IFERROR(D18/C18,0)
A19: TRANSPORT | B19: Car Insurance | C19: 0 | D19: 0 | E19: =IFERROR(C19-D19,0) | F19: =IFERROR(D19/C19,0)
A20: TRANSPORT | B20: Parking | C20: 0 | D20: 0 | E20: =IFERROR(C20-D20,0) | F20: =IFERROR(D20/C20,0)
A21: TRANSPORT | B21: Public Transport | C21: 0 | D21: 0 | E21: =IFERROR(C21-D21,0) | F21: =IFERROR(D21/C21,0)
A22: TRANSPORT TOTAL | C22: =SUM(C17:C21) | D22: =SUM(D17:D21) | E22: =IFERROR(C22-D22,0) | F22: =IFERROR(D22/C22,0)
A23: FOOD & DINING
A24: FOOD & DINING | B24: Groceries | C24: 0 | D24: 0 | E24: =IFERROR(C24-D24,0) | F24: =IFERROR(D24/C24,0)
A25: FOOD & DINING | B25: Restaurants | C25: 0 | D25: 0 | E25: =IFERROR(C25-D25,0) | F25: =IFERROR(D25/C25,0)
A26: FOOD & DINING | B26: Coffee | C26: 0 | D26: 0 | E26: =IFERROR(C26-D26,0) | F26: =IFERROR(D26/C26,0)
A27: FOOD & DINING | B27: Food Delivery | C27: 0 | D27: 0 | E27: =IFERROR(C27-D27,0) | F27: =IFERROR(D27/C27,0)
A28: FOOD & DINING | B28: Work Lunch | C28: 0 | D28: 0 | E28: =IFERROR(C28-D28,0) | F28: =IFERROR(D28/C28,0)
A29: FOOD & DINING TOTAL | C29: =SUM(C24:C28) | D29: =SUM(D24:D28) | E29: =IFERROR(C29-D29,0) | F29: =IFERROR(D29/C29,0)
A30: HEALTH & WELLNESS
A31: HEALTH & WELLNESS | B31: Health Insurance | C31: 0 | D31: 0 | E31: =IFERROR(C31-D31,0) | F31: =IFERROR(D31/C31,0)
A32: HEALTH & WELLNESS | B32: Gym | C32: 0 | D32: 0 | E32: =IFERROR(C32-D32,0) | F32: =IFERROR(D32/C32,0)
A33: HEALTH & WELLNESS | B33: Pharmacy | C33: 0 | D33: 0 | E33: =IFERROR(C33-D33,0) | F33: =IFERROR(D33/C33,0)
A34: HEALTH & WELLNESS | B34: Doctor | C34: 0 | D34: 0 | E34: =IFERROR(C34-D34,0) | F34: =IFERROR(D34/C34,0)
A35: HEALTH & WELLNESS | B35: Dental | C35: 0 | D35: 0 | E35: =IFERROR(C35-D35,0) | F35: =IFERROR(D35/C35,0)
A36: HEALTH & WELLNESS TOTAL | C36: =SUM(C31:C35) | D36: =SUM(D31:D35) | E36: =IFERROR(C36-D36,0) | F36: =IFERROR(D36/C36,0)
A37: LIFESTYLE
A38: LIFESTYLE | B38: Streaming Services | C38: 0 | D38: 0 | E38: =IFERROR(C38-D38,0) | F38: =IFERROR(D38/C38,0)
A39: LIFESTYLE | B39: Entertainment | C39: 0 | D39: 0 | E39: =IFERROR(C39-D39,0) | F39: =IFERROR(D39/C39,0)
A40: LIFESTYLE | B40: Hobbies | C40: 0 | D40: 0 | E40: =IFERROR(C40-D40,0) | F40: =IFERROR(D40/C40,0)
...

Sheet May
A1: MAY · MONTHLY BUDGET
A2: Track your income and expenses for May
A3: CATEGORY | B3: SUBCATEGORY | C3: BUDGETED | D3: ACTUAL | E3: DIFFERENCE | F3: % USED | G3: NOTES
A4: INCOME
A5: INCOME | B5: Primary Income | C5: 0 | D5: 0 | E5: =IFERROR(C5-D5,0) | F5: =IFERROR(D5/C5,0)
A6: INCOME | B6: Side Income | C6: 0 | D6: 0 | E6: =IFERROR(C6-D6,0) | F6: =IFERROR(D6/C6,0)
A7: INCOME | B7: Other Income | C7: 0 | D7: 0 | E7: =IFERROR(C7-D7,0) | F7: =IFERROR(D7/C7,0)
A8: TOTAL INCOME | C8: =SUM(C5:C7) | D8: =SUM(D5:D7) | E8: =IFERROR(C8-D8,0) | F8: =IFERROR(D8/C8,0)
A9: HOUSING
A10: HOUSING | B10: Rent/Mortgage | C10: 0 | D10: 0 | E10: =IFERROR(C10-D10,0) | F10: =IFERROR(D10/C10,0)
A11: HOUSING | B11: Utilities | C11: 0 | D11: 0 | E11: =IFERROR(C11-D11,0) | F11: =IFERROR(D11/C11,0)
A12: HOUSING | B12: Electricity | C12: 0 | D12: 0 | E12: =IFERROR(C12-D12,0) | F12: =IFERROR(D12/C12,0)
A13: HOUSING | B13: Internet | C13: 0 | D13: 0 | E13: =IFERROR(C13-D13,0) | F13: =IFERROR(D13/C13,0)
A14: HOUSING | B14: Home Insurance | C14: 0 | D14: 0 | E14: =IFERROR(C14-D14,0) | F14: =IFERROR(D14/C14,0)
A15: HOUSING TOTAL | C15: =SUM(C10:C14) | D15: =SUM(D10:D14) | E15: =IFERROR(C15-D15,0) | F15: =IFERROR(D15/C15,0)
A16: TRANSPORT
A17: TRANSPORT | B17: Car Payment | C17: 0 | D17: 0 | E17: =IFERROR(C17-D17,0) | F17: =IFERROR(D17/C17,0)
A18: TRANSPORT | B18: Fuel | C18: 0 | D18: 0 | E18: =IFERROR(C18-D18,0) | F18: =IFERROR(D18/C18,0)
A19: TRANSPORT | B19: Car Insurance | C19: 0 | D19: 0 | E19: =IFERROR(C19-D19,0) | F19: =IFERROR(D19/C19,0)
A20: TRANSPORT | B20: Parking | C20: 0 | D20: 0 | E20: =IFERROR(C20-D20,0) | F20: =IFERROR(D20/C20,0)
A21: TRANSPORT | B21: Public Transport | C21: 0 | D21: 0 | E21: =IFERROR(C21-D21,0) | F21: =IFERROR(D21/C21,0)
A22: TRANSPORT TOTAL | C22: =SUM(C17:C21) | D22: =SUM(D17:D21) | E22: =IFERROR(C22-D22,0) | F22: =IFERROR(D22/C22,0)
A23: FOOD & DINING
A24: FOOD & DINING | B24: Groceries | C24: 0 | D24: 0 | E24: =IFERROR(C24-D24,0) | F24: =IFERROR(D24/C24,0)
A25: FOOD & DINING | B25: Restaurants | C25: 0 | D25: 0 | E25: =IFERROR(C25-D25,0) | F25: =IFERROR(D25/C25,0)
A26: FOOD & DINING | B26: Coffee | C26: 0 | D26: 0 | E26: =IFERROR(C26-D26,0) | F26: =IFERROR(D26/C26,0)
A27: FOOD & DINING | B27: Food Delivery | C27: 0 | D27: 0 | E27: =IFERROR(C27-D27,0) | F27: =IFERROR(D27/C27,0)
A28: FOOD & DINING | B28: Work Lunch | C28: 0 | D28: 0 | E28: =IFERROR(C28-D28,0) | F28: =IFERROR(D28/C28,0)
A29: FOOD & DINING TOTAL | C29: =SUM(C24:C28) | D29: =SUM(D24:D28) | E29: =IFERROR(C29-D29,0) | F29: =IFERROR(D29/C29,0)
A30: HEALTH & WELLNESS
A31: HEALTH & WELLNESS | B31: Health Insurance | C31: 0 | D31: 0 | E31: =IFERROR(C31-D31,0) | F31: =IFERROR(D31/C31,0)
A32: HEALTH & WELLNESS | B32: Gym | C32: 0 | D32: 0 | E32: =IFERROR(C32-D32,0) | F32: =IFERROR(D32/C32,0)
A33: HEALTH & WELLNESS | B33: Pharmacy | C33: 0 | D33: 0 | E33: =IFERROR(C33-D33,0) | F33: =IFERROR(D33/C33,0)
A34: HEALTH & WELLNESS | B34: Doctor | C34: 0 | D34: 0 | E34: =IFERROR(C34-D34,0) | F34: =IFERROR(D34/C34,0)
A35: HEALTH & WELLNESS | B35: Dental | C35: 0 | D35: 0 | E35: =IFERROR(C35-D35,0) | F35: =IFERROR(D35/C35,0)
A36: HEALTH & WELLNESS TOTAL | C36: =SUM(C31:C35) | D36: =SUM(D31:D35) | E36: =IFERROR(C36-D36,0) | F36: =IFERROR(D36/C36,0)
A37: LIFESTYLE
A38: LIFESTYLE | B38: Streaming Services | C38: 0 | D38: 0 | E38: =IFERROR(C38-D38,0) | F38: =IFERROR(D38/C38,0)
A39: LIFESTYLE | B39: Entertainment | C39: 0 | D39: 0 | E39: =IFERROR(C39-D39,0) | F39: =IFERROR(D39/C39,0)
A40: LIFESTYLE | B40: Hobbies | C40: 0 | D40: 0 | E40: =IFERROR(C40-D40,0) | F40: =IFERROR(D40/C40,0)
...

Sheet Jun
A1: JUNE · MONTHLY BUDGET
A2: Track your income and expenses for June
A3: CATEGORY | B3: SUBCATEGORY | C3: BUDGETED | D3: ACTUAL | E3: DIFFERENCE | F3: % USED | G3: NOTES
A4: INCOME
A5: INCOME | B5: Primary Income | C5: 0 | D5: 0 | E5: =IFERROR(C5-D5,0) | F5: =IFERROR(D5/C5,0)
A6: INCOME | B6: Side Income | C6: 0 | D6: 0 | E6: =IFERROR(C6-D6,0) | F6: =IFERROR(D6/C6,0)
A7: INCOME | B7: Other Income | C7: 0 | D7: 0 | E7: =IFERROR(C7-D7,0) | F7: =IFERROR(D7/C7,0)
A8: TOTAL INCOME | C8: =SUM(C5:C7) | D8: =SUM(D5:D7) | E8: =IFERROR(C8-D8,0) | F8: =IFERROR(D8/C8,0)
A9: HOUSING
A10: HOUSING | B10: Rent/Mortgage | C10: 0 | D10: 0 | E10: =IFERROR(C10-D10,0) | F10: =IFERROR(D10/C10,0)
A11: HOUSING | B11: Utilities | C11: 0 | D11: 0 | E11: =IFERROR(C11-D11,0) | F11: =IFERROR(D11/C11,0)
A12: HOUSING | B12: Electricity | C12: 0 | D12: 0 | E12: =IFERROR(C12-D12,0) | F12: =IFERROR(D12/C12,0)
A13: HOUSING | B13: Internet | C13: 0 | D13: 0 | E13: =IFERROR(C13-D13,0) | F13: =IFERROR(D13/C13,0)
A14: HOUSING | B14: Home Insurance | C14: 0 | D14: 0 | E14: =IFERROR(C14-D14,0) | F14: =IFERROR(D14/C14,0)
A15: HOUSING TOTAL | C15: =SUM(C10:C14) | D15: =SUM(D10:D14) | E15: =IFERROR(C15-D15,0) | F15: =IFERROR(D15/C15,0)
A16: TRANSPORT
A17: TRANSPORT | B17: Car Payment | C17: 0 | D17: 0 | E17: =IFERROR(C17-D17,0) | F17: =IFERROR(D17/C17,0)
A18: TRANSPORT | B18: Fuel | C18: 0 | D18: 0 | E18: =IFERROR(C18-D18,0) | F18: =IFERROR(D18/C18,0)
A19: TRANSPORT | B19: Car Insurance | C19: 0 | D19: 0 | E19: =IFERROR(C19-D19,0) | F19: =IFERROR(D19/C19,0)
A20: TRANSPORT | B20: Parking | C20: 0 | D20: 0 | E20: =IFERROR(C20-D20,0) | F20: =IFERROR(D20/C20,0)
A21: TRANSPORT | B21: Public Transport | C21: 0 | D21: 0 | E21: =IFERROR(C21-D21,0) | F21: =IFERROR(D21/C21,0)
A22: TRANSPORT TOTAL | C22: =SUM(C17:C21) | D22: =SUM(D17:D21) | E22: =IFERROR(C22-D22,0) | F22: =IFERROR(D22/C22,0)
A23: FOOD & DINING
A24: FOOD & DINING | B24: Groceries | C24: 0 | D24: 0 | E24: =IFERROR(C24-D24,0) | F24: =IFERROR(D24/C24,0)
A25: FOOD & DINING | B25: Restaurants | C25: 0 | D25: 0 | E25: =IFERROR(C25-D25,0) | F25: =IFERROR(D25/C25,0)
A26: FOOD & DINING | B26: Coffee | C26: 0 | D26: 0 | E26: =IFERROR(C26-D26,0) | F26: =IFERROR(D26/C26,0)
A27: FOOD & DINING | B27: Food Delivery | C27: 0 | D27: 0 | E27: =IFERROR(C27-D27,0) | F27: =IFERROR(D27/C27,0)
A28: FOOD & DINING | B28: Work Lunch | C28: 0 | D28: 0 | E28: =IFERROR(C28-D28,0) | F28: =IFERROR(D28/C28,0)
A29: FOOD & DINING TOTAL | C29: =SUM(C24:C28) | D29: =SUM(D24:D28) | E29: =IFERROR(C29-D29,0) | F29: =IFERROR(D29/C29,0)
A30: HEALTH & WELLNESS
A31: HEALTH & WELLNESS | B31: Health Insurance | C31: 0 | D31: 0 | E31: =IFERROR(C31-D31,0) | F31: =IFERROR(D31/C31,0)
A32: HEALTH & WELLNESS | B32: Gym | C32: 0 | D32: 0 | E32: =IFERROR(C32-D32,0) | F32: =IFERROR(D32/C32,0)
A33: HEALTH & WELLNESS | B33: Pharmacy | C33: 0 | D33: 0 | E33: =IFERROR(C33-D33,0) | F33: =IFERROR(D33/C33,0)
A34: HEALTH & WELLNESS | B34: Doctor | C34: 0 | D34: 0 | E34: =IFERROR(C34-D34,0) | F34: =IFERROR(D34/C34,0)
A35: HEALTH & WELLNESS | B35: Dental | C35: 0 | D35: 0 | E35: =IFERROR(C35-D35,0) | F35: =IFERROR(D35/C35,0)
A36: HEALTH & WELLNESS TOTAL | C36: =SUM(C31:C35) | D36: =SUM(D31:D35) | E36: =IFERROR(C36-D36,0) | F36: =IFERROR(D36/C36,0)
A37: LIFESTYLE
A38: LIFESTYLE | B38: Streaming Services | C38: 0 | D38: 0 | E38: =IFERROR(C38-D38,0) | F38: =IFERROR(D38/C38,0)
A39: LIFESTYLE | B39: Entertainment | C39: 0 | D39: 0 | E39: =IFERROR(C39-D39,0) | F39: =IFERROR(D39/C39,0)
A40: LIFESTYLE | B40: Hobbies | C40: 0 | D40: 0 | E40: =IFERROR(C40-D40,0) | F40: =IFERROR(D40/C40,0)
...

Sheet Jul
A1: JULY · MONTHLY BUDGET
A2: Track your income and expenses for July
A3: CATEGORY | B3: SUBCATEGORY | C3: BUDGETED | D3: ACTUAL | E3: DIFFERENCE | F3: % USED | G3: NOTES
A4: INCOME
A5: INCOME | B5: Primary Income | C5: 0 | D5: 0 | E5: =IFERROR(C5-D5,0) | F5: =IFERROR(D5/C5,0)
A6: INCOME | B6: Side Income | C6: 0 | D6: 0 | E6: =IFERROR(C6-D6,0) | F6: =IFERROR(D6/C6,0)
A7: INCOME | B7: Other Income | C7: 0 | D7: 0 | E7: =IFERROR(C7-D7,0) | F7: =IFERROR(D7/C7,0)
A8: TOTAL INCOME | C8: =SUM(C5:C7) | D8: =SUM(D5:D7) | E8: =IFERROR(C8-D8,0) | F8: =IFERROR(D8/C8,0)
A9: HOUSING
A10: HOUSING | B10: Rent/Mortgage | C10: 0 | D10: 0 | E10: =IFERROR(C10-D10,0) | F10: =IFERROR(D10/C10,0)
A11: HOUSING | B11: Utilities | C11: 0 | D11: 0 | E11: =IFERROR(C11-D11,0) | F11: =IFERROR(D11/C11,0)
A12: HOUSING | B12: Electricity | C12: 0 | D12: 0 | E12: =IFERROR(C12-D12,0) | F12: =IFERROR(D12/C12,0)
A13: HOUSING | B13: Internet | C13: 0 | D13: 0 | E13: =IFERROR(C13-D13,0) | F13: =IFERROR(D13/C13,0)
A14: HOUSING | B14: Home Insurance | C14: 0 | D14: 0 | E14: =IFERROR(C14-D14,0) | F14: =IFERROR(D14/C14,0)
A15: HOUSING TOTAL | C15: =SUM(C10:C14) | D15: =SUM(D10:D14) | E15: =IFERROR(C15-D15,0) | F15: =IFERROR(D15/C15,0)
A16: TRANSPORT
A17: TRANSPORT | B17: Car Payment | C17: 0 | D17: 0 | E17: =IFERROR(C17-D17,0) | F17: =IFERROR(D17/C17,0)
A18: TRANSPORT | B18: Fuel | C18: 0 | D18: 0 | E18: =IFERROR(C18-D18,0) | F18: =IFERROR(D18/C18,0)
A19: TRANSPORT | B19: Car Insurance | C19: 0 | D19: 0 | E19: =IFERROR(C19-D19,0) | F19: =IFERROR(D19/C19,0)
A20: TRANSPORT | B20: Parking | C20: 0 | D20: 0 | E20: =IFERROR(C20-D20,0) | F20: =IFERROR(D20/C20,0)
A21: TRANSPORT | B21: Public Transport | C21: 0 | D21: 0 | E21: =IFERROR(C21-D21,0) | F21: =IFERROR(D21/C21,0)
A22: TRANSPORT TOTAL | C22: =SUM(C17:C21) | D22: =SUM(D17:D21) | E22: =IFERROR(C22-D22,0) | F22: =IFERROR(D22/C22,0)
A23: FOOD & DINING
A24: FOOD & DINING | B24: Groceries | C24: 0 | D24: 0 | E24: =IFERROR(C24-D24,0) | F24: =IFERROR(D24/C24,0)
A25: FOOD & DINING | B25: Restaurants | C25: 0 | D25: 0 | E25: =IFERROR(C25-D25,0) | F25: =IFERROR(D25/C25,0)
A26: FOOD & DINING | B26: Coffee | C26: 0 | D26: 0 | E26: =IFERROR(C26-D26,0) | F26: =IFERROR(D26/C26,0)
A27: FOOD & DINING | B27: Food Delivery | C27: 0 | D27: 0 | E27: =IFERROR(C27-D27,0) | F27: =IFERROR(D27/C27,0)
A28: FOOD & DINING | B28: Work Lunch | C28: 0 | D28: 0 | E28: =IFERROR(C28-D28,0) | F28: =IFERROR(D28/C28,0)
A29: FOOD & DINING TOTAL | C29: =SUM(C24:C28) | D29: =SUM(D24:D28) | E29: =IFERROR(C29-D29,0) | F29: =IFERROR(D29/C29,0)
A30: HEALTH & WELLNESS
A31: HEALTH & WELLNESS | B31: Health Insurance | C31: 0 | D31: 0 | E31: =IFERROR(C31-D31,0) | F31: =IFERROR(D31/C31,0)
A32: HEALTH & WELLNESS | B32: Gym | C32: 0 | D32: 0 | E32: =IFERROR(C32-D32,0) | F32: =IFERROR(D32/C32,0)
A33: HEALTH & WELLNESS | B33: Pharmacy | C33: 0 | D33: 0 | E33: =IFERROR(C33-D33,0) | F33: =IFERROR(D33/C33,0)
A34: HEALTH & WELLNESS | B34: Doctor | C34: 0 | D34: 0 | E34: =IFERROR(C34-D34,0) | F34: =IFERROR(D34/C34,0)
A35: HEALTH & WELLNESS | B35: Dental | C35: 0 | D35: 0 | E35: =IFERROR(C35-D35,0) | F35: =IFERROR(D35/C35,0)
A36: HEALTH & WELLNESS TOTAL | C36: =SUM(C31:C35) | D36: =SUM(D31:D35) | E36: =IFERROR(C36-D36,0) | F36: =IFERROR(D36/C36,0)
A37: LIFESTYLE
A38: LIFESTYLE | B38: Streaming Services | C38: 0 | D38: 0 | E38: =IFERROR(C38-D38,0) | F38: =IFERROR(D38/C38,0)
A39: LIFESTYLE | B39: Entertainment | C39: 0 | D39: 0 | E39: =IFERROR(C39-D39,0) | F39: =IFERROR(D39/C39,0)
A40: LIFESTYLE | B40: Hobbies | C40: 0 | D40: 0 | E40: =IFERROR(C40-D40,0) | F40: =IFERROR(D40/C40,0)
...

Sheet Aug
A1: AUGUST · MONTHLY BUDGET
A2: Track your income and expenses for August
A3: CATEGORY | B3: SUBCATEGORY | C3: BUDGETED | D3: ACTUAL | E3: DIFFERENCE | F3: % USED | G3: NOTES
A4: INCOME
A5: INCOME | B5: Primary Income | C5: 0 | D5: 0 | E5: =IFERROR(C5-D5,0) | F5: =IFERROR(D5/C5,0)
A6: INCOME | B6: Side Income | C6: 0 | D6: 0 | E6: =IFERROR(C6-D6,0) | F6: =IFERROR(D6/C6,0)
A7: INCOME | B7: Other Income | C7: 0 | D7: 0 | E7: =IFERROR(C7-D7,0) | F7: =IFERROR(D7/C7,0)
A8: TOTAL INCOME | C8: =SUM(C5:C7) | D8: =SUM(D5:D7) | E8: =IFERROR(C8-D8,0) | F8: =IFERROR(D8/C8,0)
A9: HOUSING
A10: HOUSING | B10: Rent/Mortgage | C10: 0 | D10: 0 | E10: =IFERROR(C10-D10,0) | F10: =IFERROR(D10/C10,0)
A11: HOUSING | B11: Utilities | C11: 0 | D11: 0 | E11: =IFERROR(C11-D11,0) | F11: =IFERROR(D11/C11,0)
A12: HOUSING | B12: Electricity | C12: 0 | D12: 0 | E12: =IFERROR(C12-D12,0) | F12: =IFERROR(D12/C12,0)
A13: HOUSING | B13: Internet | C13: 0 | D13: 0 | E13: =IFERROR(C13-D13,0) | F13: =IFERROR(D13/C13,0)
A14: HOUSING | B14: Home Insurance | C14: 0 | D14: 0 | E14: =IFERROR(C14-D14,0) | F14: =IFERROR(D14/C14,0)
A15: HOUSING TOTAL | C15: =SUM(C10:C14) | D15: =SUM(D10:D14) | E15: =IFERROR(C15-D15,0) | F15: =IFERROR(D15/C15,0)
A16: TRANSPORT
A17: TRANSPORT | B17: Car Payment | C17: 0 | D17: 0 | E17: =IFERROR(C17-D17,0) | F17: =IFERROR(D17/C17,0)
A18: TRANSPORT | B18: Fuel | C18: 0 | D18: 0 | E18: =IFERROR(C18-D18,0) | F18: =IFERROR(D18/C18,0)
A19: TRANSPORT | B19: Car Insurance | C19: 0 | D19: 0 | E19: =IFERROR(C19-D19,0) | F19: =IFERROR(D19/C19,0)
A20: TRANSPORT | B20: Parking | C20: 0 | D20: 0 | E20: =IFERROR(C20-D20,0) | F20: =IFERROR(D20/C20,0)
A21: TRANSPORT | B21: Public Transport | C21: 0 | D21: 0 | E21: =IFERROR(C21-D21,0) | F21: =IFERROR(D21/C21,0)
A22: TRANSPORT TOTAL | C22: =SUM(C17:C21) | D22: =SUM(D17:D21) | E22: =IFERROR(C22-D22,0) | F22: =IFERROR(D22/C22,0)
A23: FOOD & DINING
A24: FOOD & DINING | B24: Groceries | C24: 0 | D24: 0 | E24: =IFERROR(C24-D24,0) | F24: =IFERROR(D24/C24,0)
A25: FOOD & DINING | B25: Restaurants | C25: 0 | D25: 0 | E25: =IFERROR(C25-D25,0) | F25: =IFERROR(D25/C25,0)
A26: FOOD & DINING | B26: Coffee | C26: 0 | D26: 0 | E26: =IFERROR(C26-D26,0) | F26: =IFERROR(D26/C26,0)
A27: FOOD & DINING | B27: Food Delivery | C27: 0 | D27: 0 | E27: =IFERROR(C27-D27,0) | F27: =IFERROR(D27/C27,0)
A28: FOOD & DINING | B28: Work Lunch | C28: 0 | D28: 0 | E28: =IFERROR(C28-D28,0) | F28: =IFERROR(D28/C28,0)
A29: FOOD & DINING TOTAL | C29: =SUM(C24:C28) | D29: =SUM(D24:D28) | E29: =IFERROR(C29-D29,0) | F29: =IFERROR(D29/C29,0)
A30: HEALTH & WELLNESS
A31: HEALTH & WELLNESS | B31: Health Insurance | C31: 0 | D31: 0 | E31: =IFERROR(C31-D31,0) | F31: =IFERROR(D31/C31,0)
A32: HEALTH & WELLNESS | B32: Gym | C32: 0 | D32: 0 | E32: =IFERROR(C32-D32,0) | F32: =IFERROR(D32/C32,0)
A33: HEALTH & WELLNESS | B33: Pharmacy | C33: 0 | D33: 0 | E33: =IFERROR(C33-D33,0) | F33: =IFERROR(D33/C33,0)
A34: HEALTH & WELLNESS | B34: Doctor | C34: 0 | D34: 0 | E34: =IFERROR(C34-D34,0) | F34: =IFERROR(D34/C34,0)
A35: HEALTH & WELLNESS | B35: Dental | C35: 0 | D35: 0 | E35: =IFERROR(C35-D35,0) | F35: =IFERROR(D35/C35,0)
A36: HEALTH & WELLNESS TOTAL | C36: =SUM(C31:C35) | D36: =SUM(D31:D35) | E36: =IFERROR(C36-D36,0) | F36: =IFERROR(D36/C36,0)
A37: LIFESTYLE
A38: LIFESTYLE | B38: Streaming Services | C38: 0 | D38: 0 | E38: =IFERROR(C38-D38,0) | F38: =IFERROR(D38/C38,0)
A39: LIFESTYLE | B39: Entertainment | C39: 0 | D39: 0 | E39: =IFERROR(C39-D39,0) | F39: =IFERROR(D39/C39,0)
A40: LIFESTYLE | B40: Hobbies | C40: 0 | D40: 0 | E40: =IFERROR(C40-D40,0) | F40: =IFERROR(D40/C40,0)
...

Sheet Sep
A1: SEPTEMBER · MONTHLY BUDGET
A2: Track your income and expenses for September
A3: CATEGORY | B3: SUBCATEGORY | C3: BUDGETED | D3: ACTUAL | E3: DIFFERENCE | F3: % USED | G3: NOTES
A4: INCOME
A5: INCOME | B5: Primary Income | C5: 0 | D5: 0 | E5: =IFERROR(C5-D5,0) | F5: =IFERROR(D5/C5,0)
A6: INCOME | B6: Side Income | C6: 0 | D6: 0 | E6: =IFERROR(C6-D6,0) | F6: =IFERROR(D6/C6,0)
A7: INCOME | B7: Other Income | C7: 0 | D7: 0 | E7: =IFERROR(C7-D7,0) | F7: =IFERROR(D7/C7,0)
A8: TOTAL INCOME | C8: =SUM(C5:C7) | D8: =SUM(D5:D7) | E8: =IFERROR(C8-D8,0) | F8: =IFERROR(D8/C8,0)
A9: HOUSING
A10: HOUSING | B10: Rent/Mortgage | C10: 0 | D10: 0 | E10: =IFERROR(C10-D10,0) | F10: =IFERROR(D10/C10,0)
A11: HOUSING | B11: Utilities | C11: 0 | D11: 0 | E11: =IFERROR(C11-D11,0) | F11: =IFERROR(D11/C11,0)
A12: HOUSING | B12: Electricity | C12: 0 | D12: 0 | E12: =IFERROR(C12-D12,0) | F12: =IFERROR(D12/C12,0)
A13: HOUSING | B13: Internet | C13: 0 | D13: 0 | E13: =IFERROR(C13-D13,0) | F13: =IFERROR(D13/C13,0)
A14: HOUSING | B14: Home Insurance | C14: 0 | D14: 0 | E14: =IFERROR(C14-D14,0) | F14: =IFERROR(D14/C14,0)
A15: HOUSING TOTAL | C15: =SUM(C10:C14) | D15: =SUM(D10:D14) | E15: =IFERROR(C15-D15,0) | F15: =IFERROR(D15/C15,0)
A16: TRANSPORT
A17: TRANSPORT | B17: Car Payment | C17: 0 | D17: 0 | E17: =IFERROR(C17-D17,0) | F17: =IFERROR(D17/C17,0)
A18: TRANSPORT | B18: Fuel | C18: 0 | D18: 0 | E18: =IFERROR(C18-D18,0) | F18: =IFERROR(D18/C18,0)
A19: TRANSPORT | B19: Car Insurance | C19: 0 | D19: 0 | E19: =IFERROR(C19-D19,0) | F19: =IFERROR(D19/C19,0)
A20: TRANSPORT | B20: Parking | C20: 0 | D20: 0 | E20: =IFERROR(C20-D20,0) | F20: =IFERROR(D20/C20,0)
A21: TRANSPORT | B21: Public Transport | C21: 0 | D21: 0 | E21: =IFERROR(C21-D21,0) | F21: =IFERROR(D21/C21,0)
A22: TRANSPORT TOTAL | C22: =SUM(C17:C21) | D22: =SUM(D17:D21) | E22: =IFERROR(C22-D22,0) | F22: =IFERROR(D22/C22,0)
A23: FOOD & DINING
A24: FOOD & DINING | B24: Groceries | C24: 0 | D24: 0 | E24: =IFERROR(C24-D24,0) | F24: =IFERROR(D24/C24,0)
A25: FOOD & DINING | B25: Restaurants | C25: 0 | D25: 0 | E25: =IFERROR(C25-D25,0) | F25: =IFERROR(D25/C25,0)
A26: FOOD & DINING | B26: Coffee | C26: 0 | D26: 0 | E26: =IFERROR(C26-D26,0) | F26: =IFERROR(D26/C26,0)
A27: FOOD & DINING | B27: Food Delivery | C27: 0 | D27: 0 | E27: =IFERROR(C27-D27,0) | F27: =IFERROR(D27/C27,0)
A28: FOOD & DINING | B28: Work Lunch | C28: 0 | D28: 0 | E28: =IFERROR(C28-D28,0) | F28: =IFERROR(D28/C28,0)
A29: FOOD & DINING TOTAL | C29: =SUM(C24:C28) | D29: =SUM(D24:D28) | E29: =IFERROR(C29-D29,0) | F29: =IFERROR(D29/C29,0)
A30: HEALTH & WELLNESS
A31: HEALTH & WELLNESS | B31: Health Insurance | C31: 0 | D31: 0 | E31: =IFERROR(C31-D31,0) | F31: =IFERROR(D31/C31,0)
A32: HEALTH & WELLNESS | B32: Gym | C32: 0 | D32: 0 | E32: =IFERROR(C32-D32,0) | F32: =IFERROR(D32/C32,0)
A33: HEALTH & WELLNESS | B33: Pharmacy | C33: 0 | D33: 0 | E33: =IFERROR(C33-D33,0) | F33: =IFERROR(D33/C33,0)
A34: HEALTH & WELLNESS | B34: Doctor | C34: 0 | D34: 0 | E34: =IFERROR(C34-D34,0) | F34: =IFERROR(D34/C34,0)
A35: HEALTH & WELLNESS | B35: Dental | C35: 0 | D35: 0 | E35: =IFERROR(C35-D35,0) | F35: =IFERROR(D35/C35,0)
A36: HEALTH & WELLNESS TOTAL | C36: =SUM(C31:C35) | D36: =SUM(D31:D35) | E36: =IFERROR(C36-D36,0) | F36: =IFERROR(D36/C36,0)
A37: LIFESTYLE
A38: LIFESTYLE | B38: Streaming Services | C38: 0 | D38: 0 | E38: =IFERROR(C38-D38,0) | F38: =IFERROR(D38/C38,0)
A39: LIFESTYLE | B39: Entertainment | C39: 0 | D39: 0 | E39: =IFERROR(C39-D39,0) | F39: =IFERROR(D39/C39,0)
A40: LIFESTYLE | B40: Hobbies | C40: 0 | D40: 0 | E40: =IFERROR(C40-D40,0) | F40: =IFERROR(D40/C40,0)
...

Sheet Oct
A1: OCTOBER · MONTHLY BUDGET
A2: Track your income and expenses for October
A3: CATEGORY | B3: SUBCATEGORY | C3: BUDGETED | D3: ACTUAL | E3: DIFFERENCE | F3: % USED | G3: NOTES
A4: INCOME
A5: INCOME | B5: Primary Income | C5: 0 | D5: 0 | E5: =IFERROR(C5-D5,0) | F5: =IFERROR(D5/C5,0)
A6: INCOME | B6: Side Income | C6: 0 | D6: 0 | E6: =IFERROR(C6-D6,0) | F6: =IFERROR(D6/C6,0)
A7: INCOME | B7: Other Income | C7: 0 | D7: 0 | E7: =IFERROR(C7-D7,0) | F7: =IFERROR(D7/C7,0)
A8: TOTAL INCOME | C8: =SUM(C5:C7) | D8: =SUM(D5:D7) | E8: =IFERROR(C8-D8,0) | F8: =IFERROR(D8/C8,0)
A9: HOUSING
A10: HOUSING | B10: Rent/Mortgage | C10: 0 | D10: 0 | E10: =IFERROR(C10-D10,0) | F10: =IFERROR(D10/C10,0)
A11: HOUSING | B11: Utilities | C11: 0 | D11: 0 | E11: =IFERROR(C11-D11,0) | F11: =IFERROR(D11/C11,0)
A12: HOUSING | B12: Electricity | C12: 0 | D12: 0 | E12: =IFERROR(C12-D12,0) | F12: =IFERROR(D12/C12,0)
A13: HOUSING | B13: Internet | C13: 0 | D13: 0 | E13: =IFERROR(C13-D13,0) | F13: =IFERROR(D13/C13,0)
A14: HOUSING | B14: Home Insurance | C14: 0 | D14: 0 | E14: =IFERROR(C14-D14,0) | F14: =IFERROR(D14/C14,0)
A15: HOUSING TOTAL | C15: =SUM(C10:C14) | D15: =SUM(D10:D14) | E15: =IFERROR(C15-D15,0) | F15: =IFERROR(D15/C15,0)
A16: TRANSPORT
A17: TRANSPORT | B17: Car Payment | C17: 0 | D17: 0 | E17: =IFERROR(C17-D17,0) | F17: =IFERROR(D17/C17,0)
A18: TRANSPORT | B18: Fuel | C18: 0 | D18: 0 | E18: =IFERROR(C18-D18,0) | F18: =IFERROR(D18/C18,0)
A19: TRANSPORT | B19: Car Insurance | C19: 0 | D19: 0 | E19: =IFERROR(C19-D19,0) | F19: =IFERROR(D19/C19,0)
A20: TRANSPORT | B20: Parking | C20: 0 | D20: 0 | E20: =IFERROR(C20-D20,0) | F20: =IFERROR(D20/C20,0)
A21: TRANSPORT | B21: Public Transport | C21: 0 | D21: 0 | E21: =IFERROR(C21-D21,0) | F21: =IFERROR(D21/C21,0)
A22: TRANSPORT TOTAL | C22: =SUM(C17:C21) | D22: =SUM(D17:D21) | E22: =IFERROR(C22-D22,0) | F22: =IFERROR(D22/C22,0)
A23: FOOD & DINING
A24: FOOD & DINING | B24: Groceries | C24: 0 | D24: 0 | E24: =IFERROR(C24-D24,0) | F24: =IFERROR(D24/C24,0)
A25: FOOD & DINING | B25: Restaurants | C25: 0 | D25: 0 | E25: =IFERROR(C25-D25,0) | F25: =IFERROR(D25/C25,0)
A26: FOOD & DINING | B26: Coffee | C26: 0 | D26: 0 | E26: =IFERROR(C26-D26,0) | F26: =IFERROR(D26/C26,0)
A27: FOOD & DINING | B27: Food Delivery | C27: 0 | D27: 0 | E27: =IFERROR(C27-D27,0) | F27: =IFERROR(D27/C27,0)
A28: FOOD & DINING | B28: Work Lunch | C28: 0 | D28: 0 | E28: =IFERROR(C28-D28,0) | F28: =IFERROR(D28/C28,0)
A29: FOOD & DINING TOTAL | C29: =SUM(C24:C28) | D29: =SUM(D24:D28) | E29: =IFERROR(C29-D29,0) | F29: =IFERROR(D29/C29,0)
A30: HEALTH & WELLNESS
A31: HEALTH & WELLNESS | B31: Health Insurance | C31: 0 | D31: 0 | E31: =IFERROR(C31-D31,0) | F31: =IFERROR(D31/C31,0)
A32: HEALTH & WELLNESS | B32: Gym | C32: 0 | D32: 0 | E32: =IFERROR(C32-D32,0) | F32: =IFERROR(D32/C32,0)
A33: HEALTH & WELLNESS | B33: Pharmacy | C33: 0 | D33: 0 | E33: =IFERROR(C33-D33,0) | F33: =IFERROR(D33/C33,0)
A34: HEALTH & WELLNESS | B34: Doctor | C34: 0 | D34: 0 | E34: =IFERROR(C34-D34,0) | F34: =IFERROR(D34/C34,0)
A35: HEALTH & WELLNESS | B35: Dental | C35: 0 | D35: 0 | E35: =IFERROR(C35-D35,0) | F35: =IFERROR(D35/C35,0)
A36: HEALTH & WELLNESS TOTAL | C36: =SUM(C31:C35) | D36: =SUM(D31:D35) | E36: =IFERROR(C36-D36,0) | F36: =IFERROR(D36/C36,0)
A37: LIFESTYLE
A38: LIFESTYLE | B38: Streaming Services | C38: 0 | D38: 0 | E38: =IFERROR(C38-D38,0) | F38: =IFERROR(D38/C38,0)
A39: LIFESTYLE | B39: Entertainment | C39: 0 | D39: 0 | E39: =IFERROR(C39-D39,0) | F39: =IFERROR(D39/C39,0)
A40: LIFESTYLE | B40: Hobbies | C40: 0 | D40: 0 | E40: =IFERROR(C40-D40,0) | F40: =IFERROR(D40/C40,0)
...

Sheet Nov
A1: NOVEMBER · MONTHLY BUDGET
A2: Track your income and expenses for November
A3: CATEGORY | B3: SUBCATEGORY | C3: BUDGETED | D3: ACTUAL | E3: DIFFERENCE | F3: % USED | G3: NOTES
A4: INCOME
A5: INCOME | B5: Primary Income | C5: 0 | D5: 0 | E5: =IFERROR(C5-D5,0) | F5: =IFERROR(D5/C5,0)
A6: INCOME | B6: Side Income | C6: 0 | D6: 0 | E6: =IFERROR(C6-D6,0) | F6: =IFERROR(D6/C6,0)
A7: INCOME | B7: Other Income | C7: 0 | D7: 0 | E7: =IFERROR(C7-D7,0) | F7: =IFERROR(D7/C7,0)
A8: TOTAL INCOME | C8: =SUM(C5:C7) | D8: =SUM(D5:D7) | E8: =IFERROR(C8-D8,0) | F8: =IFERROR(D8/C8,0)
A9: HOUSING
A10: HOUSING | B10: Rent/Mortgage | C10: 0 | D10: 0 | E10: =IFERROR(C10-D10,0) | F10: =IFERROR(D10/C10,0)
A11: HOUSING | B11: Utilities | C11: 0 | D11: 0 | E11: =IFERROR(C11-D11,0) | F11: =IFERROR(D11/C11,0)
A12: HOUSING | B12: Electricity | C12: 0 | D12: 0 | E12: =IFERROR(C12-D12,0) | F12: =IFERROR(D12/C12,0)
A13: HOUSING | B13: Internet | C13: 0 | D13: 0 | E13: =IFERROR(C13-D13,0) | F13: =IFERROR(D13/C13,0)
A14: HOUSING | B14: Home Insurance | C14: 0 | D14: 0 | E14: =IFERROR(C14-D14,0) | F14: =IFERROR(D14/C14,0)
A15: HOUSING TOTAL | C15: =SUM(C10:C14) | D15: =SUM(D10:D14) | E15: =IFERROR(C15-D15,0) | F15: =IFERROR(D15/C15,0)
A16: TRANSPORT
A17: TRANSPORT | B17: Car Payment | C17: 0 | D17: 0 | E17: =IFERROR(C17-D17,0) | F17: =IFERROR(D17/C17,0)
A18: TRANSPORT | B18: Fuel | C18: 0 | D18: 0 | E18: =IFERROR(C18-D18,0) | F18: =IFERROR(D18/C18,0)
A19: TRANSPORT | B19: Car Insurance | C19: 0 | D19: 0 | E19: =IFERROR(C19-D19,0) | F19: =IFERROR(D19/C19,0)
A20: TRANSPORT | B20: Parking | C20: 0 | D20: 0 | E20: =IFERROR(C20-D20,0) | F20: =IFERROR(D20/C20,0)
A21: TRANSPORT | B21: Public Transport | C21: 0 | D21: 0 | E21: =IFERROR(C21-D21,0) | F21: =IFERROR(D21/C21,0)
A22: TRANSPORT TOTAL | C22: =SUM(C17:C21) | D22: =SUM(D17:D21) | E22: =IFERROR(C22-D22,0) | F22: =IFERROR(D22/C22,0)
A23: FOOD & DINING
A24: FOOD & DINING | B24: Groceries | C24: 0 | D24: 0 | E24: =IFERROR(C24-D24,0) | F24: =IFERROR(D24/C24,0)
A25: FOOD & DINING | B25: Restaurants | C25: 0 | D25: 0 | E25: =IFERROR(C25-D25,0) | F25: =IFERROR(D25/C25,0)
A26: FOOD & DINING | B26: Coffee | C26: 0 | D26: 0 | E26: =IFERROR(C26-D26,0) | F26: =IFERROR(D26/C26,0)
A27: FOOD & DINING | B27: Food Delivery | C27: 0 | D27: 0 | E27: =IFERROR(C27-D27,0) | F27: =IFERROR(D27/C27,0)
A28: FOOD & DINING | B28: Work Lunch | C28: 0 | D28: 0 | E28: =IFERROR(C28-D28,0) | F28: =IFERROR(D28/C28,0)
A29: FOOD & DINING TOTAL | C29: =SUM(C24:C28) | D29: =SUM(D24:D28) | E29: =IFERROR(C29-D29,0) | F29: =IFERROR(D29/C29,0)
A30: HEALTH & WELLNESS
A31: HEALTH & WELLNESS | B31: Health Insurance | C31: 0 | D31: 0 | E31: =IFERROR(C31-D31,0) | F31: =IFERROR(D31/C31,0)
A32: HEALTH & WELLNESS | B32: Gym | C32: 0 | D32: 0 | E32: =IFERROR(C32-D32,0) | F32: =IFERROR(D32/C32,0)
A33: HEALTH & WELLNESS | B33: Pharmacy | C33: 0 | D33: 0 | E33: =IFERROR(C33-D33,0) | F33: =IFERROR(D33/C33,0)
A34: HEALTH & WELLNESS | B34: Doctor | C34: 0 | D34: 0 | E34: =IFERROR(C34-D34,0) | F34: =IFERROR(D34/C34,0)
A35: HEALTH & WELLNESS | B35: Dental | C35: 0 | D35: 0 | E35: =IFERROR(C35-D35,0) | F35: =IFERROR(D35/C35,0)
A36: HEALTH & WELLNESS TOTAL | C36: =SUM(C31:C35) | D36: =SUM(D31:D35) | E36: =IFERROR(C36-D36,0) | F36: =IFERROR(D36/C36,0)
A37: LIFESTYLE
A38: LIFESTYLE | B38: Streaming Services | C38: 0 | D38: 0 | E38: =IFERROR(C38-D38,0) | F38: =IFERROR(D38/C38,0)
A39: LIFESTYLE | B39: Entertainment | C39: 0 | D39: 0 | E39: =IFERROR(C39-D39,0) | F39: =IFERROR(D39/C39,0)
A40: LIFESTYLE | B40: Hobbies | C40: 0 | D40: 0 | E40: =IFERROR(C40-D40,0) | F40: =IFERROR(D40/C40,0)
...

Sheet Dec
A1: DECEMBER · MONTHLY BUDGET
A2: Track your income and expenses for December
A3: CATEGORY | B3: SUBCATEGORY | C3: BUDGETED | D3: ACTUAL | E3: DIFFERENCE | F3: % USED | G3: NOTES
A4: INCOME
A5: INCOME | B5: Primary Income | C5: 0 | D5: 0 | E5: =IFERROR(C5-D5,0) | F5: =IFERROR(D5/C5,0)
A6: INCOME | B6: Side Income | C6: 0 | D6: 0 | E6: =IFERROR(C6-D6,0) | F6: =IFERROR(D6/C6,0)
A7: INCOME | B7: Other Income | C7: 0 | D7: 0 | E7: =IFERROR(C7-D7,0) | F7: =IFERROR(D7/C7,0)
A8: TOTAL INCOME | C8: =SUM(C5:C7) | D8: =SUM(D5:D7) | E8: =IFERROR(C8-D8,0) | F8: =IFERROR(D8/C8,0)
A9: HOUSING
A10: HOUSING | B10: Rent/Mortgage | C10: 0 | D10: 0 | E10: =IFERROR(C10-D10,0) | F10: =IFERROR(D10/C10,0)
A11: HOUSING | B11: Utilities | C11: 0 | D11: 0 | E11: =IFERROR(C11-D11,0) | F11: =IFERROR(D11/C11,0)
A12: HOUSING | B12: Electricity | C12: 0 | D12: 0 | E12: =IFERROR(C12-D12,0) | F12: =IFERROR(D12/C12,0)
A13: HOUSING | B13: Internet | C13: 0 | D13: 0 | E13: =IFERROR(C13-D13,0) | F13: =IFERROR(D13/C13,0)
A14: HOUSING | B14: Home Insurance | C14: 0 | D14: 0 | E14: =IFERROR(C14-D14,0) | F14: =IFERROR(D14/C14,0)
A15: HOUSING TOTAL | C15: =SUM(C10:C14) | D15: =SUM(D10:D14) | E15: =IFERROR(C15-D15,0) | F15: =IFERROR(D15/C15,0)
A16: TRANSPORT
A17: TRANSPORT | B17: Car Payment | C17: 0 | D17: 0 | E17: =IFERROR(C17-D17,0) | F17: =IFERROR(D17/C17,0)
A18: TRANSPORT | B18: Fuel | C18: 0 | D18: 0 | E18: =IFERROR(C18-D18,0) | F18: =IFERROR(D18/C18,0)
A19: TRANSPORT | B19: Car Insurance | C19: 0 | D19: 0 | E19: =IFERROR(C19-D19,0) | F19: =IFERROR(D19/C19,0)
A20: TRANSPORT | B20: Parking | C20: 0 | D20: 0 | E20: =IFERROR(C20-D20,0) | F20: =IFERROR(D20/C20,0)
A21: TRANSPORT | B21: Public Transport | C21: 0 | D21: 0 | E21: =IFERROR(C21-D21,0) | F21: =IFERROR(D21/C21,0)
A22: TRANSPORT TOTAL | C22: =SUM(C17:C21) | D22: =SUM(D17:D21) | E22: =IFERROR(C22-D22,0) | F22: =IFERROR(D22/C22,0)
A23: FOOD & DINING
A24: FOOD & DINING | B24: Groceries | C24: 0 | D24: 0 | E24: =IFERROR(C24-D24,0) | F24: =IFERROR(D24/C24,0)
A25: FOOD & DINING | B25: Restaurants | C25: 0 | D25: 0 | E25: =IFERROR(C25-D25,0) | F25: =IFERROR(D25/C25,0)
A26: FOOD & DINING | B26: Coffee | C26: 0 | D26: 0 | E26: =IFERROR(C26-D26,0) | F26: =IFERROR(D26/C26,0)
A27: FOOD & DINING | B27: Food Delivery | C27: 0 | D27: 0 | E27: =IFERROR(C27-D27,0) | F27: =IFERROR(D27/C27,0)
A28: FOOD & DINING | B28: Work Lunch | C28: 0 | D28: 0 | E28: =IFERROR(C28-D28,0) | F28: =IFERROR(D28/C28,0)
A29: FOOD & DINING TOTAL | C29: =SUM(C24:C28) | D29: =SUM(D24:D28) | E29: =IFERROR(C29-D29,0) | F29: =IFERROR(D29/C29,0)
A30: HEALTH & WELLNESS
A31: HEALTH & WELLNESS | B31: Health Insurance | C31: 0 | D31: 0 | E31: =IFERROR(C31-D31,0) | F31: =IFERROR(D31/C31,0)
A32: HEALTH & WELLNESS | B32: Gym | C32: 0 | D32: 0 | E32: =IFERROR(C32-D32,0) | F32: =IFERROR(D32/C32,0)
A33: HEALTH & WELLNESS | B33: Pharmacy | C33: 0 | D33: 0 | E33: =IFERROR(C33-D33,0) | F33: =IFERROR(D33/C33,0)
A34: HEALTH & WELLNESS | B34: Doctor | C34: 0 | D34: 0 | E34: =IFERROR(C34-D34,0) | F34: =IFERROR(D34/C34,0)
A35: HEALTH & WELLNESS | B35: Dental | C35: 0 | D35: 0 | E35: =IFERROR(C35-D35,0) | F35: =IFERROR(D35/C35,0)
A36: HEALTH & WELLNESS TOTAL | C36: =SUM(C31:C35) | D36: =SUM(D31:D35) | E36: =IFERROR(C36-D36,0) | F36: =IFERROR(D36/C36,0)
A37: LIFESTYLE
A38: LIFESTYLE | B38: Streaming Services | C38: 0 | D38: 0 | E38: =IFERROR(C38-D38,0) | F38: =IFERROR(D38/C38,0)
A39: LIFESTYLE | B39: Entertainment | C39: 0 | D39: 0 | E39: =IFERROR(C39-D39,0) | F39: =IFERROR(D39/C39,0)
A40: LIFESTYLE | B40: Hobbies | C40: 0 | D40: 0 | E40: =IFERROR(C40-D40,0) | F40: =IFERROR(D40/C40,0)
...

Sheet Debt Tracker
A1: DEBT PAYOFF TRACKER
A2: Track balances, rates, and payoff progress
A3: DEBT NAME | B3: LENDER | C3: ORIGINAL BAL | D3: CURRENT BAL | E3: INTEREST % | F3: MIN PAYMENT | G3: MONTHLY PMT | H3: EST PAYOFF DATE | I3: STATUS
A4: Credit Card 1 | C4: 0 | D4: 0 | E4: 0 | F4: 0 | G4: 0 | I4: Active
A5: Credit Card 2 | C5: 0 | D5: 0 | E5: 0 | F5: 0 | G5: 0 | I5: Active
A6: Student Loan | C6: 0 | D6: 0 | E6: 0 | F6: 0 | G6: 0 | I6: Active
A7: Car Loan | C7: 0 | D7: 0 | E7: 0 | F7: 0 | G7: 0 | I7: Active
A8: Personal Loan | C8: 0 | D8: 0 | E8: 0 | F8: 0 | G8: 0 | I8: Active
A9: Other Debt | C9: 0 | D9: 0 | E9: 0 | F9: 0 | G9: 0 | I9: Active
A10: TOTALS | C10: =SUM(C4:C9) | D10: =SUM(D4:D9) | F10: =SUM(F4:F9) | G10: =SUM(G4:G9)
A12: DEBT SUMMARY
A13: Total Outstanding Debt | D13: =IFERROR(SUM(D4:D9),0)
A14: Total Monthly Minimums | D14: =IFERROR(SUM(F4:F9),0)
A15: Debt-to-Income Ratio | D15: =IFERROR(SUM(D4:D9)/(Dashboard!D5/12),0)
A16: Highest Interest Rate Debt | D16: =IFERROR(INDEX(A4:A9,MATCH(MAX(E4:E9),E4:E9,0)),"N/A")

Sheet Bill Calendar
A1: BILL CALENDAR · 2026
A2: Track recurring bills, auto-payments, and annual costs
A3: BILL NAME | B3: CATEGORY | C3: AMOUNT | D3: DUE DATE | E3: FREQUENCY | F3: AUTO-PAY | G3: PAID? | H3: ANNUAL COST | I3: NOTES
A4: Rent/Mortgage | B4: Housing | C4: 1200 | D4: 01/01/2026 | E4: Monthly | F4: No | G4: No | H4: =IFERROR(IF(E4="Monthly",C4*12,IF(E4="Annual",C4,IF(E4="Quarterly",C4*4,C4*52))),0)
A5: Electricity | B5: Utilities | C5: 80 | D5: 01/15/2026 | E5: Monthly | F5: Yes | G5: No | H5: =IFERROR(IF(E5="Monthly",C5*12,IF(E5="Annual",C5,IF(E5="Quarterly",C5*4,C5*52))),0)
A6: Internet | B6: Utilities | C6: 60 | D6: 01/22/2026 | E6: Monthly | F6: Yes | G6: No | H6: =IFERROR(IF(E6="Monthly",C6*12,IF(E6="Annual",C6,IF(E6="Quarterly",C6*4,C6*52))),0)
A7: Phone | B7: Subscriptions | C7: 70 | D7: 01/12/2026 | E7: Monthly | F7: Yes | G7: No | H7: =IFERROR(IF(E7="Monthly",C7*12,IF(E7="Annual",C7,IF(E7="Quarterly",C7*4,C7*52))),0)
A8: Car Insurance | B8: Insurance | C8: 120 | D8: 01/20/2026 | E8: Monthly | F8: No | G8: No | H8: =IFERROR(IF(E8="Monthly",C8*12,IF(E8="Annual",C8,IF(E8="Quarterly",C8*4,C8*52))),0)
A9: Streaming | B9: Subscriptions | C9: 18 | D9: 01/08/2026 | E9: Monthly | F9: Yes | G9: No | H9: =IFERROR(IF(E9="Monthly",C9*12,IF(E9="Annual",C9,IF(E9="Quarterly",C9*4,C9*52))),0)
A10: Gym Membership | B10: Health | C10: 45 | D10: 01/01/2026 | E10: Monthly | F10: Yes | G10: No | H10: =IFERROR(IF(E10="Monthly",C10*12,IF(E10="Annual",C10,IF(E10="Quarterly",C10*4,C10*52))),0)
A11: Spotify | B11: Subscriptions | C11: 11 | D11: 01/05/2026 | E11: Monthly | F11: Yes | G11: No | H11: =IFERROR(IF(E11="Monthly",C11*12,IF(E11="Annual",C11,IF(E11="Quarterly",C11*4,C11*52))),0)
A12: Home Insurance | B12: Insurance | C12: 150 | D12: 01/01/2026 | E12: Annual | F12: No | G12: No | H12: =IFERROR(IF(E12="Monthly",C12*12,IF(E12="Annual",C12,IF(E12="Quarterly",C12*4,C12*52))),0)
A13: Car Registration | B13: Transport | C13: 85 | D13: 03/01/2026 | E13: Annual | F13: No | G13: No | H13: =IFERROR(IF(E13="Monthly",C13*12,IF(E13="Annual",C13,IF(E13="Quarterly",C13*4,C13*52))),0)
A14: MONTHLY TOTAL | C14: =SUM(C4:C13) | H14: =SUM(H4:H13)

Sheet Savings Goals
A1: SAVINGS GOALS TRACKER
A2: Monitor your savings goals and projected completion dates
A3: GOAL | B3: TARGET AMOUNT | C3: SAVED SO FAR | D3: MONTHLY CONTRIB | E3: TARGET DATE | F3: % COMPLETE | G3: PROGRESS | H3: PRIORITY
A4: Emergency Fund | B4: 10000 | C4: 0 | D4: 500 | E4: 12/31/2026 | F4: =IFERROR(C4/B4,0) | G4: =IFERROR(REPT(CHAR(9608),ROUND(F4*10,0))&REPT(CHAR(9617),10-ROUND(F4*10,0))," ") | H4: High
A5: Vacation | B5: 3000 | C5: 0 | D5: 200 | E5: 07/01/2026 | F5: =IFERROR(C5/B5,0) | G5: =IFERROR(REPT(CHAR(9608),ROUND(F5*10,0))&REPT(CHAR(9617),10-ROUND(F5*10,0))," ") | H5: Medium
A6: Home Down Payment | B6: 50000 | C6: 0 | D6: 800 | E6: 01/01/2029 | F6: =IFERROR(C6/B6,0) | G6: =IFERROR(REPT(CHAR(9608),ROUND(F6*10,0))&REPT(CHAR(9617),10-ROUND(F6*10,0))," ") | H6: High
A7: New Car | B7: 15000 | C7: 0 | D7: 300 | E7: 06/01/2027 | F7: =IFERROR(C7/B7,0) | G7: =IFERROR(REPT(CHAR(9608),ROUND(F7*10,0))&REPT(CHAR(9617),10-ROUND(F7*10,0))," ") | H7: Medium
A8: Education | B8: 8000 | C8: 0 | D8: 250 | E8: 09/01/2027 | F8: =IFERROR(C8/B8,0) | G8: =IFERROR(REPT(CHAR(9608),ROUND(F8*10,0))&REPT(CHAR(9617),10-ROUND(F8*10,0))," ") | H8: Medium
A9: Retirement Boost | B9: 20000 | C9: 0 | D9: 400 | E9: 01/01/2030 | F9: =IFERROR(C9/B9,0) | G9: =IFERROR(REPT(CHAR(9608),ROUND(F9*10,0))&REPT(CHAR(9617),10-ROUND(F9*10,0))," ") | H9: Low
A10: TOTALS | B10: =SUM(B4:B9) | C10: =SUM(C4:C9) | D10: =SUM(D4:D9) | F10: =IFERROR(SUM(C4:C9)/SUM(B4:B9),0)

Sheet Annual Overview
A1: ANNUAL OVERVIEW · 2026
A2: Year-at-a-glance: pull from all 12 monthly sheets
A3: LINE ITEM | B3: Jan | C3: Feb | D3: Mar | E3: Apr | F3: May | G3: Jun | H3: Jul | I3: Aug | J3: Sep | K3: Oct | L3: Nov | M3: Dec | N3: ANNUAL TOTAL | O3: ANNUAL BUDGET | P3: VARIANCE
A4: INCOME | B4: =IFERROR(Jan!D8,0) | C4: =IFERROR(Feb!D8,0) | D4: =IFERROR(Mar!D8,0) | E4: =IFERROR(Apr!D8,0) | F4: =IFERROR(May!D8,0) | G4: =IFERROR(Jun!D8,0) | H4: =IFERROR(Jul!D8,0) | I4: =IFERROR(Aug!D8,0) | J4: =IFERROR(Sep!D8,0) | K4: =IFERROR(Oct!D8,0) | L4: =IFERROR(Nov!D8,0) | M4: =IFERROR(Dec!D8,0) | N4: =SUM(B4:M4) | O4: 0 | P4: =IFERROR(N4-O4,0)
A5: HOUSING | B5: =IFERROR(Jan!D15,0) | C5: =IFERROR(Feb!D15,0) | D5: =IFERROR(Mar!D15,0) | E5: =IFERROR(Apr!D15,0) | F5: =IFERROR(May!D15,0) | G5: =IFERROR(Jun!D15,0) | H5: =IFERROR(Jul!D15,0) | I5: =IFERROR(Aug!D15,0) | J5: =IFERROR(Sep!D15,0) | K5: =IFERROR(Oct!D15,0) | L5: =IFERROR(Nov!D15,0) | M5: =IFERROR(Dec!D15,0) | N5: =SUM(B5:M5) | O5: 0 | P5: =IFERROR(N5-O5,0)
A6: TRANSPORT | B6: =IFERROR(Jan!D22,0) | C6: =IFERROR(Feb!D22,0) | D6: =IFERROR(Mar!D22,0) | E6: =IFERROR(Apr!D22,0) | F6: =IFERROR(May!D22,0) | G6: =IFERROR(Jun!D22,0) | H6: =IFERROR(Jul!D22,0) | I6: =IFERROR(Aug!D22,0) | J6: =IFERROR(Sep!D22,0) | K6: =IFERROR(Oct!D22,0) | L6: =IFERROR(Nov!D22,0) | M6: =IFERROR(Dec!D22,0) | N6: =SUM(B6:M6) | O6: 0 | P6: =IFERROR(N6-O6,0)
A7: FOOD & DINING | B7: =IFERROR(Jan!D29,0) | C7: =IFERROR(Feb!D29,0) | D7: =IFERROR(Mar!D29,0) | E7: =IFERROR(Apr!D29,0) | F7: =IFERROR(May!D29,0) | G7: =IFERROR(Jun!D29,0) | H7: =IFERROR(Jul!D29,0) | I7: =IFERROR(Aug!D29,0) | J7: =IFERROR(Sep!D29,0) | K7: =IFERROR(Oct!D29,0) | L7: =IFERROR(Nov!D29,0) | M7: =IFERROR(Dec!D29,0) | N7: =SUM(B7:M7) | O7: 0 | P7: =IFERROR(N7-O7,0)
A8: HEALTH & WELLNESS | B8: =IFERROR(Jan!D36,0) | C8: =IFERROR(Feb!D36,0) | D8: =IFERROR(Mar!D36,0) | E8: =IFERROR(Apr!D36,0) | F8: =IFERROR(May!D36,0) | G8: =IFERROR(Jun!D36,0) | H8: =IFERROR(Jul!D36,0) | I8: =IFERROR(Aug!D36,0) | J8: =IFERROR(Sep!D36,0) | K8: =IFERROR(Oct!D36,0) | L8: =IFERROR(Nov!D36,0) | M8: =IFERROR(Dec!D36,0) | N8: =SUM(B8:M8) | O8: 0 | P8: =IFERROR(N8-O8,0)
A9: LIFESTYLE | B9: =IFERROR(Jan!D43,0) | C9: =IFERROR(Feb!D43,0) | D9: =IFERROR(Mar!D43,0) | E9: =IFERROR(Apr!D43,0) | F9: =IFERROR(May!D43,0) | G9: =IFERROR(Jun!D43,0) | H9: =IFERROR(Jul!D43,0) | I9: =IFERROR(Aug!D43,0) | J9: =IFERROR(Sep!D43,0) | K9: =IFERROR(Oct!D43,0) | L9: =IFERROR(Nov!D43,0) | M9: =IFERROR(Dec!D43,0) | N9: =SUM(B9:M9) | O9: 0 | P9: =IFERROR(N9-O9,0)
A10: PERSONAL | B10: =IFERROR(Jan!D50,0) | C10: =IFERROR(Feb!D50,0) | D10: =IFERROR(Mar!D50,0) | E10: =IFERROR(Apr!D50,0) | F10: =IFERROR(May!D50,0) | G10: =IFERROR(Jun!D50,0) | H10: =IFERROR(Jul!D50,0) | I10: =IFERROR(Aug!D50,0) | J10: =IFERROR(Sep!D50,0) | K10: =IFERROR(Oct!D50,0) | L10: =IFERROR(Nov!D50,0) | M10: =IFERROR(Dec!D50,0) | N10: =SUM(B10:M10) | O10: 0 | P10: =IFERROR(N10-O10,0)
A11: SAVINGS & INVESTMENTS | B11: =IFERROR(Jan!D57,0) | C11: =IFERROR(Feb!D57,0) | D11: =IFERROR(Mar!D57,0) | E11: =IFERROR(Apr!D57,0) | F11: =IFERROR(May!D57,0) | G11: =IFERROR(Jun!D57,0) | H11: =IFERROR(Jul!D57,0) | I11: =IFERROR(Aug!D57,0) | J11: =IFERROR(Sep!D57,0) | K11: =IFERROR(Oct!D57,0) | L11: =IFERROR(Nov!D57,0) | M11: =IFERROR(Dec!D57,0) | N11: =SUM(B11:M11) | O11: 0 | P11: =IFERROR(N11-O11,0)
A12: DEBT PAYMENTS | B12: =IFERROR(Jan!D64,0) | C12: =IFERROR(Feb!D64,0) | D12: =IFERROR(Mar!D64,0) | E12: =IFERROR(Apr!D64,0) | F12: =IFERROR(May!D64,0) | G12: =IFERROR(Jun!D64,0) | H12: =IFERROR(Jul!D64,0) | I12: =IFERROR(Aug!D64,0) | J12: =IFERROR(Sep!D64,0) | K12: =IFERROR(Oct!D64,0) | L12: =IFERROR(Nov!D64,0) | M12: =IFERROR(Dec!D64,0) | N12: =SUM(B12:M12) | O12: 0 | P12: =IFERROR(N12-O12,0)
A13: GRAND TOTAL EXPENSES | B13: =IFERROR(Jan!D65,0) | C13: =IFERROR(Feb!D65,0) | D13: =IFERROR(Mar!D65,0) | E13: =IFERROR(Apr!D65,0) | F13: =IFERROR(May!D65,0) | G13: =IFERROR(Jun!D65,0) | H13: =IFERROR(Jul!D65,0) | I13: =IFERROR(Aug!D65,0) | J13: =IFERROR(Sep!D65,0) | K13: =IFERROR(Oct!D65,0) | L13: =IFERROR(Nov!D65,0) | M13: =IFERROR(Dec!D65,0) | N13: =SUM(B13:M13) | O13: 0 | P13: =IFERROR(N13-O13,0)
A14: NET CASH FLOW | B14: =IFERROR(Jan!D66,0) | C14: =IFERROR(Feb!D66,0) | D14: =IFERROR(Mar!D66,0) | E14: =IFERROR(Apr!D66,0) | F14: =IFERROR(May!D66,0) | G14: =IFERROR(Jun!D66,0) | H14: =IFERROR(Jul!D66,0) | I14: =IFERROR(Aug!D66,0) | J14: =IFERROR(Sep!D66,0) | K14: =IFERROR(Oct!D66,0) | L14: =IFERROR(Nov!D66,0) | M14: =IFERROR(Dec!D66,0) | N14: =SUM(B14:M14) | O14: 0 | P14: =IFERROR(N14-O14,0)
A17: KEY METRICS
A18: Best Month (lowest spend) | D18: =IFERROR(INDEX(B3:M3,MATCH(MIN(B13:M13),B13:M13,0)),"N/A")
A19: Worst Month (highest spend) | D19: =IFERROR(INDEX(B3:M3,MATCH(MAX(B13:M13),B13:M13,0)),"N/A")
A20: Annual Savings Rate | D20: =IFERROR((N4-N13)/N4,0)
A21: Average Monthly Spend | D21: =IFERROR(N13/12,0)
