Workbook

Sheet Dashboard
A1: DASHBOARD · THE ULTIMATE MONTHLY BUDGET · 2026
A2: Your complete financial picture at a glance
A3: BUDGET OVERVIEW | P3: Category | Q3: Amount
A4: Annual Income | B4: =Jan!D11+Feb!D11+Mar!D11+Apr!D11+May!D11+Jun!D11+Jul!D11+Aug!D11+Sep!D11+Oct!D11+Nov!D11+Dec!D11 | P4: HOUSING | Q4: =Jan!D19+Feb!D19+Mar!D19+Apr!D19+May!D19+Jun!D19+Jul!D19+Aug!D19+Sep!D19+Oct!D19+Nov!D19+Dec!D19
A5: Annual Expenses | B5: =Jan!D76+Feb!D76+Mar!D76+Apr!D76+May!D76+Jun!D76+Jul!D76+Aug!D76+Sep!D76+Oct!D76+Nov!D76+Dec!D76 | P5: TRANSPORT | Q5: =Jan!D27+Feb!D27+Mar!D27+Apr!D27+May!D27+Jun!D27+Jul!D27+Aug!D27+Sep!D27+Oct!D27+Nov!D27+Dec!D27
A6: Annual Savings | B6: =Jan!D67+Feb!D67+Mar!D67+Apr!D67+May!D67+Jun!D67+Jul!D67+Aug!D67+Sep!D67+Oct!D67+Nov!D67+Dec!D67 | P6: FOOD & DINING | Q6: =Jan!D35+Feb!D35+Mar!D35+Apr!D35+May!D35+Jun!D35+Jul!D35+Aug!D35+Sep!D35+Oct!D35+Nov!D35+Dec!D35
A7: Savings Rate | B7: =IFERROR(B6/B4,0) | P7: HEALTH & WELLNESS | Q7: =Jan!D43+Feb!D43+Mar!D43+Apr!D43+May!D43+Jun!D43+Jul!D43+Aug!D43+Sep!D43+Oct!D43+Nov!D43+Dec!D43
A8: Best Month | B8: =INDEX({"Jan","Feb","Mar","Apr","May","Jun","Jul","Aug","Sep","Oct","Nov","Dec"},MATCH(MAX(Jan!D77,Feb!D77,Mar!D77,Apr!D77,May!D77,Jun!D77,Jul!D77,Aug!D77,Sep!D77,Oct!D77,Nov!D77,Dec!D77),{Jan!D77,Feb!D77,Mar!D77,Apr!D77,May!D77,Jun!D77,Jul!D77,Aug!D77,Sep!D77,Oct!D77,Nov!D77,Dec!D77},0)) | P8: LIFESTYLE | Q8: =Jan!D51+Feb!D51+Mar!D51+Apr!D51+May!D51+Jun!D51+Jul!D51+Aug!D51+Sep!D51+Oct!D51+Nov!D51+Dec!D51
A9: Worst Month | B9: =INDEX({"Jan","Feb","Mar","Apr","May","Jun","Jul","Aug","Sep","Oct","Nov","Dec"},MATCH(MIN(Jan!D77,Feb!D77,Mar!D77,Apr!D77,May!D77,Jun!D77,Jul!D77,Aug!D77,Sep!D77,Oct!D77,Nov!D77,Dec!D77),{Jan!D77,Feb!D77,Mar!D77,Apr!D77,May!D77,Jun!D77,Jul!D77,Aug!D77,Sep!D77,Oct!D77,Nov!D77,Dec!D77},0)) | P9: CHILDREN & FAMILY | Q9: =Jan!D59+Feb!D59+Mar!D59+Apr!D59+May!D59+Jun!D59+Jul!D59+Aug!D59+Sep!D59+Oct!D59+Nov!D59+Dec!D59
A10: Metric | B10: Jan | C10: Feb | D10: Mar | E10: Apr | F10: May | G10: Jun | H10: Jul | I10: Aug | J10: Sep | K10: Oct | L10: Nov | M10: Dec | P10: SAVINGS & INVESTMENTS | Q10: =Jan!D67+Feb!D67+Mar!D67+Apr!D67+May!D67+Jun!D67+Jul!D67+Aug!D67+Sep!D67+Oct!D67+Nov!D67+Dec!D67
A11: Monthly Income | B11: =Jan!D11 | C11: =Feb!D11 | D11: =Mar!D11 | E11: =Apr!D11 | F11: =May!D11 | G11: =Jun!D11 | H11: =Jul!D11 | I11: =Aug!D11 | J11: =Sep!D11 | K11: =Oct!D11 | L11: =Nov!D11 | M11: =Dec!D11 | P11: DEBT PAYMENTS | Q11: =Jan!D75+Feb!D75+Mar!D75+Apr!D75+May!D75+Jun!D75+Jul!D75+Aug!D75+Sep!D75+Oct!D75+Nov!D75+Dec!D75
A12: Cumulative Income | B12: =B11 | C12: =B12+C11 | D12: =C12+D11 | E12: =D12+E11 | F12: =E12+F11 | G12: =F12+G11 | H12: =G12+H11 | I12: =H12+I11 | J12: =I12+J11 | ... M12: =L12+M11 | P12: Goal | Q12: Target
A13: Monthly Expenses | B13: =Jan!D76 | C13: =Feb!D76 | D13: =Mar!D76 | E13: =Apr!D76 | F13: =May!D76 | G13: =Jun!D76 | H13: =Jul!D76 | I13: =Aug!D76 | J13: =Sep!D76 | K13: =Oct!D76 | L13: =Nov!D76 | M13: =Dec!D76 | P13: Emergency Fund | Q13: 50000
A14: Monthly Savings | B14: =Jan!D67 | C14: =Feb!D67 | D14: =Mar!D67 | E14: =Apr!D67 | F14: =May!D67 | G14: =Jun!D67 | H14: =Jul!D67 | I14: =Aug!D67 | J14: =Sep!D67 | K14: =Oct!D67 | L14: =Nov!D67 | M14: =Dec!D67 | P14: Vacation — Japan | Q14: 25000
A15: Cumul Savings | B15: =B14 | C15: =B15+C14 | D15: =C15+D14 | E15: =D15+E14 | F15: =E15+F14 | G15: =F15+G14 | H15: =G15+H14 | I15: =H15+I14 | J15: =I15+J14 | ... M15: =L15+M14 | P15: Home Down Payment | Q15: 250000
A16: Net Flow | B16: =Jan!D77 | C16: =Feb!D77 | D16: =Mar!D77 | E16: =Apr!D77 | F16: =May!D77 | G16: =Jun!D77 | H16: =Jul!D77 | I16: =Aug!D77 | J16: =Sep!D77 | K16: =Oct!D77 | L16: =Nov!D77 | M16: =Dec!D77 | P16: New Car | Q16: 80000
A17: Category | B17: HOUSING | C17: TRANSPORT | D17: FOOD & DINING | E17: HEALTH & WELLNESS | F17: LIFESTYLE | G17: CHILDREN & FAMILY | H17: SAVINGS & INVESTMENTS | I17: DEBT PAYMENTS | P17: Retirement Boost | Q17: 100000
A18: Annual Amount | B18: =Jan!D19+Feb!D19+Mar!D19+Apr!D19+May!D19+Jun!D19+Jul!D19+Aug!D19+Sep!D19+Oct!D19+Nov!D19+Dec!D19 | C18: =Jan!D27+Feb!D27+Mar!D27+Apr!D27+May!D27+Jun!D27+Jul!D27+Aug!D27+Sep!D27+Oct!D27+Nov!D27+Dec!D27 | D18: =Jan!D35+Feb!D35+Mar!D35+Apr!D35+May!D35+Jun!D35+Jul!D35+Aug!D35+Sep!D35+Oct!D35+Nov!D35+Dec!D35 | E18: =Jan!D43+Feb!D43+Mar!D43+Apr!D43+May!D43+Jun!D43+Jul!D43+Aug!D43+Sep!D43+Oct!D43+Nov!D43+Dec!D43 | F18: =Jan!D51+Feb!D51+Mar!D51+Apr!D51+May!D51+Jun!D51+Jul!D51+Aug!D51+Sep!D51+Oct!D51+Nov!D51+Dec!D51 | G18: =Jan!D59+Feb!D59+Mar!D59+Apr!D59+May!D59+Jun!D59+Jul!D59+Aug!D59+Sep!D59+Oct!D59+Nov!D59+Dec!D59 | H18: =Jan!D67+Feb!D67+Mar!D67+Apr!D67+May!D67+Jun!D67+Jul!D67+Aug!D67+Sep!D67+Oct!D67+Nov!D67+Dec!D67 | I18: =Jan!D75+Feb!D75+Mar!D75+Apr!D75+May!D75+Jun!D75+Jul!D75+Aug!D75+Sep!D75+Oct!D75+Nov!D75+Dec!D75 | P18: Education Fund | Q18: 40000
A19: Goal | B19: Emergency Fund | C19: Vacation — Japan | D19: Home Down Payment | E19: New Car | F19: Retirement Boost | G19: Education Fund | H19: Wedding Fund | I19: Home Renovation | P19: Wedding Fund | Q19: 60000
A20: Target | B20: 50000 | C20: 25000 | D20: 250000 | E20: 80000 | F20: 100000 | G20: 40000 | H20: 60000 | I20: 35000 | P20: Home Renovation | Q20: 35000

Sheet Jan
A1: JANUARY · MONTHLY BUDGET
A2: Track your income, expenses, and savings for the month
A3: CATEGORY | B3: SUBCATEGORY | C3: BUDGETED | D3: ACTUAL | E3: DIFFERENCE | F3: % USED | G3: NOTES
A4: INCOME
A5: INCOME | B5: Primary Salary | C5: 0 | D5: 0 | E5: =C5-D5 | F5: =IFERROR(D5/C5,0)
A6: INCOME | B6: Freelance | C6: 0 | D6: 0 | E6: =C6-D6 | F6: =IFERROR(D6/C6,0)
A7: INCOME | B7: Rental Income | C7: 0 | D7: 0 | E7: =C7-D7 | F7: =IFERROR(D7/C7,0)
A8: INCOME | B8: Dividends | C8: 0 | D8: 0 | E8: =C8-D8 | F8: =IFERROR(D8/C8,0)
A9: INCOME | B9: Side Business | C9: 0 | D9: 0 | E9: =C9-D9 | F9: =IFERROR(D9/C9,0)
A10: INCOME | B10: Other Income | C10: 0 | D10: 0 | E10: =C10-D10 | F10: =IFERROR(D10/C10,0)
A11: TOTAL INCOME | C11: =SUM(C5:C10) | D11: =SUM(D5:D10) | E11: =C11-D11 | F11: =IFERROR(D11/C11,0)
A12: HOUSING
A13: HOUSING | B13: Rent/Mortgage | C13: 0 | D13: 0 | E13: =C13-D13 | F13: =IFERROR(D13/C13,0)
A14: HOUSING | B14: Electricity | C14: 0 | D14: 0 | E14: =C14-D14 | F14: =IFERROR(D14/C14,0)
A15: HOUSING | B15: Water | C15: 0 | D15: 0 | E15: =C15-D15 | F15: =IFERROR(D15/C15,0)
A16: HOUSING | B16: Internet | C16: 0 | D16: 0 | E16: =C16-D16 | F16: =IFERROR(D16/C16,0)
A17: HOUSING | B17: Home Insurance | C17: 0 | D17: 0 | E17: =C17-D17 | F17: =IFERROR(D17/C17,0)
A18: HOUSING | B18: Maintenance | C18: 0 | D18: 0 | E18: =C18-D18 | F18: =IFERROR(D18/C18,0)
A19: HOUSING TOTAL | C19: =SUM(C13:C18) | D19: =SUM(D13:D18) | E19: =C19-D19 | F19: =IFERROR(D19/C19,0)
A20: TRANSPORT
A21: TRANSPORT | B21: Car Payment | C21: 0 | D21: 0 | E21: =C21-D21 | F21: =IFERROR(D21/C21,0)
A22: TRANSPORT | B22: Fuel | C22: 0 | D22: 0 | E22: =C22-D22 | F22: =IFERROR(D22/C22,0)
A23: TRANSPORT | B23: Car Insurance | C23: 0 | D23: 0 | E23: =C23-D23 | F23: =IFERROR(D23/C23,0)
A24: TRANSPORT | B24: Parking | C24: 0 | D24: 0 | E24: =C24-D24 | F24: =IFERROR(D24/C24,0)
A25: TRANSPORT | B25: Public Transport | C25: 0 | D25: 0 | E25: =C25-D25 | F25: =IFERROR(D25/C25,0)
A26: TRANSPORT | B26: Ride Share | C26: 0 | D26: 0 | E26: =C26-D26 | F26: =IFERROR(D26/C26,0)
A27: TRANSPORT TOTAL | C27: =SUM(C21:C26) | D27: =SUM(D21:D26) | E27: =C27-D27 | F27: =IFERROR(D27/C27,0)
A28: FOOD & DINING
A29: FOOD & DINING | B29: Groceries | C29: 0 | D29: 0 | E29: =C29-D29 | F29: =IFERROR(D29/C29,0)
A30: FOOD & DINING | B30: Restaurants | C30: 0 | D30: 0 | E30: =C30-D30 | F30: =IFERROR(D30/C30,0)
A31: FOOD & DINING | B31: Coffee Shops | C31: 0 | D31: 0 | E31: =C31-D31 | F31: =IFERROR(D31/C31,0)
A32: FOOD & DINING | B32: Food Delivery | C32: 0 | D32: 0 | E32: =C32-D32 | F32: =IFERROR(D32/C32,0)
A33: FOOD & DINING | B33: Work Lunch | C33: 0 | D33: 0 | E33: =C33-D33 | F33: =IFERROR(D33/C33,0)
A34: FOOD & DINING | B34: Other | C34: 0 | D34: 0 | E34: =C34-D34 | F34: =IFERROR(D34/C34,0)
A35: FOOD & DINING TOTAL | C35: =SUM(C29:C34) | D35: =SUM(D29:D34) | E35: =C35-D35 | F35: =IFERROR(D35/C35,0)
A36: HEALTH & WELLNESS
A37: HEALTH & WELLNESS | B37: Health Insurance | C37: 0 | D37: 0 | E37: =C37-D37 | F37: =IFERROR(D37/C37,0)
A38: HEALTH & WELLNESS | B38: Gym Membership | C38: 0 | D38: 0 | E38: =C38-D38 | F38: =IFERROR(D38/C38,0)
A39: HEALTH & WELLNESS | B39: Pharmacy | C39: 0 | D39: 0 | E39: =C39-D39 | F39: =IFERROR(D39/C39,0)
A40: HEALTH & WELLNESS | B40: Doctor Visits | C40: 0 | D40: 0 | E40: =C40-D40 | F40: =IFERROR(D40/C40,0)
...

Sheet Feb
A1: FEBRUARY · MONTHLY BUDGET
A2: Track your income, expenses, and savings for the month
A3: CATEGORY | B3: SUBCATEGORY | C3: BUDGETED | D3: ACTUAL | E3: DIFFERENCE | F3: % USED | G3: NOTES
A4: INCOME
A5: INCOME | B5: Primary Salary | C5: 0 | D5: 0 | E5: =C5-D5 | F5: =IFERROR(D5/C5,0)
A6: INCOME | B6: Freelance | C6: 0 | D6: 0 | E6: =C6-D6 | F6: =IFERROR(D6/C6,0)
A7: INCOME | B7: Rental Income | C7: 0 | D7: 0 | E7: =C7-D7 | F7: =IFERROR(D7/C7,0)
A8: INCOME | B8: Dividends | C8: 0 | D8: 0 | E8: =C8-D8 | F8: =IFERROR(D8/C8,0)
A9: INCOME | B9: Side Business | C9: 0 | D9: 0 | E9: =C9-D9 | F9: =IFERROR(D9/C9,0)
A10: INCOME | B10: Other Income | C10: 0 | D10: 0 | E10: =C10-D10 | F10: =IFERROR(D10/C10,0)
A11: TOTAL INCOME | C11: =SUM(C5:C10) | D11: =SUM(D5:D10) | E11: =C11-D11 | F11: =IFERROR(D11/C11,0)
A12: HOUSING
A13: HOUSING | B13: Rent/Mortgage | C13: 0 | D13: 0 | E13: =C13-D13 | F13: =IFERROR(D13/C13,0)
A14: HOUSING | B14: Electricity | C14: 0 | D14: 0 | E14: =C14-D14 | F14: =IFERROR(D14/C14,0)
A15: HOUSING | B15: Water | C15: 0 | D15: 0 | E15: =C15-D15 | F15: =IFERROR(D15/C15,0)
A16: HOUSING | B16: Internet | C16: 0 | D16: 0 | E16: =C16-D16 | F16: =IFERROR(D16/C16,0)
A17: HOUSING | B17: Home Insurance | C17: 0 | D17: 0 | E17: =C17-D17 | F17: =IFERROR(D17/C17,0)
A18: HOUSING | B18: Maintenance | C18: 0 | D18: 0 | E18: =C18-D18 | F18: =IFERROR(D18/C18,0)
A19: HOUSING TOTAL | C19: =SUM(C13:C18) | D19: =SUM(D13:D18) | E19: =C19-D19 | F19: =IFERROR(D19/C19,0)
A20: TRANSPORT
A21: TRANSPORT | B21: Car Payment | C21: 0 | D21: 0 | E21: =C21-D21 | F21: =IFERROR(D21/C21,0)
A22: TRANSPORT | B22: Fuel | C22: 0 | D22: 0 | E22: =C22-D22 | F22: =IFERROR(D22/C22,0)
A23: TRANSPORT | B23: Car Insurance | C23: 0 | D23: 0 | E23: =C23-D23 | F23: =IFERROR(D23/C23,0)
A24: TRANSPORT | B24: Parking | C24: 0 | D24: 0 | E24: =C24-D24 | F24: =IFERROR(D24/C24,0)
A25: TRANSPORT | B25: Public Transport | C25: 0 | D25: 0 | E25: =C25-D25 | F25: =IFERROR(D25/C25,0)
A26: TRANSPORT | B26: Ride Share | C26: 0 | D26: 0 | E26: =C26-D26 | F26: =IFERROR(D26/C26,0)
A27: TRANSPORT TOTAL | C27: =SUM(C21:C26) | D27: =SUM(D21:D26) | E27: =C27-D27 | F27: =IFERROR(D27/C27,0)
A28: FOOD & DINING
A29: FOOD & DINING | B29: Groceries | C29: 0 | D29: 0 | E29: =C29-D29 | F29: =IFERROR(D29/C29,0)
A30: FOOD & DINING | B30: Restaurants | C30: 0 | D30: 0 | E30: =C30-D30 | F30: =IFERROR(D30/C30,0)
A31: FOOD & DINING | B31: Coffee Shops | C31: 0 | D31: 0 | E31: =C31-D31 | F31: =IFERROR(D31/C31,0)
A32: FOOD & DINING | B32: Food Delivery | C32: 0 | D32: 0 | E32: =C32-D32 | F32: =IFERROR(D32/C32,0)
A33: FOOD & DINING | B33: Work Lunch | C33: 0 | D33: 0 | E33: =C33-D33 | F33: =IFERROR(D33/C33,0)
A34: FOOD & DINING | B34: Other | C34: 0 | D34: 0 | E34: =C34-D34 | F34: =IFERROR(D34/C34,0)
A35: FOOD & DINING TOTAL | C35: =SUM(C29:C34) | D35: =SUM(D29:D34) | E35: =C35-D35 | F35: =IFERROR(D35/C35,0)
A36: HEALTH & WELLNESS
A37: HEALTH & WELLNESS | B37: Health Insurance | C37: 0 | D37: 0 | E37: =C37-D37 | F37: =IFERROR(D37/C37,0)
A38: HEALTH & WELLNESS | B38: Gym Membership | C38: 0 | D38: 0 | E38: =C38-D38 | F38: =IFERROR(D38/C38,0)
A39: HEALTH & WELLNESS | B39: Pharmacy | C39: 0 | D39: 0 | E39: =C39-D39 | F39: =IFERROR(D39/C39,0)
A40: HEALTH & WELLNESS | B40: Doctor Visits | C40: 0 | D40: 0 | E40: =C40-D40 | F40: =IFERROR(D40/C40,0)
...

Sheet Mar
A1: MARCH · MONTHLY BUDGET
A2: Track your income, expenses, and savings for the month
A3: CATEGORY | B3: SUBCATEGORY | C3: BUDGETED | D3: ACTUAL | E3: DIFFERENCE | F3: % USED | G3: NOTES
A4: INCOME
A5: INCOME | B5: Primary Salary | C5: 0 | D5: 0 | E5: =C5-D5 | F5: =IFERROR(D5/C5,0)
A6: INCOME | B6: Freelance | C6: 0 | D6: 0 | E6: =C6-D6 | F6: =IFERROR(D6/C6,0)
A7: INCOME | B7: Rental Income | C7: 0 | D7: 0 | E7: =C7-D7 | F7: =IFERROR(D7/C7,0)
A8: INCOME | B8: Dividends | C8: 0 | D8: 0 | E8: =C8-D8 | F8: =IFERROR(D8/C8,0)
A9: INCOME | B9: Side Business | C9: 0 | D9: 0 | E9: =C9-D9 | F9: =IFERROR(D9/C9,0)
A10: INCOME | B10: Other Income | C10: 0 | D10: 0 | E10: =C10-D10 | F10: =IFERROR(D10/C10,0)
A11: TOTAL INCOME | C11: =SUM(C5:C10) | D11: =SUM(D5:D10) | E11: =C11-D11 | F11: =IFERROR(D11/C11,0)
A12: HOUSING
A13: HOUSING | B13: Rent/Mortgage | C13: 0 | D13: 0 | E13: =C13-D13 | F13: =IFERROR(D13/C13,0)
A14: HOUSING | B14: Electricity | C14: 0 | D14: 0 | E14: =C14-D14 | F14: =IFERROR(D14/C14,0)
A15: HOUSING | B15: Water | C15: 0 | D15: 0 | E15: =C15-D15 | F15: =IFERROR(D15/C15,0)
A16: HOUSING | B16: Internet | C16: 0 | D16: 0 | E16: =C16-D16 | F16: =IFERROR(D16/C16,0)
A17: HOUSING | B17: Home Insurance | C17: 0 | D17: 0 | E17: =C17-D17 | F17: =IFERROR(D17/C17,0)
A18: HOUSING | B18: Maintenance | C18: 0 | D18: 0 | E18: =C18-D18 | F18: =IFERROR(D18/C18,0)
A19: HOUSING TOTAL | C19: =SUM(C13:C18) | D19: =SUM(D13:D18) | E19: =C19-D19 | F19: =IFERROR(D19/C19,0)
A20: TRANSPORT
A21: TRANSPORT | B21: Car Payment | C21: 0 | D21: 0 | E21: =C21-D21 | F21: =IFERROR(D21/C21,0)
A22: TRANSPORT | B22: Fuel | C22: 0 | D22: 0 | E22: =C22-D22 | F22: =IFERROR(D22/C22,0)
A23: TRANSPORT | B23: Car Insurance | C23: 0 | D23: 0 | E23: =C23-D23 | F23: =IFERROR(D23/C23,0)
A24: TRANSPORT | B24: Parking | C24: 0 | D24: 0 | E24: =C24-D24 | F24: =IFERROR(D24/C24,0)
A25: TRANSPORT | B25: Public Transport | C25: 0 | D25: 0 | E25: =C25-D25 | F25: =IFERROR(D25/C25,0)
A26: TRANSPORT | B26: Ride Share | C26: 0 | D26: 0 | E26: =C26-D26 | F26: =IFERROR(D26/C26,0)
A27: TRANSPORT TOTAL | C27: =SUM(C21:C26) | D27: =SUM(D21:D26) | E27: =C27-D27 | F27: =IFERROR(D27/C27,0)
A28: FOOD & DINING
A29: FOOD & DINING | B29: Groceries | C29: 0 | D29: 0 | E29: =C29-D29 | F29: =IFERROR(D29/C29,0)
A30: FOOD & DINING | B30: Restaurants | C30: 0 | D30: 0 | E30: =C30-D30 | F30: =IFERROR(D30/C30,0)
A31: FOOD & DINING | B31: Coffee Shops | C31: 0 | D31: 0 | E31: =C31-D31 | F31: =IFERROR(D31/C31,0)
A32: FOOD & DINING | B32: Food Delivery | C32: 0 | D32: 0 | E32: =C32-D32 | F32: =IFERROR(D32/C32,0)
A33: FOOD & DINING | B33: Work Lunch | C33: 0 | D33: 0 | E33: =C33-D33 | F33: =IFERROR(D33/C33,0)
A34: FOOD & DINING | B34: Other | C34: 0 | D34: 0 | E34: =C34-D34 | F34: =IFERROR(D34/C34,0)
A35: FOOD & DINING TOTAL | C35: =SUM(C29:C34) | D35: =SUM(D29:D34) | E35: =C35-D35 | F35: =IFERROR(D35/C35,0)
A36: HEALTH & WELLNESS
A37: HEALTH & WELLNESS | B37: Health Insurance | C37: 0 | D37: 0 | E37: =C37-D37 | F37: =IFERROR(D37/C37,0)
A38: HEALTH & WELLNESS | B38: Gym Membership | C38: 0 | D38: 0 | E38: =C38-D38 | F38: =IFERROR(D38/C38,0)
A39: HEALTH & WELLNESS | B39: Pharmacy | C39: 0 | D39: 0 | E39: =C39-D39 | F39: =IFERROR(D39/C39,0)
A40: HEALTH & WELLNESS | B40: Doctor Visits | C40: 0 | D40: 0 | E40: =C40-D40 | F40: =IFERROR(D40/C40,0)
...

Sheet Apr
A1: APRIL · MONTHLY BUDGET
A2: Track your income, expenses, and savings for the month
A3: CATEGORY | B3: SUBCATEGORY | C3: BUDGETED | D3: ACTUAL | E3: DIFFERENCE | F3: % USED | G3: NOTES
A4: INCOME
A5: INCOME | B5: Primary Salary | C5: 0 | D5: 0 | E5: =C5-D5 | F5: =IFERROR(D5/C5,0)
A6: INCOME | B6: Freelance | C6: 0 | D6: 0 | E6: =C6-D6 | F6: =IFERROR(D6/C6,0)
A7: INCOME | B7: Rental Income | C7: 0 | D7: 0 | E7: =C7-D7 | F7: =IFERROR(D7/C7,0)
A8: INCOME | B8: Dividends | C8: 0 | D8: 0 | E8: =C8-D8 | F8: =IFERROR(D8/C8,0)
A9: INCOME | B9: Side Business | C9: 0 | D9: 0 | E9: =C9-D9 | F9: =IFERROR(D9/C9,0)
A10: INCOME | B10: Other Income | C10: 0 | D10: 0 | E10: =C10-D10 | F10: =IFERROR(D10/C10,0)
A11: TOTAL INCOME | C11: =SUM(C5:C10) | D11: =SUM(D5:D10) | E11: =C11-D11 | F11: =IFERROR(D11/C11,0)
A12: HOUSING
A13: HOUSING | B13: Rent/Mortgage | C13: 0 | D13: 0 | E13: =C13-D13 | F13: =IFERROR(D13/C13,0)
A14: HOUSING | B14: Electricity | C14: 0 | D14: 0 | E14: =C14-D14 | F14: =IFERROR(D14/C14,0)
A15: HOUSING | B15: Water | C15: 0 | D15: 0 | E15: =C15-D15 | F15: =IFERROR(D15/C15,0)
A16: HOUSING | B16: Internet | C16: 0 | D16: 0 | E16: =C16-D16 | F16: =IFERROR(D16/C16,0)
A17: HOUSING | B17: Home Insurance | C17: 0 | D17: 0 | E17: =C17-D17 | F17: =IFERROR(D17/C17,0)
A18: HOUSING | B18: Maintenance | C18: 0 | D18: 0 | E18: =C18-D18 | F18: =IFERROR(D18/C18,0)
A19: HOUSING TOTAL | C19: =SUM(C13:C18) | D19: =SUM(D13:D18) | E19: =C19-D19 | F19: =IFERROR(D19/C19,0)
A20: TRANSPORT
A21: TRANSPORT | B21: Car Payment | C21: 0 | D21: 0 | E21: =C21-D21 | F21: =IFERROR(D21/C21,0)
A22: TRANSPORT | B22: Fuel | C22: 0 | D22: 0 | E22: =C22-D22 | F22: =IFERROR(D22/C22,0)
A23: TRANSPORT | B23: Car Insurance | C23: 0 | D23: 0 | E23: =C23-D23 | F23: =IFERROR(D23/C23,0)
A24: TRANSPORT | B24: Parking | C24: 0 | D24: 0 | E24: =C24-D24 | F24: =IFERROR(D24/C24,0)
A25: TRANSPORT | B25: Public Transport | C25: 0 | D25: 0 | E25: =C25-D25 | F25: =IFERROR(D25/C25,0)
A26: TRANSPORT | B26: Ride Share | C26: 0 | D26: 0 | E26: =C26-D26 | F26: =IFERROR(D26/C26,0)
A27: TRANSPORT TOTAL | C27: =SUM(C21:C26) | D27: =SUM(D21:D26) | E27: =C27-D27 | F27: =IFERROR(D27/C27,0)
A28: FOOD & DINING
A29: FOOD & DINING | B29: Groceries | C29: 0 | D29: 0 | E29: =C29-D29 | F29: =IFERROR(D29/C29,0)
A30: FOOD & DINING | B30: Restaurants | C30: 0 | D30: 0 | E30: =C30-D30 | F30: =IFERROR(D30/C30,0)
A31: FOOD & DINING | B31: Coffee Shops | C31: 0 | D31: 0 | E31: =C31-D31 | F31: =IFERROR(D31/C31,0)
A32: FOOD & DINING | B32: Food Delivery | C32: 0 | D32: 0 | E32: =C32-D32 | F32: =IFERROR(D32/C32,0)
A33: FOOD & DINING | B33: Work Lunch | C33: 0 | D33: 0 | E33: =C33-D33 | F33: =IFERROR(D33/C33,0)
A34: FOOD & DINING | B34: Other | C34: 0 | D34: 0 | E34: =C34-D34 | F34: =IFERROR(D34/C34,0)
A35: FOOD & DINING TOTAL | C35: =SUM(C29:C34) | D35: =SUM(D29:D34) | E35: =C35-D35 | F35: =IFERROR(D35/C35,0)
A36: HEALTH & WELLNESS
A37: HEALTH & WELLNESS | B37: Health Insurance | C37: 0 | D37: 0 | E37: =C37-D37 | F37: =IFERROR(D37/C37,0)
A38: HEALTH & WELLNESS | B38: Gym Membership | C38: 0 | D38: 0 | E38: =C38-D38 | F38: =IFERROR(D38/C38,0)
A39: HEALTH & WELLNESS | B39: Pharmacy | C39: 0 | D39: 0 | E39: =C39-D39 | F39: =IFERROR(D39/C39,0)
A40: HEALTH & WELLNESS | B40: Doctor Visits | C40: 0 | D40: 0 | E40: =C40-D40 | F40: =IFERROR(D40/C40,0)
...

Sheet May
A1: MAY · MONTHLY BUDGET
A2: Track your income, expenses, and savings for the month
A3: CATEGORY | B3: SUBCATEGORY | C3: BUDGETED | D3: ACTUAL | E3: DIFFERENCE | F3: % USED | G3: NOTES
A4: INCOME
A5: INCOME | B5: Primary Salary | C5: 0 | D5: 0 | E5: =C5-D5 | F5: =IFERROR(D5/C5,0)
A6: INCOME | B6: Freelance | C6: 0 | D6: 0 | E6: =C6-D6 | F6: =IFERROR(D6/C6,0)
A7: INCOME | B7: Rental Income | C7: 0 | D7: 0 | E7: =C7-D7 | F7: =IFERROR(D7/C7,0)
A8: INCOME | B8: Dividends | C8: 0 | D8: 0 | E8: =C8-D8 | F8: =IFERROR(D8/C8,0)
A9: INCOME | B9: Side Business | C9: 0 | D9: 0 | E9: =C9-D9 | F9: =IFERROR(D9/C9,0)
A10: INCOME | B10: Other Income | C10: 0 | D10: 0 | E10: =C10-D10 | F10: =IFERROR(D10/C10,0)
A11: TOTAL INCOME | C11: =SUM(C5:C10) | D11: =SUM(D5:D10) | E11: =C11-D11 | F11: =IFERROR(D11/C11,0)
A12: HOUSING
A13: HOUSING | B13: Rent/Mortgage | C13: 0 | D13: 0 | E13: =C13-D13 | F13: =IFERROR(D13/C13,0)
A14: HOUSING | B14: Electricity | C14: 0 | D14: 0 | E14: =C14-D14 | F14: =IFERROR(D14/C14,0)
A15: HOUSING | B15: Water | C15: 0 | D15: 0 | E15: =C15-D15 | F15: =IFERROR(D15/C15,0)
A16: HOUSING | B16: Internet | C16: 0 | D16: 0 | E16: =C16-D16 | F16: =IFERROR(D16/C16,0)
A17: HOUSING | B17: Home Insurance | C17: 0 | D17: 0 | E17: =C17-D17 | F17: =IFERROR(D17/C17,0)
A18: HOUSING | B18: Maintenance | C18: 0 | D18: 0 | E18: =C18-D18 | F18: =IFERROR(D18/C18,0)
A19: HOUSING TOTAL | C19: =SUM(C13:C18) | D19: =SUM(D13:D18) | E19: =C19-D19 | F19: =IFERROR(D19/C19,0)
A20: TRANSPORT
A21: TRANSPORT | B21: Car Payment | C21: 0 | D21: 0 | E21: =C21-D21 | F21: =IFERROR(D21/C21,0)
A22: TRANSPORT | B22: Fuel | C22: 0 | D22: 0 | E22: =C22-D22 | F22: =IFERROR(D22/C22,0)
A23: TRANSPORT | B23: Car Insurance | C23: 0 | D23: 0 | E23: =C23-D23 | F23: =IFERROR(D23/C23,0)
A24: TRANSPORT | B24: Parking | C24: 0 | D24: 0 | E24: =C24-D24 | F24: =IFERROR(D24/C24,0)
A25: TRANSPORT | B25: Public Transport | C25: 0 | D25: 0 | E25: =C25-D25 | F25: =IFERROR(D25/C25,0)
A26: TRANSPORT | B26: Ride Share | C26: 0 | D26: 0 | E26: =C26-D26 | F26: =IFERROR(D26/C26,0)
A27: TRANSPORT TOTAL | C27: =SUM(C21:C26) | D27: =SUM(D21:D26) | E27: =C27-D27 | F27: =IFERROR(D27/C27,0)
A28: FOOD & DINING
A29: FOOD & DINING | B29: Groceries | C29: 0 | D29: 0 | E29: =C29-D29 | F29: =IFERROR(D29/C29,0)
A30: FOOD & DINING | B30: Restaurants | C30: 0 | D30: 0 | E30: =C30-D30 | F30: =IFERROR(D30/C30,0)
A31: FOOD & DINING | B31: Coffee Shops | C31: 0 | D31: 0 | E31: =C31-D31 | F31: =IFERROR(D31/C31,0)
A32: FOOD & DINING | B32: Food Delivery | C32: 0 | D32: 0 | E32: =C32-D32 | F32: =IFERROR(D32/C32,0)
A33: FOOD & DINING | B33: Work Lunch | C33: 0 | D33: 0 | E33: =C33-D33 | F33: =IFERROR(D33/C33,0)
A34: FOOD & DINING | B34: Other | C34: 0 | D34: 0 | E34: =C34-D34 | F34: =IFERROR(D34/C34,0)
A35: FOOD & DINING TOTAL | C35: =SUM(C29:C34) | D35: =SUM(D29:D34) | E35: =C35-D35 | F35: =IFERROR(D35/C35,0)
A36: HEALTH & WELLNESS
A37: HEALTH & WELLNESS | B37: Health Insurance | C37: 0 | D37: 0 | E37: =C37-D37 | F37: =IFERROR(D37/C37,0)
A38: HEALTH & WELLNESS | B38: Gym Membership | C38: 0 | D38: 0 | E38: =C38-D38 | F38: =IFERROR(D38/C38,0)
A39: HEALTH & WELLNESS | B39: Pharmacy | C39: 0 | D39: 0 | E39: =C39-D39 | F39: =IFERROR(D39/C39,0)
A40: HEALTH & WELLNESS | B40: Doctor Visits | C40: 0 | D40: 0 | E40: =C40-D40 | F40: =IFERROR(D40/C40,0)
...

Sheet Jun
A1: JUNE · MONTHLY BUDGET
A2: Track your income, expenses, and savings for the month
A3: CATEGORY | B3: SUBCATEGORY | C3: BUDGETED | D3: ACTUAL | E3: DIFFERENCE | F3: % USED | G3: NOTES
A4: INCOME
A5: INCOME | B5: Primary Salary | C5: 0 | D5: 0 | E5: =C5-D5 | F5: =IFERROR(D5/C5,0)
A6: INCOME | B6: Freelance | C6: 0 | D6: 0 | E6: =C6-D6 | F6: =IFERROR(D6/C6,0)
A7: INCOME | B7: Rental Income | C7: 0 | D7: 0 | E7: =C7-D7 | F7: =IFERROR(D7/C7,0)
A8: INCOME | B8: Dividends | C8: 0 | D8: 0 | E8: =C8-D8 | F8: =IFERROR(D8/C8,0)
A9: INCOME | B9: Side Business | C9: 0 | D9: 0 | E9: =C9-D9 | F9: =IFERROR(D9/C9,0)
A10: INCOME | B10: Other Income | C10: 0 | D10: 0 | E10: =C10-D10 | F10: =IFERROR(D10/C10,0)
A11: TOTAL INCOME | C11: =SUM(C5:C10) | D11: =SUM(D5:D10) | E11: =C11-D11 | F11: =IFERROR(D11/C11,0)
A12: HOUSING
A13: HOUSING | B13: Rent/Mortgage | C13: 0 | D13: 0 | E13: =C13-D13 | F13: =IFERROR(D13/C13,0)
A14: HOUSING | B14: Electricity | C14: 0 | D14: 0 | E14: =C14-D14 | F14: =IFERROR(D14/C14,0)
A15: HOUSING | B15: Water | C15: 0 | D15: 0 | E15: =C15-D15 | F15: =IFERROR(D15/C15,0)
A16: HOUSING | B16: Internet | C16: 0 | D16: 0 | E16: =C16-D16 | F16: =IFERROR(D16/C16,0)
A17: HOUSING | B17: Home Insurance | C17: 0 | D17: 0 | E17: =C17-D17 | F17: =IFERROR(D17/C17,0)
A18: HOUSING | B18: Maintenance | C18: 0 | D18: 0 | E18: =C18-D18 | F18: =IFERROR(D18/C18,0)
A19: HOUSING TOTAL | C19: =SUM(C13:C18) | D19: =SUM(D13:D18) | E19: =C19-D19 | F19: =IFERROR(D19/C19,0)
A20: TRANSPORT
A21: TRANSPORT | B21: Car Payment | C21: 0 | D21: 0 | E21: =C21-D21 | F21: =IFERROR(D21/C21,0)
A22: TRANSPORT | B22: Fuel | C22: 0 | D22: 0 | E22: =C22-D22 | F22: =IFERROR(D22/C22,0)
A23: TRANSPORT | B23: Car Insurance | C23: 0 | D23: 0 | E23: =C23-D23 | F23: =IFERROR(D23/C23,0)
A24: TRANSPORT | B24: Parking | C24: 0 | D24: 0 | E24: =C24-D24 | F24: =IFERROR(D24/C24,0)
A25: TRANSPORT | B25: Public Transport | C25: 0 | D25: 0 | E25: =C25-D25 | F25: =IFERROR(D25/C25,0)
A26: TRANSPORT | B26: Ride Share | C26: 0 | D26: 0 | E26: =C26-D26 | F26: =IFERROR(D26/C26,0)
A27: TRANSPORT TOTAL | C27: =SUM(C21:C26) | D27: =SUM(D21:D26) | E27: =C27-D27 | F27: =IFERROR(D27/C27,0)
A28: FOOD & DINING
A29: FOOD & DINING | B29: Groceries | C29: 0 | D29: 0 | E29: =C29-D29 | F29: =IFERROR(D29/C29,0)
A30: FOOD & DINING | B30: Restaurants | C30: 0 | D30: 0 | E30: =C30-D30 | F30: =IFERROR(D30/C30,0)
A31: FOOD & DINING | B31: Coffee Shops | C31: 0 | D31: 0 | E31: =C31-D31 | F31: =IFERROR(D31/C31,0)
A32: FOOD & DINING | B32: Food Delivery | C32: 0 | D32: 0 | E32: =C32-D32 | F32: =IFERROR(D32/C32,0)
A33: FOOD & DINING | B33: Work Lunch | C33: 0 | D33: 0 | E33: =C33-D33 | F33: =IFERROR(D33/C33,0)
A34: FOOD & DINING | B34: Other | C34: 0 | D34: 0 | E34: =C34-D34 | F34: =IFERROR(D34/C34,0)
A35: FOOD & DINING TOTAL | C35: =SUM(C29:C34) | D35: =SUM(D29:D34) | E35: =C35-D35 | F35: =IFERROR(D35/C35,0)
A36: HEALTH & WELLNESS
A37: HEALTH & WELLNESS | B37: Health Insurance | C37: 0 | D37: 0 | E37: =C37-D37 | F37: =IFERROR(D37/C37,0)
A38: HEALTH & WELLNESS | B38: Gym Membership | C38: 0 | D38: 0 | E38: =C38-D38 | F38: =IFERROR(D38/C38,0)
A39: HEALTH & WELLNESS | B39: Pharmacy | C39: 0 | D39: 0 | E39: =C39-D39 | F39: =IFERROR(D39/C39,0)
A40: HEALTH & WELLNESS | B40: Doctor Visits | C40: 0 | D40: 0 | E40: =C40-D40 | F40: =IFERROR(D40/C40,0)
...

Sheet Jul
A1: JULY · MONTHLY BUDGET
A2: Track your income, expenses, and savings for the month
A3: CATEGORY | B3: SUBCATEGORY | C3: BUDGETED | D3: ACTUAL | E3: DIFFERENCE | F3: % USED | G3: NOTES
A4: INCOME
A5: INCOME | B5: Primary Salary | C5: 0 | D5: 0 | E5: =C5-D5 | F5: =IFERROR(D5/C5,0)
A6: INCOME | B6: Freelance | C6: 0 | D6: 0 | E6: =C6-D6 | F6: =IFERROR(D6/C6,0)
A7: INCOME | B7: Rental Income | C7: 0 | D7: 0 | E7: =C7-D7 | F7: =IFERROR(D7/C7,0)
A8: INCOME | B8: Dividends | C8: 0 | D8: 0 | E8: =C8-D8 | F8: =IFERROR(D8/C8,0)
A9: INCOME | B9: Side Business | C9: 0 | D9: 0 | E9: =C9-D9 | F9: =IFERROR(D9/C9,0)
A10: INCOME | B10: Other Income | C10: 0 | D10: 0 | E10: =C10-D10 | F10: =IFERROR(D10/C10,0)
A11: TOTAL INCOME | C11: =SUM(C5:C10) | D11: =SUM(D5:D10) | E11: =C11-D11 | F11: =IFERROR(D11/C11,0)
A12: HOUSING
A13: HOUSING | B13: Rent/Mortgage | C13: 0 | D13: 0 | E13: =C13-D13 | F13: =IFERROR(D13/C13,0)
A14: HOUSING | B14: Electricity | C14: 0 | D14: 0 | E14: =C14-D14 | F14: =IFERROR(D14/C14,0)
A15: HOUSING | B15: Water | C15: 0 | D15: 0 | E15: =C15-D15 | F15: =IFERROR(D15/C15,0)
A16: HOUSING | B16: Internet | C16: 0 | D16: 0 | E16: =C16-D16 | F16: =IFERROR(D16/C16,0)
A17: HOUSING | B17: Home Insurance | C17: 0 | D17: 0 | E17: =C17-D17 | F17: =IFERROR(D17/C17,0)
A18: HOUSING | B18: Maintenance | C18: 0 | D18: 0 | E18: =C18-D18 | F18: =IFERROR(D18/C18,0)
A19: HOUSING TOTAL | C19: =SUM(C13:C18) | D19: =SUM(D13:D18) | E19: =C19-D19 | F19: =IFERROR(D19/C19,0)
A20: TRANSPORT
A21: TRANSPORT | B21: Car Payment | C21: 0 | D21: 0 | E21: =C21-D21 | F21: =IFERROR(D21/C21,0)
A22: TRANSPORT | B22: Fuel | C22: 0 | D22: 0 | E22: =C22-D22 | F22: =IFERROR(D22/C22,0)
A23: TRANSPORT | B23: Car Insurance | C23: 0 | D23: 0 | E23: =C23-D23 | F23: =IFERROR(D23/C23,0)
A24: TRANSPORT | B24: Parking | C24: 0 | D24: 0 | E24: =C24-D24 | F24: =IFERROR(D24/C24,0)
A25: TRANSPORT | B25: Public Transport | C25: 0 | D25: 0 | E25: =C25-D25 | F25: =IFERROR(D25/C25,0)
A26: TRANSPORT | B26: Ride Share | C26: 0 | D26: 0 | E26: =C26-D26 | F26: =IFERROR(D26/C26,0)
A27: TRANSPORT TOTAL | C27: =SUM(C21:C26) | D27: =SUM(D21:D26) | E27: =C27-D27 | F27: =IFERROR(D27/C27,0)
A28: FOOD & DINING
A29: FOOD & DINING | B29: Groceries | C29: 0 | D29: 0 | E29: =C29-D29 | F29: =IFERROR(D29/C29,0)
A30: FOOD & DINING | B30: Restaurants | C30: 0 | D30: 0 | E30: =C30-D30 | F30: =IFERROR(D30/C30,0)
A31: FOOD & DINING | B31: Coffee Shops | C31: 0 | D31: 0 | E31: =C31-D31 | F31: =IFERROR(D31/C31,0)
A32: FOOD & DINING | B32: Food Delivery | C32: 0 | D32: 0 | E32: =C32-D32 | F32: =IFERROR(D32/C32,0)
A33: FOOD & DINING | B33: Work Lunch | C33: 0 | D33: 0 | E33: =C33-D33 | F33: =IFERROR(D33/C33,0)
A34: FOOD & DINING | B34: Other | C34: 0 | D34: 0 | E34: =C34-D34 | F34: =IFERROR(D34/C34,0)
A35: FOOD & DINING TOTAL | C35: =SUM(C29:C34) | D35: =SUM(D29:D34) | E35: =C35-D35 | F35: =IFERROR(D35/C35,0)
A36: HEALTH & WELLNESS
A37: HEALTH & WELLNESS | B37: Health Insurance | C37: 0 | D37: 0 | E37: =C37-D37 | F37: =IFERROR(D37/C37,0)
A38: HEALTH & WELLNESS | B38: Gym Membership | C38: 0 | D38: 0 | E38: =C38-D38 | F38: =IFERROR(D38/C38,0)
A39: HEALTH & WELLNESS | B39: Pharmacy | C39: 0 | D39: 0 | E39: =C39-D39 | F39: =IFERROR(D39/C39,0)
A40: HEALTH & WELLNESS | B40: Doctor Visits | C40: 0 | D40: 0 | E40: =C40-D40 | F40: =IFERROR(D40/C40,0)
...

Sheet Aug
A1: AUGUST · MONTHLY BUDGET
A2: Track your income, expenses, and savings for the month
A3: CATEGORY | B3: SUBCATEGORY | C3: BUDGETED | D3: ACTUAL | E3: DIFFERENCE | F3: % USED | G3: NOTES
A4: INCOME
A5: INCOME | B5: Primary Salary | C5: 0 | D5: 0 | E5: =C5-D5 | F5: =IFERROR(D5/C5,0)
A6: INCOME | B6: Freelance | C6: 0 | D6: 0 | E6: =C6-D6 | F6: =IFERROR(D6/C6,0)
A7: INCOME | B7: Rental Income | C7: 0 | D7: 0 | E7: =C7-D7 | F7: =IFERROR(D7/C7,0)
A8: INCOME | B8: Dividends | C8: 0 | D8: 0 | E8: =C8-D8 | F8: =IFERROR(D8/C8,0)
A9: INCOME | B9: Side Business | C9: 0 | D9: 0 | E9: =C9-D9 | F9: =IFERROR(D9/C9,0)
A10: INCOME | B10: Other Income | C10: 0 | D10: 0 | E10: =C10-D10 | F10: =IFERROR(D10/C10,0)
A11: TOTAL INCOME | C11: =SUM(C5:C10) | D11: =SUM(D5:D10) | E11: =C11-D11 | F11: =IFERROR(D11/C11,0)
A12: HOUSING
A13: HOUSING | B13: Rent/Mortgage | C13: 0 | D13: 0 | E13: =C13-D13 | F13: =IFERROR(D13/C13,0)
A14: HOUSING | B14: Electricity | C14: 0 | D14: 0 | E14: =C14-D14 | F14: =IFERROR(D14/C14,0)
A15: HOUSING | B15: Water | C15: 0 | D15: 0 | E15: =C15-D15 | F15: =IFERROR(D15/C15,0)
A16: HOUSING | B16: Internet | C16: 0 | D16: 0 | E16: =C16-D16 | F16: =IFERROR(D16/C16,0)
A17: HOUSING | B17: Home Insurance | C17: 0 | D17: 0 | E17: =C17-D17 | F17: =IFERROR(D17/C17,0)
A18: HOUSING | B18: Maintenance | C18: 0 | D18: 0 | E18: =C18-D18 | F18: =IFERROR(D18/C18,0)
A19: HOUSING TOTAL | C19: =SUM(C13:C18) | D19: =SUM(D13:D18) | E19: =C19-D19 | F19: =IFERROR(D19/C19,0)
A20: TRANSPORT
A21: TRANSPORT | B21: Car Payment | C21: 0 | D21: 0 | E21: =C21-D21 | F21: =IFERROR(D21/C21,0)
A22: TRANSPORT | B22: Fuel | C22: 0 | D22: 0 | E22: =C22-D22 | F22: =IFERROR(D22/C22,0)
A23: TRANSPORT | B23: Car Insurance | C23: 0 | D23: 0 | E23: =C23-D23 | F23: =IFERROR(D23/C23,0)
A24: TRANSPORT | B24: Parking | C24: 0 | D24: 0 | E24: =C24-D24 | F24: =IFERROR(D24/C24,0)
A25: TRANSPORT | B25: Public Transport | C25: 0 | D25: 0 | E25: =C25-D25 | F25: =IFERROR(D25/C25,0)
A26: TRANSPORT | B26: Ride Share | C26: 0 | D26: 0 | E26: =C26-D26 | F26: =IFERROR(D26/C26,0)
A27: TRANSPORT TOTAL | C27: =SUM(C21:C26) | D27: =SUM(D21:D26) | E27: =C27-D27 | F27: =IFERROR(D27/C27,0)
A28: FOOD & DINING
A29: FOOD & DINING | B29: Groceries | C29: 0 | D29: 0 | E29: =C29-D29 | F29: =IFERROR(D29/C29,0)
A30: FOOD & DINING | B30: Restaurants | C30: 0 | D30: 0 | E30: =C30-D30 | F30: =IFERROR(D30/C30,0)
A31: FOOD & DINING | B31: Coffee Shops | C31: 0 | D31: 0 | E31: =C31-D31 | F31: =IFERROR(D31/C31,0)
A32: FOOD & DINING | B32: Food Delivery | C32: 0 | D32: 0 | E32: =C32-D32 | F32: =IFERROR(D32/C32,0)
A33: FOOD & DINING | B33: Work Lunch | C33: 0 | D33: 0 | E33: =C33-D33 | F33: =IFERROR(D33/C33,0)
A34: FOOD & DINING | B34: Other | C34: 0 | D34: 0 | E34: =C34-D34 | F34: =IFERROR(D34/C34,0)
A35: FOOD & DINING TOTAL | C35: =SUM(C29:C34) | D35: =SUM(D29:D34) | E35: =C35-D35 | F35: =IFERROR(D35/C35,0)
A36: HEALTH & WELLNESS
A37: HEALTH & WELLNESS | B37: Health Insurance | C37: 0 | D37: 0 | E37: =C37-D37 | F37: =IFERROR(D37/C37,0)
A38: HEALTH & WELLNESS | B38: Gym Membership | C38: 0 | D38: 0 | E38: =C38-D38 | F38: =IFERROR(D38/C38,0)
A39: HEALTH & WELLNESS | B39: Pharmacy | C39: 0 | D39: 0 | E39: =C39-D39 | F39: =IFERROR(D39/C39,0)
A40: HEALTH & WELLNESS | B40: Doctor Visits | C40: 0 | D40: 0 | E40: =C40-D40 | F40: =IFERROR(D40/C40,0)
...

Sheet Sep
A1: SEPTEMBER · MONTHLY BUDGET
A2: Track your income, expenses, and savings for the month
A3: CATEGORY | B3: SUBCATEGORY | C3: BUDGETED | D3: ACTUAL | E3: DIFFERENCE | F3: % USED | G3: NOTES
A4: INCOME
A5: INCOME | B5: Primary Salary | C5: 0 | D5: 0 | E5: =C5-D5 | F5: =IFERROR(D5/C5,0)
A6: INCOME | B6: Freelance | C6: 0 | D6: 0 | E6: =C6-D6 | F6: =IFERROR(D6/C6,0)
A7: INCOME | B7: Rental Income | C7: 0 | D7: 0 | E7: =C7-D7 | F7: =IFERROR(D7/C7,0)
A8: INCOME | B8: Dividends | C8: 0 | D8: 0 | E8: =C8-D8 | F8: =IFERROR(D8/C8,0)
A9: INCOME | B9: Side Business | C9: 0 | D9: 0 | E9: =C9-D9 | F9: =IFERROR(D9/C9,0)
A10: INCOME | B10: Other Income | C10: 0 | D10: 0 | E10: =C10-D10 | F10: =IFERROR(D10/C10,0)
A11: TOTAL INCOME | C11: =SUM(C5:C10) | D11: =SUM(D5:D10) | E11: =C11-D11 | F11: =IFERROR(D11/C11,0)
A12: HOUSING
A13: HOUSING | B13: Rent/Mortgage | C13: 0 | D13: 0 | E13: =C13-D13 | F13: =IFERROR(D13/C13,0)
A14: HOUSING | B14: Electricity | C14: 0 | D14: 0 | E14: =C14-D14 | F14: =IFERROR(D14/C14,0)
A15: HOUSING | B15: Water | C15: 0 | D15: 0 | E15: =C15-D15 | F15: =IFERROR(D15/C15,0)
A16: HOUSING | B16: Internet | C16: 0 | D16: 0 | E16: =C16-D16 | F16: =IFERROR(D16/C16,0)
A17: HOUSING | B17: Home Insurance | C17: 0 | D17: 0 | E17: =C17-D17 | F17: =IFERROR(D17/C17,0)
A18: HOUSING | B18: Maintenance | C18: 0 | D18: 0 | E18: =C18-D18 | F18: =IFERROR(D18/C18,0)
A19: HOUSING TOTAL | C19: =SUM(C13:C18) | D19: =SUM(D13:D18) | E19: =C19-D19 | F19: =IFERROR(D19/C19,0)
A20: TRANSPORT
A21: TRANSPORT | B21: Car Payment | C21: 0 | D21: 0 | E21: =C21-D21 | F21: =IFERROR(D21/C21,0)
A22: TRANSPORT | B22: Fuel | C22: 0 | D22: 0 | E22: =C22-D22 | F22: =IFERROR(D22/C22,0)
A23: TRANSPORT | B23: Car Insurance | C23: 0 | D23: 0 | E23: =C23-D23 | F23: =IFERROR(D23/C23,0)
A24: TRANSPORT | B24: Parking | C24: 0 | D24: 0 | E24: =C24-D24 | F24: =IFERROR(D24/C24,0)
A25: TRANSPORT | B25: Public Transport | C25: 0 | D25: 0 | E25: =C25-D25 | F25: =IFERROR(D25/C25,0)
A26: TRANSPORT | B26: Ride Share | C26: 0 | D26: 0 | E26: =C26-D26 | F26: =IFERROR(D26/C26,0)
A27: TRANSPORT TOTAL | C27: =SUM(C21:C26) | D27: =SUM(D21:D26) | E27: =C27-D27 | F27: =IFERROR(D27/C27,0)
A28: FOOD & DINING
A29: FOOD & DINING | B29: Groceries | C29: 0 | D29: 0 | E29: =C29-D29 | F29: =IFERROR(D29/C29,0)
A30: FOOD & DINING | B30: Restaurants | C30: 0 | D30: 0 | E30: =C30-D30 | F30: =IFERROR(D30/C30,0)
A31: FOOD & DINING | B31: Coffee Shops | C31: 0 | D31: 0 | E31: =C31-D31 | F31: =IFERROR(D31/C31,0)
A32: FOOD & DINING | B32: Food Delivery | C32: 0 | D32: 0 | E32: =C32-D32 | F32: =IFERROR(D32/C32,0)
A33: FOOD & DINING | B33: Work Lunch | C33: 0 | D33: 0 | E33: =C33-D33 | F33: =IFERROR(D33/C33,0)
A34: FOOD & DINING | B34: Other | C34: 0 | D34: 0 | E34: =C34-D34 | F34: =IFERROR(D34/C34,0)
A35: FOOD & DINING TOTAL | C35: =SUM(C29:C34) | D35: =SUM(D29:D34) | E35: =C35-D35 | F35: =IFERROR(D35/C35,0)
A36: HEALTH & WELLNESS
A37: HEALTH & WELLNESS | B37: Health Insurance | C37: 0 | D37: 0 | E37: =C37-D37 | F37: =IFERROR(D37/C37,0)
A38: HEALTH & WELLNESS | B38: Gym Membership | C38: 0 | D38: 0 | E38: =C38-D38 | F38: =IFERROR(D38/C38,0)
A39: HEALTH & WELLNESS | B39: Pharmacy | C39: 0 | D39: 0 | E39: =C39-D39 | F39: =IFERROR(D39/C39,0)
A40: HEALTH & WELLNESS | B40: Doctor Visits | C40: 0 | D40: 0 | E40: =C40-D40 | F40: =IFERROR(D40/C40,0)
...

Sheet Oct
A1: OCTOBER · MONTHLY BUDGET
A2: Track your income, expenses, and savings for the month
A3: CATEGORY | B3: SUBCATEGORY | C3: BUDGETED | D3: ACTUAL | E3: DIFFERENCE | F3: % USED | G3: NOTES
A4: INCOME
A5: INCOME | B5: Primary Salary | C5: 0 | D5: 0 | E5: =C5-D5 | F5: =IFERROR(D5/C5,0)
A6: INCOME | B6: Freelance | C6: 0 | D6: 0 | E6: =C6-D6 | F6: =IFERROR(D6/C6,0)
A7: INCOME | B7: Rental Income | C7: 0 | D7: 0 | E7: =C7-D7 | F7: =IFERROR(D7/C7,0)
A8: INCOME | B8: Dividends | C8: 0 | D8: 0 | E8: =C8-D8 | F8: =IFERROR(D8/C8,0)
A9: INCOME | B9: Side Business | C9: 0 | D9: 0 | E9: =C9-D9 | F9: =IFERROR(D9/C9,0)
A10: INCOME | B10: Other Income | C10: 0 | D10: 0 | E10: =C10-D10 | F10: =IFERROR(D10/C10,0)
A11: TOTAL INCOME | C11: =SUM(C5:C10) | D11: =SUM(D5:D10) | E11: =C11-D11 | F11: =IFERROR(D11/C11,0)
A12: HOUSING
A13: HOUSING | B13: Rent/Mortgage | C13: 0 | D13: 0 | E13: =C13-D13 | F13: =IFERROR(D13/C13,0)
A14: HOUSING | B14: Electricity | C14: 0 | D14: 0 | E14: =C14-D14 | F14: =IFERROR(D14/C14,0)
A15: HOUSING | B15: Water | C15: 0 | D15: 0 | E15: =C15-D15 | F15: =IFERROR(D15/C15,0)
A16: HOUSING | B16: Internet | C16: 0 | D16: 0 | E16: =C16-D16 | F16: =IFERROR(D16/C16,0)
A17: HOUSING | B17: Home Insurance | C17: 0 | D17: 0 | E17: =C17-D17 | F17: =IFERROR(D17/C17,0)
A18: HOUSING | B18: Maintenance | C18: 0 | D18: 0 | E18: =C18-D18 | F18: =IFERROR(D18/C18,0)
A19: HOUSING TOTAL | C19: =SUM(C13:C18) | D19: =SUM(D13:D18) | E19: =C19-D19 | F19: =IFERROR(D19/C19,0)
A20: TRANSPORT
A21: TRANSPORT | B21: Car Payment | C21: 0 | D21: 0 | E21: =C21-D21 | F21: =IFERROR(D21/C21,0)
A22: TRANSPORT | B22: Fuel | C22: 0 | D22: 0 | E22: =C22-D22 | F22: =IFERROR(D22/C22,0)
A23: TRANSPORT | B23: Car Insurance | C23: 0 | D23: 0 | E23: =C23-D23 | F23: =IFERROR(D23/C23,0)
A24: TRANSPORT | B24: Parking | C24: 0 | D24: 0 | E24: =C24-D24 | F24: =IFERROR(D24/C24,0)
A25: TRANSPORT | B25: Public Transport | C25: 0 | D25: 0 | E25: =C25-D25 | F25: =IFERROR(D25/C25,0)
A26: TRANSPORT | B26: Ride Share | C26: 0 | D26: 0 | E26: =C26-D26 | F26: =IFERROR(D26/C26,0)
A27: TRANSPORT TOTAL | C27: =SUM(C21:C26) | D27: =SUM(D21:D26) | E27: =C27-D27 | F27: =IFERROR(D27/C27,0)
A28: FOOD & DINING
A29: FOOD & DINING | B29: Groceries | C29: 0 | D29: 0 | E29: =C29-D29 | F29: =IFERROR(D29/C29,0)
A30: FOOD & DINING | B30: Restaurants | C30: 0 | D30: 0 | E30: =C30-D30 | F30: =IFERROR(D30/C30,0)
A31: FOOD & DINING | B31: Coffee Shops | C31: 0 | D31: 0 | E31: =C31-D31 | F31: =IFERROR(D31/C31,0)
A32: FOOD & DINING | B32: Food Delivery | C32: 0 | D32: 0 | E32: =C32-D32 | F32: =IFERROR(D32/C32,0)
A33: FOOD & DINING | B33: Work Lunch | C33: 0 | D33: 0 | E33: =C33-D33 | F33: =IFERROR(D33/C33,0)
A34: FOOD & DINING | B34: Other | C34: 0 | D34: 0 | E34: =C34-D34 | F34: =IFERROR(D34/C34,0)
A35: FOOD & DINING TOTAL | C35: =SUM(C29:C34) | D35: =SUM(D29:D34) | E35: =C35-D35 | F35: =IFERROR(D35/C35,0)
A36: HEALTH & WELLNESS
A37: HEALTH & WELLNESS | B37: Health Insurance | C37: 0 | D37: 0 | E37: =C37-D37 | F37: =IFERROR(D37/C37,0)
A38: HEALTH & WELLNESS | B38: Gym Membership | C38: 0 | D38: 0 | E38: =C38-D38 | F38: =IFERROR(D38/C38,0)
A39: HEALTH & WELLNESS | B39: Pharmacy | C39: 0 | D39: 0 | E39: =C39-D39 | F39: =IFERROR(D39/C39,0)
A40: HEALTH & WELLNESS | B40: Doctor Visits | C40: 0 | D40: 0 | E40: =C40-D40 | F40: =IFERROR(D40/C40,0)
...

Sheet Nov
A1: NOVEMBER · MONTHLY BUDGET
A2: Track your income, expenses, and savings for the month
A3: CATEGORY | B3: SUBCATEGORY | C3: BUDGETED | D3: ACTUAL | E3: DIFFERENCE | F3: % USED | G3: NOTES
A4: INCOME
A5: INCOME | B5: Primary Salary | C5: 0 | D5: 0 | E5: =C5-D5 | F5: =IFERROR(D5/C5,0)
A6: INCOME | B6: Freelance | C6: 0 | D6: 0 | E6: =C6-D6 | F6: =IFERROR(D6/C6,0)
A7: INCOME | B7: Rental Income | C7: 0 | D7: 0 | E7: =C7-D7 | F7: =IFERROR(D7/C7,0)
A8: INCOME | B8: Dividends | C8: 0 | D8: 0 | E8: =C8-D8 | F8: =IFERROR(D8/C8,0)
A9: INCOME | B9: Side Business | C9: 0 | D9: 0 | E9: =C9-D9 | F9: =IFERROR(D9/C9,0)
A10: INCOME | B10: Other Income | C10: 0 | D10: 0 | E10: =C10-D10 | F10: =IFERROR(D10/C10,0)
A11: TOTAL INCOME | C11: =SUM(C5:C10) | D11: =SUM(D5:D10) | E11: =C11-D11 | F11: =IFERROR(D11/C11,0)
A12: HOUSING
A13: HOUSING | B13: Rent/Mortgage | C13: 0 | D13: 0 | E13: =C13-D13 | F13: =IFERROR(D13/C13,0)
A14: HOUSING | B14: Electricity | C14: 0 | D14: 0 | E14: =C14-D14 | F14: =IFERROR(D14/C14,0)
A15: HOUSING | B15: Water | C15: 0 | D15: 0 | E15: =C15-D15 | F15: =IFERROR(D15/C15,0)
A16: HOUSING | B16: Internet | C16: 0 | D16: 0 | E16: =C16-D16 | F16: =IFERROR(D16/C16,0)
A17: HOUSING | B17: Home Insurance | C17: 0 | D17: 0 | E17: =C17-D17 | F17: =IFERROR(D17/C17,0)
A18: HOUSING | B18: Maintenance | C18: 0 | D18: 0 | E18: =C18-D18 | F18: =IFERROR(D18/C18,0)
A19: HOUSING TOTAL | C19: =SUM(C13:C18) | D19: =SUM(D13:D18) | E19: =C19-D19 | F19: =IFERROR(D19/C19,0)
A20: TRANSPORT
A21: TRANSPORT | B21: Car Payment | C21: 0 | D21: 0 | E21: =C21-D21 | F21: =IFERROR(D21/C21,0)
A22: TRANSPORT | B22: Fuel | C22: 0 | D22: 0 | E22: =C22-D22 | F22: =IFERROR(D22/C22,0)
A23: TRANSPORT | B23: Car Insurance | C23: 0 | D23: 0 | E23: =C23-D23 | F23: =IFERROR(D23/C23,0)
A24: TRANSPORT | B24: Parking | C24: 0 | D24: 0 | E24: =C24-D24 | F24: =IFERROR(D24/C24,0)
A25: TRANSPORT | B25: Public Transport | C25: 0 | D25: 0 | E25: =C25-D25 | F25: =IFERROR(D25/C25,0)
A26: TRANSPORT | B26: Ride Share | C26: 0 | D26: 0 | E26: =C26-D26 | F26: =IFERROR(D26/C26,0)
A27: TRANSPORT TOTAL | C27: =SUM(C21:C26) | D27: =SUM(D21:D26) | E27: =C27-D27 | F27: =IFERROR(D27/C27,0)
A28: FOOD & DINING
A29: FOOD & DINING | B29: Groceries | C29: 0 | D29: 0 | E29: =C29-D29 | F29: =IFERROR(D29/C29,0)
A30: FOOD & DINING | B30: Restaurants | C30: 0 | D30: 0 | E30: =C30-D30 | F30: =IFERROR(D30/C30,0)
A31: FOOD & DINING | B31: Coffee Shops | C31: 0 | D31: 0 | E31: =C31-D31 | F31: =IFERROR(D31/C31,0)
A32: FOOD & DINING | B32: Food Delivery | C32: 0 | D32: 0 | E32: =C32-D32 | F32: =IFERROR(D32/C32,0)
A33: FOOD & DINING | B33: Work Lunch | C33: 0 | D33: 0 | E33: =C33-D33 | F33: =IFERROR(D33/C33,0)
A34: FOOD & DINING | B34: Other | C34: 0 | D34: 0 | E34: =C34-D34 | F34: =IFERROR(D34/C34,0)
A35: FOOD & DINING TOTAL | C35: =SUM(C29:C34) | D35: =SUM(D29:D34) | E35: =C35-D35 | F35: =IFERROR(D35/C35,0)
A36: HEALTH & WELLNESS
A37: HEALTH & WELLNESS | B37: Health Insurance | C37: 0 | D37: 0 | E37: =C37-D37 | F37: =IFERROR(D37/C37,0)
A38: HEALTH & WELLNESS | B38: Gym Membership | C38: 0 | D38: 0 | E38: =C38-D38 | F38: =IFERROR(D38/C38,0)
A39: HEALTH & WELLNESS | B39: Pharmacy | C39: 0 | D39: 0 | E39: =C39-D39 | F39: =IFERROR(D39/C39,0)
A40: HEALTH & WELLNESS | B40: Doctor Visits | C40: 0 | D40: 0 | E40: =C40-D40 | F40: =IFERROR(D40/C40,0)
...

Sheet Dec
A1: DECEMBER · MONTHLY BUDGET
A2: Track your income, expenses, and savings for the month
A3: CATEGORY | B3: SUBCATEGORY | C3: BUDGETED | D3: ACTUAL | E3: DIFFERENCE | F3: % USED | G3: NOTES
A4: INCOME
A5: INCOME | B5: Primary Salary | C5: 0 | D5: 0 | E5: =C5-D5 | F5: =IFERROR(D5/C5,0)
A6: INCOME | B6: Freelance | C6: 0 | D6: 0 | E6: =C6-D6 | F6: =IFERROR(D6/C6,0)
A7: INCOME | B7: Rental Income | C7: 0 | D7: 0 | E7: =C7-D7 | F7: =IFERROR(D7/C7,0)
A8: INCOME | B8: Dividends | C8: 0 | D8: 0 | E8: =C8-D8 | F8: =IFERROR(D8/C8,0)
A9: INCOME | B9: Side Business | C9: 0 | D9: 0 | E9: =C9-D9 | F9: =IFERROR(D9/C9,0)
A10: INCOME | B10: Other Income | C10: 0 | D10: 0 | E10: =C10-D10 | F10: =IFERROR(D10/C10,0)
A11: TOTAL INCOME | C11: =SUM(C5:C10) | D11: =SUM(D5:D10) | E11: =C11-D11 | F11: =IFERROR(D11/C11,0)
A12: HOUSING
A13: HOUSING | B13: Rent/Mortgage | C13: 0 | D13: 0 | E13: =C13-D13 | F13: =IFERROR(D13/C13,0)
A14: HOUSING | B14: Electricity | C14: 0 | D14: 0 | E14: =C14-D14 | F14: =IFERROR(D14/C14,0)
A15: HOUSING | B15: Water | C15: 0 | D15: 0 | E15: =C15-D15 | F15: =IFERROR(D15/C15,0)
A16: HOUSING | B16: Internet | C16: 0 | D16: 0 | E16: =C16-D16 | F16: =IFERROR(D16/C16,0)
A17: HOUSING | B17: Home Insurance | C17: 0 | D17: 0 | E17: =C17-D17 | F17: =IFERROR(D17/C17,0)
A18: HOUSING | B18: Maintenance | C18: 0 | D18: 0 | E18: =C18-D18 | F18: =IFERROR(D18/C18,0)
A19: HOUSING TOTAL | C19: =SUM(C13:C18) | D19: =SUM(D13:D18) | E19: =C19-D19 | F19: =IFERROR(D19/C19,0)
A20: TRANSPORT
A21: TRANSPORT | B21: Car Payment | C21: 0 | D21: 0 | E21: =C21-D21 | F21: =IFERROR(D21/C21,0)
A22: TRANSPORT | B22: Fuel | C22: 0 | D22: 0 | E22: =C22-D22 | F22: =IFERROR(D22/C22,0)
A23: TRANSPORT | B23: Car Insurance | C23: 0 | D23: 0 | E23: =C23-D23 | F23: =IFERROR(D23/C23,0)
A24: TRANSPORT | B24: Parking | C24: 0 | D24: 0 | E24: =C24-D24 | F24: =IFERROR(D24/C24,0)
A25: TRANSPORT | B25: Public Transport | C25: 0 | D25: 0 | E25: =C25-D25 | F25: =IFERROR(D25/C25,0)
A26: TRANSPORT | B26: Ride Share | C26: 0 | D26: 0 | E26: =C26-D26 | F26: =IFERROR(D26/C26,0)
A27: TRANSPORT TOTAL | C27: =SUM(C21:C26) | D27: =SUM(D21:D26) | E27: =C27-D27 | F27: =IFERROR(D27/C27,0)
A28: FOOD & DINING
A29: FOOD & DINING | B29: Groceries | C29: 0 | D29: 0 | E29: =C29-D29 | F29: =IFERROR(D29/C29,0)
A30: FOOD & DINING | B30: Restaurants | C30: 0 | D30: 0 | E30: =C30-D30 | F30: =IFERROR(D30/C30,0)
A31: FOOD & DINING | B31: Coffee Shops | C31: 0 | D31: 0 | E31: =C31-D31 | F31: =IFERROR(D31/C31,0)
A32: FOOD & DINING | B32: Food Delivery | C32: 0 | D32: 0 | E32: =C32-D32 | F32: =IFERROR(D32/C32,0)
A33: FOOD & DINING | B33: Work Lunch | C33: 0 | D33: 0 | E33: =C33-D33 | F33: =IFERROR(D33/C33,0)
A34: FOOD & DINING | B34: Other | C34: 0 | D34: 0 | E34: =C34-D34 | F34: =IFERROR(D34/C34,0)
A35: FOOD & DINING TOTAL | C35: =SUM(C29:C34) | D35: =SUM(D29:D34) | E35: =C35-D35 | F35: =IFERROR(D35/C35,0)
A36: HEALTH & WELLNESS
A37: HEALTH & WELLNESS | B37: Health Insurance | C37: 0 | D37: 0 | E37: =C37-D37 | F37: =IFERROR(D37/C37,0)
A38: HEALTH & WELLNESS | B38: Gym Membership | C38: 0 | D38: 0 | E38: =C38-D38 | F38: =IFERROR(D38/C38,0)
A39: HEALTH & WELLNESS | B39: Pharmacy | C39: 0 | D39: 0 | E39: =C39-D39 | F39: =IFERROR(D39/C39,0)
A40: HEALTH & WELLNESS | B40: Doctor Visits | C40: 0 | D40: 0 | E40: =C40-D40 | F40: =IFERROR(D40/C40,0)
...

Sheet Annual Budget
A1: ANNUAL BUDGET · 2026
A2: Full year comparison across all months
A3: LINE ITEM | B3: Jan | C3: Feb | D3: Mar | E3: Apr | F3: May | G3: Jun | H3: Jul | I3: Aug | J3: Sep | K3: Oct | L3: Nov | M3: Dec | N3: ANNUAL TOTAL | O3: ANNUAL BUDGET | P3: VARIANCE
A4: INCOME | B4: =Jan!D11 | C4: =Feb!D11 | D4: =Mar!D11 | E4: =Apr!D11 | F4: =May!D11 | G4: =Jun!D11 | H4: =Jul!D11 | I4: =Aug!D11 | J4: =Sep!D11 | K4: =Oct!D11 | L4: =Nov!D11 | M4: =Dec!D11 | N4: =SUM(B4:M4) | O4: 0 | P4: =N4-O4
A5: HOUSING | B5: =Jan!D19 | C5: =Feb!D19 | D5: =Mar!D19 | E5: =Apr!D19 | F5: =May!D19 | G5: =Jun!D19 | H5: =Jul!D19 | I5: =Aug!D19 | J5: =Sep!D19 | K5: =Oct!D19 | L5: =Nov!D19 | M5: =Dec!D19 | N5: =SUM(B5:M5) | O5: 0 | P5: =N5-O5
A6: TRANSPORT | B6: =Jan!D27 | C6: =Feb!D27 | D6: =Mar!D27 | E6: =Apr!D27 | F6: =May!D27 | G6: =Jun!D27 | H6: =Jul!D27 | I6: =Aug!D27 | J6: =Sep!D27 | K6: =Oct!D27 | L6: =Nov!D27 | M6: =Dec!D27 | N6: =SUM(B6:M6) | O6: 0 | P6: =N6-O6
A7: FOOD & DINING | B7: =Jan!D35 | C7: =Feb!D35 | D7: =Mar!D35 | E7: =Apr!D35 | F7: =May!D35 | G7: =Jun!D35 | H7: =Jul!D35 | I7: =Aug!D35 | J7: =Sep!D35 | K7: =Oct!D35 | L7: =Nov!D35 | M7: =Dec!D35 | N7: =SUM(B7:M7) | O7: 0 | P7: =N7-O7
A8: HEALTH & WELLNESS | B8: =Jan!D43 | C8: =Feb!D43 | D8: =Mar!D43 | E8: =Apr!D43 | F8: =May!D43 | G8: =Jun!D43 | H8: =Jul!D43 | I8: =Aug!D43 | J8: =Sep!D43 | K8: =Oct!D43 | L8: =Nov!D43 | M8: =Dec!D43 | N8: =SUM(B8:M8) | O8: 0 | P8: =N8-O8
A9: LIFESTYLE | B9: =Jan!D51 | C9: =Feb!D51 | D9: =Mar!D51 | E9: =Apr!D51 | F9: =May!D51 | G9: =Jun!D51 | H9: =Jul!D51 | I9: =Aug!D51 | J9: =Sep!D51 | K9: =Oct!D51 | L9: =Nov!D51 | M9: =Dec!D51 | N9: =SUM(B9:M9) | O9: 0 | P9: =N9-O9
A10: CHILDREN & FAMILY | B10: =Jan!D59 | C10: =Feb!D59 | D10: =Mar!D59 | E10: =Apr!D59 | F10: =May!D59 | G10: =Jun!D59 | H10: =Jul!D59 | I10: =Aug!D59 | J10: =Sep!D59 | K10: =Oct!D59 | L10: =Nov!D59 | M10: =Dec!D59 | N10: =SUM(B10:M10) | O10: 0 | P10: =N10-O10
A11: SAVINGS & INVESTMENTS | B11: =Jan!D67 | C11: =Feb!D67 | D11: =Mar!D67 | E11: =Apr!D67 | F11: =May!D67 | G11: =Jun!D67 | H11: =Jul!D67 | I11: =Aug!D67 | J11: =Sep!D67 | K11: =Oct!D67 | L11: =Nov!D67 | M11: =Dec!D67 | N11: =SUM(B11:M11) | O11: 0 | P11: =N11-O11
A12: DEBT PAYMENTS | B12: =Jan!D75 | C12: =Feb!D75 | D12: =Mar!D75 | E12: =Apr!D75 | F12: =May!D75 | G12: =Jun!D75 | H12: =Jul!D75 | I12: =Aug!D75 | J12: =Sep!D75 | K12: =Oct!D75 | L12: =Nov!D75 | M12: =Dec!D75 | N12: =SUM(B12:M12) | O12: 0 | P12: =N12-O12
A13: GRAND TOTAL EXPENSES | B13: =Jan!D76 | C13: =Feb!D76 | D13: =Mar!D76 | E13: =Apr!D76 | F13: =May!D76 | G13: =Jun!D76 | H13: =Jul!D76 | I13: =Aug!D76 | J13: =Sep!D76 | K13: =Oct!D76 | L13: =Nov!D76 | M13: =Dec!D76 | N13: =SUM(B13:M13) | O13: 0 | P13: =N13-O13
A14: NET CASH FLOW | B14: =Jan!D77 | C14: =Feb!D77 | D14: =Mar!D77 | E14: =Apr!D77 | F14: =May!D77 | G14: =Jun!D77 | H14: =Jul!D77 | I14: =Aug!D77 | J14: =Sep!D77 | K14: =Oct!D77 | L14: =Nov!D77 | M14: =Dec!D77 | N14: =SUM(B14:M14) | O14: 0 | P14: =N14-O14

Sheet Savings Tracker
A1: SAVINGS TRACKER · 2026
A2: Monitor your progress towards financial goals
A3: SAVINGS GOAL | B3: TARGET | C3: SAVED SO FAR | D3: MONTHLY CONTRIB | E3: TARGET DATE | F3: % COMPLETE | G3: PROGRESS | H3: PRIORITY
A4: Emergency Fund | B4: 50000 | C4: 0 | D4: 0 | E4: 2026-12-31 | F4: =IFERROR(C4/B4,0) | G4: =REPT(CHAR(9608),ROUND(F4*10,0))&REPT(CHAR(9617),10-ROUND(F4*10,0)) | H4: High
A5: Vacation — Japan | B5: 25000 | C5: 0 | D5: 0 | E5: 2026-12-31 | F5: =IFERROR(C5/B5,0) | G5: =REPT(CHAR(9608),ROUND(F5*10,0))&REPT(CHAR(9617),10-ROUND(F5*10,0)) | H5: High
A6: Home Down Payment | B6: 250000 | C6: 0 | D6: 0 | E6: 2026-12-31 | F6: =IFERROR(C6/B6,0) | G6: =REPT(CHAR(9608),ROUND(F6*10,0))&REPT(CHAR(9617),10-ROUND(F6*10,0)) | H6: High
A7: New Car | B7: 80000 | C7: 0 | D7: 0 | E7: 2026-12-31 | F7: =IFERROR(C7/B7,0) | G7: =REPT(CHAR(9608),ROUND(F7*10,0))&REPT(CHAR(9617),10-ROUND(F7*10,0)) | H7: Medium
A8: Retirement Boost | B8: 100000 | C8: 0 | D8: 0 | E8: 2026-12-31 | F8: =IFERROR(C8/B8,0) | G8: =REPT(CHAR(9608),ROUND(F8*10,0))&REPT(CHAR(9617),10-ROUND(F8*10,0)) | H8: High
A9: Education Fund | B9: 40000 | C9: 0 | D9: 0 | E9: 2026-12-31 | F9: =IFERROR(C9/B9,0) | G9: =REPT(CHAR(9608),ROUND(F9*10,0))&REPT(CHAR(9617),10-ROUND(F9*10,0)) | H9: Medium
A10: Wedding Fund | B10: 60000 | C10: 0 | D10: 0 | E10: 2026-12-31 | F10: =IFERROR(C10/B10,0) | G10: =REPT(CHAR(9608),ROUND(F10*10,0))&REPT(CHAR(9617),10-ROUND(F10*10,0)) | H10: Low
A11: Home Renovation | B11: 35000 | C11: 0 | D11: 0 | E11: 2026-12-31 | F11: =IFERROR(C11/B11,0) | G11: =REPT(CHAR(9608),ROUND(F11*10,0))&REPT(CHAR(9617),10-ROUND(F11*10,0)) | H11: Medium
A12: TOTALS | B12: =SUM(B4:B11) | C12: =SUM(C4:C11) | D12: =SUM(D4:D11)
