Workbook

Sheet Dashboard
A1: PERSONAL FINANCE COMMAND CENTER · 2026
A2: Live Summary · All figures update automatically from monthly sheets
A3: ANNUAL INCOME | E3: LEFT TO SPEND | K3: HOUSING | L3: =IFERROR(Jan!D15,0)
A4: =B10 | E4: =IFERROR(B11-B12,0) | K4: TRANSPORT | L4: =IFERROR(Jan!D22,0)
A5: ANNUAL SAVINGS | E5: SAVINGS RATE | K5: FOOD & DINING | L5: =IFERROR(Jan!D29,0)
A6: =IFERROR(Jan!D57+Feb!D57+Mar!D57+Apr!D57+May!D57+Jun!D57+Jul!D57+Aug!D57+Sep!D57+Oct!D57+Nov!D57+Dec!D57,0) | E6: =IFERROR((B10-B12*12)/B10,0) | K6: HEALTH & WELLNESS | L6: =IFERROR(Jan!D36,0)
K7: LIFESTYLE | L7: =IFERROR(Jan!D43,0)
A8: BUDGET SUMMARY | E8: SAVINGS SNAPSHOT | K8: PERSONAL | L8: =IFERROR(Jan!D50,0)
K9: SAVINGS & INVESTMENTS | L9: =IFERROR(Jan!D57,0)
A10: Annual Income | C10: 0 | E10: Emergency Fund Goal | G10: 0 | K10: DEBT PAYMENTS | L10: =IFERROR(Jan!D64,0)
A11: Monthly Income | C11: =IFERROR(B10/12,0) | E11: Emergency Fund Current | G11: 0
A12: This Month Expenses | C12: =IFERROR(Jan!D65,0) | E12: % Funded | G12: =IFERROR(F11/F10,0) | K12: Month | L12: Income | M12: Expenses
A13: Left to Spend | C13: =IFERROR(B11-B12,0) | E13: Monthly Target | G13: 0 | K13: Jan | L13: =IFERROR(Jan!D8,0) | M13: =IFERROR(Jan!D65,0)
A14: Annual Savings Rate | C14: =IFERROR((B10-B12*12)/B10,0) | E14: YTD Saved | G14: =IFERROR(Jan!D57+Feb!D57+Mar!D57+Apr!D57+May!D57+Jun!D57+Jul!D57+Aug!D57+Sep!D57+Oct!D57+Nov!D57+Dec!D57,0) | K14: Feb | L14: =IFERROR(Feb!D8,0) | M14: =IFERROR(Feb!D65,0)
A15: YTD Savings | C15: =IFERROR(Jan!D57+Feb!D57+Mar!D57+Apr!D57+May!D57+Jun!D57+Jul!D57+Aug!D57+Sep!D57+Oct!D57+Nov!D57+Dec!D57,0) | E15: Months to Goal | G15: =IFERROR((F10-F11)/F13,0) | K15: Mar | L15: =IFERROR(Mar!D8,0) | M15: =IFERROR(Mar!D65,0)
K16: Apr | L16: =IFERROR(Apr!D8,0) | M16: =IFERROR(Apr!D65,0)
A17: TOP EXPENSE CATEGORIES · JANUARY | E17: BILLS THIS MONTH | K17: May | L17: =IFERROR(May!D8,0) | M17: =IFERROR(May!D65,0)
A18: CATEGORY | B18: BUDGETED | C18: ACTUAL | E18: BILL NAME | F18: AMOUNT | G18: DUE | K18: Jun | L18: =IFERROR(Jun!D8,0) | M18: =IFERROR(Jun!D65,0)
A19: HOUSING | B19: =IFERROR(Jan!C15,0) | C19: =IFERROR(Jan!D15,0) | E19: Hyra/Mortgage | F19: 12500 | G19: 1:a | K19: Jul | L19: =IFERROR(Jul!D8,0) | M19: =IFERROR(Jul!D65,0)
A20: TRANSPORT | B20: =IFERROR(Jan!C22,0) | C20: =IFERROR(Jan!D22,0) | E20: El | F20: 850 | G20: 15:e | K20: Aug | L20: =IFERROR(Aug!D8,0) | M20: =IFERROR(Aug!D65,0)
A21: FOOD & DINING | B21: =IFERROR(Jan!C29,0) | C21: =IFERROR(Jan!D29,0) | E21: Internet | F21: 499 | G21: 22:a | K21: Sep | L21: =IFERROR(Sep!D8,0) | M21: =IFERROR(Sep!D65,0)
A22: HEALTH & WELLNESS | B22: =IFERROR(Jan!C36,0) | C22: =IFERROR(Jan!D36,0) | E22: Streaming | F22: 139 | G22: 8:e | K22: Oct | L22: =IFERROR(Oct!D8,0) | M22: =IFERROR(Oct!D65,0)
A23: LIFESTYLE | B23: =IFERROR(Jan!C43,0) | C23: =IFERROR(Jan!D43,0) | E23: Telefon | F23: 699 | G23: 12:e | K23: Nov | L23: =IFERROR(Nov!D8,0) | M23: =IFERROR(Nov!D65,0)
A24: PERSONAL | B24: =IFERROR(Jan!C50,0) | C24: =IFERROR(Jan!D50,0) | E24: Försäkring | F24: 1200 | G24: 1:a | K24: Dec | L24: =IFERROR(Dec!D8,0) | M24: =IFERROR(Dec!D65,0)

Sheet Jan
A1: JANUARY · MONTHLY BUDGET
A2: Track your income and expenses for January
A3: CATEGORY | B3: SUBCATEGORY | C3: BUDGETED | D3: ACTUAL | E3: DIFFERENCE | F3: % USED | G3: NOTES
A4: INCOME
A5: INCOME | B5: Primary Income | C5: 0 | D5: 0 | E5: =C5-D5 | F5: =IFERROR(D5/C5,0)
A6: INCOME | B6: Side Income | C6: 0 | D6: 0 | E6: =C6-D6 | F6: =IFERROR(D6/C6,0)
A7: INCOME | B7: Other Income | C7: 0 | D7: 0 | E7: =C7-D7 | F7: =IFERROR(D7/C7,0)
A8: TOTAL INCOME | C8: =SUM(C5:C7) | D8: =SUM(D5:D7) | E8: =C8-D8 | F8: =IFERROR(D8/C8,0)
A9: HOUSING
A10: HOUSING | B10: Rent/Mortgage | C10: 0 | D10: 0 | E10: =C10-D10 | F10: =IFERROR(D10/C10,0)
A11: HOUSING | B11: Utilities | C11: 0 | D11: 0 | E11: =C11-D11 | F11: =IFERROR(D11/C11,0)
A12: HOUSING | B12: Electricity | C12: 0 | D12: 0 | E12: =C12-D12 | F12: =IFERROR(D12/C12,0)
A13: HOUSING | B13: Internet | C13: 0 | D13: 0 | E13: =C13-D13 | F13: =IFERROR(D13/C13,0)
A14: HOUSING | B14: Home Insurance | C14: 0 | D14: 0 | E14: =C14-D14 | F14: =IFERROR(D14/C14,0)
A15: Subtotal — HOUSING | C15: =SUM(C10:C14) | D15: =SUM(D10:D14) | E15: =C15-D15 | F15: =IFERROR(D15/C15,0)
A16: TRANSPORT
A17: TRANSPORT | B17: Car Payment | C17: 0 | D17: 0 | E17: =C17-D17 | F17: =IFERROR(D17/C17,0)
A18: TRANSPORT | B18: Fuel | C18: 0 | D18: 0 | E18: =C18-D18 | F18: =IFERROR(D18/C18,0)
A19: TRANSPORT | B19: Car Insurance | C19: 0 | D19: 0 | E19: =C19-D19 | F19: =IFERROR(D19/C19,0)
A20: TRANSPORT | B20: Parking | C20: 0 | D20: 0 | E20: =C20-D20 | F20: =IFERROR(D20/C20,0)
A21: TRANSPORT | B21: Public Transport | C21: 0 | D21: 0 | E21: =C21-D21 | F21: =IFERROR(D21/C21,0)
A22: Subtotal — TRANSPORT | C22: =SUM(C17:C21) | D22: =SUM(D17:D21) | E22: =C22-D22 | F22: =IFERROR(D22/C22,0)
A23: FOOD & DINING
A24: FOOD & DINING | B24: Groceries | C24: 0 | D24: 0 | E24: =C24-D24 | F24: =IFERROR(D24/C24,0)
A25: FOOD & DINING | B25: Restaurants | C25: 0 | D25: 0 | E25: =C25-D25 | F25: =IFERROR(D25/C25,0)
A26: FOOD & DINING | B26: Coffee | C26: 0 | D26: 0 | E26: =C26-D26 | F26: =IFERROR(D26/C26,0)
A27: FOOD & DINING | B27: Food Delivery | C27: 0 | D27: 0 | E27: =C27-D27 | F27: =IFERROR(D27/C27,0)
A28: FOOD & DINING | B28: Work Lunch | C28: 0 | D28: 0 | E28: =C28-D28 | F28: =IFERROR(D28/C28,0)
A29: Subtotal — FOOD & DINING | C29: =SUM(C24:C28) | D29: =SUM(D24:D28) | E29: =C29-D29 | F29: =IFERROR(D29/C29,0)
A30: HEALTH & WELLNESS
A31: HEALTH & WELLNESS | B31: Health Insurance | C31: 0 | D31: 0 | E31: =C31-D31 | F31: =IFERROR(D31/C31,0)
A32: HEALTH & WELLNESS | B32: Gym | C32: 0 | D32: 0 | E32: =C32-D32 | F32: =IFERROR(D32/C32,0)
A33: HEALTH & WELLNESS | B33: Pharmacy | C33: 0 | D33: 0 | E33: =C33-D33 | F33: =IFERROR(D33/C33,0)
A34: HEALTH & WELLNESS | B34: Doctor | C34: 0 | D34: 0 | E34: =C34-D34 | F34: =IFERROR(D34/C34,0)
A35: HEALTH & WELLNESS | B35: Dental | C35: 0 | D35: 0 | E35: =C35-D35 | F35: =IFERROR(D35/C35,0)
A36: Subtotal — HEALTH & WELLNESS | C36: =SUM(C31:C35) | D36: =SUM(D31:D35) | E36: =C36-D36 | F36: =IFERROR(D36/C36,0)
A37: LIFESTYLE
A38: LIFESTYLE | B38: Streaming Services | C38: 0 | D38: 0 | E38: =C38-D38 | F38: =IFERROR(D38/C38,0)
A39: LIFESTYLE | B39: Entertainment | C39: 0 | D39: 0 | E39: =C39-D39 | F39: =IFERROR(D39/C39,0)
A40: LIFESTYLE | B40: Hobbies | C40: 0 | D40: 0 | E40: =C40-D40 | F40: =IFERROR(D40/C40,0)
...

Sheet Feb
A1: FEBRUARY · MONTHLY BUDGET
A2: Track your income and expenses for February
A3: CATEGORY | B3: SUBCATEGORY | C3: BUDGETED | D3: ACTUAL | E3: DIFFERENCE | F3: % USED | G3: NOTES
A4: INCOME
A5: INCOME | B5: Primary Income | C5: 0 | D5: 0 | E5: =C5-D5 | F5: =IFERROR(D5/C5,0)
A6: INCOME | B6: Side Income | C6: 0 | D6: 0 | E6: =C6-D6 | F6: =IFERROR(D6/C6,0)
A7: INCOME | B7: Other Income | C7: 0 | D7: 0 | E7: =C7-D7 | F7: =IFERROR(D7/C7,0)
A8: TOTAL INCOME | C8: =SUM(C5:C7) | D8: =SUM(D5:D7) | E8: =C8-D8 | F8: =IFERROR(D8/C8,0)
A9: HOUSING
A10: HOUSING | B10: Rent/Mortgage | C10: 0 | D10: 0 | E10: =C10-D10 | F10: =IFERROR(D10/C10,0)
A11: HOUSING | B11: Utilities | C11: 0 | D11: 0 | E11: =C11-D11 | F11: =IFERROR(D11/C11,0)
A12: HOUSING | B12: Electricity | C12: 0 | D12: 0 | E12: =C12-D12 | F12: =IFERROR(D12/C12,0)
A13: HOUSING | B13: Internet | C13: 0 | D13: 0 | E13: =C13-D13 | F13: =IFERROR(D13/C13,0)
A14: HOUSING | B14: Home Insurance | C14: 0 | D14: 0 | E14: =C14-D14 | F14: =IFERROR(D14/C14,0)
A15: Subtotal — HOUSING | C15: =SUM(C10:C14) | D15: =SUM(D10:D14) | E15: =C15-D15 | F15: =IFERROR(D15/C15,0)
A16: TRANSPORT
A17: TRANSPORT | B17: Car Payment | C17: 0 | D17: 0 | E17: =C17-D17 | F17: =IFERROR(D17/C17,0)
A18: TRANSPORT | B18: Fuel | C18: 0 | D18: 0 | E18: =C18-D18 | F18: =IFERROR(D18/C18,0)
A19: TRANSPORT | B19: Car Insurance | C19: 0 | D19: 0 | E19: =C19-D19 | F19: =IFERROR(D19/C19,0)
A20: TRANSPORT | B20: Parking | C20: 0 | D20: 0 | E20: =C20-D20 | F20: =IFERROR(D20/C20,0)
A21: TRANSPORT | B21: Public Transport | C21: 0 | D21: 0 | E21: =C21-D21 | F21: =IFERROR(D21/C21,0)
A22: Subtotal — TRANSPORT | C22: =SUM(C17:C21) | D22: =SUM(D17:D21) | E22: =C22-D22 | F22: =IFERROR(D22/C22,0)
A23: FOOD & DINING
A24: FOOD & DINING | B24: Groceries | C24: 0 | D24: 0 | E24: =C24-D24 | F24: =IFERROR(D24/C24,0)
A25: FOOD & DINING | B25: Restaurants | C25: 0 | D25: 0 | E25: =C25-D25 | F25: =IFERROR(D25/C25,0)
A26: FOOD & DINING | B26: Coffee | C26: 0 | D26: 0 | E26: =C26-D26 | F26: =IFERROR(D26/C26,0)
A27: FOOD & DINING | B27: Food Delivery | C27: 0 | D27: 0 | E27: =C27-D27 | F27: =IFERROR(D27/C27,0)
A28: FOOD & DINING | B28: Work Lunch | C28: 0 | D28: 0 | E28: =C28-D28 | F28: =IFERROR(D28/C28,0)
A29: Subtotal — FOOD & DINING | C29: =SUM(C24:C28) | D29: =SUM(D24:D28) | E29: =C29-D29 | F29: =IFERROR(D29/C29,0)
A30: HEALTH & WELLNESS
A31: HEALTH & WELLNESS | B31: Health Insurance | C31: 0 | D31: 0 | E31: =C31-D31 | F31: =IFERROR(D31/C31,0)
A32: HEALTH & WELLNESS | B32: Gym | C32: 0 | D32: 0 | E32: =C32-D32 | F32: =IFERROR(D32/C32,0)
A33: HEALTH & WELLNESS | B33: Pharmacy | C33: 0 | D33: 0 | E33: =C33-D33 | F33: =IFERROR(D33/C33,0)
A34: HEALTH & WELLNESS | B34: Doctor | C34: 0 | D34: 0 | E34: =C34-D34 | F34: =IFERROR(D34/C34,0)
A35: HEALTH & WELLNESS | B35: Dental | C35: 0 | D35: 0 | E35: =C35-D35 | F35: =IFERROR(D35/C35,0)
A36: Subtotal — HEALTH & WELLNESS | C36: =SUM(C31:C35) | D36: =SUM(D31:D35) | E36: =C36-D36 | F36: =IFERROR(D36/C36,0)
A37: LIFESTYLE
A38: LIFESTYLE | B38: Streaming Services | C38: 0 | D38: 0 | E38: =C38-D38 | F38: =IFERROR(D38/C38,0)
A39: LIFESTYLE | B39: Entertainment | C39: 0 | D39: 0 | E39: =C39-D39 | F39: =IFERROR(D39/C39,0)
A40: LIFESTYLE | B40: Hobbies | C40: 0 | D40: 0 | E40: =C40-D40 | F40: =IFERROR(D40/C40,0)
...

Sheet Mar
A1: MARCH · MONTHLY BUDGET
A2: Track your income and expenses for March
A3: CATEGORY | B3: SUBCATEGORY | C3: BUDGETED | D3: ACTUAL | E3: DIFFERENCE | F3: % USED | G3: NOTES
A4: INCOME
A5: INCOME | B5: Primary Income | C5: 0 | D5: 0 | E5: =C5-D5 | F5: =IFERROR(D5/C5,0)
A6: INCOME | B6: Side Income | C6: 0 | D6: 0 | E6: =C6-D6 | F6: =IFERROR(D6/C6,0)
A7: INCOME | B7: Other Income | C7: 0 | D7: 0 | E7: =C7-D7 | F7: =IFERROR(D7/C7,0)
A8: TOTAL INCOME | C8: =SUM(C5:C7) | D8: =SUM(D5:D7) | E8: =C8-D8 | F8: =IFERROR(D8/C8,0)
A9: HOUSING
A10: HOUSING | B10: Rent/Mortgage | C10: 0 | D10: 0 | E10: =C10-D10 | F10: =IFERROR(D10/C10,0)
A11: HOUSING | B11: Utilities | C11: 0 | D11: 0 | E11: =C11-D11 | F11: =IFERROR(D11/C11,0)
A12: HOUSING | B12: Electricity | C12: 0 | D12: 0 | E12: =C12-D12 | F12: =IFERROR(D12/C12,0)
A13: HOUSING | B13: Internet | C13: 0 | D13: 0 | E13: =C13-D13 | F13: =IFERROR(D13/C13,0)
A14: HOUSING | B14: Home Insurance | C14: 0 | D14: 0 | E14: =C14-D14 | F14: =IFERROR(D14/C14,0)
A15: Subtotal — HOUSING | C15: =SUM(C10:C14) | D15: =SUM(D10:D14) | E15: =C15-D15 | F15: =IFERROR(D15/C15,0)
A16: TRANSPORT
A17: TRANSPORT | B17: Car Payment | C17: 0 | D17: 0 | E17: =C17-D17 | F17: =IFERROR(D17/C17,0)
A18: TRANSPORT | B18: Fuel | C18: 0 | D18: 0 | E18: =C18-D18 | F18: =IFERROR(D18/C18,0)
A19: TRANSPORT | B19: Car Insurance | C19: 0 | D19: 0 | E19: =C19-D19 | F19: =IFERROR(D19/C19,0)
A20: TRANSPORT | B20: Parking | C20: 0 | D20: 0 | E20: =C20-D20 | F20: =IFERROR(D20/C20,0)
A21: TRANSPORT | B21: Public Transport | C21: 0 | D21: 0 | E21: =C21-D21 | F21: =IFERROR(D21/C21,0)
A22: Subtotal — TRANSPORT | C22: =SUM(C17:C21) | D22: =SUM(D17:D21) | E22: =C22-D22 | F22: =IFERROR(D22/C22,0)
A23: FOOD & DINING
A24: FOOD & DINING | B24: Groceries | C24: 0 | D24: 0 | E24: =C24-D24 | F24: =IFERROR(D24/C24,0)
A25: FOOD & DINING | B25: Restaurants | C25: 0 | D25: 0 | E25: =C25-D25 | F25: =IFERROR(D25/C25,0)
A26: FOOD & DINING | B26: Coffee | C26: 0 | D26: 0 | E26: =C26-D26 | F26: =IFERROR(D26/C26,0)
A27: FOOD & DINING | B27: Food Delivery | C27: 0 | D27: 0 | E27: =C27-D27 | F27: =IFERROR(D27/C27,0)
A28: FOOD & DINING | B28: Work Lunch | C28: 0 | D28: 0 | E28: =C28-D28 | F28: =IFERROR(D28/C28,0)
A29: Subtotal — FOOD & DINING | C29: =SUM(C24:C28) | D29: =SUM(D24:D28) | E29: =C29-D29 | F29: =IFERROR(D29/C29,0)
A30: HEALTH & WELLNESS
A31: HEALTH & WELLNESS | B31: Health Insurance | C31: 0 | D31: 0 | E31: =C31-D31 | F31: =IFERROR(D31/C31,0)
A32: HEALTH & WELLNESS | B32: Gym | C32: 0 | D32: 0 | E32: =C32-D32 | F32: =IFERROR(D32/C32,0)
A33: HEALTH & WELLNESS | B33: Pharmacy | C33: 0 | D33: 0 | E33: =C33-D33 | F33: =IFERROR(D33/C33,0)
A34: HEALTH & WELLNESS | B34: Doctor | C34: 0 | D34: 0 | E34: =C34-D34 | F34: =IFERROR(D34/C34,0)
A35: HEALTH & WELLNESS | B35: Dental | C35: 0 | D35: 0 | E35: =C35-D35 | F35: =IFERROR(D35/C35,0)
A36: Subtotal — HEALTH & WELLNESS | C36: =SUM(C31:C35) | D36: =SUM(D31:D35) | E36: =C36-D36 | F36: =IFERROR(D36/C36,0)
A37: LIFESTYLE
A38: LIFESTYLE | B38: Streaming Services | C38: 0 | D38: 0 | E38: =C38-D38 | F38: =IFERROR(D38/C38,0)
A39: LIFESTYLE | B39: Entertainment | C39: 0 | D39: 0 | E39: =C39-D39 | F39: =IFERROR(D39/C39,0)
A40: LIFESTYLE | B40: Hobbies | C40: 0 | D40: 0 | E40: =C40-D40 | F40: =IFERROR(D40/C40,0)
...

Sheet Apr
A1: APRIL · MONTHLY BUDGET
A2: Track your income and expenses for April
A3: CATEGORY | B3: SUBCATEGORY | C3: BUDGETED | D3: ACTUAL | E3: DIFFERENCE | F3: % USED | G3: NOTES
A4: INCOME
A5: INCOME | B5: Primary Income | C5: 0 | D5: 0 | E5: =C5-D5 | F5: =IFERROR(D5/C5,0)
A6: INCOME | B6: Side Income | C6: 0 | D6: 0 | E6: =C6-D6 | F6: =IFERROR(D6/C6,0)
A7: INCOME | B7: Other Income | C7: 0 | D7: 0 | E7: =C7-D7 | F7: =IFERROR(D7/C7,0)
A8: TOTAL INCOME | C8: =SUM(C5:C7) | D8: =SUM(D5:D7) | E8: =C8-D8 | F8: =IFERROR(D8/C8,0)
A9: HOUSING
A10: HOUSING | B10: Rent/Mortgage | C10: 0 | D10: 0 | E10: =C10-D10 | F10: =IFERROR(D10/C10,0)
A11: HOUSING | B11: Utilities | C11: 0 | D11: 0 | E11: =C11-D11 | F11: =IFERROR(D11/C11,0)
A12: HOUSING | B12: Electricity | C12: 0 | D12: 0 | E12: =C12-D12 | F12: =IFERROR(D12/C12,0)
A13: HOUSING | B13: Internet | C13: 0 | D13: 0 | E13: =C13-D13 | F13: =IFERROR(D13/C13,0)
A14: HOUSING | B14: Home Insurance | C14: 0 | D14: 0 | E14: =C14-D14 | F14: =IFERROR(D14/C14,0)
A15: Subtotal — HOUSING | C15: =SUM(C10:C14) | D15: =SUM(D10:D14) | E15: =C15-D15 | F15: =IFERROR(D15/C15,0)
A16: TRANSPORT
A17: TRANSPORT | B17: Car Payment | C17: 0 | D17: 0 | E17: =C17-D17 | F17: =IFERROR(D17/C17,0)
A18: TRANSPORT | B18: Fuel | C18: 0 | D18: 0 | E18: =C18-D18 | F18: =IFERROR(D18/C18,0)
A19: TRANSPORT | B19: Car Insurance | C19: 0 | D19: 0 | E19: =C19-D19 | F19: =IFERROR(D19/C19,0)
A20: TRANSPORT | B20: Parking | C20: 0 | D20: 0 | E20: =C20-D20 | F20: =IFERROR(D20/C20,0)
A21: TRANSPORT | B21: Public Transport | C21: 0 | D21: 0 | E21: =C21-D21 | F21: =IFERROR(D21/C21,0)
A22: Subtotal — TRANSPORT | C22: =SUM(C17:C21) | D22: =SUM(D17:D21) | E22: =C22-D22 | F22: =IFERROR(D22/C22,0)
A23: FOOD & DINING
A24: FOOD & DINING | B24: Groceries | C24: 0 | D24: 0 | E24: =C24-D24 | F24: =IFERROR(D24/C24,0)
A25: FOOD & DINING | B25: Restaurants | C25: 0 | D25: 0 | E25: =C25-D25 | F25: =IFERROR(D25/C25,0)
A26: FOOD & DINING | B26: Coffee | C26: 0 | D26: 0 | E26: =C26-D26 | F26: =IFERROR(D26/C26,0)
A27: FOOD & DINING | B27: Food Delivery | C27: 0 | D27: 0 | E27: =C27-D27 | F27: =IFERROR(D27/C27,0)
A28: FOOD & DINING | B28: Work Lunch | C28: 0 | D28: 0 | E28: =C28-D28 | F28: =IFERROR(D28/C28,0)
A29: Subtotal — FOOD & DINING | C29: =SUM(C24:C28) | D29: =SUM(D24:D28) | E29: =C29-D29 | F29: =IFERROR(D29/C29,0)
A30: HEALTH & WELLNESS
A31: HEALTH & WELLNESS | B31: Health Insurance | C31: 0 | D31: 0 | E31: =C31-D31 | F31: =IFERROR(D31/C31,0)
A32: HEALTH & WELLNESS | B32: Gym | C32: 0 | D32: 0 | E32: =C32-D32 | F32: =IFERROR(D32/C32,0)
A33: HEALTH & WELLNESS | B33: Pharmacy | C33: 0 | D33: 0 | E33: =C33-D33 | F33: =IFERROR(D33/C33,0)
A34: HEALTH & WELLNESS | B34: Doctor | C34: 0 | D34: 0 | E34: =C34-D34 | F34: =IFERROR(D34/C34,0)
A35: HEALTH & WELLNESS | B35: Dental | C35: 0 | D35: 0 | E35: =C35-D35 | F35: =IFERROR(D35/C35,0)
A36: Subtotal — HEALTH & WELLNESS | C36: =SUM(C31:C35) | D36: =SUM(D31:D35) | E36: =C36-D36 | F36: =IFERROR(D36/C36,0)
A37: LIFESTYLE
A38: LIFESTYLE | B38: Streaming Services | C38: 0 | D38: 0 | E38: =C38-D38 | F38: =IFERROR(D38/C38,0)
A39: LIFESTYLE | B39: Entertainment | C39: 0 | D39: 0 | E39: =C39-D39 | F39: =IFERROR(D39/C39,0)
A40: LIFESTYLE | B40: Hobbies | C40: 0 | D40: 0 | E40: =C40-D40 | F40: =IFERROR(D40/C40,0)
...

Sheet May
A1: MAY · MONTHLY BUDGET
A2: Track your income and expenses for May
A3: CATEGORY | B3: SUBCATEGORY | C3: BUDGETED | D3: ACTUAL | E3: DIFFERENCE | F3: % USED | G3: NOTES
A4: INCOME
A5: INCOME | B5: Primary Income | C5: 0 | D5: 0 | E5: =C5-D5 | F5: =IFERROR(D5/C5,0)
A6: INCOME | B6: Side Income | C6: 0 | D6: 0 | E6: =C6-D6 | F6: =IFERROR(D6/C6,0)
A7: INCOME | B7: Other Income | C7: 0 | D7: 0 | E7: =C7-D7 | F7: =IFERROR(D7/C7,0)
A8: TOTAL INCOME | C8: =SUM(C5:C7) | D8: =SUM(D5:D7) | E8: =C8-D8 | F8: =IFERROR(D8/C8,0)
A9: HOUSING
A10: HOUSING | B10: Rent/Mortgage | C10: 0 | D10: 0 | E10: =C10-D10 | F10: =IFERROR(D10/C10,0)
A11: HOUSING | B11: Utilities | C11: 0 | D11: 0 | E11: =C11-D11 | F11: =IFERROR(D11/C11,0)
A12: HOUSING | B12: Electricity | C12: 0 | D12: 0 | E12: =C12-D12 | F12: =IFERROR(D12/C12,0)
A13: HOUSING | B13: Internet | C13: 0 | D13: 0 | E13: =C13-D13 | F13: =IFERROR(D13/C13,0)
A14: HOUSING | B14: Home Insurance | C14: 0 | D14: 0 | E14: =C14-D14 | F14: =IFERROR(D14/C14,0)
A15: Subtotal — HOUSING | C15: =SUM(C10:C14) | D15: =SUM(D10:D14) | E15: =C15-D15 | F15: =IFERROR(D15/C15,0)
A16: TRANSPORT
A17: TRANSPORT | B17: Car Payment | C17: 0 | D17: 0 | E17: =C17-D17 | F17: =IFERROR(D17/C17,0)
A18: TRANSPORT | B18: Fuel | C18: 0 | D18: 0 | E18: =C18-D18 | F18: =IFERROR(D18/C18,0)
A19: TRANSPORT | B19: Car Insurance | C19: 0 | D19: 0 | E19: =C19-D19 | F19: =IFERROR(D19/C19,0)
A20: TRANSPORT | B20: Parking | C20: 0 | D20: 0 | E20: =C20-D20 | F20: =IFERROR(D20/C20,0)
A21: TRANSPORT | B21: Public Transport | C21: 0 | D21: 0 | E21: =C21-D21 | F21: =IFERROR(D21/C21,0)
A22: Subtotal — TRANSPORT | C22: =SUM(C17:C21) | D22: =SUM(D17:D21) | E22: =C22-D22 | F22: =IFERROR(D22/C22,0)
A23: FOOD & DINING
A24: FOOD & DINING | B24: Groceries | C24: 0 | D24: 0 | E24: =C24-D24 | F24: =IFERROR(D24/C24,0)
A25: FOOD & DINING | B25: Restaurants | C25: 0 | D25: 0 | E25: =C25-D25 | F25: =IFERROR(D25/C25,0)
A26: FOOD & DINING | B26: Coffee | C26: 0 | D26: 0 | E26: =C26-D26 | F26: =IFERROR(D26/C26,0)
A27: FOOD & DINING | B27: Food Delivery | C27: 0 | D27: 0 | E27: =C27-D27 | F27: =IFERROR(D27/C27,0)
A28: FOOD & DINING | B28: Work Lunch | C28: 0 | D28: 0 | E28: =C28-D28 | F28: =IFERROR(D28/C28,0)
A29: Subtotal — FOOD & DINING | C29: =SUM(C24:C28) | D29: =SUM(D24:D28) | E29: =C29-D29 | F29: =IFERROR(D29/C29,0)
A30: HEALTH & WELLNESS
A31: HEALTH & WELLNESS | B31: Health Insurance | C31: 0 | D31: 0 | E31: =C31-D31 | F31: =IFERROR(D31/C31,0)
A32: HEALTH & WELLNESS | B32: Gym | C32: 0 | D32: 0 | E32: =C32-D32 | F32: =IFERROR(D32/C32,0)
A33: HEALTH & WELLNESS | B33: Pharmacy | C33: 0 | D33: 0 | E33: =C33-D33 | F33: =IFERROR(D33/C33,0)
A34: HEALTH & WELLNESS | B34: Doctor | C34: 0 | D34: 0 | E34: =C34-D34 | F34: =IFERROR(D34/C34,0)
A35: HEALTH & WELLNESS | B35: Dental | C35: 0 | D35: 0 | E35: =C35-D35 | F35: =IFERROR(D35/C35,0)
A36: Subtotal — HEALTH & WELLNESS | C36: =SUM(C31:C35) | D36: =SUM(D31:D35) | E36: =C36-D36 | F36: =IFERROR(D36/C36,0)
A37: LIFESTYLE
A38: LIFESTYLE | B38: Streaming Services | C38: 0 | D38: 0 | E38: =C38-D38 | F38: =IFERROR(D38/C38,0)
A39: LIFESTYLE | B39: Entertainment | C39: 0 | D39: 0 | E39: =C39-D39 | F39: =IFERROR(D39/C39,0)
A40: LIFESTYLE | B40: Hobbies | C40: 0 | D40: 0 | E40: =C40-D40 | F40: =IFERROR(D40/C40,0)
...

Sheet Jun
A1: JUNE · MONTHLY BUDGET
A2: Track your income and expenses for June
A3: CATEGORY | B3: SUBCATEGORY | C3: BUDGETED | D3: ACTUAL | E3: DIFFERENCE | F3: % USED | G3: NOTES
A4: INCOME
A5: INCOME | B5: Primary Income | C5: 0 | D5: 0 | E5: =C5-D5 | F5: =IFERROR(D5/C5,0)
A6: INCOME | B6: Side Income | C6: 0 | D6: 0 | E6: =C6-D6 | F6: =IFERROR(D6/C6,0)
A7: INCOME | B7: Other Income | C7: 0 | D7: 0 | E7: =C7-D7 | F7: =IFERROR(D7/C7,0)
A8: TOTAL INCOME | C8: =SUM(C5:C7) | D8: =SUM(D5:D7) | E8: =C8-D8 | F8: =IFERROR(D8/C8,0)
A9: HOUSING
A10: HOUSING | B10: Rent/Mortgage | C10: 0 | D10: 0 | E10: =C10-D10 | F10: =IFERROR(D10/C10,0)
A11: HOUSING | B11: Utilities | C11: 0 | D11: 0 | E11: =C11-D11 | F11: =IFERROR(D11/C11,0)
A12: HOUSING | B12: Electricity | C12: 0 | D12: 0 | E12: =C12-D12 | F12: =IFERROR(D12/C12,0)
A13: HOUSING | B13: Internet | C13: 0 | D13: 0 | E13: =C13-D13 | F13: =IFERROR(D13/C13,0)
A14: HOUSING | B14: Home Insurance | C14: 0 | D14: 0 | E14: =C14-D14 | F14: =IFERROR(D14/C14,0)
A15: Subtotal — HOUSING | C15: =SUM(C10:C14) | D15: =SUM(D10:D14) | E15: =C15-D15 | F15: =IFERROR(D15/C15,0)
A16: TRANSPORT
A17: TRANSPORT | B17: Car Payment | C17: 0 | D17: 0 | E17: =C17-D17 | F17: =IFERROR(D17/C17,0)
A18: TRANSPORT | B18: Fuel | C18: 0 | D18: 0 | E18: =C18-D18 | F18: =IFERROR(D18/C18,0)
A19: TRANSPORT | B19: Car Insurance | C19: 0 | D19: 0 | E19: =C19-D19 | F19: =IFERROR(D19/C19,0)
A20: TRANSPORT | B20: Parking | C20: 0 | D20: 0 | E20: =C20-D20 | F20: =IFERROR(D20/C20,0)
A21: TRANSPORT | B21: Public Transport | C21: 0 | D21: 0 | E21: =C21-D21 | F21: =IFERROR(D21/C21,0)
A22: Subtotal — TRANSPORT | C22: =SUM(C17:C21) | D22: =SUM(D17:D21) | E22: =C22-D22 | F22: =IFERROR(D22/C22,0)
A23: FOOD & DINING
A24: FOOD & DINING | B24: Groceries | C24: 0 | D24: 0 | E24: =C24-D24 | F24: =IFERROR(D24/C24,0)
A25: FOOD & DINING | B25: Restaurants | C25: 0 | D25: 0 | E25: =C25-D25 | F25: =IFERROR(D25/C25,0)
A26: FOOD & DINING | B26: Coffee | C26: 0 | D26: 0 | E26: =C26-D26 | F26: =IFERROR(D26/C26,0)
A27: FOOD & DINING | B27: Food Delivery | C27: 0 | D27: 0 | E27: =C27-D27 | F27: =IFERROR(D27/C27,0)
A28: FOOD & DINING | B28: Work Lunch | C28: 0 | D28: 0 | E28: =C28-D28 | F28: =IFERROR(D28/C28,0)
A29: Subtotal — FOOD & DINING | C29: =SUM(C24:C28) | D29: =SUM(D24:D28) | E29: =C29-D29 | F29: =IFERROR(D29/C29,0)
A30: HEALTH & WELLNESS
A31: HEALTH & WELLNESS | B31: Health Insurance | C31: 0 | D31: 0 | E31: =C31-D31 | F31: =IFERROR(D31/C31,0)
A32: HEALTH & WELLNESS | B32: Gym | C32: 0 | D32: 0 | E32: =C32-D32 | F32: =IFERROR(D32/C32,0)
A33: HEALTH & WELLNESS | B33: Pharmacy | C33: 0 | D33: 0 | E33: =C33-D33 | F33: =IFERROR(D33/C33,0)
A34: HEALTH & WELLNESS | B34: Doctor | C34: 0 | D34: 0 | E34: =C34-D34 | F34: =IFERROR(D34/C34,0)
A35: HEALTH & WELLNESS | B35: Dental | C35: 0 | D35: 0 | E35: =C35-D35 | F35: =IFERROR(D35/C35,0)
A36: Subtotal — HEALTH & WELLNESS | C36: =SUM(C31:C35) | D36: =SUM(D31:D35) | E36: =C36-D36 | F36: =IFERROR(D36/C36,0)
A37: LIFESTYLE
A38: LIFESTYLE | B38: Streaming Services | C38: 0 | D38: 0 | E38: =C38-D38 | F38: =IFERROR(D38/C38,0)
A39: LIFESTYLE | B39: Entertainment | C39: 0 | D39: 0 | E39: =C39-D39 | F39: =IFERROR(D39/C39,0)
A40: LIFESTYLE | B40: Hobbies | C40: 0 | D40: 0 | E40: =C40-D40 | F40: =IFERROR(D40/C40,0)
...

Sheet Jul
A1: JULY · MONTHLY BUDGET
A2: Track your income and expenses for July
A3: CATEGORY | B3: SUBCATEGORY | C3: BUDGETED | D3: ACTUAL | E3: DIFFERENCE | F3: % USED | G3: NOTES
A4: INCOME
A5: INCOME | B5: Primary Income | C5: 0 | D5: 0 | E5: =C5-D5 | F5: =IFERROR(D5/C5,0)
A6: INCOME | B6: Side Income | C6: 0 | D6: 0 | E6: =C6-D6 | F6: =IFERROR(D6/C6,0)
A7: INCOME | B7: Other Income | C7: 0 | D7: 0 | E7: =C7-D7 | F7: =IFERROR(D7/C7,0)
A8: TOTAL INCOME | C8: =SUM(C5:C7) | D8: =SUM(D5:D7) | E8: =C8-D8 | F8: =IFERROR(D8/C8,0)
A9: HOUSING
A10: HOUSING | B10: Rent/Mortgage | C10: 0 | D10: 0 | E10: =C10-D10 | F10: =IFERROR(D10/C10,0)
A11: HOUSING | B11: Utilities | C11: 0 | D11: 0 | E11: =C11-D11 | F11: =IFERROR(D11/C11,0)
A12: HOUSING | B12: Electricity | C12: 0 | D12: 0 | E12: =C12-D12 | F12: =IFERROR(D12/C12,0)
A13: HOUSING | B13: Internet | C13: 0 | D13: 0 | E13: =C13-D13 | F13: =IFERROR(D13/C13,0)
A14: HOUSING | B14: Home Insurance | C14: 0 | D14: 0 | E14: =C14-D14 | F14: =IFERROR(D14/C14,0)
A15: Subtotal — HOUSING | C15: =SUM(C10:C14) | D15: =SUM(D10:D14) | E15: =C15-D15 | F15: =IFERROR(D15/C15,0)
A16: TRANSPORT
A17: TRANSPORT | B17: Car Payment | C17: 0 | D17: 0 | E17: =C17-D17 | F17: =IFERROR(D17/C17,0)
A18: TRANSPORT | B18: Fuel | C18: 0 | D18: 0 | E18: =C18-D18 | F18: =IFERROR(D18/C18,0)
A19: TRANSPORT | B19: Car Insurance | C19: 0 | D19: 0 | E19: =C19-D19 | F19: =IFERROR(D19/C19,0)
A20: TRANSPORT | B20: Parking | C20: 0 | D20: 0 | E20: =C20-D20 | F20: =IFERROR(D20/C20,0)
A21: TRANSPORT | B21: Public Transport | C21: 0 | D21: 0 | E21: =C21-D21 | F21: =IFERROR(D21/C21,0)
A22: Subtotal — TRANSPORT | C22: =SUM(C17:C21) | D22: =SUM(D17:D21) | E22: =C22-D22 | F22: =IFERROR(D22/C22,0)
A23: FOOD & DINING
A24: FOOD & DINING | B24: Groceries | C24: 0 | D24: 0 | E24: =C24-D24 | F24: =IFERROR(D24/C24,0)
A25: FOOD & DINING | B25: Restaurants | C25: 0 | D25: 0 | E25: =C25-D25 | F25: =IFERROR(D25/C25,0)
A26: FOOD & DINING | B26: Coffee | C26: 0 | D26: 0 | E26: =C26-D26 | F26: =IFERROR(D26/C26,0)
A27: FOOD & DINING | B27: Food Delivery | C27: 0 | D27: 0 | E27: =C27-D27 | F27: =IFERROR(D27/C27,0)
A28: FOOD & DINING | B28: Work Lunch | C28: 0 | D28: 0 | E28: =C28-D28 | F28: =IFERROR(D28/C28,0)
A29: Subtotal — FOOD & DINING | C29: =SUM(C24:C28) | D29: =SUM(D24:D28) | E29: =C29-D29 | F29: =IFERROR(D29/C29,0)
A30: HEALTH & WELLNESS
A31: HEALTH & WELLNESS | B31: Health Insurance | C31: 0 | D31: 0 | E31: =C31-D31 | F31: =IFERROR(D31/C31,0)
A32: HEALTH & WELLNESS | B32: Gym | C32: 0 | D32: 0 | E32: =C32-D32 | F32: =IFERROR(D32/C32,0)
A33: HEALTH & WELLNESS | B33: Pharmacy | C33: 0 | D33: 0 | E33: =C33-D33 | F33: =IFERROR(D33/C33,0)
A34: HEALTH & WELLNESS | B34: Doctor | C34: 0 | D34: 0 | E34: =C34-D34 | F34: =IFERROR(D34/C34,0)
A35: HEALTH & WELLNESS | B35: Dental | C35: 0 | D35: 0 | E35: =C35-D35 | F35: =IFERROR(D35/C35,0)
A36: Subtotal — HEALTH & WELLNESS | C36: =SUM(C31:C35) | D36: =SUM(D31:D35) | E36: =C36-D36 | F36: =IFERROR(D36/C36,0)
A37: LIFESTYLE
A38: LIFESTYLE | B38: Streaming Services | C38: 0 | D38: 0 | E38: =C38-D38 | F38: =IFERROR(D38/C38,0)
A39: LIFESTYLE | B39: Entertainment | C39: 0 | D39: 0 | E39: =C39-D39 | F39: =IFERROR(D39/C39,0)
A40: LIFESTYLE | B40: Hobbies | C40: 0 | D40: 0 | E40: =C40-D40 | F40: =IFERROR(D40/C40,0)
...

Sheet Aug
A1: AUGUST · MONTHLY BUDGET
A2: Track your income and expenses for August
A3: CATEGORY | B3: SUBCATEGORY | C3: BUDGETED | D3: ACTUAL | E3: DIFFERENCE | F3: % USED | G3: NOTES
A4: INCOME
A5: INCOME | B5: Primary Income | C5: 0 | D5: 0 | E5: =C5-D5 | F5: =IFERROR(D5/C5,0)
A6: INCOME | B6: Side Income | C6: 0 | D6: 0 | E6: =C6-D6 | F6: =IFERROR(D6/C6,0)
A7: INCOME | B7: Other Income | C7: 0 | D7: 0 | E7: =C7-D7 | F7: =IFERROR(D7/C7,0)
A8: TOTAL INCOME | C8: =SUM(C5:C7) | D8: =SUM(D5:D7) | E8: =C8-D8 | F8: =IFERROR(D8/C8,0)
A9: HOUSING
A10: HOUSING | B10: Rent/Mortgage | C10: 0 | D10: 0 | E10: =C10-D10 | F10: =IFERROR(D10/C10,0)
A11: HOUSING | B11: Utilities | C11: 0 | D11: 0 | E11: =C11-D11 | F11: =IFERROR(D11/C11,0)
A12: HOUSING | B12: Electricity | C12: 0 | D12: 0 | E12: =C12-D12 | F12: =IFERROR(D12/C12,0)
A13: HOUSING | B13: Internet | C13: 0 | D13: 0 | E13: =C13-D13 | F13: =IFERROR(D13/C13,0)
A14: HOUSING | B14: Home Insurance | C14: 0 | D14: 0 | E14: =C14-D14 | F14: =IFERROR(D14/C14,0)
A15: Subtotal — HOUSING | C15: =SUM(C10:C14) | D15: =SUM(D10:D14) | E15: =C15-D15 | F15: =IFERROR(D15/C15,0)
A16: TRANSPORT
A17: TRANSPORT | B17: Car Payment | C17: 0 | D17: 0 | E17: =C17-D17 | F17: =IFERROR(D17/C17,0)
A18: TRANSPORT | B18: Fuel | C18: 0 | D18: 0 | E18: =C18-D18 | F18: =IFERROR(D18/C18,0)
A19: TRANSPORT | B19: Car Insurance | C19: 0 | D19: 0 | E19: =C19-D19 | F19: =IFERROR(D19/C19,0)
A20: TRANSPORT | B20: Parking | C20: 0 | D20: 0 | E20: =C20-D20 | F20: =IFERROR(D20/C20,0)
A21: TRANSPORT | B21: Public Transport | C21: 0 | D21: 0 | E21: =C21-D21 | F21: =IFERROR(D21/C21,0)
A22: Subtotal — TRANSPORT | C22: =SUM(C17:C21) | D22: =SUM(D17:D21) | E22: =C22-D22 | F22: =IFERROR(D22/C22,0)
A23: FOOD & DINING
A24: FOOD & DINING | B24: Groceries | C24: 0 | D24: 0 | E24: =C24-D24 | F24: =IFERROR(D24/C24,0)
A25: FOOD & DINING | B25: Restaurants | C25: 0 | D25: 0 | E25: =C25-D25 | F25: =IFERROR(D25/C25,0)
A26: FOOD & DINING | B26: Coffee | C26: 0 | D26: 0 | E26: =C26-D26 | F26: =IFERROR(D26/C26,0)
A27: FOOD & DINING | B27: Food Delivery | C27: 0 | D27: 0 | E27: =C27-D27 | F27: =IFERROR(D27/C27,0)
A28: FOOD & DINING | B28: Work Lunch | C28: 0 | D28: 0 | E28: =C28-D28 | F28: =IFERROR(D28/C28,0)
A29: Subtotal — FOOD & DINING | C29: =SUM(C24:C28) | D29: =SUM(D24:D28) | E29: =C29-D29 | F29: =IFERROR(D29/C29,0)
A30: HEALTH & WELLNESS
A31: HEALTH & WELLNESS | B31: Health Insurance | C31: 0 | D31: 0 | E31: =C31-D31 | F31: =IFERROR(D31/C31,0)
A32: HEALTH & WELLNESS | B32: Gym | C32: 0 | D32: 0 | E32: =C32-D32 | F32: =IFERROR(D32/C32,0)
A33: HEALTH & WELLNESS | B33: Pharmacy | C33: 0 | D33: 0 | E33: =C33-D33 | F33: =IFERROR(D33/C33,0)
A34: HEALTH & WELLNESS | B34: Doctor | C34: 0 | D34: 0 | E34: =C34-D34 | F34: =IFERROR(D34/C34,0)
A35: HEALTH & WELLNESS | B35: Dental | C35: 0 | D35: 0 | E35: =C35-D35 | F35: =IFERROR(D35/C35,0)
A36: Subtotal — HEALTH & WELLNESS | C36: =SUM(C31:C35) | D36: =SUM(D31:D35) | E36: =C36-D36 | F36: =IFERROR(D36/C36,0)
A37: LIFESTYLE
A38: LIFESTYLE | B38: Streaming Services | C38: 0 | D38: 0 | E38: =C38-D38 | F38: =IFERROR(D38/C38,0)
A39: LIFESTYLE | B39: Entertainment | C39: 0 | D39: 0 | E39: =C39-D39 | F39: =IFERROR(D39/C39,0)
A40: LIFESTYLE | B40: Hobbies | C40: 0 | D40: 0 | E40: =C40-D40 | F40: =IFERROR(D40/C40,0)
...

Sheet Sep
A1: SEPTEMBER · MONTHLY BUDGET
A2: Track your income and expenses for September
A3: CATEGORY | B3: SUBCATEGORY | C3: BUDGETED | D3: ACTUAL | E3: DIFFERENCE | F3: % USED | G3: NOTES
A4: INCOME
A5: INCOME | B5: Primary Income | C5: 0 | D5: 0 | E5: =C5-D5 | F5: =IFERROR(D5/C5,0)
A6: INCOME | B6: Side Income | C6: 0 | D6: 0 | E6: =C6-D6 | F6: =IFERROR(D6/C6,0)
A7: INCOME | B7: Other Income | C7: 0 | D7: 0 | E7: =C7-D7 | F7: =IFERROR(D7/C7,0)
A8: TOTAL INCOME | C8: =SUM(C5:C7) | D8: =SUM(D5:D7) | E8: =C8-D8 | F8: =IFERROR(D8/C8,0)
A9: HOUSING
A10: HOUSING | B10: Rent/Mortgage | C10: 0 | D10: 0 | E10: =C10-D10 | F10: =IFERROR(D10/C10,0)
A11: HOUSING | B11: Utilities | C11: 0 | D11: 0 | E11: =C11-D11 | F11: =IFERROR(D11/C11,0)
A12: HOUSING | B12: Electricity | C12: 0 | D12: 0 | E12: =C12-D12 | F12: =IFERROR(D12/C12,0)
A13: HOUSING | B13: Internet | C13: 0 | D13: 0 | E13: =C13-D13 | F13: =IFERROR(D13/C13,0)
A14: HOUSING | B14: Home Insurance | C14: 0 | D14: 0 | E14: =C14-D14 | F14: =IFERROR(D14/C14,0)
A15: Subtotal — HOUSING | C15: =SUM(C10:C14) | D15: =SUM(D10:D14) | E15: =C15-D15 | F15: =IFERROR(D15/C15,0)
A16: TRANSPORT
A17: TRANSPORT | B17: Car Payment | C17: 0 | D17: 0 | E17: =C17-D17 | F17: =IFERROR(D17/C17,0)
A18: TRANSPORT | B18: Fuel | C18: 0 | D18: 0 | E18: =C18-D18 | F18: =IFERROR(D18/C18,0)
A19: TRANSPORT | B19: Car Insurance | C19: 0 | D19: 0 | E19: =C19-D19 | F19: =IFERROR(D19/C19,0)
A20: TRANSPORT | B20: Parking | C20: 0 | D20: 0 | E20: =C20-D20 | F20: =IFERROR(D20/C20,0)
A21: TRANSPORT | B21: Public Transport | C21: 0 | D21: 0 | E21: =C21-D21 | F21: =IFERROR(D21/C21,0)
A22: Subtotal — TRANSPORT | C22: =SUM(C17:C21) | D22: =SUM(D17:D21) | E22: =C22-D22 | F22: =IFERROR(D22/C22,0)
A23: FOOD & DINING
A24: FOOD & DINING | B24: Groceries | C24: 0 | D24: 0 | E24: =C24-D24 | F24: =IFERROR(D24/C24,0)
A25: FOOD & DINING | B25: Restaurants | C25: 0 | D25: 0 | E25: =C25-D25 | F25: =IFERROR(D25/C25,0)
A26: FOOD & DINING | B26: Coffee | C26: 0 | D26: 0 | E26: =C26-D26 | F26: =IFERROR(D26/C26,0)
A27: FOOD & DINING | B27: Food Delivery | C27: 0 | D27: 0 | E27: =C27-D27 | F27: =IFERROR(D27/C27,0)
A28: FOOD & DINING | B28: Work Lunch | C28: 0 | D28: 0 | E28: =C28-D28 | F28: =IFERROR(D28/C28,0)
A29: Subtotal — FOOD & DINING | C29: =SUM(C24:C28) | D29: =SUM(D24:D28) | E29: =C29-D29 | F29: =IFERROR(D29/C29,0)
A30: HEALTH & WELLNESS
A31: HEALTH & WELLNESS | B31: Health Insurance | C31: 0 | D31: 0 | E31: =C31-D31 | F31: =IFERROR(D31/C31,0)
A32: HEALTH & WELLNESS | B32: Gym | C32: 0 | D32: 0 | E32: =C32-D32 | F32: =IFERROR(D32/C32,0)
A33: HEALTH & WELLNESS | B33: Pharmacy | C33: 0 | D33: 0 | E33: =C33-D33 | F33: =IFERROR(D33/C33,0)
A34: HEALTH & WELLNESS | B34: Doctor | C34: 0 | D34: 0 | E34: =C34-D34 | F34: =IFERROR(D34/C34,0)
A35: HEALTH & WELLNESS | B35: Dental | C35: 0 | D35: 0 | E35: =C35-D35 | F35: =IFERROR(D35/C35,0)
A36: Subtotal — HEALTH & WELLNESS | C36: =SUM(C31:C35) | D36: =SUM(D31:D35) | E36: =C36-D36 | F36: =IFERROR(D36/C36,0)
A37: LIFESTYLE
A38: LIFESTYLE | B38: Streaming Services | C38: 0 | D38: 0 | E38: =C38-D38 | F38: =IFERROR(D38/C38,0)
A39: LIFESTYLE | B39: Entertainment | C39: 0 | D39: 0 | E39: =C39-D39 | F39: =IFERROR(D39/C39,0)
A40: LIFESTYLE | B40: Hobbies | C40: 0 | D40: 0 | E40: =C40-D40 | F40: =IFERROR(D40/C40,0)
...

Sheet Oct
A1: OCTOBER · MONTHLY BUDGET
A2: Track your income and expenses for October
A3: CATEGORY | B3: SUBCATEGORY | C3: BUDGETED | D3: ACTUAL | E3: DIFFERENCE | F3: % USED | G3: NOTES
A4: INCOME
A5: INCOME | B5: Primary Income | C5: 0 | D5: 0 | E5: =C5-D5 | F5: =IFERROR(D5/C5,0)
A6: INCOME | B6: Side Income | C6: 0 | D6: 0 | E6: =C6-D6 | F6: =IFERROR(D6/C6,0)
A7: INCOME | B7: Other Income | C7: 0 | D7: 0 | E7: =C7-D7 | F7: =IFERROR(D7/C7,0)
A8: TOTAL INCOME | C8: =SUM(C5:C7) | D8: =SUM(D5:D7) | E8: =C8-D8 | F8: =IFERROR(D8/C8,0)
A9: HOUSING
A10: HOUSING | B10: Rent/Mortgage | C10: 0 | D10: 0 | E10: =C10-D10 | F10: =IFERROR(D10/C10,0)
A11: HOUSING | B11: Utilities | C11: 0 | D11: 0 | E11: =C11-D11 | F11: =IFERROR(D11/C11,0)
A12: HOUSING | B12: Electricity | C12: 0 | D12: 0 | E12: =C12-D12 | F12: =IFERROR(D12/C12,0)
A13: HOUSING | B13: Internet | C13: 0 | D13: 0 | E13: =C13-D13 | F13: =IFERROR(D13/C13,0)
A14: HOUSING | B14: Home Insurance | C14: 0 | D14: 0 | E14: =C14-D14 | F14: =IFERROR(D14/C14,0)
A15: Subtotal — HOUSING | C15: =SUM(C10:C14) | D15: =SUM(D10:D14) | E15: =C15-D15 | F15: =IFERROR(D15/C15,0)
A16: TRANSPORT
A17: TRANSPORT | B17: Car Payment | C17: 0 | D17: 0 | E17: =C17-D17 | F17: =IFERROR(D17/C17,0)
A18: TRANSPORT | B18: Fuel | C18: 0 | D18: 0 | E18: =C18-D18 | F18: =IFERROR(D18/C18,0)
A19: TRANSPORT | B19: Car Insurance | C19: 0 | D19: 0 | E19: =C19-D19 | F19: =IFERROR(D19/C19,0)
A20: TRANSPORT | B20: Parking | C20: 0 | D20: 0 | E20: =C20-D20 | F20: =IFERROR(D20/C20,0)
A21: TRANSPORT | B21: Public Transport | C21: 0 | D21: 0 | E21: =C21-D21 | F21: =IFERROR(D21/C21,0)
A22: Subtotal — TRANSPORT | C22: =SUM(C17:C21) | D22: =SUM(D17:D21) | E22: =C22-D22 | F22: =IFERROR(D22/C22,0)
A23: FOOD & DINING
A24: FOOD & DINING | B24: Groceries | C24: 0 | D24: 0 | E24: =C24-D24 | F24: =IFERROR(D24/C24,0)
A25: FOOD & DINING | B25: Restaurants | C25: 0 | D25: 0 | E25: =C25-D25 | F25: =IFERROR(D25/C25,0)
A26: FOOD & DINING | B26: Coffee | C26: 0 | D26: 0 | E26: =C26-D26 | F26: =IFERROR(D26/C26,0)
A27: FOOD & DINING | B27: Food Delivery | C27: 0 | D27: 0 | E27: =C27-D27 | F27: =IFERROR(D27/C27,0)
A28: FOOD & DINING | B28: Work Lunch | C28: 0 | D28: 0 | E28: =C28-D28 | F28: =IFERROR(D28/C28,0)
A29: Subtotal — FOOD & DINING | C29: =SUM(C24:C28) | D29: =SUM(D24:D28) | E29: =C29-D29 | F29: =IFERROR(D29/C29,0)
A30: HEALTH & WELLNESS
A31: HEALTH & WELLNESS | B31: Health Insurance | C31: 0 | D31: 0 | E31: =C31-D31 | F31: =IFERROR(D31/C31,0)
A32: HEALTH & WELLNESS | B32: Gym | C32: 0 | D32: 0 | E32: =C32-D32 | F32: =IFERROR(D32/C32,0)
A33: HEALTH & WELLNESS | B33: Pharmacy | C33: 0 | D33: 0 | E33: =C33-D33 | F33: =IFERROR(D33/C33,0)
A34: HEALTH & WELLNESS | B34: Doctor | C34: 0 | D34: 0 | E34: =C34-D34 | F34: =IFERROR(D34/C34,0)
A35: HEALTH & WELLNESS | B35: Dental | C35: 0 | D35: 0 | E35: =C35-D35 | F35: =IFERROR(D35/C35,0)
A36: Subtotal — HEALTH & WELLNESS | C36: =SUM(C31:C35) | D36: =SUM(D31:D35) | E36: =C36-D36 | F36: =IFERROR(D36/C36,0)
A37: LIFESTYLE
A38: LIFESTYLE | B38: Streaming Services | C38: 0 | D38: 0 | E38: =C38-D38 | F38: =IFERROR(D38/C38,0)
A39: LIFESTYLE | B39: Entertainment | C39: 0 | D39: 0 | E39: =C39-D39 | F39: =IFERROR(D39/C39,0)
A40: LIFESTYLE | B40: Hobbies | C40: 0 | D40: 0 | E40: =C40-D40 | F40: =IFERROR(D40/C40,0)
...

Sheet Nov
A1: NOVEMBER · MONTHLY BUDGET
A2: Track your income and expenses for November
A3: CATEGORY | B3: SUBCATEGORY | C3: BUDGETED | D3: ACTUAL | E3: DIFFERENCE | F3: % USED | G3: NOTES
A4: INCOME
A5: INCOME | B5: Primary Income | C5: 0 | D5: 0 | E5: =C5-D5 | F5: =IFERROR(D5/C5,0)
A6: INCOME | B6: Side Income | C6: 0 | D6: 0 | E6: =C6-D6 | F6: =IFERROR(D6/C6,0)
A7: INCOME | B7: Other Income | C7: 0 | D7: 0 | E7: =C7-D7 | F7: =IFERROR(D7/C7,0)
A8: TOTAL INCOME | C8: =SUM(C5:C7) | D8: =SUM(D5:D7) | E8: =C8-D8 | F8: =IFERROR(D8/C8,0)
A9: HOUSING
A10: HOUSING | B10: Rent/Mortgage | C10: 0 | D10: 0 | E10: =C10-D10 | F10: =IFERROR(D10/C10,0)
A11: HOUSING | B11: Utilities | C11: 0 | D11: 0 | E11: =C11-D11 | F11: =IFERROR(D11/C11,0)
A12: HOUSING | B12: Electricity | C12: 0 | D12: 0 | E12: =C12-D12 | F12: =IFERROR(D12/C12,0)
A13: HOUSING | B13: Internet | C13: 0 | D13: 0 | E13: =C13-D13 | F13: =IFERROR(D13/C13,0)
A14: HOUSING | B14: Home Insurance | C14: 0 | D14: 0 | E14: =C14-D14 | F14: =IFERROR(D14/C14,0)
A15: Subtotal — HOUSING | C15: =SUM(C10:C14) | D15: =SUM(D10:D14) | E15: =C15-D15 | F15: =IFERROR(D15/C15,0)
A16: TRANSPORT
A17: TRANSPORT | B17: Car Payment | C17: 0 | D17: 0 | E17: =C17-D17 | F17: =IFERROR(D17/C17,0)
A18: TRANSPORT | B18: Fuel | C18: 0 | D18: 0 | E18: =C18-D18 | F18: =IFERROR(D18/C18,0)
A19: TRANSPORT | B19: Car Insurance | C19: 0 | D19: 0 | E19: =C19-D19 | F19: =IFERROR(D19/C19,0)
A20: TRANSPORT | B20: Parking | C20: 0 | D20: 0 | E20: =C20-D20 | F20: =IFERROR(D20/C20,0)
A21: TRANSPORT | B21: Public Transport | C21: 0 | D21: 0 | E21: =C21-D21 | F21: =IFERROR(D21/C21,0)
A22: Subtotal — TRANSPORT | C22: =SUM(C17:C21) | D22: =SUM(D17:D21) | E22: =C22-D22 | F22: =IFERROR(D22/C22,0)
A23: FOOD & DINING
A24: FOOD & DINING | B24: Groceries | C24: 0 | D24: 0 | E24: =C24-D24 | F24: =IFERROR(D24/C24,0)
A25: FOOD & DINING | B25: Restaurants | C25: 0 | D25: 0 | E25: =C25-D25 | F25: =IFERROR(D25/C25,0)
A26: FOOD & DINING | B26: Coffee | C26: 0 | D26: 0 | E26: =C26-D26 | F26: =IFERROR(D26/C26,0)
A27: FOOD & DINING | B27: Food Delivery | C27: 0 | D27: 0 | E27: =C27-D27 | F27: =IFERROR(D27/C27,0)
A28: FOOD & DINING | B28: Work Lunch | C28: 0 | D28: 0 | E28: =C28-D28 | F28: =IFERROR(D28/C28,0)
A29: Subtotal — FOOD & DINING | C29: =SUM(C24:C28) | D29: =SUM(D24:D28) | E29: =C29-D29 | F29: =IFERROR(D29/C29,0)
A30: HEALTH & WELLNESS
A31: HEALTH & WELLNESS | B31: Health Insurance | C31: 0 | D31: 0 | E31: =C31-D31 | F31: =IFERROR(D31/C31,0)
A32: HEALTH & WELLNESS | B32: Gym | C32: 0 | D32: 0 | E32: =C32-D32 | F32: =IFERROR(D32/C32,0)
A33: HEALTH & WELLNESS | B33: Pharmacy | C33: 0 | D33: 0 | E33: =C33-D33 | F33: =IFERROR(D33/C33,0)
A34: HEALTH & WELLNESS | B34: Doctor | C34: 0 | D34: 0 | E34: =C34-D34 | F34: =IFERROR(D34/C34,0)
A35: HEALTH & WELLNESS | B35: Dental | C35: 0 | D35: 0 | E35: =C35-D35 | F35: =IFERROR(D35/C35,0)
A36: Subtotal — HEALTH & WELLNESS | C36: =SUM(C31:C35) | D36: =SUM(D31:D35) | E36: =C36-D36 | F36: =IFERROR(D36/C36,0)
A37: LIFESTYLE
A38: LIFESTYLE | B38: Streaming Services | C38: 0 | D38: 0 | E38: =C38-D38 | F38: =IFERROR(D38/C38,0)
A39: LIFESTYLE | B39: Entertainment | C39: 0 | D39: 0 | E39: =C39-D39 | F39: =IFERROR(D39/C39,0)
A40: LIFESTYLE | B40: Hobbies | C40: 0 | D40: 0 | E40: =C40-D40 | F40: =IFERROR(D40/C40,0)
...

Sheet Dec
A1: DECEMBER · MONTHLY BUDGET
A2: Track your income and expenses for December
A3: CATEGORY | B3: SUBCATEGORY | C3: BUDGETED | D3: ACTUAL | E3: DIFFERENCE | F3: % USED | G3: NOTES
A4: INCOME
A5: INCOME | B5: Primary Income | C5: 0 | D5: 0 | E5: =C5-D5 | F5: =IFERROR(D5/C5,0)
A6: INCOME | B6: Side Income | C6: 0 | D6: 0 | E6: =C6-D6 | F6: =IFERROR(D6/C6,0)
A7: INCOME | B7: Other Income | C7: 0 | D7: 0 | E7: =C7-D7 | F7: =IFERROR(D7/C7,0)
A8: TOTAL INCOME | C8: =SUM(C5:C7) | D8: =SUM(D5:D7) | E8: =C8-D8 | F8: =IFERROR(D8/C8,0)
A9: HOUSING
A10: HOUSING | B10: Rent/Mortgage | C10: 0 | D10: 0 | E10: =C10-D10 | F10: =IFERROR(D10/C10,0)
A11: HOUSING | B11: Utilities | C11: 0 | D11: 0 | E11: =C11-D11 | F11: =IFERROR(D11/C11,0)
A12: HOUSING | B12: Electricity | C12: 0 | D12: 0 | E12: =C12-D12 | F12: =IFERROR(D12/C12,0)
A13: HOUSING | B13: Internet | C13: 0 | D13: 0 | E13: =C13-D13 | F13: =IFERROR(D13/C13,0)
A14: HOUSING | B14: Home Insurance | C14: 0 | D14: 0 | E14: =C14-D14 | F14: =IFERROR(D14/C14,0)
A15: Subtotal — HOUSING | C15: =SUM(C10:C14) | D15: =SUM(D10:D14) | E15: =C15-D15 | F15: =IFERROR(D15/C15,0)
A16: TRANSPORT
A17: TRANSPORT | B17: Car Payment | C17: 0 | D17: 0 | E17: =C17-D17 | F17: =IFERROR(D17/C17,0)
A18: TRANSPORT | B18: Fuel | C18: 0 | D18: 0 | E18: =C18-D18 | F18: =IFERROR(D18/C18,0)
A19: TRANSPORT | B19: Car Insurance | C19: 0 | D19: 0 | E19: =C19-D19 | F19: =IFERROR(D19/C19,0)
A20: TRANSPORT | B20: Parking | C20: 0 | D20: 0 | E20: =C20-D20 | F20: =IFERROR(D20/C20,0)
A21: TRANSPORT | B21: Public Transport | C21: 0 | D21: 0 | E21: =C21-D21 | F21: =IFERROR(D21/C21,0)
A22: Subtotal — TRANSPORT | C22: =SUM(C17:C21) | D22: =SUM(D17:D21) | E22: =C22-D22 | F22: =IFERROR(D22/C22,0)
A23: FOOD & DINING
A24: FOOD & DINING | B24: Groceries | C24: 0 | D24: 0 | E24: =C24-D24 | F24: =IFERROR(D24/C24,0)
A25: FOOD & DINING | B25: Restaurants | C25: 0 | D25: 0 | E25: =C25-D25 | F25: =IFERROR(D25/C25,0)
A26: FOOD & DINING | B26: Coffee | C26: 0 | D26: 0 | E26: =C26-D26 | F26: =IFERROR(D26/C26,0)
A27: FOOD & DINING | B27: Food Delivery | C27: 0 | D27: 0 | E27: =C27-D27 | F27: =IFERROR(D27/C27,0)
A28: FOOD & DINING | B28: Work Lunch | C28: 0 | D28: 0 | E28: =C28-D28 | F28: =IFERROR(D28/C28,0)
A29: Subtotal — FOOD & DINING | C29: =SUM(C24:C28) | D29: =SUM(D24:D28) | E29: =C29-D29 | F29: =IFERROR(D29/C29,0)
A30: HEALTH & WELLNESS
A31: HEALTH & WELLNESS | B31: Health Insurance | C31: 0 | D31: 0 | E31: =C31-D31 | F31: =IFERROR(D31/C31,0)
A32: HEALTH & WELLNESS | B32: Gym | C32: 0 | D32: 0 | E32: =C32-D32 | F32: =IFERROR(D32/C32,0)
A33: HEALTH & WELLNESS | B33: Pharmacy | C33: 0 | D33: 0 | E33: =C33-D33 | F33: =IFERROR(D33/C33,0)
A34: HEALTH & WELLNESS | B34: Doctor | C34: 0 | D34: 0 | E34: =C34-D34 | F34: =IFERROR(D34/C34,0)
A35: HEALTH & WELLNESS | B35: Dental | C35: 0 | D35: 0 | E35: =C35-D35 | F35: =IFERROR(D35/C35,0)
A36: Subtotal — HEALTH & WELLNESS | C36: =SUM(C31:C35) | D36: =SUM(D31:D35) | E36: =C36-D36 | F36: =IFERROR(D36/C36,0)
A37: LIFESTYLE
A38: LIFESTYLE | B38: Streaming Services | C38: 0 | D38: 0 | E38: =C38-D38 | F38: =IFERROR(D38/C38,0)
A39: LIFESTYLE | B39: Entertainment | C39: 0 | D39: 0 | E39: =C39-D39 | F39: =IFERROR(D39/C39,0)
A40: LIFESTYLE | B40: Hobbies | C40: 0 | D40: 0 | E40: =C40-D40 | F40: =IFERROR(D40/C40,0)
...

Sheet Annual Overview
A1: ANNUAL OVERVIEW · 2026
A2: All figures linked automatically from monthly sheets
A3: LINE ITEM | B3: Jan | C3: Feb | D3: Mar | E3: Apr | F3: May | G3: Jun | H3: Jul | I3: Aug | J3: Sep | K3: Oct | L3: Nov | M3: Dec | N3: ANNUAL TOTAL | O3: ANNUAL BUDGET | P3: VARIANCE
A4: INCOME | B4: =Jan!D8 | C4: =Feb!D8 | D4: =Mar!D8 | E4: =Apr!D8 | F4: =May!D8 | G4: =Jun!D8 | H4: =Jul!D8 | I4: =Aug!D8 | J4: =Sep!D8 | K4: =Oct!D8 | L4: =Nov!D8 | M4: =Dec!D8 | N4: =SUM(B4:M4) | O4: 0 | P4: =IFERROR(N4-O4,0)
A5: — Housing | B5: =Jan!D15 | C5: =Feb!D15 | D5: =Mar!D15 | E5: =Apr!D15 | F5: =May!D15 | G5: =Jun!D15 | H5: =Jul!D15 | I5: =Aug!D15 | J5: =Sep!D15 | K5: =Oct!D15 | L5: =Nov!D15 | M5: =Dec!D15 | N5: =SUM(B5:M5) | O5: 0 | P5: =IFERROR(N5-O5,0)
A6: — Transport | B6: =Jan!D22 | C6: =Feb!D22 | D6: =Mar!D22 | E6: =Apr!D22 | F6: =May!D22 | G6: =Jun!D22 | H6: =Jul!D22 | I6: =Aug!D22 | J6: =Sep!D22 | K6: =Oct!D22 | L6: =Nov!D22 | M6: =Dec!D22 | N6: =SUM(B6:M6) | O6: 0 | P6: =IFERROR(N6-O6,0)
A7: — Food & Dining | B7: =Jan!D29 | C7: =Feb!D29 | D7: =Mar!D29 | E7: =Apr!D29 | F7: =May!D29 | G7: =Jun!D29 | H7: =Jul!D29 | I7: =Aug!D29 | J7: =Sep!D29 | K7: =Oct!D29 | L7: =Nov!D29 | M7: =Dec!D29 | N7: =SUM(B7:M7) | O7: 0 | P7: =IFERROR(N7-O7,0)
A8: — Health & Wellness | B8: =Jan!D36 | C8: =Feb!D36 | D8: =Mar!D36 | E8: =Apr!D36 | F8: =May!D36 | G8: =Jun!D36 | H8: =Jul!D36 | I8: =Aug!D36 | J8: =Sep!D36 | K8: =Oct!D36 | L8: =Nov!D36 | M8: =Dec!D36 | N8: =SUM(B8:M8) | O8: 0 | P8: =IFERROR(N8-O8,0)
A9: — Lifestyle | B9: =Jan!D43 | C9: =Feb!D43 | D9: =Mar!D43 | E9: =Apr!D43 | F9: =May!D43 | G9: =Jun!D43 | H9: =Jul!D43 | I9: =Aug!D43 | J9: =Sep!D43 | K9: =Oct!D43 | L9: =Nov!D43 | M9: =Dec!D43 | N9: =SUM(B9:M9) | O9: 0 | P9: =IFERROR(N9-O9,0)
A10: — Personal | B10: =Jan!D50 | C10: =Feb!D50 | D10: =Mar!D50 | E10: =Apr!D50 | F10: =May!D50 | G10: =Jun!D50 | H10: =Jul!D50 | I10: =Aug!D50 | J10: =Sep!D50 | K10: =Oct!D50 | L10: =Nov!D50 | M10: =Dec!D50 | N10: =SUM(B10:M10) | O10: 0 | P10: =IFERROR(N10-O10,0)
A11: — Savings & Investments | B11: =Jan!D57 | C11: =Feb!D57 | D11: =Mar!D57 | E11: =Apr!D57 | F11: =May!D57 | G11: =Jun!D57 | H11: =Jul!D57 | I11: =Aug!D57 | J11: =Sep!D57 | K11: =Oct!D57 | L11: =Nov!D57 | M11: =Dec!D57 | N11: =SUM(B11:M11) | O11: 0 | P11: =IFERROR(N11-O11,0)
A12: — Debt Payments | B12: =Jan!D64 | C12: =Feb!D64 | D12: =Mar!D64 | E12: =Apr!D64 | F12: =May!D64 | G12: =Jun!D64 | H12: =Jul!D64 | I12: =Aug!D64 | J12: =Sep!D64 | K12: =Oct!D64 | L12: =Nov!D64 | M12: =Dec!D64 | N12: =SUM(B12:M12) | O12: 0 | P12: =IFERROR(N12-O12,0)
A13: GRAND TOTAL EXPENSES | B13: =Jan!D65 | C13: =Feb!D65 | D13: =Mar!D65 | E13: =Apr!D65 | F13: =May!D65 | G13: =Jun!D65 | H13: =Jul!D65 | I13: =Aug!D65 | J13: =Sep!D65 | K13: =Oct!D65 | L13: =Nov!D65 | M13: =Dec!D65 | N13: =SUM(B13:M13) | O13: 0 | P13: =IFERROR(N13-O13,0)
A14: NET CASH FLOW | B14: =Jan!D66 | C14: =Feb!D66 | D14: =Mar!D66 | E14: =Apr!D66 | F14: =May!D66 | G14: =Jun!D66 | H14: =Jul!D66 | I14: =Aug!D66 | J14: =Sep!D66 | K14: =Oct!D66 | L14: =Nov!D66 | M14: =Dec!D66 | N14: =SUM(B14:M14) | O14: 0 | P14: =IFERROR(N14-O14,0)
A16: KEY METRICS
A17: Best Month (lowest spend) | D17: =IFERROR(INDEX(B3:M3,MATCH(MIN(B13:M13),B13:M13,0)),"-")
A18: Worst Month (highest spend) | D18: =IFERROR(INDEX(B3:M3,MATCH(MAX(B13:M13),B13:M13,0)),"-")
A19: Annual Savings Rate | D19: =IFERROR((N4-N13)/N4,0)
A20: Avg Monthly Spend | D20: =IFERROR(N13/12,0)
A21: Avg Monthly Income | D21: =IFERROR(N4/12,0)

Sheet Debt Tracker
A1: DEBT PAYOFF TRACKER
A2: Avalanche = highest rate first · Snowball = lowest balance first
A3: DEBT NAME | B3: LENDER | C3: ORIGINAL BAL | D3: CURRENT BAL | E3: INTEREST % | F3: MIN PAYMENT | G3: MONTHLY PMT | H3: EST PAYOFF | I3: STATUS
A4: Credit Card 1 | C4: 0 | D4: 0 | E4: 0 | F4: 0 | G4: 0 | I4: Active
A5: Credit Card 2 | C5: 0 | D5: 0 | E5: 0 | F5: 0 | G5: 0 | I5: Active
A6: Student Loan | C6: 0 | D6: 0 | E6: 0 | F6: 0 | G6: 0 | I6: Active
A7: Car Loan | C7: 0 | D7: 0 | E7: 0 | F7: 0 | G7: 0 | I7: Active
A8: Personal Loan | C8: 0 | D8: 0 | E8: 0 | F8: 0 | G8: 0 | I8: Active
A9: Other | C9: 0 | D9: 0 | E9: 0 | F9: 0 | G9: 0 | I9: Active
A10: TOTALS | C10: =SUM(C4:C9) | D10: =SUM(D4:D9) | F10: =SUM(F4:F9) | G10: =SUM(G4:G9)
A12: DEBT SUMMARY
A13: Total Outstanding | D13: =SUM(D4:D9)
A14: Total Monthly Minimums | D14: =SUM(F4:F9)
A15: Highest Rate Debt | D15: =IFERROR(INDEX(A4:A9,MATCH(MAX(E4:E9),E4:E9,0)),"-")
A16: Debt-to-Income (monthly) | D16: =IFERROR(SUM(G4:G9)/(Dashboard!B10/12),0)

Sheet Bill Calendar
A1: BILL CALENDAR · 2026
A2: Green = paid · Gold = auto-pay · Never miss a payment
A3: BILL NAME | B3: CATEGORY | C3: AMOUNT | D3: DUE DATE | E3: FREQUENCY | F3: AUTO-PAY | G3: PAID? | H3: ANNUAL COST | I3: NOTES
A4: Hyra/Mortgage | B4: Housing | C4: 12500 | D4: 2026-01-01 | E4: Monthly | F4: No | G4: No | H4: =IFERROR(IF(E4="Monthly",C4*12,IF(E4="Quarterly",C4*4,IF(E4="Annual",C4,C4*52))),0)
A5: El | B5: Utilities | C5: 850 | D5: 2026-01-15 | E5: Monthly | F5: No | G5: No | H5: =IFERROR(IF(E5="Monthly",C5*12,IF(E5="Quarterly",C5*4,IF(E5="Annual",C5,C5*52))),0)
A6: Internet | B6: Utilities | C6: 499 | D6: 2026-01-22 | E6: Monthly | F6: Yes | G6: No | H6: =IFERROR(IF(E6="Monthly",C6*12,IF(E6="Quarterly",C6*4,IF(E6="Annual",C6,C6*52))),0)
A7: Netflix/Streaming | B7: Lifestyle | C7: 139 | D7: 2026-01-08 | E7: Monthly | F7: Yes | G7: No | H7: =IFERROR(IF(E7="Monthly",C7*12,IF(E7="Quarterly",C7*4,IF(E7="Annual",C7,C7*52))),0)
A8: Telefon | B8: Utilities | C8: 699 | D8: 2026-01-12 | E8: Monthly | F8: Yes | G8: No | H8: =IFERROR(IF(E8="Monthly",C8*12,IF(E8="Quarterly",C8*4,IF(E8="Annual",C8,C8*52))),0)
A9: Hemförsäkring | B9: Insurance | C9: 1200 | D9: 2026-01-01 | E9: Monthly | F9: Yes | G9: No | H9: =IFERROR(IF(E9="Monthly",C9*12,IF(E9="Quarterly",C9*4,IF(E9="Annual",C9,C9*52))),0)
A10: Gym | B10: Health | C10: 400 | D10: 2026-01-05 | E10: Monthly | F10: Yes | G10: No | H10: =IFERROR(IF(E10="Monthly",C10*12,IF(E10="Quarterly",C10*4,IF(E10="Annual",C10,C10*52))),0)
A11: Bilförsäkring | B11: Insurance | C11: 1100 | D11: 2026-01-20 | E11: Monthly | F11: Yes | G11: No | H11: =IFERROR(IF(E11="Monthly",C11*12,IF(E11="Quarterly",C11*4,IF(E11="Annual",C11,C11*52))),0)
A12: Spotify | B12: Lifestyle | C12: 109 | D12: 2026-01-14 | E12: Monthly | F12: Yes | G12: No | H12: =IFERROR(IF(E12="Monthly",C12*12,IF(E12="Quarterly",C12*4,IF(E12="Annual",C12,C12*52))),0)
A13: A-kassa/Facket | B13: Other | C13: 350 | D13: 2026-01-01 | E13: Monthly | F13: Yes | G13: No | H13: =IFERROR(IF(E13="Monthly",C13*12,IF(E13="Quarterly",C13*4,IF(E13="Annual",C13,C13*52))),0)
A14: MONTHLY TOTAL | C14: =SUM(C4:C13) | H14: =SUM(H4:H13)

Sheet Savings Goals
A1: SAVINGS GOALS TRACKER
A2: Set targets · Track progress · Automate contributions
A3: GOAL | B3: TARGET | C3: SAVED SO FAR | D3: MONTHLY CONTRIB | E3: TARGET DATE | F3: % COMPLETE | G3: PROGRESS | H3: PRIORITY
A4: Emergency Fund (3mo) | B4: 50000 | C4: 0 | D4: 500 | E4: 2026-12-31 | F4: =IFERROR(C4/B4,0) | G4: =REPT(CHAR(9608),ROUND(F4*10,0))&REPT(CHAR(9617),10-ROUND(F4*10,0)) | H4: High
A5: Japan Trip | B5: 25000 | C5: 0 | D5: 200 | E5: 2026-09-01 | F5: =IFERROR(C5/B5,0) | G5: =REPT(CHAR(9608),ROUND(F5*10,0))&REPT(CHAR(9617),10-ROUND(F5*10,0)) | H5: Medium
A6: Home Down Payment | B6: 250000 | C6: 0 | D6: 800 | E6: 2029-01-01 | F6: =IFERROR(C6/B6,0) | G6: =REPT(CHAR(9608),ROUND(F6*10,0))&REPT(CHAR(9617),10-ROUND(F6*10,0)) | H6: High
A7: New Car | B7: 80000 | C7: 0 | D7: 300 | E7: 2027-06-01 | F7: =IFERROR(C7/B7,0) | G7: =REPT(CHAR(9608),ROUND(F7*10,0))&REPT(CHAR(9617),10-ROUND(F7*10,0)) | H7: Medium
A8: Retirement Boost | B8: 100000 | C8: 0 | D8: 400 | E8: 2030-01-01 | F8: =IFERROR(C8/B8,0) | G8: =REPT(CHAR(9608),ROUND(F8*10,0))&REPT(CHAR(9617),10-ROUND(F8*10,0)) | H8: High
A9: Education Fund | B9: 40000 | C9: 0 | D9: 250 | E9: 2028-01-01 | F9: =IFERROR(C9/B9,0) | G9: =REPT(CHAR(9608),ROUND(F9*10,0))&REPT(CHAR(9617),10-ROUND(F9*10,0)) | H9: Low
A10: TOTALS | B10: =SUM(B4:B9) | C10: =SUM(C4:C9) | D10: =SUM(D4:D9) | F10: =IFERROR(SUM(C4:C9)/SUM(B4:B9),0)

Sheet Spending Tracker
A1: DAYS WITHOUT SPENDING · 2026
A2: Mark each no-spend day with X · Watch your streak grow
A3: MONTH | B3: 1 | C3: 2 | D3: 3 | E3: 4 | F3: 5 | G3: 6 | H3: 7 | I3: 8 | J3: 9 | K3: 10 | L3: 11 | M3: 12 | N3: 13 | O3: 14 | P3: 15 | Q3: 16 | R3: 17 | S3: 18 | T3: 19 | U3: 20 | V3: 21 | W3: 22 | X3: 23 | Y3: 24 | Z3: 25 | AA3: 26 | AB3: 27 | AC3: 28 | AD3: 29 | AE3: 30 | AF3: 31 | AG3: NO-SPEND DAYS
A4: January | AG4: =COUNTIF(B4:AF4,"X")
A5: February | AG5: =COUNTIF(B5:AF5,"X")
A6: March | AG6: =COUNTIF(B6:AF6,"X")
A7: April | AG7: =COUNTIF(B7:AF7,"X")
A8: May | AG8: =COUNTIF(B8:AF8,"X")
A9: June | AG9: =COUNTIF(B9:AF9,"X")
A10: July | AG10: =COUNTIF(B10:AF10,"X")
A11: August | AG11: =COUNTIF(B11:AF11,"X")
A12: September | AG12: =COUNTIF(B12:AF12,"X")
A13: October | AG13: =COUNTIF(B13:AF13,"X")
A14: November | AG14: =COUNTIF(B14:AF14,"X")
A15: December | AG15: =COUNTIF(B15:AF15,"X")
A16: ANNUAL TOTAL NO-SPEND DAYS | AG16: =AG4+AG5+AG6+AG7+AG8+AG9+AG10+AG11+AG12+AG13+AG14+AG15
